Workbook

Sheet ASSAY RAW DATA
F1: R&R TEST RESULT TABLE (ASSAY) | J1: DATE | K1: 20120726
D2: PRODUCT: | E2: H2O2(ASSAY) | G2: TEST DATE | I2: 20110710~20120720
B4: 技師\次數 | D4: A1 | E4: A2 | F4: A3 | G4: A4 | H4: A5 | I4: B1 | J4: B2 | K4: B3 | L4: B4 | M4: B5
B5: 文美
B6: 文美
B8: 妍希
B9: 妍希
B19: 3g upw+h2o2定量至100g
B20: ↓
B21: 取1g+upw定量至250ml
B22: ↓
B23: 取sample 25g滴定

Sheet H2O2-ASSAY
F1: ='ASSAY RAW DATA'!F1 -> R&R TEST RESULT TABLE (ASSAY)
K2: NDC | L2: =1.41*(D47/D63) -> #DIV/0!
F3: DATE | G3: ='ASSAY RAW DATA'!K1 -> 20120726
F4: PRODUCT | G4: ='ASSAY RAW DATA'!E2 -> H2O2(ASSAY)
D5: 1 | E5: 2 | F5: 3 | G5: 4 | H5: 5 | I5: 6 | J5: 7 | K5: 8 | L5: 9 | M5: 10 | O5: AVE
B6: ='ASSAY RAW DATA'!B5 -> 文美 | D6: ='ASSAY RAW DATA'!D5 -> 0 | E6: ='ASSAY RAW DATA'!E5 -> 0 | F6: ='ASSAY RAW DATA'!F5 -> 0 | G6: ='ASSAY RAW DATA'!G5 -> 0 | H6: ='ASSAY RAW DATA'!H5 -> 0 | I6: ='ASSAY RAW DATA'!I5 -> 0 | J6: ='ASSAY RAW DATA'!J5 -> 0 | K6: ='ASSAY RAW DATA'!K5 -> 0 | ... M6: ='ASSAY RAW DATA'!M5 -> 0 | O6: =SUM(D6:M6)/10 -> 0
B7: ='ASSAY RAW DATA'!B6 -> 文美 | D7: ='ASSAY RAW DATA'!D6 -> 0 | E7: ='ASSAY RAW DATA'!E6 -> 0 | F7: ='ASSAY RAW DATA'!F6 -> 0 | G7: ='ASSAY RAW DATA'!G6 -> 0 | H7: ='ASSAY RAW DATA'!H6 -> 0 | I7: ='ASSAY RAW DATA'!I6 -> 0 | J7: ='ASSAY RAW DATA'!J6 -> 0 | K7: ='ASSAY RAW DATA'!K6 -> 0 | ... M7: ='ASSAY RAW DATA'!M6 -> 0 | O7: =SUM(D7:M7)/10 -> 0
B8: AVE | D8: =AVERAGE(D6:D7) -> 0 | E8: =AVERAGE(E6:E7) -> 0 | F8: =AVERAGE(F6:F7) -> 0 | G8: =AVERAGE(G6:G7) -> 0 | H8: =AVERAGE(H6:H7) -> 0 | I8: =AVERAGE(I6:I7) -> 0 | J8: =AVERAGE(J6:J7) -> 0 | K8: =AVERAGE(K6:K7) -> 0 | ... M8: =AVERAGE(M6:M7) -> 0 | N8: Xa | O8: =AVERAGE(O6:O7) -> 0
B9: RANGE | D9: =MAX(D6:D7)-MIN(D6:D7) -> 0 | E9: =MAX(E6:E7)-MIN(E6:E7) -> 0 | F9: =MAX(F6:F7)-MIN(F6:F7) -> 0 | G9: =MAX(G6:G7)-MIN(G6:G7) -> 0 | H9: =MAX(H6:H7)-MIN(H6:H7) -> 0 | I9: =MAX(I6:I7)-MIN(I6:I7) -> 0 | J9: =MAX(J6:J7)-MIN(J6:J7) -> 0 | K9: =MAX(K6:K7)-MIN(K6:K7) -> 0 | ... M9: =MAX(M6:M7)-MIN(M6:M7) -> 0 | N9: Ra | O9: =SUM(D9:M9)/10 -> 0
B10: ='ASSAY RAW DATA'!B8 -> 妍希 | D10: ='ASSAY RAW DATA'!D8 -> 0 | E10: ='ASSAY RAW DATA'!E8 -> 0 | F10: ='ASSAY RAW DATA'!F8 -> 0 | G10: ='ASSAY RAW DATA'!G8 -> 0 | H10: ='ASSAY RAW DATA'!H8 -> 0 | I10: ='ASSAY RAW DATA'!I8 -> 0 | J10: ='ASSAY RAW DATA'!J8 -> 0 | K10: ='ASSAY RAW DATA'!K8 -> 0 | ... M10: ='ASSAY RAW DATA'!M8 -> 0 | O10: =SUM(D10:M10)/10 -> 0
B11: ='ASSAY RAW DATA'!B9 -> 妍希 | D11: ='ASSAY RAW DATA'!D9 -> 0 | E11: ='ASSAY RAW DATA'!E9 -> 0 | F11: ='ASSAY RAW DATA'!F9 -> 0 | G11: ='ASSAY RAW DATA'!G9 -> 0 | H11: ='ASSAY RAW DATA'!H9 -> 0 | I11: ='ASSAY RAW DATA'!I9 -> 0 | J11: ='ASSAY RAW DATA'!J9 -> 0 | K11: ='ASSAY RAW DATA'!K9 -> 0 | ... M11: ='ASSAY RAW DATA'!M9 -> 0 | O11: =SUM(D11:M11)/10 -> 0
B12: AVE | D12: =AVERAGE(D10:D11) -> 0 | E12: =AVERAGE(E10:E11) -> 0 | F12: =AVERAGE(F10:F11) -> 0 | G12: =AVERAGE(G10:G11) -> 0 | H12: =AVERAGE(H10:H11) -> 0 | I12: =AVERAGE(I10:I11) -> 0 | J12: =AVERAGE(J10:J11) -> 0 | K12: =AVERAGE(K10:K11) -> 0 | ... M12: =AVERAGE(M10:M11) -> 0 | N12: Xb | O12: =SUM(D12:M12)/10 -> 0
B13: RANGE | D13: =MAX(D10:D11)-MIN(D10:D11) -> 0 | E13: =MAX(E10:E11)-MIN(E10:E11) -> 0 | F13: =MAX(F10:F11)-MIN(F10:F11) -> 0 | G13: =MAX(G10:G11)-MIN(G10:G11) -> 0 | H13: =MAX(H10:H11)-MIN(H10:H11) -> 0 | I13: =MAX(I10:I11)-MIN(I10:I11) -> 0 | J13: =MAX(J10:J11)-MIN(J10:J11) -> 0 | K13: =MAX(K10:K11)-MIN(K10:K11) -> 0 | ... M13: =MAX(M10:M11)-MIN(M10:M11) -> 0 | N13: Rb | O13: =SUM(D13:M13)/10 -> 0
B14: PART | N14: X | O14: =(O12+O8)/2 -> 0
B15: AVE | C15: Xp | D15: =(D12+D8)/2 -> 0 | E15: =(E12+E8)/2 -> 0 | F15: =(F12+F8)/2 -> 0 | G15: =(G12+G8)/2 -> 0 | H15: =(H12+H8)/2 -> 0 | I15: =(I12+I8)/2 -> 0 | J15: =(J12+J8)/2 -> 0 | K15: =(K12+K8)/2 -> 0 | ... M15: =(M12+M8)/2 -> 0 | N15: Rp | O15: =MAX(A15:M15)-MIN(A15:M15) -> 0
B16: R=(Ra+Rb)/2 | N16: R | O16: =(O13+O9)/2 -> 0
B17: Max X-MaxB=X diff | N17: X diff | O17: =MAX(O8,O12)-MIN(O8,O12) -> 0
B19: R8D4=UCLR
B20: R8D4=LCLR
B22: Gage Repeatability and Reproducibility Report
E23: =G4 -> H2O2(ASSAY) | I23: Gage Nane | J23: ASSAY R&R | K23: Date: | L23: ='ASSAY RAW DATA'!I2 -> 20110710~20120720
B24: Part No.and Name | I24: Gage No | K24: performed by
B25: Characteristics: | I25: Gage Type: | J25: METAL
B26: Specification:
E27: R= | F27: =O16 -> 0 | G27: x diff= | H27: =O17 -> 0 | I27: Rp= | J27: =O15 -> 0
B28: From date sheet: | I28: %Total Variation(TV)
E29: n= | F29: 2 | G29: test= | H29: 10
B30: Measurement Unit Analysis
B31: Repeatability-Equipment Variation(EV) | D31: EV = | E31: R × K1 | G31: Trials | H31: K1 | I31: %EV=100(EV/TV)
D32: =F27 -> 0 | E32: * | F32: =H32 -> 4.56 | G32: 2 | H32: 4.56 | I32: =100*(D33/D51) -> #DIV/0! | J32: %
B33: = | D33: =D32*F32 -> 0 | G33: 3 | H33: 3.05
B34: 重複性-設備變異
B35: Reproducibity-Appraiser Variation(AV) | D35: AV= | E35: √【（Xdiff X K2）2-（EV2/nr）】 | I35: %AV=100(AV/TV)
I36: =100*(E37/D51) -> #DIV/0! | J36: %
D37: = | E37: =D59 -> 0
F38: Appraisers | G38: 2 | H38: 3 | I38: n=number of parts
F39: k2 | G39: 0.7071 | H39: 0.5231 | I39: r=number of trials
B40: 再現性-評價者變異
B41: Repeatability& Reproducibility(R&R) | D41: R&R= | E41: √(EV2+AV2 | I41: %R&R=100(R&R/TV)
D42: = | I42: =100*(E43/D51) -> #DIV/0! | J42: %
...

Sheet Sheet1
B1: 附件2
D2: R&R 測試報告表
C4: 測試日期 | D4: 2016.01
C5: 測試項目 | D5: IPA-Assay
D6: R&R | F6: 判定 | H6: NDC
C7: Assay | D7: ='H2O2-ASSAY'!I42 -> #DIV/0! | F7: - | H7: ='H2O2-ASSAY'!L2 -> #DIV/0!
B8: Metal | C8: Na
C9: Mg
C10: Al
C11: K
C12: Ca
C13: Cr
C14: Mn
C15: Fe
C16: Ni
C17: Co
C18: Cu
C19: Zn
C20: Pb
C21: Particle 0.5um | D21: - | F21: - | H21: -
C22: Particle 0.2um | D22: - | F22: - | H22: -
C24: 判定基準:
C25: <10%= 良好
C26: 10%~30%=中等
C27: >30%=不合格
C28: 值須>5以上,當NDC數據≧5時,量具研究才是有效的結果.
C29: 分析高專(主任) | E29: 分析課 | G29: 品管課 | I29: 物流課 | K29: 部門長
I31: (TLEQA920010102A4)
