Workbook

Sheet POUND-TYS
A1: 磅單序號B | B1: 出荷日期 | C1: 客戶名稱 | D1: 化學品名 | E1: LORRY NO | F1: LOT NO | G1: 淨重A | H1: 淨重B | I1: 牌照號碼
A2: T3720 | B2: 43687 | C2: HEN-I | D2: H2SO4-96% | E2: W59 | G2: 90 | H2: 90 | I2: HBB7392
A3: T1261 | B3: 43700 | C3: HEN-I | D3: H2SO4-96% | E3: 026 | G3: 50 | H3: 50 | I3: HBB7392
A4: 2429 | B4: 43706 | C4: E-KAY | D4: H2SO4-96% | E4: 02H | F4: TS69H28 | G4: 20240 | H4: 160 | I4: 93YZ
A5: 2398 | B5: 43709 | C5: HEN-I | D5: H2SO4 | E5: 006 | G5: 70 | H5: 20430 | I5: 43F2
A6: T2361 | B6: 43709 | C6: HEN-I | D6: H2SO4-96% | E6: 016 | G6: 20 | H6: 20 | I6: 70X2
A7: 2401 | B7: 43709 | C7: UMC12AP5 | D7: HF | E7: 602 | F7: TFA9H29 | G7: 6640 | H7: 120 | I7: 45F2
A8: 2388 | B8: 43709 | C8: FDAC | D8: HF | E8: 603 | G8: 10 | H8: 6470 | I8: 63XY
A9: T2353 | B9: 43709 | C9: FDAC | D9: HF | E9: 062 | G9: 70 | H9: 70 | I9: 57X3
A10: 2396 | B10: 43709 | C10: UMC8C | D10: H2O2 | E10: 610 | F10: TO19H27 | G10: 7110 | H10: 70 | I10: 49XX
A11: 2367 | B11: 43709 | C11: TSMC14P1 | D11: H2SO4-96% | E11: 607 | F11: TS69H27 | G11: 10940 | H11: 150 | I11: 48F2
A12: 2376 | B12: 43709 | C12: MMT | D12: H2SO4-96% | E12: 611 | F12: TS69H30 | G12: 10190 | H12: 100 | I12: 57XX
A13: T2333 | B13: 43709 | C13: HEN-I | D13: H2SO4 | E13: 006 | G13: 70 | H13: 70 | I13: 43F2
A14: T11909011 | B14: 43709 | C14: HEN-I | D14: H2SO4 | E14: 013 | G14: 360 | H14: 360 | I14: 45V8
A15: T1332 | B15: 43709 | C15: HEN-I | D15: H2SO4-96% | E15: 611 | G15: 120 | H15: 120 | I15: 57XX
A16: 2426 | B16: 43709 | C16: PSMC | D16: H2SO4 | E16: 104 | F16: TS99H29 | G16: 1750 | H16: 130 | I16: ZI60
A17: 2380 | B17: 43709 | C17: PSMC | D17: H2O2 | E17: 608 | F17: TO19H28 | G17: 2840 | H17: 50 | I17: 42XY
A18: 2369 | B18: 43709 | C18: HEN-I | D18: H2SO4 | E18: 007 | G18: 0 | H18: 20370 | I18: 29XY
A19: 2377 | B19: 43709 | C19: MMT | D19: HF | E19: 313 | F19: TF59H29 | G19: 3910 | H19: 10 | I19: 95XX
A20: 2393 | B20: 43709 | C20: VISC | D20: H2O2 | E20: 602 | F20: TO19H28 | G20: 6100 | H20: 60 | I20: 53XX
A21: T2310 | B21: 43709 | C21: HEN-I | D21: H2SO4-96% | E21: 627 | G21: 60 | H21: 60 | I21: 72X5
A22: T2355 | B22: 43709 | C22: HEN-I | D22: H2SO4-96% | E22: 014 | G22: 20 | H22: 20 | I22: 36W5
A23: 2425 | B23: 43709 | C23: PSMC | D23: IPA | E23: 106 | F23: TI09H30 | G23: 760 | H23: 10 | I23: ZI60
A24: 2420 | B24: 43709 | C24: PSMC-P3 | D24: HF | E24: 108 | F24: TF59H28 | G24: 1080 | H24: 0 | I24: ZI60
A25: 2402 | B25: 43709 | C25: TSMC12A | D25: H2SO4-96% | E25: 619 | F25: TS69H30 | G25: 10180 | H25: 10 | I25: 06F2
A26: 2387 | B26: 43709 | C26: PSMC-P1 | D26: NH4OH | E26: 603 | F26: TW29H29 | G26: 4490 | H26: 790 | I26: 29XZ
A27: 2403 | B27: 43709 | C27: TSMC14P1 | D27: H2O2 | E27: 014 | F27: TO19H30 | G27: 12250 | H27: 130 | I27: 77W3
A28: 2389 | B28: 43709 | C28: MMT | D28: NH4OH | E28: 610 | F28: TW29H30 | G28: 5010 | H28: 40 | I28: 71X5
A29: 2400 | B29: 43709 | C29: TSMC12P2 | D29: H2SO4-96% | E29: 622 | F29: TS69H30 | G29: 12040 | H29: 60 | I29: 83V9
A30: 2395 | B30: 43709 | C30: INNOLUX6 | D30: CH3COOH | E30: 003 | F30: TA09H19 | G30: 14180 | H30: 200 | I30: 46V8
A31: 2386 | B31: 43709 | C31: PSMC-P2 | D31: NH4OH | E31: 608 | F31: TW29H30 | G31: 4980 | H31: 0 | I31: 70X5
A32: 2399 | B32: 43709 | C32: HEN-I | D32: H2SO4-96% | E32: 612 | G32: 250 | H32: 11870 | I32: 60XX
A33: 2424 | B33: 43709 | C33: PSMC | D33: IPA | E33: 105 | F33: TI09H29 | G33: 740 | H33: 10 | I33: ZI60
A34: 2421 | B34: 43709 | C34: PSMC-P3 | D34: HF | E34: 109 | F34: TF59H28 | G34: 1030 | H34: 10 | I34: ZI60
A35: 2391 | B35: 43709 | C35: HEN-I | D35: H2SO4-96% | E35: 615 | G35: 50 | H35: 11080 | I35: 53ZA
A36: 2383 | B36: 43709 | C36: HEN-I | D36: H2SO4-96% | E36: 08G | G36: 50 | H36: 17070 | I36: HBB8082
A37: 2390 | B37: 43709 | C37: PSMC-P2 | D37: H2SO4 | E37: 630 | F37: TS99H30 | G37: 10940 | H37: 20 | I37: 21XY
A38: 2379 | B38: 43709 | C38: HEN-I | D38: H2SO4-96% | E38: 628 | G38: 30 | H38: 10110 | I38: 82V9
A39: T2115 | B39: 43709 | C39: HEN-I | D39: H2SO4-96% | E39: 612 | G39: 250 | H39: 250 | I39: 60XX
A40: 2392 | B40: 43709 | C40: HEN-I | D40: H2SO4-96% | E40: 016 | G40: 20 | H40: 20330 | I40: 70X2
...

Sheet TYS
A1: 磅單排序序號 | B1: 磅單序號B | C1: 出荷日期 | D1: 客戶名稱 | E1: 化學品料號 | F1: LORRY NO | G1: LOT NO | H1: 開始時間 | I1: 結束時間 | J1: 異常說明 | K1: LOT | L1: 淨重A | M1: 淨重B | N1: 出荷時間 | O1: 回廠時間
A2: 117262 | B2: 2598 | C2: 43712 | D2: MMT | E2: W2 | F2: 609 | G2: TW29I01 | H2: 09:50 | I2: 14:20 | K2: =MID(G2,2,15)&"L"&F2 -> TW29I01L609 | L2: =VLOOKUP($B2,'POUND-TYS'!$A:$I,7,FALSE) -> 5020 | M2: =VLOOKUP($B2,'POUND-TYS'!$A:$I,8,FALSE) -> 60 | N2: =C2 -> 43712 | O2: =N2 -> 43712
A3: 117271 | B3: 2617 | C3: 43712 | D3: VISC | E3: W2 | F3: 605 | G3: TW29I01 | H3: 14:30 | I3: 17:40 | K3: =MID(G3,2,15)&"L"&F3 -> TW29I01L605 | L3: =VLOOKUP($B3,'POUND-TYS'!$A:$I,7,FALSE) -> 4970 | M3: =VLOOKUP($B3,'POUND-TYS'!$A:$I,8,FALSE) -> 820 | N3: =C3 -> 43712 | O3: =N3 -> 43712
A4: 117255 | B4: 2589 | C4: 43712 | D4: VISC2A | E4: S9 | F4: 218 | G4: TS99I02 | H4: 08:10 | I4: 13:10 | K4: =MID(G4,2,15)&"L"&F4 -> TS99I02L218 | L4: =VLOOKUP($B4,'POUND-TYS'!$A:$I,7,FALSE) -> 20000 | M4: =VLOOKUP($B4,'POUND-TYS'!$A:$I,8,FALSE) -> 5390 | N4: =C4 -> 43712 | O4: =N4 -> 43712
A5: 117273 | B5: 2614 | C5: 43712 | D5: MMT | E5: S6 | F5: 617 | G5: TS69I02 | H5: 13:20 | I5: 17:10 | K5: =MID(G5,2,15)&"L"&F5 -> TS69I02L617 | L5: =VLOOKUP($B5,'POUND-TYS'!$A:$I,7,FALSE) -> 11070 | M5: =VLOOKUP($B5,'POUND-TYS'!$A:$I,8,FALSE) -> 80 | N5: =C5 -> 43712 | O5: =N5 -> 43712
A6: 117260 | B6: 2586 | C6: 43712 | D6: WTK | E6: O1 | F6: 605 | G6: TO19H30 | H6: 08:30 | I6: 12:30 | K6: =MID(G6,2,15)&"L"&F6 -> TO19H30L605 | L6: =VLOOKUP($B6,'POUND-TYS'!$A:$I,7,FALSE) -> 7100 | M6: =VLOOKUP($B6,'POUND-TYS'!$A:$I,8,FALSE) -> 490 | N6: =C6 -> 43712 | O6: =N6 -> 43712
A7: 117263 | B7: 2608 | C7: 43712 | D7: MMT | E7: F5 | F7: 329 | G7: TF59I02 | H7: 12:40 | I7: 16:20 | K7: =MID(G7,2,15)&"L"&F7 -> TF59I02L329 | L7: =VLOOKUP($B7,'POUND-TYS'!$A:$I,7,FALSE) -> 12670 | M7: =VLOOKUP($B7,'POUND-TYS'!$A:$I,8,FALSE) -> 7690 | N7: =C7 -> 43712 | O7: =N7 -> 43712
A8: 117261 | B8: 2610 | C8: 43712 | D8: UMC8F | E8: S9 | F8: 616 | G8: TS99I01 | H8: 08:10 | I8: 16:00 | J8: 先驗後充 | K8: =MID(G8,2,15)&"L"&F8 -> TS99I01L616 | L8: =VLOOKUP($B8,'POUND-TYS'!$A:$I,7,FALSE) -> 11080 | M8: =VLOOKUP($B8,'POUND-TYS'!$A:$I,8,FALSE) -> 10 | N8: =C8 -> 43712 | O8: =N8 -> 43712
A9: 117272 | B9: 2616 | C9: 43712 | D9: UMC12A | E9: S6 | F9: 627 | G9: TS69I02 | H9: 05:40 | I9: 17:30 | J9: 先驗後充 | K9: =MID(G9,2,15)&"L"&F9 -> TS69I02L627 | L9: =VLOOKUP($B9,'POUND-TYS'!$A:$I,7,FALSE) -> 11170 | M9: =VLOOKUP($B9,'POUND-TYS'!$A:$I,8,FALSE) -> 60 | N9: =C9 -> 43712 | O9: =N9 -> 43712
A10: 51288 | B10: T2537 | C10: 43712 | D10: E-KAY | E10: S6 | F10: 048 | H10: 06:40 | I10: 09:20 | K10: =MID(G10,2,15)&"L"&F10 -> L048 | L10: =VLOOKUP($B10,'POUND-TYS'!$A:$I,7,FALSE) -> 20350 | M10: =VLOOKUP($B10,'POUND-TYS'!$A:$I,8,FALSE) -> 20350 | N10: =C10 -> 43712 | O10: =N10 -> 43712
A11: 51295 | B11: T2573 | C11: 43712 | D11: E-KAY | E11: S6 | F11: 02H | H11: 06:40 | I11: 09:20 | K11: =MID(G11,2,15)&"L"&F11 -> L02H | L11: =VLOOKUP($B11,'POUND-TYS'!$A:$I,7,FALSE) -> 19770 | M11: =VLOOKUP($B11,'POUND-TYS'!$A:$I,8,FALSE) -> 160 | N11: =C11 -> 43712 | O11: =N11 -> 43712
A12: 51269 | B12: 2603 | C12: 43712 | D12: PSMC-P3 | E12: F5 | F12: 106 | G12: TF59I01 | H12: 12:30 | I12: 15:35 | K12: =MID(G12,2,15)&"L"&F12 -> TF59I01L106 | L12: =VLOOKUP($B12,'POUND-TYS'!$A:$I,7,FALSE) -> 1080 | M12: =VLOOKUP($B12,'POUND-TYS'!$A:$I,8,FALSE) -> 10 | N12: =C12 -> 43712 | O12: =N12 -> 43712
A13: 51271 | B13: 2607 | C13: 43712 | D13: PSMC-P3 | E13: F5 | F13: 107 | G13: TF59I01 | H13: 12:30 | I13: 15:35 | K13: =MID(G13,2,15)&"L"&F13 -> TF59I01L107 | L13: =VLOOKUP($B13,'POUND-TYS'!$A:$I,7,FALSE) -> 1100 | M13: =VLOOKUP($B13,'POUND-TYS'!$A:$I,8,FALSE) -> 20 | N13: =C13 -> 43712 | O13: =N13 -> 43712
A14: 51281 | B14: 2619 | C14: 43712 | D14: TSMC12P2 | E14: S6 | F14: 622 | G14: TS69I02 | H14: 15:45 | I14: 21:10 | J14: 先驗後充 | K14: =MID(G14,2,15)&"L"&F14 -> TS69I02L622 | L14: =VLOOKUP($B14,'POUND-TYS'!$A:$I,7,FALSE) -> 12070 | M14: =VLOOKUP($B14,'POUND-TYS'!$A:$I,8,FALSE) -> 70 | N14: =C14 -> 43712 | O14: =N14 -> 43712
A15: 51249 | B15: 2560 | C15: 43712 | D15: TSMC14P3 | E15: O1 | F15: 009 | G15: TO19H31 | H15: 00:00 | I15: 05:30 | J15: 實際出廠9/3 20:00. 先驗後充 | K15: =MID(G15,2,15)&"L"&F15 -> TO19H31L009 | L15: =VLOOKUP($B15,'POUND-TYS'!$A:$I,7,FALSE) -> 11420 | M15: =VLOOKUP($B15,'POUND-TYS'!$A:$I,8,FALSE) -> 60 | N15: =C15 -> 43712 | O15: =N15 -> 43712
A16: 51264 | B16: 2596 | C16: 43712 | D16: TSMC12A | E16: S6 | F16: 619 | G16: TS69I02 | H16: 08:40 | I16: 13:40 | J16: 先驗後充 | K16: =MID(G16,2,15)&"L"&F16 -> TS69I02L619 | L16: =VLOOKUP($B16,'POUND-TYS'!$A:$I,7,FALSE) -> 10100 | M16: =VLOOKUP($B16,'POUND-TYS'!$A:$I,8,FALSE) -> 30 | N16: =C16 -> 43712 | O16: =N16 -> 43712
A17: 51283 | B17: 2634 | C17: 43712 | D17: TNC | E17: N7 | F17: 301 | H17: 13:55 | I17: 16:38 | K17: =MID(G17,2,15)&"L"&F17 -> L301 | L17: =VLOOKUP($B17,'POUND-TYS'!$A:$I,7,FALSE) -> 40 | M17: =VLOOKUP($B17,'POUND-TYS'!$A:$I,8,FALSE) -> 3810 | N17: =C17 -> 43712 | O17: =N17 -> 43712
A18: 51277 | B18: 2615 | C18: 43712 | D18: INNOLUX6 | E18: A4 | F18: 426 | G18: WZ1983102 | H18: 04:00 | I18: 17:00 | K18: =MID(G18,2,15)&"L"&F18 -> Z1983102L426 | L18: =VLOOKUP($B18,'POUND-TYS'!$A:$I,7,FALSE) -> 18270 | M18: =VLOOKUP($B18,'POUND-TYS'!$A:$I,8,FALSE) -> 150 | N18: =C18 -> 43712 | O18: =N18 -> 43712
A19: 51260 | B19: 2592 | C19: 43712 | D19: GTC | E19: L1 | F19: 101 | G19: TL19H29 | H19: 07:45 | I19: 12:10 | K19: =MID(G19,2,15)&"L"&F19 -> TL19H29L101 | L19: =VLOOKUP($B19,'POUND-TYS'!$A:$I,7,FALSE) -> 1190 | M19: =VLOOKUP($B19,'POUND-TYS'!$A:$I,8,FALSE) -> 10 | N19: =C19 -> 43712 | O19: =N19 -> 43712
A20: 51258 | B20: 2590 | C20: 43712 | D20: GTC | E20: L1 | F20: 102 | G20: TL19H29 | H20: 07:45 | I20: 12:10 | K20: =MID(G20,2,15)&"L"&F20 -> TL19H29L102 | L20: =VLOOKUP($B20,'POUND-TYS'!$A:$I,7,FALSE) -> 1180 | M20: =VLOOKUP($B20,'POUND-TYS'!$A:$I,8,FALSE) -> 10 | N20: =C20 -> 43712 | O20: =N20 -> 43712
A21: 51268 | B21: 2602 | C21: 43712 | D21: PSMC-P2 | E21: W2 | F21: 608 | G21: TW29I02 | H21: 12:25 | I21: 15:35 | K21: =MID(G21,2,15)&"L"&F21 -> TW29I02L608 | L21: =VLOOKUP($B21,'POUND-TYS'!$A:$I,7,FALSE) -> 4940 | M21: =VLOOKUP($B21,'POUND-TYS'!$A:$I,8,FALSE) -> 0 | N21: =C21 -> 43712 | O21: =N21 -> 43712
A22: 51266 | B22: 2600 | C22: 43712 | D22: INNOLUX2 | E22: A4 | F22: 602 | G22: WZ1982709 | H22: 05:00 | I22: 15:30 | J22: 先驗後充 | K22: =MID(G22,2,15)&"L"&F22 -> Z1982709L602 | L22: =VLOOKUP($B22,'POUND-TYS'!$A:$I,7,FALSE) -> 8780 | M22: =VLOOKUP($B22,'POUND-TYS'!$A:$I,8,FALSE) -> 0 | N22: =C22 -> 43712 | O22: =N22 -> 43712
A23: 51263 | B23: 2595 | C23: 43712 | D23: PSMC-P1 | E23: S9 | F23: 613 | G23: TS99I02 | H23: 09:30 | I23: 13:50 | K23: =MID(G23,2,15)&"L"&F23 -> TS99I02L613 | L23: =VLOOKUP($B23,'POUND-TYS'!$A:$I,7,FALSE) -> 10910 | M23: =VLOOKUP($B23,'POUND-TYS'!$A:$I,8,FALSE) -> 2360 | N23: =C23 -> 43712 | O23: =N23 -> 43712
A24: 51294 | B24: T2565 | C24: 43712 | D24: TNC | E24: N7 | F24: 301 | H24: 07:10 | I24: 09:30 | K24: =MID(G24,2,15)&"L"&F24 -> L301 | L24: =VLOOKUP($B24,'POUND-TYS'!$A:$I,7,FALSE) -> 40 | M24: =VLOOKUP($B24,'POUND-TYS'!$A:$I,8,FALSE) -> 40 | N24: =C24 -> 43712 | O24: =N24 -> 43712
A25: 51259 | B25: 2591 | C25: 43712 | D25: PSMC | E25: S9 | F25: 102 | G25: TS99H30 | H25: 09:40 | I25: 13:00 | K25: =MID(G25,2,15)&"L"&F25 -> TS99H30L102 | L25: =VLOOKUP($B25,'POUND-TYS'!$A:$I,7,FALSE) -> 1720 | M25: =VLOOKUP($B25,'POUND-TYS'!$A:$I,8,FALSE) -> 20 | N25: =C25 -> 43712 | O25: =N25 -> 43712
A26: 51261 | B26: 2593 | C26: 43712 | D26: PSMC | E26: I0 | F26: 103 | G26: TI09I01 | H26: 09:40 | I26: 13:00 | K26: =MID(G26,2,15)&"L"&F26 -> TI09I01L103 | L26: =VLOOKUP($B26,'POUND-TYS'!$A:$I,7,FALSE) -> 730 | M26: =VLOOKUP($B26,'POUND-TYS'!$A:$I,8,FALSE) -> 0 | N26: =C26 -> 43712 | O26: =N26 -> 43712
A27: 51262 | B27: 2594 | C27: 43712 | D27: PSMC | E27: I0 | F27: 104 | G27: TI09I01 | H27: 09:40 | I27: 13:00 | K27: =MID(G27,2,15)&"L"&F27 -> TI09I01L104 | L27: =VLOOKUP($B27,'POUND-TYS'!$A:$I,7,FALSE) -> 770 | M27: =VLOOKUP($B27,'POUND-TYS'!$A:$I,8,FALSE) -> 20 | N27: =C27 -> 43712 | O27: =N27 -> 43712
A28: 51270 | B28: 2606 | C28: 43712 | D28: PSMC | E28: O1 | F28: 608 | G28: TO19I01 | H28: 13:15 | I28: 15:50 | K28: =MID(G28,2,15)&"L"&F28 -> TO19I01L608 | L28: =VLOOKUP($B28,'POUND-TYS'!$A:$I,7,FALSE) -> 3510 | M28: =VLOOKUP($B28,'POUND-TYS'!$A:$I,8,FALSE) -> 60 | N28: =C28 -> 43712 | O28: =N28 -> 43712
A29: 51274 | B29: 2611 | C29: 43712 | D29: TSMC15P2 | E29: S6 | F29: 021 | G29: TS69H28 | H29: 07:00 | I29: 16:00 | J29: 先驗後充 | K29: =MID(G29,2,15)&"L"&F29 -> TS69H28L021 | L29: =VLOOKUP($B29,'POUND-TYS'!$A:$I,7,FALSE) -> 20320 | M29: =VLOOKUP($B29,'POUND-TYS'!$A:$I,8,FALSE) -> 20 | N29: =C29 -> 43712 | O29: =N29 -> 43712
K30: =MID(G30,2,15)&"L"&F30 -> L | L30: =VLOOKUP($B30,'POUND-TYS'!$A:$I,7,FALSE) -> #N/A | M30: =VLOOKUP($B30,'POUND-TYS'!$A:$I,8,FALSE) -> #N/A | N30: =C30 -> 0 | O30: =N30 -> 0
K31: =MID(G31,2,15)&"L"&F31 -> L | L31: =VLOOKUP($B31,'POUND-TYS'!$A:$I,7,FALSE) -> #N/A | M31: =VLOOKUP($B31,'POUND-TYS'!$A:$I,8,FALSE) -> #N/A | N31: =C31 -> 0 | O31: =N31 -> 0
K32: =MID(G32,2,15)&"L"&F32 -> L | L32: =VLOOKUP($B32,'POUND-TYS'!$A:$I,7,FALSE) -> #N/A | M32: =VLOOKUP($B32,'POUND-TYS'!$A:$I,8,FALSE) -> #N/A | N32: =C32 -> 0 | O32: =N32 -> 0
K33: =MID(G33,2,15)&"L"&F33 -> L | L33: =VLOOKUP($B33,'POUND-TYS'!$A:$I,7,FALSE) -> #N/A | M33: =VLOOKUP($B33,'POUND-TYS'!$A:$I,8,FALSE) -> #N/A | N33: =C33 -> 0 | O33: =N33 -> 0
K34: =MID(G34,2,15)&"L"&F34 -> L | L34: =VLOOKUP($B34,'POUND-TYS'!$A:$I,7,FALSE) -> #N/A | M34: =VLOOKUP($B34,'POUND-TYS'!$A:$I,8,FALSE) -> #N/A | N34: =C34 -> 0 | O34: =N34 -> 0
K35: =MID(G35,2,15)&"L"&F35 -> L | L35: =VLOOKUP($B35,'POUND-TYS'!$A:$I,7,FALSE) -> #N/A | M35: =VLOOKUP($B35,'POUND-TYS'!$A:$I,8,FALSE) -> #N/A | N35: =C35 -> 0 | O35: =N35 -> 0
K36: =MID(G36,2,15)&"L"&F36 -> L | L36: =VLOOKUP($B36,'POUND-TYS'!$A:$I,7,FALSE) -> #N/A | M36: =VLOOKUP($B36,'POUND-TYS'!$A:$I,8,FALSE) -> #N/A | N36: =C36 -> 0 | O36: =N36 -> 0
K37: =MID(G37,2,15)&"L"&F37 -> L | L37: =VLOOKUP($B37,'POUND-TYS'!$A:$I,7,FALSE) -> #N/A | M37: =VLOOKUP($B37,'POUND-TYS'!$A:$I,8,FALSE) -> #N/A | N37: =C37 -> 0 | O37: =N37 -> 0
K38: =MID(G38,2,15)&"L"&F38 -> L | L38: =VLOOKUP($B38,'POUND-TYS'!$A:$I,7,FALSE) -> #N/A | M38: =VLOOKUP($B38,'POUND-TYS'!$A:$I,8,FALSE) -> #N/A | N38: =C38 -> 0 | O38: =N38 -> 0
K39: =MID(G39,2,15)&"L"&F39 -> L | L39: =VLOOKUP($B39,'POUND-TYS'!$A:$I,7,FALSE) -> #N/A | M39: =VLOOKUP($B39,'POUND-TYS'!$A:$I,8,FALSE) -> #N/A | N39: =C39 -> 0 | O39: =N39 -> 0
K40: =MID(G40,2,15)&"L"&F40 -> L | L40: =VLOOKUP($B40,'POUND-TYS'!$A:$I,7,FALSE) -> #N/A | M40: =VLOOKUP($B40,'POUND-TYS'!$A:$I,8,FALSE) -> #N/A | N40: =C40 -> 0 | O40: =N40 -> 0
...
