Workbook

Sheet POUND-TYS
A1: 磅單序號B | B1: 出荷日期 | C1: 客戶名稱 | D1: 化學品名 | E1: LORRY NO | F1: LOT NO | G1: 淨重A | H1: 淨重B | I1: 牌照號碼
A2: 4049 | B2: 43637 | C2: PSMC-P3 | D2: HF | E2: 101 | F2: TF59F17 | G2: 1090 | H2: 10 | I2: ZI60
A3: T3989 | B3: 43637 | C3: HEN-I | D3: H2SO4 | E3: 007 | G3: 0 | H3: 0 | I3: 29XY
A4: 4024 | B4: 43637 | C4: PSMC | D4: H2SO4 | E4: 104 | F4: TS99F17 | G4: 1740 | H4: 0 | I4: ZI60
A5: T3841 | B5: 43637 | C5: E-KAY | D5: H2SO4-96% | E5: 02H | G5: 20240 | H5: 20240 | I5: 93YZ
A6: 4046 | B6: 43637 | C6: MMT | D6: HF | E6: 334 | F6: TF59F20 | G6: 9220 | H6: 4470 | I6: 35Y3
A7: 4006 | B7: 43637 | C7: MTTW | D7: H2SO4-96% | E7: 612 | F7: TS69F18 | G7: 11750 | H7: 240 | I7: 60XX
A8: 4172 | B8: 43637 | C8: E-KAY | D8: H2SO4-96% | E8: 02H | F8: TS69F18 | G8: 20240 | H8: 80 | I8: 93YZ
A9: TT4002 | B9: 43637 | C9: E-KAY | D9: H2SO4-96% | E9: 048 | G9: 20290 | H9: 30 | I9: ZI58
A10: 4017 | B10: 43637 | C10: HEN-I | D10: H2SO4-96% | E10: 014 | G10: 30 | H10: 20310 | I10: 36W5
A11: 4042 | B11: 43637 | C11: MMT | D11: H2SO4-96% | E11: 608 | F11: TS69F19 | G11: 10140 | H11: 50 | I11: 30F2
A12: 4003 | B12: 43637 | C12: VISC | D12: H2SO4 | E12: 605 | F12: TS99F18 | G12: 10170 | H12: 1080 | I12: 52ZA
A13: 3987 | B13: 43637 | C13: TSMC14P3 | D13: H2O2 | E13: 009 | F13: TO19F17 | G13: 11930 | H13: 40 | I13: 35XZ
A14: 3993 | B14: 43637 | C14: HEN-I | D14: H2SO4 | E14: 002 | G14: 70 | H14: 20410 | I14: 40XY
A15: 4034 | B15: 43637 | C15: HEN-I | D15: H2SO4-96% | E15: 10G | G15: 80 | H15: 17130 | I15: 41F2
A16: T4002 | B16: 43637 | C16: HEN-I | D16: H2SO4-96% | E16: 048 | G16: 30 | H16: 30 | I16: ZI58
A17: 4051 | B17: 43637 | C17: TSMC3 | D17: H2SO4-96% | E17: 628 | F17: TS69F19 | G17: 10330 | H17: 10 | I17: 82V9
A18: T3970 | B18: 43637 | C18: HEN-I | D18: H2SO4-96% | E18: 627 | G18: 70 | H18: 70 | I18: 72X5
A19: 3994 | B19: 43637 | C19: TSMC15P2 | D19: H2SO4-96% | E19: 001 | F19: TS69F17 | G19: 20300 | H19: 370 | I19: 19XY
A20: 4048 | B20: 43637 | C20: PSMC-P3 | D20: HF | E20: 102 | F20: TF59F18 | G20: 1070 | H20: 20 | I20: ZI60
A21: 4032 | B21: 43637 | C21: FST | D21: PWMAE-B | E21: 602 | F21: TM49F13 | G21: 6970 | H21: 0 | I21: 60X3
A22: 4061 | B22: 43637 | C22: TSMC12P2 | D22: H2SO4-96% | E22: 625 | F22: TS69F18 | G22: 11830 | H22: 10 | I22: 69X5
A23: 4004 | B23: 43637 | C23: TSMC15P1 | D23: H2SO4-96% | E23: 019 | F23: TS69F16 | G23: 20360 | H23: 70 | I23: 33Y3
A24: 4026 | B24: 43637 | C24: VISC2A | D24: H2SO4 | E24: 218 | F24: TS99F08 | G24: 20200 | H24: 1680 | I24: 50XX
A25: 4008 | B25: 43637 | C25: TSMC14P1 | D25: H2O2 | E25: 016 | F25: TO19F18 | G25: 12110 | H25: 60 | I25: 60W5
A26: 4060 | B26: 43637 | C26: HEN-I | D26: H2SO4 | E26: 007 | G26: 0 | H26: 20390 | I26: 29XY
A27: T3981 | B27: 43637 | C27: HEN-I | D27: H2SO4-96% | E27: 10G | G27: 80 | H27: 80 | I27: 41F2
A28: T4059 | B28: 43637 | C28: HEN-I | D28: H2SO4 | E28: 744 | G28: 0 | H28: 0 | I28: 99YZ
A29: 4055 | B29: 43637 | C29: TSMC14P1 | D29: H2SO4-96% | E29: 607 | F29: TS69F17 | G29: 11070 | H29: 150 | I29: 48F2
A30: 4062 | B30: 43637 | C30: TSMC14P3 | D30: H2O2 | E30: 006 | F30: TO19F18 | G30: 12020 | H30: 30 | I30: 97YZ
A31: 4031 | B31: 43637 | C31: PSMC-P1 | D31: HF | E31: 302 | F31: TF59F17 | G31: 3110 | H31: 280 | I31: ZI60
A32: 3996 | B32: 43637 | C32: HEN-I | D32: H2SO4-96% | E32: 11G | G32: 0 | H32: 17120 | I32: HBB7391
A33: T3840 | B33: 43637 | C33: HEN-I | D33: H2SO4-96% | E33: 020 | G33: 80 | H33: 80 | I33: 33W5
A34: 4052 | B34: 43637 | C34: INNOLUX6 | D34: AL-E | E34: 426 | F34: WZ1961709 | G34: 18020 | H34: 140 | I34: 37W5
A35: 4016 | B35: 43637 | C35: UMC8A | D35: NH4OH | E35: 606 | F35: TW29F17 | G35: 4750 | H35: 80 | I35: 65XX
A36: 4028 | B36: 43637 | C36: PSMC | D36: IPA | E36: 102 | F36: TI09F19 | G36: 750 | H36: 0 | I36: ZI60
A37: 4027 | B37: 43637 | C37: PSMC | D37: IPA | E37: 103 | F37: TI09F19 | G37: 740 | H37: 0 | I37: ZI60
A38: 4045 | B38: 43637 | C38: UMC8A | D38: H2O2 | E38: 605 | F38: TO19F16 | G38: 7120 | H38: 2200 | I38: 59XX
A39: 4018 | B39: 43637 | C39: PSMC-P1 | D39: NH4OH | E39: 603 | F39: TW29F19 | G39: 4450 | H39: 830 | I39: 29XZ
A40: 4041 | B40: 43637 | C40: CPTL2 | D40: MO-AL-MO | E40: LT88 | F40: WZ1930520 | G40: 15130 | H40: 40 | I40: 30XZ
...

Sheet TYS
A1: 編號 | B1: 磅單序號B | C1: 出荷日期 | D1: 客戶名稱 | E1: 化學品料號 | F1: LORRY NO | G1: LOT NO | H1: 開始時間 | I1: 結束時間 | J1: 異常說明 | K1: LOT | L1: 淨重A | M1: 淨重B
A2: 1 | B2: 4053 | C2: 43637 | D2: MMT | E2: W2 | F2: 610 | G2: TW29F15 | H2: 13:40 | I2: 18:10 | K2: =MID(G2,2,15)&"L"&F2 -> TW29F15L610 | L2: =VLOOKUP($B2,'POUND-TYS'!$A:$I,7,FALSE) -> 5010 | M2: =VLOOKUP($B2,'POUND-TYS'!$A:$I,8,FALSE) -> 30
A3: 2 | B3: 4028 | C3: 43637 | D3: PSMC | E3: I0 | F3: 102 | G3: TI09F19 | H3: 10:10 | I3: 12:30 | K3: =MID(G3,2,15)&"L"&F3 -> TI09F19L102 | L3: =VLOOKUP($B3,'POUND-TYS'!$A:$I,7,FALSE) -> 750 | M3: =VLOOKUP($B3,'POUND-TYS'!$A:$I,8,FALSE) -> 0
A4: 3 | B4: 3994 | C4: 43637 | D4: TSMC15P2 | E4: S6 | F4: 001 | G4: TS69F17 | H4: 00:05 | I4: 07:30 | J4: 先驗後充 | K4: =MID(G4,2,15)&"L"&F4 -> TS69F17L001 | L4: =VLOOKUP($B4,'POUND-TYS'!$A:$I,7,FALSE) -> 20300 | M4: =VLOOKUP($B4,'POUND-TYS'!$A:$I,8,FALSE) -> 370
A5: 4 | B5: 4048 | C5: 43637 | D5: PSMC-P3 | E5: F5 | F5: 102 | G5: TF59F18 | H5: 14:10 | I5: 16:50 | K5: =MID(G5,2,15)&"L"&F5 -> TF59F18L102 | L5: =VLOOKUP($B5,'POUND-TYS'!$A:$I,7,FALSE) -> 1070 | M5: =VLOOKUP($B5,'POUND-TYS'!$A:$I,8,FALSE) -> 20
A6: 5 | B6: 4049 | C6: 43637 | D6: PSMC-P3 | E6: F5 | F6: 101 | G6: TF59F17 | H6: 14:10 | I6: 16:50 | K6: =MID(G6,2,15)&"L"&F6 -> TF59F17L101 | L6: =VLOOKUP($B6,'POUND-TYS'!$A:$I,7,FALSE) -> 1090 | M6: =VLOOKUP($B6,'POUND-TYS'!$A:$I,8,FALSE) -> 10
A7: 6 | B7: 4032 | C7: 43637 | D7: FST | E7: M4 | F7: 602 | G7: TM49F13 | H7: 05:00 | I7: 14:00 | K7: =MID(G7,2,15)&"L"&F7 -> TM49F13L602 | L7: =VLOOKUP($B7,'POUND-TYS'!$A:$I,7,FALSE) -> 6970 | M7: =VLOOKUP($B7,'POUND-TYS'!$A:$I,8,FALSE) -> 0
A8: 7 | B8: 4045 | C8: 43637 | D8: UMC8A | E8: O1 | F8: 605 | G8: TO19F16 | H8: 13:00 | I8: 16:20 | K8: =MID(G8,2,15)&"L"&F8 -> TO19F16L605 | L8: =VLOOKUP($B8,'POUND-TYS'!$A:$I,7,FALSE) -> 7120 | M8: =VLOOKUP($B8,'POUND-TYS'!$A:$I,8,FALSE) -> 2200
A9: 8 | B9: 4027 | C9: 43637 | D9: PSMC | E9: I0 | F9: 103 | G9: TI09F19 | H9: 10:10 | I9: 12:30 | K9: =MID(G9,2,15)&"L"&F9 -> TI09F19L103 | L9: =VLOOKUP($B9,'POUND-TYS'!$A:$I,7,FALSE) -> 740 | M9: =VLOOKUP($B9,'POUND-TYS'!$A:$I,8,FALSE) -> 0
A10: 9 | B10: 4055 | C10: 43637 | D10: TSMC14P1 | E10: S6 | F10: 607 | G10: TS69F17 | H10: 06:40 | I10: 18:50 | J10: 先驗後充 | K10: =MID(G10,2,15)&"L"&F10 -> TS69F17L607 | L10: =VLOOKUP($B10,'POUND-TYS'!$A:$I,7,FALSE) -> 11070 | M10: =VLOOKUP($B10,'POUND-TYS'!$A:$I,8,FALSE) -> 150
A11: 10 | B11: 3998 | C11: 43637 | D11: UMC8S | E11: O1 | F11: 606 | G11: TO19F16 | H11: 05:00 | I11: 09:00 | K11: =MID(G11,2,15)&"L"&F11 -> TO19F16L606 | L11: =VLOOKUP($B11,'POUND-TYS'!$A:$I,7,FALSE) -> 7120 | M11: =VLOOKUP($B11,'POUND-TYS'!$A:$I,8,FALSE) -> 30
A12: 11 | B12: 4006 | C12: 43637 | D12: MTTW | E12: S6 | F12: 612 | G12: TS69F18 | H12: 05:30 | I12: 10:00 | K12: =MID(G12,2,15)&"L"&F12 -> TS69F18L612 | L12: =VLOOKUP($B12,'POUND-TYS'!$A:$I,7,FALSE) -> 11750 | M12: =VLOOKUP($B12,'POUND-TYS'!$A:$I,8,FALSE) -> 240
A13: 12 | B13: 4042 | C13: 43637 | D13: MMT | E13: S6 | F13: 608 | G13: TS69F19 | H13: 12:20 | I13: 16:10 | K13: =MID(G13,2,15)&"L"&F13 -> TS69F19L608 | L13: =VLOOKUP($B13,'POUND-TYS'!$A:$I,7,FALSE) -> 10140 | M13: =VLOOKUP($B13,'POUND-TYS'!$A:$I,8,FALSE) -> 50
A14: 13 | B14: 4016 | C14: 43637 | D14: UMC8A | E14: W2 | F14: 606 | G14: TW29F17 | H14: 08:00 | I14: 12:10 | J14: 先驗後充 | K14: =MID(G14,2,15)&"L"&F14 -> TW29F17L606 | L14: =VLOOKUP($B14,'POUND-TYS'!$A:$I,7,FALSE) -> 4750 | M14: =VLOOKUP($B14,'POUND-TYS'!$A:$I,8,FALSE) -> 80
A15: 14 | B15: 3993 | C15: 43637 | D15: HEN-I | E15: S9 | F15: 002 | H15: 05:45 | I15: 07:40 | K15: =MID(G15,2,15)&"L"&F15 -> L002 | L15: =VLOOKUP($B15,'POUND-TYS'!$A:$I,7,FALSE) -> 70 | M15: =VLOOKUP($B15,'POUND-TYS'!$A:$I,8,FALSE) -> 20410
A16: 15 | B16: T3989 | C16: 43637 | D16: HEN-I | E16: S9 | F16: 007 | H16: 05:45 | I16: 07:40 | K16: =MID(G16,2,15)&"L"&F16 -> L007 | L16: =VLOOKUP($B16,'POUND-TYS'!$A:$I,7,FALSE) -> 0 | M16: =VLOOKUP($B16,'POUND-TYS'!$A:$I,8,FALSE) -> 0
A17: 16 | B17: 4043 | C17: 43637 | D17: VISC2B | E17: S9 | F17: 603 | G17: TS99F18 | H17: 12:25 | I17: 16:40 | K17: =MID(G17,2,15)&"L"&F17 -> TS99F18L603 | L17: =VLOOKUP($B17,'POUND-TYS'!$A:$I,7,FALSE) -> 10240 | M17: =VLOOKUP($B17,'POUND-TYS'!$A:$I,8,FALSE) -> 110
A18: 17 | B18: 4024 | C18: 43637 | D18: PSMC | E18: S9 | F18: 104 | G18: TS99F17 | H18: 10:10 | I18: 12:30 | K18: =MID(G18,2,15)&"L"&F18 -> TS99F17L104 | L18: =VLOOKUP($B18,'POUND-TYS'!$A:$I,7,FALSE) -> 1740 | M18: =VLOOKUP($B18,'POUND-TYS'!$A:$I,8,FALSE) -> 0
A19: 18 | B19: 4018 | C19: 43637 | D19: PSMC-P1 | E19: W2 | F19: 603 | G19: TW29F19 | H19: 09:17 | I19: 12:05 | K19: =MID(G19,2,15)&"L"&F19 -> TW29F19L603 | L19: =VLOOKUP($B19,'POUND-TYS'!$A:$I,7,FALSE) -> 4450 | M19: =VLOOKUP($B19,'POUND-TYS'!$A:$I,8,FALSE) -> 830
A20: 19 | B20: 4026 | C20: 43637 | D20: VISC2A | E20: S9 | F20: 218 | G20: TS99F08 | H20: 08:10 | I20: 13:30 | K20: =MID(G20,2,15)&"L"&F20 -> TS99F08L218 | L20: =VLOOKUP($B20,'POUND-TYS'!$A:$I,7,FALSE) -> 20200 | M20: =VLOOKUP($B20,'POUND-TYS'!$A:$I,8,FALSE) -> 1680
A21: 20 | B21: 3996 | C21: 43637 | D21: HEN-I | E21: S6 | F21: 11G | H21: 06:10 | I21: 08:00 | K21: =MID(G21,2,15)&"L"&F21 -> L11G | L21: =VLOOKUP($B21,'POUND-TYS'!$A:$I,7,FALSE) -> 0 | M21: =VLOOKUP($B21,'POUND-TYS'!$A:$I,8,FALSE) -> 17120
A22: 21 | B22: T3981 | C22: 43637 | D22: HEN-I | E22: S6 | F22: 10G | H22: 06:10 | I22: 08:00 | K22: =MID(G22,2,15)&"L"&F22 -> L10G | L22: =VLOOKUP($B22,'POUND-TYS'!$A:$I,7,FALSE) -> 80 | M22: =VLOOKUP($B22,'POUND-TYS'!$A:$I,8,FALSE) -> 80
A23: 22 | B23: 4052 | C23: 43637 | D23: INNOLUX6 | E23: A4 | F23: 426 | G23: WZ1961709 | H23: 05:30 | I23: 17:50 | K23: =MID(G23,2,15)&"L"&F23 -> Z1961709L426 | L23: =VLOOKUP($B23,'POUND-TYS'!$A:$I,7,FALSE) -> 18020 | M23: =VLOOKUP($B23,'POUND-TYS'!$A:$I,8,FALSE) -> 140
A24: 23 | B24: 4107 | C24: 43638 | D24: PSMC-P3 | E24: F5 | F24: 105 | G24: TF59F18 | H24: 13:30 | I24: 16:30 | K24: =MID(G24,2,15)&"L"&F24 -> TF59F18L105 | L24: =VLOOKUP($B24,'POUND-TYS'!$A:$I,7,FALSE) -> 1080 | M24: =VLOOKUP($B24,'POUND-TYS'!$A:$I,8,FALSE) -> 10
A25: 24 | B25: 4096 | C25: 43638 | D25: PSMC | E25: O1 | F25: 608 | G25: TO19F21 | H25: 16:40 | I25: 19:50 | K25: =MID(G25,2,15)&"L"&F25 -> TO19F21L608 | L25: =VLOOKUP($B25,'POUND-TYS'!$A:$I,7,FALSE) -> 7190 | M25: =VLOOKUP($B25,'POUND-TYS'!$A:$I,8,FALSE) -> 4410
A26: 25 | B26: 4106 | C26: 43638 | D26: PSMC-P3 | E26: F5 | F26: 103 | G26: TF59F18 | H26: 13:30 | I26: 16:30 | K26: =MID(G26,2,15)&"L"&F26 -> TF59F18L103 | L26: =VLOOKUP($B26,'POUND-TYS'!$A:$I,7,FALSE) -> 1080 | M26: =VLOOKUP($B26,'POUND-TYS'!$A:$I,8,FALSE) -> 0
A27: 26 | B27: 4079 | C27: 43638 | D27: MMT | E27: S6 | F27: 611 | G27: TS69F20 | H27: 08:00 | I27: 12:00 | K27: =MID(G27,2,15)&"L"&F27 -> TS69F20L611 | L27: =VLOOKUP($B27,'POUND-TYS'!$A:$I,7,FALSE) -> 10250 | M27: =VLOOKUP($B27,'POUND-TYS'!$A:$I,8,FALSE) -> 100
A28: 27 | B28: 4108 | C28: 43638 | D28: PSMC-P3 | E28: F5 | F28: 106 | G28: TF59F19 | H28: 16:40 | I28: 19:30 | K28: =MID(G28,2,15)&"L"&F28 -> TF59F19L106 | L28: =VLOOKUP($B28,'POUND-TYS'!$A:$I,7,FALSE) -> 1080 | M28: =VLOOKUP($B28,'POUND-TYS'!$A:$I,8,FALSE) -> 10
A29: 28 | B29: 4090 | C29: 43638 | D29: TSMC14P3 | E29: O1 | F29: 011 | G29: TO19F18 | H29: 03:00 | I29: 15:45 | J29: 先驗後充 | K29: =MID(G29,2,15)&"L"&F29 -> TO19F18L011 | L29: =VLOOKUP($B29,'POUND-TYS'!$A:$I,7,FALSE) -> 11950 | M29: =VLOOKUP($B29,'POUND-TYS'!$A:$I,8,FALSE) -> 120
A30: 29 | B30: T4054 | C30: 43638 | D30: FDAC | E30: F5 | F30: 602 | H30: 05:10 | I30: 13:50 | K30: =MID(G30,2,15)&"L"&F30 -> L602 | L30: =VLOOKUP($B30,'POUND-TYS'!$A:$I,7,FALSE) -> 130 | M30: =VLOOKUP($B30,'POUND-TYS'!$A:$I,8,FALSE) -> 130
A31: 30 | B31: 4085 | C31: 43638 | D31: FDAC | E31: F5 | F31: 603 | H31: 05:10 | I31: 13:50 | K31: =MID(G31,2,15)&"L"&F31 -> L603 | L31: =VLOOKUP($B31,'POUND-TYS'!$A:$I,7,FALSE) -> 20 | M31: =VLOOKUP($B31,'POUND-TYS'!$A:$I,8,FALSE) -> 5910
A32: 31 | B32: 4078 | C32: 43638 | D32: PSMC-P1 | E32: S9 | F32: 604 | G32: TS99F19 | H32: 08:20 | I32: 11:55 | K32: =MID(G32,2,15)&"L"&F32 -> TS99F19L604 | L32: =VLOOKUP($B32,'POUND-TYS'!$A:$I,7,FALSE) -> 10250 | M32: =VLOOKUP($B32,'POUND-TYS'!$A:$I,8,FALSE) -> 2520
A33: 32 | B33: 4092 | C33: 43638 | D33: MMT | E33: F5 | F33: 329 | G33: TF59F21 | H33: 12:15 | I33: 17:00 | K33: =MID(G33,2,15)&"L"&F33 -> TF59F21L329 | L33: =VLOOKUP($B33,'POUND-TYS'!$A:$I,7,FALSE) -> 19050 | M33: =VLOOKUP($B33,'POUND-TYS'!$A:$I,8,FALSE) -> 14330
A34: 33 | B34: 4084 | C34: 43638 | D34: PSMC-P2 | E34: S9 | F34: 629 | G34: TS99F17 | H34: 08:50 | I34: 13:10 | K34: =MID(G34,2,15)&"L"&F34 -> TS99F17L629 | L34: =VLOOKUP($B34,'POUND-TYS'!$A:$I,7,FALSE) -> 10960 | M34: =VLOOKUP($B34,'POUND-TYS'!$A:$I,8,FALSE) -> 0
A35: 34 | B35: 4091 | C35: 43638 | D35: UMC8C | E35: O1 | F35: 610 | G35: TO19F18 | H35: 12:20 | I35: 16:30 | K35: =MID(G35,2,15)&"L"&F35 -> TO19F18L610 | L35: =VLOOKUP($B35,'POUND-TYS'!$A:$I,7,FALSE) -> 7060 | M35: =VLOOKUP($B35,'POUND-TYS'!$A:$I,8,FALSE) -> 30
A36: 35 | B36: 4122 | C36: 43639 | D36: HEN-I | E36: S6 | F36: 035 | H36: 10:10 | I36: 12:00 | K36: =MID(G36,2,15)&"L"&F36 -> L035 | L36: =VLOOKUP($B36,'POUND-TYS'!$A:$I,7,FALSE) -> 90 | M36: =VLOOKUP($B36,'POUND-TYS'!$A:$I,8,FALSE) -> 20380
A37: 36 | B37: 4118 | C37: 43639 | D37: TSMC14P1 | E37: O1 | F37: 014 | G37: TO19F20 | H37: 03:15 | I37: 10:45 | J37: 實際出廠：6/22 南轉.先驗後充 | K37: =MID(G37,2,15)&"L"&F37 -> TO19F20L014 | L37: =VLOOKUP($B37,'POUND-TYS'!$A:$I,7,FALSE) -> 12110 | M37: =VLOOKUP($B37,'POUND-TYS'!$A:$I,8,FALSE) -> 150
A38: 37 | B38: 4136 | C38: 43639 | D38: INNOLUX5 | E38: A4 | F38: 028 | G38: WZ1961807 | H38: 03:40 | I38: 17:00 | K38: =MID(G38,2,15)&"L"&F38 -> Z1961807L028 | L38: =VLOOKUP($B38,'POUND-TYS'!$A:$I,7,FALSE) -> 20530 | M38: =VLOOKUP($B38,'POUND-TYS'!$A:$I,8,FALSE) -> 310
A39: 38 | B39: 4113 | C39: 43639 | D39: MMT | E39: S6 | F39: 617 | G39: TS69F20 | H39: 05:00 | I39: 08:52 | K39: =MID(G39,2,15)&"L"&F39 -> TS69F20L617 | L39: =VLOOKUP($B39,'POUND-TYS'!$A:$I,7,FALSE) -> 11010 | M39: =VLOOKUP($B39,'POUND-TYS'!$A:$I,8,FALSE) -> 90
A40: 39 | B40: 4128 | C40: 43639 | D40: UMC12A | E40: S6 | F40: 626 | G40: TS69F19 | H40: 02:50 | I40: 13:00 | K40: =MID(G40,2,15)&"L"&F40 -> TS69F19L626 | L40: =VLOOKUP($B40,'POUND-TYS'!$A:$I,7,FALSE) -> 11870 | M40: =VLOOKUP($B40,'POUND-TYS'!$A:$I,8,FALSE) -> 20
...

Sheet BARCODE
A1: 出荷日期 | B1: LORRY NO | C1: 品名 | D1: Lot No | E1: 假出庫數量 | F1: 殘量 | G1: 實際出庫數量 | H1: PDA殘量 | I1: 客戶名稱 | K1: 假出庫數量 | L1: 殘量 | M1: 出車時間 | N1: 回廠時間
A2: 43637 | C2: HF氫氟酸 | D2: TF59F03B020-6 | I2: 內部領料 | K2: {=SUM(IF(TYS!$C$1:$C$250=$A2,IF(TYS!$K$1:$K$250=IFERROR(LEFT($D2,FIND("-",$D2,1)-1),$D2),TYS!$L$1:$L$250,0),0))} -> 0 | L2: {=SUM(IF(TYS!$C$1:$C$250=$A2,IF(TYS!$K$1:$K$250=IFERROR(LEFT($D2,FIND("-",$D2,1)-1),$D2),TYS!$M$1:$M$250,0),0))} -> 0 | M2: {=VLOOKUP(SUM(IF(TYS!$C$1:$C$250=$A2,IF(TYS!$K$1:$K$250=IFERROR(LEFT($D2,FIND("-",$D2,1)-1),$D2),TYS!$A$1:$A$250,0),0)),TYS!$A:$I,8,FALSE)} -> #N/A | N2: {=VLOOKUP(SUM(IF(TYS!$C$1:$C$250=$A2,IF(TYS!$K$1:$K$250=IFERROR(LEFT($D2,FIND("-",$D2,1)-1),$D2),TYS!$A$1:$A$250,0),0)),TYS!$A:$I,9,FALSE)} -> #N/A
A3: 43637 | B3: F5L101 | C3: HF氫氟酸 | D3: TF59F17L101-2 | I3: 力積電P3 | K3: {=SUM(IF(TYS!$C$1:$C$250=$A3,IF(TYS!$K$1:$K$250=IFERROR(LEFT($D3,FIND("-",$D3,1)-1),$D3),TYS!$L$1:$L$250,0),0))} -> 1090 | L3: {=SUM(IF(TYS!$C$1:$C$250=$A3,IF(TYS!$K$1:$K$250=IFERROR(LEFT($D3,FIND("-",$D3,1)-1),$D3),TYS!$M$1:$M$250,0),0))} -> 10 | M3: {=VLOOKUP(SUM(IF(TYS!$C$1:$C$250=$A3,IF(TYS!$K$1:$K$250=IFERROR(LEFT($D3,FIND("-",$D3,1)-1),$D3),TYS!$A$1:$A$250,0),0)),TYS!$A:$I,8,FALSE)} -> 14:10 | N3: {=VLOOKUP(SUM(IF(TYS!$C$1:$C$250=$A3,IF(TYS!$K$1:$K$250=IFERROR(LEFT($D3,FIND("-",$D3,1)-1),$D3),TYS!$A$1:$A$250,0),0)),TYS!$A:$I,9,FALSE)} -> 16:50
A4: 43637 | B4: F5L302 | C4: HF氫氟酸 | D4: TF59F17L302-2 | I4: 力積電P1 | K4: {=SUM(IF(TYS!$C$1:$C$250=$A4,IF(TYS!$K$1:$K$250=IFERROR(LEFT($D4,FIND("-",$D4,1)-1),$D4),TYS!$L$1:$L$250,0),0))} -> 3110 | L4: {=SUM(IF(TYS!$C$1:$C$250=$A4,IF(TYS!$K$1:$K$250=IFERROR(LEFT($D4,FIND("-",$D4,1)-1),$D4),TYS!$M$1:$M$250,0),0))} -> 280 | M4: {=VLOOKUP(SUM(IF(TYS!$C$1:$C$250=$A4,IF(TYS!$K$1:$K$250=IFERROR(LEFT($D4,FIND("-",$D4,1)-1),$D4),TYS!$A$1:$A$250,0),0)),TYS!$A:$I,8,FALSE)} -> 09:40 | N4: {=VLOOKUP(SUM(IF(TYS!$C$1:$C$250=$A4,IF(TYS!$K$1:$K$250=IFERROR(LEFT($D4,FIND("-",$D4,1)-1),$D4),TYS!$A$1:$A$250,0),0)),TYS!$A:$I,9,FALSE)} -> 13:10
A5: 43637 | B5: F5L102 | C5: HF氫氟酸 | D5: TF59F18L102-2 | I5: 力積電P3 | K5: {=SUM(IF(TYS!$C$1:$C$250=$A5,IF(TYS!$K$1:$K$250=IFERROR(LEFT($D5,FIND("-",$D5,1)-1),$D5),TYS!$L$1:$L$250,0),0))} -> 1070 | L5: {=SUM(IF(TYS!$C$1:$C$250=$A5,IF(TYS!$K$1:$K$250=IFERROR(LEFT($D5,FIND("-",$D5,1)-1),$D5),TYS!$M$1:$M$250,0),0))} -> 20 | M5: {=VLOOKUP(SUM(IF(TYS!$C$1:$C$250=$A5,IF(TYS!$K$1:$K$250=IFERROR(LEFT($D5,FIND("-",$D5,1)-1),$D5),TYS!$A$1:$A$250,0),0)),TYS!$A:$I,8,FALSE)} -> 14:10 | N5: {=VLOOKUP(SUM(IF(TYS!$C$1:$C$250=$A5,IF(TYS!$K$1:$K$250=IFERROR(LEFT($D5,FIND("-",$D5,1)-1),$D5),TYS!$A$1:$A$250,0),0)),TYS!$A:$I,9,FALSE)} -> 16:50
A6: 43638 | B6: F5L103 | C6: HF氫氟酸 | D6: TF59F18L103-2 | I6: 力積電P3 | K6: {=SUM(IF(TYS!$C$1:$C$250=$A6,IF(TYS!$K$1:$K$250=IFERROR(LEFT($D6,FIND("-",$D6,1)-1),$D6),TYS!$L$1:$L$250,0),0))} -> 1080 | L6: {=SUM(IF(TYS!$C$1:$C$250=$A6,IF(TYS!$K$1:$K$250=IFERROR(LEFT($D6,FIND("-",$D6,1)-1),$D6),TYS!$M$1:$M$250,0),0))} -> 0 | M6: {=VLOOKUP(SUM(IF(TYS!$C$1:$C$250=$A6,IF(TYS!$K$1:$K$250=IFERROR(LEFT($D6,FIND("-",$D6,1)-1),$D6),TYS!$A$1:$A$250,0),0)),TYS!$A:$I,8,FALSE)} -> 13:30 | N6: {=VLOOKUP(SUM(IF(TYS!$C$1:$C$250=$A6,IF(TYS!$K$1:$K$250=IFERROR(LEFT($D6,FIND("-",$D6,1)-1),$D6),TYS!$A$1:$A$250,0),0)),TYS!$A:$I,9,FALSE)} -> 16:30
A7: 43638 | B7: F5L105 | C7: HF氫氟酸 | D7: TF59F18L105-2 | I7: 力積電P3 | K7: {=SUM(IF(TYS!$C$1:$C$250=$A7,IF(TYS!$K$1:$K$250=IFERROR(LEFT($D7,FIND("-",$D7,1)-1),$D7),TYS!$L$1:$L$250,0),0))} -> 1080 | L7: {=SUM(IF(TYS!$C$1:$C$250=$A7,IF(TYS!$K$1:$K$250=IFERROR(LEFT($D7,FIND("-",$D7,1)-1),$D7),TYS!$M$1:$M$250,0),0))} -> 10 | M7: {=VLOOKUP(SUM(IF(TYS!$C$1:$C$250=$A7,IF(TYS!$K$1:$K$250=IFERROR(LEFT($D7,FIND("-",$D7,1)-1),$D7),TYS!$A$1:$A$250,0),0)),TYS!$A:$I,8,FALSE)} -> 13:30 | N7: {=VLOOKUP(SUM(IF(TYS!$C$1:$C$250=$A7,IF(TYS!$K$1:$K$250=IFERROR(LEFT($D7,FIND("-",$D7,1)-1),$D7),TYS!$A$1:$A$250,0),0)),TYS!$A:$I,9,FALSE)} -> 16:30
A8: 43638 | B8: F5L106 | C8: HF氫氟酸 | D8: TF59F19L106-2 | I8: 力積電P3 | K8: {=SUM(IF(TYS!$C$1:$C$250=$A8,IF(TYS!$K$1:$K$250=IFERROR(LEFT($D8,FIND("-",$D8,1)-1),$D8),TYS!$L$1:$L$250,0),0))} -> 1080 | L8: {=SUM(IF(TYS!$C$1:$C$250=$A8,IF(TYS!$K$1:$K$250=IFERROR(LEFT($D8,FIND("-",$D8,1)-1),$D8),TYS!$M$1:$M$250,0),0))} -> 10 | M8: {=VLOOKUP(SUM(IF(TYS!$C$1:$C$250=$A8,IF(TYS!$K$1:$K$250=IFERROR(LEFT($D8,FIND("-",$D8,1)-1),$D8),TYS!$A$1:$A$250,0),0)),TYS!$A:$I,8,FALSE)} -> 16:40 | N8: {=VLOOKUP(SUM(IF(TYS!$C$1:$C$250=$A8,IF(TYS!$K$1:$K$250=IFERROR(LEFT($D8,FIND("-",$D8,1)-1),$D8),TYS!$A$1:$A$250,0),0)),TYS!$A:$I,9,FALSE)} -> 19:30
A9: 43639 | B9: F5L107 | C9: HF氫氟酸 | D9: TF59F19L107-2 | I9: 力積電P3 | K9: {=SUM(IF(TYS!$C$1:$C$250=$A9,IF(TYS!$K$1:$K$250=IFERROR(LEFT($D9,FIND("-",$D9,1)-1),$D9),TYS!$L$1:$L$250,0),0))} -> 1100 | L9: {=SUM(IF(TYS!$C$1:$C$250=$A9,IF(TYS!$K$1:$K$250=IFERROR(LEFT($D9,FIND("-",$D9,1)-1),$D9),TYS!$M$1:$M$250,0),0))} -> 20 | M9: {=VLOOKUP(SUM(IF(TYS!$C$1:$C$250=$A9,IF(TYS!$K$1:$K$250=IFERROR(LEFT($D9,FIND("-",$D9,1)-1),$D9),TYS!$A$1:$A$250,0),0)),TYS!$A:$I,8,FALSE)} -> 13:05 | N9: {=VLOOKUP(SUM(IF(TYS!$C$1:$C$250=$A9,IF(TYS!$K$1:$K$250=IFERROR(LEFT($D9,FIND("-",$D9,1)-1),$D9),TYS!$A$1:$A$250,0),0)),TYS!$A:$I,9,FALSE)} -> 16:00
A10: 43639 | B10: F5L301 | C10: HF氫氟酸 | D10: TF59F19L301-2 | I10: 力積電P1 | K10: {=SUM(IF(TYS!$C$1:$C$250=$A10,IF(TYS!$K$1:$K$250=IFERROR(LEFT($D10,FIND("-",$D10,1)-1),$D10),TYS!$L$1:$L$250,0),0))} -> 3110 | L10: {=SUM(IF(TYS!$C$1:$C$250=$A10,IF(TYS!$K$1:$K$250=IFERROR(LEFT($D10,FIND("-",$D10,1)-1),$D10),TYS!$M$1:$M$250,0),0))} -> 20 | M10: {=VLOOKUP(SUM(IF(TYS!$C$1:$C$250=$A10,IF(TYS!$K$1:$K$250=IFERROR(LEFT($D10,FIND("-",$D10,1)-1),$D10),TYS!$A$1:$A$250,0),0)),TYS!$A:$I,8,FALSE)} -> 13:00 | N10: {=VLOOKUP(SUM(IF(TYS!$C$1:$C$250=$A10,IF(TYS!$K$1:$K$250=IFERROR(LEFT($D10,FIND("-",$D10,1)-1),$D10),TYS!$A$1:$A$250,0),0)),TYS!$A:$I,9,FALSE)} -> 16:00
A11: 43639 | B11: F5L108 | C11: HF氫氟酸 | D11: TF59F20L108-2 | I11: 力積電P3 | K11: {=SUM(IF(TYS!$C$1:$C$250=$A11,IF(TYS!$K$1:$K$250=IFERROR(LEFT($D11,FIND("-",$D11,1)-1),$D11),TYS!$L$1:$L$250,0),0))} -> 1070 | L11: {=SUM(IF(TYS!$C$1:$C$250=$A11,IF(TYS!$K$1:$K$250=IFERROR(LEFT($D11,FIND("-",$D11,1)-1),$D11),TYS!$M$1:$M$250,0),0))} -> 320 | M11: {=VLOOKUP(SUM(IF(TYS!$C$1:$C$250=$A11,IF(TYS!$K$1:$K$250=IFERROR(LEFT($D11,FIND("-",$D11,1)-1),$D11),TYS!$A$1:$A$250,0),0)),TYS!$A:$I,8,FALSE)} -> 13:05 | N11: {=VLOOKUP(SUM(IF(TYS!$C$1:$C$250=$A11,IF(TYS!$K$1:$K$250=IFERROR(LEFT($D11,FIND("-",$D11,1)-1),$D11),TYS!$A$1:$A$250,0),0)),TYS!$A:$I,9,FALSE)} -> 16:00
A12: 43640 | B12: F5L109 | C12: HF氫氟酸 | D12: TF59F20L109-2 | I12: 力積電P3 | K12: {=SUM(IF(TYS!$C$1:$C$250=$A12,IF(TYS!$K$1:$K$250=IFERROR(LEFT($D12,FIND("-",$D12,1)-1),$D12),TYS!$L$1:$L$250,0),0))} -> 1050 | L12: {=SUM(IF(TYS!$C$1:$C$250=$A12,IF(TYS!$K$1:$K$250=IFERROR(LEFT($D12,FIND("-",$D12,1)-1),$D12),TYS!$M$1:$M$250,0),0))} -> 0 | M12: {=VLOOKUP(SUM(IF(TYS!$C$1:$C$250=$A12,IF(TYS!$K$1:$K$250=IFERROR(LEFT($D12,FIND("-",$D12,1)-1),$D12),TYS!$A$1:$A$250,0),0)),TYS!$A:$I,8,FALSE)} -> 09:00 | N12: {=VLOOKUP(SUM(IF(TYS!$C$1:$C$250=$A12,IF(TYS!$K$1:$K$250=IFERROR(LEFT($D12,FIND("-",$D12,1)-1),$D12),TYS!$A$1:$A$250,0),0)),TYS!$A:$I,9,FALSE)} -> 12:00
A13: 43637 | B13: F5L334 | C13: HF氫氟酸 | D13: TF59F20L334 | I13: 台灣美光科技/MMT | K13: {=SUM(IF(TYS!$C$1:$C$250=$A13,IF(TYS!$K$1:$K$250=IFERROR(LEFT($D13,FIND("-",$D13,1)-1),$D13),TYS!$L$1:$L$250,0),0))} -> 9220 | L13: {=SUM(IF(TYS!$C$1:$C$250=$A13,IF(TYS!$K$1:$K$250=IFERROR(LEFT($D13,FIND("-",$D13,1)-1),$D13),TYS!$M$1:$M$250,0),0))} -> 4470 | M13: {=VLOOKUP(SUM(IF(TYS!$C$1:$C$250=$A13,IF(TYS!$K$1:$K$250=IFERROR(LEFT($D13,FIND("-",$D13,1)-1),$D13),TYS!$A$1:$A$250,0),0)),TYS!$A:$I,8,FALSE)} -> 12:45 | N13: {=VLOOKUP(SUM(IF(TYS!$C$1:$C$250=$A13,IF(TYS!$K$1:$K$250=IFERROR(LEFT($D13,FIND("-",$D13,1)-1),$D13),TYS!$A$1:$A$250,0),0)),TYS!$A:$I,9,FALSE)} -> 16:40
A14: 43640 | B14: F5L101 | C14: HF氫氟酸 | D14: TF59F21L101 | I14: 力積電P3 | K14: {=SUM(IF(TYS!$C$1:$C$250=$A14,IF(TYS!$K$1:$K$250=IFERROR(LEFT($D14,FIND("-",$D14,1)-1),$D14),TYS!$L$1:$L$250,0),0))} -> 1100 | L14: {=SUM(IF(TYS!$C$1:$C$250=$A14,IF(TYS!$K$1:$K$250=IFERROR(LEFT($D14,FIND("-",$D14,1)-1),$D14),TYS!$M$1:$M$250,0),0))} -> 470 | M14: {=VLOOKUP(SUM(IF(TYS!$C$1:$C$250=$A14,IF(TYS!$K$1:$K$250=IFERROR(LEFT($D14,FIND("-",$D14,1)-1),$D14),TYS!$A$1:$A$250,0),0)),TYS!$A:$I,8,FALSE)} -> 09:00 | N14: {=VLOOKUP(SUM(IF(TYS!$C$1:$C$250=$A14,IF(TYS!$K$1:$K$250=IFERROR(LEFT($D14,FIND("-",$D14,1)-1),$D14),TYS!$A$1:$A$250,0),0)),TYS!$A:$I,9,FALSE)} -> 12:00
... A64: 43640 | B64: S6L016 | C64: 96%H2SO4硫酸 | D64: TS69F20L016-2 | I64: 台積電/TSMC F15-P1 | K64: {=SUM(IF(TYS!$C$1:$C$250=$A64,IF(TYS!$K$1:$K$250=IFERROR(LEFT($D64,FIND("-",$D64,1)-1),$D64),TYS!$L$1:$L$250,0),0))} -> 20440 | L64: {=SUM(IF(TYS!$C$1:$C$250=$A64,IF(TYS!$K$1:$K$250=IFERROR(LEFT($D64,FIND("-",$D64,1)-1),$D64),TYS!$M$1:$M$250,0),0))} -> 30 | M64: {=VLOOKUP(SUM(IF(TYS!$C$1:$C$250=$A64,IF(TYS!$K$1:$K$250=IFERROR(LEFT($D64,FIND("-",$D64,1)-1),$D64),TYS!$A$1:$A$250,0),0)),TYS!$A:$I,8,FALSE)} -> 00:00 | N64: {=VLOOKUP(SUM(IF(TYS!$C$1:$C$250=$A64,IF(TYS!$K$1:$K$250=IFERROR(LEFT($D64,FIND("-",$D64,1)-1),$D64),TYS!$A$1:$A$250,0),0)),TYS!$A:$I,9,FALSE)} -> 03:10
A65: 43637 | B65: S6L036 | C65: 96%H2SO4硫酸 | D65: TS69F20L036 | H65: 40 | I65: 聯芯USCX | K65: {=SUM(IF(TYS!$C$1:$C$250=$A65,IF(TYS!$K$1:$K$250=IFERROR(LEFT($D65,FIND("-",$D65,1)-1),$D65),TYS!$L$1:$L$250,0),0))} -> 0 | L65: {=SUM(IF(TYS!$C$1:$C$250=$A65,IF(TYS!$K$1:$K$250=IFERROR(LEFT($D65,FIND("-",$D65,1)-1),$D65),TYS!$M$1:$M$250,0),0))} -> 0 | M65: {=VLOOKUP(SUM(IF(TYS!$C$1:$C$250=$A65,IF(TYS!$K$1:$K$250=IFERROR(LEFT($D65,FIND("-",$D65,1)-1),$D65),TYS!$A$1:$A$250,0),0)),TYS!$A:$I,8,FALSE)} -> #N/A | N65: {=VLOOKUP(SUM(IF(TYS!$C$1:$C$250=$A65,IF(TYS!$K$1:$K$250=IFERROR(LEFT($D65,FIND("-",$D65,1)-1),$D65),TYS!$A$1:$A$250,0),0)),TYS!$A:$I,9,FALSE)} -> #N/A
A66: 43637 | B66: S6L055 | C66: 96%H2SO4硫酸 | D66: TS69F20L055-2 | I66: 聯芯USCX | K66: {=SUM(IF(TYS!$C$1:$C$250=$A66,IF(TYS!$K$1:$K$250=IFERROR(LEFT($D66,FIND("-",$D66,1)-1),$D66),TYS!$L$1:$L$250,0),0))} -> 0 | L66: {=SUM(IF(TYS!$C$1:$C$250=$A66,IF(TYS!$K$1:$K$250=IFERROR(LEFT($D66,FIND("-",$D66,1)-1),$D66),TYS!$M$1:$M$250,0),0))} -> 0 | M66: {=VLOOKUP(SUM(IF(TYS!$C$1:$C$250=$A66,IF(TYS!$K$1:$K$250=IFERROR(LEFT($D66,FIND("-",$D66,1)-1),$D66),TYS!$A$1:$A$250,0),0)),TYS!$A:$I,8,FALSE)} -> #N/A | N66: {=VLOOKUP(SUM(IF(TYS!$C$1:$C$250=$A66,IF(TYS!$K$1:$K$250=IFERROR(LEFT($D66,FIND("-",$D66,1)-1),$D66),TYS!$A$1:$A$250,0),0)),TYS!$A:$I,9,FALSE)} -> #N/A
A67: 43638 | B67: S6L611 | C67: 96%H2SO4硫酸 | D67: TS69F20L611-2 | I67: 台灣美光科技/MMT | K67: {=SUM(IF(TYS!$C$1:$C$250=$A67,IF(TYS!$K$1:$K$250=IFERROR(LEFT($D67,FIND("-",$D67,1)-1),$D67),TYS!$L$1:$L$250,0),0))} -> 10250 | L67: {=SUM(IF(TYS!$C$1:$C$250=$A67,IF(TYS!$K$1:$K$250=IFERROR(LEFT($D67,FIND("-",$D67,1)-1),$D67),TYS!$M$1:$M$250,0),0))} -> 100 | M67: {=VLOOKUP(SUM(IF(TYS!$C$1:$C$250=$A67,IF(TYS!$K$1:$K$250=IFERROR(LEFT($D67,FIND("-",$D67,1)-1),$D67),TYS!$A$1:$A$250,0),0)),TYS!$A:$I,8,FALSE)} -> 08:00 | N67: {=VLOOKUP(SUM(IF(TYS!$C$1:$C$250=$A67,IF(TYS!$K$1:$K$250=IFERROR(LEFT($D67,FIND("-",$D67,1)-1),$D67),TYS!$A$1:$A$250,0),0)),TYS!$A:$I,9,FALSE)} -> 12:00
A68: 43639 | B68: S6L617 | C68: 96%H2SO4硫酸 | D68: TS69F20L617-2 | I68: 台灣美光科技/MMT | K68: {=SUM(IF(TYS!$C$1:$C$250=$A68,IF(TYS!$K$1:$K$250=IFERROR(LEFT($D68,FIND("-",$D68,1)-1),$D68),TYS!$L$1:$L$250,0),0))} -> 11010 | L68: {=SUM(IF(TYS!$C$1:$C$250=$A68,IF(TYS!$K$1:$K$250=IFERROR(LEFT($D68,FIND("-",$D68,1)-1),$D68),TYS!$M$1:$M$250,0),0))} -> 90 | M68: {=VLOOKUP(SUM(IF(TYS!$C$1:$C$250=$A68,IF(TYS!$K$1:$K$250=IFERROR(LEFT($D68,FIND("-",$D68,1)-1),$D68),TYS!$A$1:$A$250,0),0)),TYS!$A:$I,8,FALSE)} -> 05:00 | N68: {=VLOOKUP(SUM(IF(TYS!$C$1:$C$250=$A68,IF(TYS!$K$1:$K$250=IFERROR(LEFT($D68,FIND("-",$D68,1)-1),$D68),TYS!$A$1:$A$250,0),0)),TYS!$A:$I,9,FALSE)} -> 08:52
A69: 43639 | B69: S6L622 | C69: 96%H2SO4硫酸 | D69: TS69F20L622-2 | I69: 台積F12-P2 | K69: {=SUM(IF(TYS!$C$1:$C$250=$A69,IF(TYS!$K$1:$K$250=IFERROR(LEFT($D69,FIND("-",$D69,1)-1),$D69),TYS!$L$1:$L$250,0),0))} -> 11900 | L69: {=SUM(IF(TYS!$C$1:$C$250=$A69,IF(TYS!$K$1:$K$250=IFERROR(LEFT($D69,FIND("-",$D69,1)-1),$D69),TYS!$M$1:$M$250,0),0))} -> 80 | M69: {=VLOOKUP(SUM(IF(TYS!$C$1:$C$250=$A69,IF(TYS!$K$1:$K$250=IFERROR(LEFT($D69,FIND("-",$D69,1)-1),$D69),TYS!$A$1:$A$250,0),0)),TYS!$A:$I,8,FALSE)} -> 03:00 | N69: {=VLOOKUP(SUM(IF(TYS!$C$1:$C$250=$A69,IF(TYS!$K$1:$K$250=IFERROR(LEFT($D69,FIND("-",$D69,1)-1),$D69),TYS!$A$1:$A$250,0),0)),TYS!$A:$I,9,FALSE)} -> 10:00
A70: 43639 | B70: S6L624 | C70: 96%H2SO4硫酸 | D70: TS69F20L624-2 | I70: 台積電/TSMC-12 | K70: {=SUM(IF(TYS!$C$1:$C$250=$A70,IF(TYS!$K$1:$K$250=IFERROR(LEFT($D70,FIND("-",$D70,1)-1),$D70),TYS!$L$1:$L$250,0),0))} -> 11820 | L70: {=SUM(IF(TYS!$C$1:$C$250=$A70,IF(TYS!$K$1:$K$250=IFERROR(LEFT($D70,FIND("-",$D70,1)-1),$D70),TYS!$M$1:$M$250,0),0))} -> 70 | M70: {=VLOOKUP(SUM(IF(TYS!$C$1:$C$250=$A70,IF(TYS!$K$1:$K$250=IFERROR(LEFT($D70,FIND("-",$D70,1)-1),$D70),TYS!$A$1:$A$250,0),0)),TYS!$A:$I,8,FALSE)} -> 12:20 | N70: {=VLOOKUP(SUM(IF(TYS!$C$1:$C$250=$A70,IF(TYS!$K$1:$K$250=IFERROR(LEFT($D70,FIND("-",$D70,1)-1),$D70),TYS!$A$1:$A$250,0),0)),TYS!$A:$I,9,FALSE)} -> 18:30
A71: 43640 | B71: S6L014 | C71: 96%H2SO4硫酸 | D71: TS69F21L014-2 | I71: 台積電/TSMC F15-P2 | K71: {=SUM(IF(TYS!$C$1:$C$250=$A71,IF(TYS!$K$1:$K$250=IFERROR(LEFT($D71,FIND("-",$D71,1)-1),$D71),TYS!$L$1:$L$250,0),0))} -> 20310 | L71: {=SUM(IF(TYS!$C$1:$C$250=$A71,IF(TYS!$K$1:$K$250=IFERROR(LEFT($D71,FIND("-",$D71,1)-1),$D71),TYS!$M$1:$M$250,0),0))} -> 40 | M71: {=VLOOKUP(SUM(IF(TYS!$C$1:$C$250=$A71,IF(TYS!$K$1:$K$250=IFERROR(LEFT($D71,FIND("-",$D71,1)-1),$D71),TYS!$A$1:$A$250,0),0)),TYS!$A:$I,8,FALSE)} -> 00:00 | N71: {=VLOOKUP(SUM(IF(TYS!$C$1:$C$250=$A71,IF(TYS!$K$1:$K$250=IFERROR(LEFT($D71,FIND("-",$D71,1)-1),$D71),TYS!$A$1:$A$250,0),0)),TYS!$A:$I,9,FALSE)} -> 06:30
A72: 43640 | B72: S6L048 | C72: 96%H2SO4硫酸 | D72: TS69F21L048-2 | I72: 義鎧科技 | K72: {=SUM(IF(TYS!$C$1:$C$250=$A72,IF(TYS!$K$1:$K$250=IFERROR(LEFT($D72,FIND("-",$D72,1)-1),$D72),TYS!$L$1:$L$250,0),0))} -> 0 | L72: {=SUM(IF(TYS!$C$1:$C$250=$A72,IF(TYS!$K$1:$K$250=IFERROR(LEFT($D72,FIND("-",$D72,1)-1),$D72),TYS!$M$1:$M$250,0),0))} -> 0 | M72: {=VLOOKUP(SUM(IF(TYS!$C$1:$C$250=$A72,IF(TYS!$K$1:$K$250=IFERROR(LEFT($D72,FIND("-",$D72,1)-1),$D72),TYS!$A$1:$A$250,0),0)),TYS!$A:$I,8,FALSE)} -> #N/A | N72: {=VLOOKUP(SUM(IF(TYS!$C$1:$C$250=$A72,IF(TYS!$K$1:$K$250=IFERROR(LEFT($D72,FIND("-",$D72,1)-1),$D72),TYS!$A$1:$A$250,0),0)),TYS!$A:$I,9,FALSE)} -> #N/A
A73: 43639 | B73: S6L615 | C73: 96%H2SO4硫酸 | D73: TS69F21L615 | I73: 台灣美光科技/MMT | K73: {=SUM(IF(TYS!$C$1:$C$250=$A73,IF(TYS!$K$1:$K$250=IFERROR(LEFT($D73,FIND("-",$D73,1)-1),$D73),TYS!$L$1:$L$250,0),0))} -> 11040 | L73: {=SUM(IF(TYS!$C$1:$C$250=$A73,IF(TYS!$K$1:$K$250=IFERROR(LEFT($D73,FIND("-",$D73,1)-1),$D73),TYS!$M$1:$M$250,0),0))} -> 140 | M73: {=VLOOKUP(SUM(IF(TYS!$C$1:$C$250=$A73,IF(TYS!$K$1:$K$250=IFERROR(LEFT($D73,FIND("-",$D73,1)-1),$D73),TYS!$A$1:$A$250,0),0)),TYS!$A:$I,8,FALSE)} -> 16:20 | N73: {=VLOOKUP(SUM(IF(TYS!$C$1:$C$250=$A73,IF(TYS!$K$1:$K$250=IFERROR(LEFT($D73,FIND("-",$D73,1)-1),$D73),TYS!$A$1:$A$250,0),0)),TYS!$A:$I,9,FALSE)} -> 20:50
A74: 43639 | B74: S6L621 | C74: 96%H2SO4硫酸 | D74: TS69F21L621 | I74: 美光晶圓1 | K74: {=SUM(IF(TYS!$C$1:$C$250=$A74,IF(TYS!$K$1:$K$250=IFERROR(LEFT($D74,FIND("-",$D74,1)-1),$D74),TYS!$L$1:$L$250,0),0))} -> 11730 | L74: {=SUM(IF(TYS!$C$1:$C$250=$A74,IF(TYS!$K$1:$K$250=IFERROR(LEFT($D74,FIND("-",$D74,1)-1),$D74),TYS!$M$1:$M$250,0),0))} -> 80 | M74: {=VLOOKUP(SUM(IF(TYS!$C$1:$C$250=$A74,IF(TYS!$K$1:$K$250=IFERROR(LEFT($D74,FIND("-",$D74,1)-1),$D74),TYS!$A$1:$A$250,0),0)),TYS!$A:$I,8,FALSE)} -> 12:10 | N74: {=VLOOKUP(SUM(IF(TYS!$C$1:$C$250=$A74,IF(TYS!$K$1:$K$250=IFERROR(LEFT($D74,FIND("-",$D74,1)-1),$D74),TYS!$A$1:$A$250,0),0)),TYS!$A:$I,9,FALSE)} -> 16:00
A75: 43640 | B75: S6L608 | C75: 96%H2SO4硫酸 | D75: TS69F22L608 | I75: 台灣美光科技/MMT | K75: {=SUM(IF(TYS!$C$1:$C$250=$A75,IF(TYS!$K$1:$K$250=IFERROR(LEFT($D75,FIND("-",$D75,1)-1),$D75),TYS!$L$1:$L$250,0),0))} -> 10190 | L75: {=SUM(IF(TYS!$C$1:$C$250=$A75,IF(TYS!$K$1:$K$250=IFERROR(LEFT($D75,FIND("-",$D75,1)-1),$D75),TYS!$M$1:$M$250,0),0))} -> 60 | M75: {=VLOOKUP(SUM(IF(TYS!$C$1:$C$250=$A75,IF(TYS!$K$1:$K$250=IFERROR(LEFT($D75,FIND("-",$D75,1)-1),$D75),TYS!$A$1:$A$250,0),0)),TYS!$A:$I,8,FALSE)} -> 12:50 | N75: {=VLOOKUP(SUM(IF(TYS!$C$1:$C$250=$A75,IF(TYS!$K$1:$K$250=IFERROR(LEFT($D75,FIND("-",$D75,1)-1),$D75),TYS!$A$1:$A$250,0),0)),TYS!$A:$I,9,FALSE)} -> 16:30
A76: 43640 | B76: S6L612 | C76: 96%H2SO4硫酸 | D76: TS69F22L612 | I76: 美光晶圓1 | K76: {=SUM(IF(TYS!$C$1:$C$250=$A76,IF(TYS!$K$1:$K$250=IFERROR(LEFT($D76,FIND("-",$D76,1)-1),$D76),TYS!$L$1:$L$250,0),0))} -> 11720 | L76: {=SUM(IF(TYS!$C$1:$C$250=$A76,IF(TYS!$K$1:$K$250=IFERROR(LEFT($D76,FIND("-",$D76,1)-1),$D76),TYS!$M$1:$M$250,0),0))} -> 270 | M76: {=VLOOKUP(SUM(IF(TYS!$C$1:$C$250=$A76,IF(TYS!$K$1:$K$250=IFERROR(LEFT($D76,FIND("-",$D76,1)-1),$D76),TYS!$A$1:$A$250,0),0)),TYS!$A:$I,8,FALSE)} -> 12:10 | N76: {=VLOOKUP(SUM(IF(TYS!$C$1:$C$250=$A76,IF(TYS!$K$1:$K$250=IFERROR(LEFT($D76,FIND("-",$D76,1)-1),$D76),TYS!$A$1:$A$250,0),0)),TYS!$A:$I,9,FALSE)} -> 16:20
A77: 43640 | B77: S6L625 | C77: 96%H2SO4硫酸 | D77: TS69F22L625 | H77: 10 | I77: 台積F12-P2 | K77: {=SUM(IF(TYS!$C$1:$C$250=$A77,IF(TYS!$K$1:$K$250=IFERROR(LEFT($D77,FIND("-",$D77,1)-1),$D77),TYS!$L$1:$L$250,0),0))} -> 11830 | L77: {=SUM(IF(TYS!$C$1:$C$250=$A77,IF(TYS!$K$1:$K$250=IFERROR(LEFT($D77,FIND("-",$D77,1)-1),$D77),TYS!$M$1:$M$250,0),0))} -> 20 | M77: {=VLOOKUP(SUM(IF(TYS!$C$1:$C$250=$A77,IF(TYS!$K$1:$K$250=IFERROR(LEFT($D77,FIND("-",$D77,1)-1),$D77),TYS!$A$1:$A$250,0),0)),TYS!$A:$I,8,FALSE)} -> 16:30 | N77: {=VLOOKUP(SUM(IF(TYS!$C$1:$C$250=$A77,IF(TYS!$K$1:$K$250=IFERROR(LEFT($D77,FIND("-",$D77,1)-1),$D77),TYS!$A$1:$A$250,0),0)),TYS!$A:$I,9,FALSE)} -> 23:55
A78: 43640 | B78: S6L628 | C78: 96%H2SO4硫酸 | D78: TS69F22L628 | H78: 10 | I78: 台積電0030 | K78: {=SUM(IF(TYS!$C$1:$C$250=$A78,IF(TYS!$K$1:$K$250=IFERROR(LEFT($D78,FIND("-",$D78,1)-1),$D78),TYS!$L$1:$L$250,0),0))} -> 10090 | L78: {=SUM(IF(TYS!$C$1:$C$250=$A78,IF(TYS!$K$1:$K$250=IFERROR(LEFT($D78,FIND("-",$D78,1)-1),$D78),TYS!$M$1:$M$250,0),0))} -> 50 | M78: {=VLOOKUP(SUM(IF(TYS!$C$1:$C$250=$A78,IF(TYS!$K$1:$K$250=IFERROR(LEFT($D78,FIND("-",$D78,1)-1),$D78),TYS!$A$1:$A$250,0),0)),TYS!$A:$I,8,FALSE)} -> 07:50 | N78: {=VLOOKUP(SUM(IF(TYS!$C$1:$C$250=$A78,IF(TYS!$K$1:$K$250=IFERROR(LEFT($D78,FIND("-",$D78,1)-1),$D78),TYS!$A$1:$A$250,0),0)),TYS!$A:$I,9,FALSE)} -> 12:30
A79: 43637 | B79: S9L218 | C79: H2SO4硫酸 | D79: TS99F08L218-2 | I79: 世界先進2A | K79: {=SUM(IF(TYS!$C$1:$C$250=$A79,IF(TYS!$K$1:$K$250=IFERROR(LEFT($D79,FIND("-",$D79,1)-1),$D79),TYS!$L$1:$L$250,0),0))} -> 20200 | L79: {=SUM(IF(TYS!$C$1:$C$250=$A79,IF(TYS!$K$1:$K$250=IFERROR(LEFT($D79,FIND("-",$D79,1)-1),$D79),TYS!$M$1:$M$250,0),0))} -> 1680 | M79: {=VLOOKUP(SUM(IF(TYS!$C$1:$C$250=$A79,IF(TYS!$K$1:$K$250=IFERROR(LEFT($D79,FIND("-",$D79,1)-1),$D79),TYS!$A$1:$A$250,0),0)),TYS!$A:$I,8,FALSE)} -> 08:10 | N79: {=VLOOKUP(SUM(IF(TYS!$C$1:$C$250=$A79,IF(TYS!$K$1:$K$250=IFERROR(LEFT($D79,FIND("-",$D79,1)-1),$D79),TYS!$A$1:$A$250,0),0)),TYS!$A:$I,9,FALSE)} -> 13:30
A80: 43637 | B80: S9LW61 | C80: H2SO4硫酸 | D80: TS99F15LW61-2 | I80: Nexchip | K80: {=SUM(IF(TYS!$C$1:$C$250=$A80,IF(TYS!$K$1:$K$250=IFERROR(LEFT($D80,FIND("-",$D80,1)-1),$D80),TYS!$L$1:$L$250,0),0))} -> 0 | L80: {=SUM(IF(TYS!$C$1:$C$250=$A80,IF(TYS!$K$1:$K$250=IFERROR(LEFT($D80,FIND("-",$D80,1)-1),$D80),TYS!$M$1:$M$250,0),0))} -> 0 | M80: {=VLOOKUP(SUM(IF(TYS!$C$1:$C$250=$A80,IF(TYS!$K$1:$K$250=IFERROR(LEFT($D80,FIND("-",$D80,1)-1),$D80),TYS!$A$1:$A$250,0),0)),TYS!$A:$I,8,FALSE)} -> #N/A | N80: {=VLOOKUP(SUM(IF(TYS!$C$1:$C$250=$A80,IF(TYS!$K$1:$K$250=IFERROR(LEFT($D80,FIND("-",$D80,1)-1),$D80),TYS!$A$1:$A$250,0),0)),TYS!$A:$I,9,FALSE)} -> #N/A
A81: 43637 | B81: S9L104 | C81: H2SO4硫酸 | D81: TS99F17L104-2 | I81: 力積電8A | K81: {=SUM(IF(TYS!$C$1:$C$250=$A81,IF(TYS!$K$1:$K$250=IFERROR(LEFT($D81,FIND("-",$D81,1)-1),$D81),TYS!$L$1:$L$250,0),0))} -> 1740 | L81: {=SUM(IF(TYS!$C$1:$C$250=$A81,IF(TYS!$K$1:$K$250=IFERROR(LEFT($D81,FIND("-",$D81,1)-1),$D81),TYS!$M$1:$M$250,0),0))} -> 0 | M81: {=VLOOKUP(SUM(IF(TYS!$C$1:$C$250=$A81,IF(TYS!$K$1:$K$250=IFERROR(LEFT($D81,FIND("-",$D81,1)-1),$D81),TYS!$A$1:$A$250,0),0)),TYS!$A:$I,8,FALSE)} -> 10:10 | N81: {=VLOOKUP(SUM(IF(TYS!$C$1:$C$250=$A81,IF(TYS!$K$1:$K$250=IFERROR(LEFT($D81,FIND("-",$D81,1)-1),$D81),TYS!$A$1:$A$250,0),0)),TYS!$A:$I,9,FALSE)} -> 12:30
A82: 43638 | B82: S9L629 | C82: H2SO4硫酸 | D82: TS99F17L629-2 | I82: 力積電P2 | K82: {=SUM(IF(TYS!$C$1:$C$250=$A82,IF(TYS!$K$1:$K$250=IFERROR(LEFT($D82,FIND("-",$D82,1)-1),$D82),TYS!$L$1:$L$250,0),0))} -> 10960 | L82: {=SUM(IF(TYS!$C$1:$C$250=$A82,IF(TYS!$K$1:$K$250=IFERROR(LEFT($D82,FIND("-",$D82,1)-1),$D82),TYS!$M$1:$M$250,0),0))} -> 0 | M82: {=VLOOKUP(SUM(IF(TYS!$C$1:$C$250=$A82,IF(TYS!$K$1:$K$250=IFERROR(LEFT($D82,FIND("-",$D82,1)-1),$D82),TYS!$A$1:$A$250,0),0)),TYS!$A:$I,8,FALSE)} -> 08:50 | N82: {=VLOOKUP(SUM(IF(TYS!$C$1:$C$250=$A82,IF(TYS!$K$1:$K$250=IFERROR(LEFT($D82,FIND("-",$D82,1)-1),$D82),TYS!$A$1:$A$250,0),0)),TYS!$A:$I,9,FALSE)} -> 13:10
A83: 43640 | C83: H2SO4硫酸 | D83: TS99F18D330 | I83: 力積電8B | K83: {=SUM(IF(TYS!$C$1:$C$250=$A83,IF(TYS!$K$1:$K$250=IFERROR(LEFT($D83,FIND("-",$D83,1)-1),$D83),TYS!$L$1:$L$250,0),0))} -> 0 | L83: {=SUM(IF(TYS!$C$1:$C$250=$A83,IF(TYS!$K$1:$K$250=IFERROR(LEFT($D83,FIND("-",$D83,1)-1),$D83),TYS!$M$1:$M$250,0),0))} -> 0 | M83: {=VLOOKUP(SUM(IF(TYS!$C$1:$C$250=$A83,IF(TYS!$K$1:$K$250=IFERROR(LEFT($D83,FIND("-",$D83,1)-1),$D83),TYS!$A$1:$A$250,0),0)),TYS!$A:$I,8,FALSE)} -> #N/A | N83: {=VLOOKUP(SUM(IF(TYS!$C$1:$C$250=$A83,IF(TYS!$K$1:$K$250=IFERROR(LEFT($D83,FIND("-",$D83,1)-1),$D83),TYS!$A$1:$A$250,0),0)),TYS!$A:$I,9,FALSE)} -> #N/A
A84: 43638 | B84: S9L101 | C84: H2SO4硫酸 | D84: TS99F18L101-2 | I84: 力積電8A | K84: {=SUM(IF(TYS!$C$1:$C$250=$A84,IF(TYS!$K$1:$K$250=IFERROR(LEFT($D84,FIND("-",$D84,1)-1),$D84),TYS!$L$1:$L$250,0),0))} -> 1760 | L84: {=SUM(IF(TYS!$C$1:$C$250=$A84,IF(TYS!$K$1:$K$250=IFERROR(LEFT($D84,FIND("-",$D84,1)-1),$D84),TYS!$M$1:$M$250,0),0))} -> 20 | M84: {=VLOOKUP(SUM(IF(TYS!$C$1:$C$250=$A84,IF(TYS!$K$1:$K$250=IFERROR(LEFT($D84,FIND("-",$D84,1)-1),$D84),TYS!$A$1:$A$250,0),0)),TYS!$A:$I,8,FALSE)} -> 12:00 | N84: {=VLOOKUP(SUM(IF(TYS!$C$1:$C$250=$A84,IF(TYS!$K$1:$K$250=IFERROR(LEFT($D84,FIND("-",$D84,1)-1),$D84),TYS!$A$1:$A$250,0),0)),TYS!$A:$I,9,FALSE)} -> 15:10
A85: 43637 | B85: S9L603 | C85: H2SO4硫酸 | D85: TS99F18L603-2 | I85: 世界先進2B | K85: {=SUM(IF(TYS!$C$1:$C$250=$A85,IF(TYS!$K$1:$K$250=IFERROR(LEFT($D85,FIND("-",$D85,1)-1),$D85),TYS!$L$1:$L$250,0),0))} -> 10240 | L85: {=SUM(IF(TYS!$C$1:$C$250=$A85,IF(TYS!$K$1:$K$250=IFERROR(LEFT($D85,FIND("-",$D85,1)-1),$D85),TYS!$M$1:$M$250,0),0))} -> 110 | M85: {=VLOOKUP(SUM(IF(TYS!$C$1:$C$250=$A85,IF(TYS!$K$1:$K$250=IFERROR(LEFT($D85,FIND("-",$D85,1)-1),$D85),TYS!$A$1:$A$250,0),0)),TYS!$A:$I,8,FALSE)} -> 12:25 | N85: {=VLOOKUP(SUM(IF(TYS!$C$1:$C$250=$A85,IF(TYS!$K$1:$K$250=IFERROR(LEFT($D85,FIND("-",$D85,1)-1),$D85),TYS!$A$1:$A$250,0),0)),TYS!$A:$I,9,FALSE)} -> 16:40
A86: 43637 | B86: S9L605 | C86: H2SO4硫酸 | D86: TS99F18L605-2 | I86: 世界先進/VISC | K86: {=SUM(IF(TYS!$C$1:$C$250=$A86,IF(TYS!$K$1:$K$250=IFERROR(LEFT($D86,FIND("-",$D86,1)-1),$D86),TYS!$L$1:$L$250,0),0))} -> 10170 | L86: {=SUM(IF(TYS!$C$1:$C$250=$A86,IF(TYS!$K$1:$K$250=IFERROR(LEFT($D86,FIND("-",$D86,1)-1),$D86),TYS!$M$1:$M$250,0),0))} -> 1080 | M86: {=VLOOKUP(SUM(IF(TYS!$C$1:$C$250=$A86,IF(TYS!$K$1:$K$250=IFERROR(LEFT($D86,FIND("-",$D86,1)-1),$D86),TYS!$A$1:$A$250,0),0)),TYS!$A:$I,8,FALSE)} -> 05:10 | N86: {=VLOOKUP(SUM(IF(TYS!$C$1:$C$250=$A86,IF(TYS!$K$1:$K$250=IFERROR(LEFT($D86,FIND("-",$D86,1)-1),$D86),TYS!$A$1:$A$250,0),0)),TYS!$A:$I,9,FALSE)} -> 09:45
A87: 43639 | B87: S9L102 | C87: H2SO4硫酸 | D87: TS99F19L102-2 | I87: 力積電8A | K87: {=SUM(IF(TYS!$C$1:$C$250=$A87,IF(TYS!$K$1:$K$250=IFERROR(LEFT($D87,FIND("-",$D87,1)-1),$D87),TYS!$L$1:$L$250,0),0))} -> 1720 | L87: {=SUM(IF(TYS!$C$1:$C$250=$A87,IF(TYS!$K$1:$K$250=IFERROR(LEFT($D87,FIND("-",$D87,1)-1),$D87),TYS!$M$1:$M$250,0),0))} -> 20 | M87: {=VLOOKUP(SUM(IF(TYS!$C$1:$C$250=$A87,IF(TYS!$K$1:$K$250=IFERROR(LEFT($D87,FIND("-",$D87,1)-1),$D87),TYS!$A$1:$A$250,0),0)),TYS!$A:$I,8,FALSE)} -> 14:20 | N87: {=VLOOKUP(SUM(IF(TYS!$C$1:$C$250=$A87,IF(TYS!$K$1:$K$250=IFERROR(LEFT($D87,FIND("-",$D87,1)-1),$D87),TYS!$A$1:$A$250,0),0)),TYS!$A:$I,9,FALSE)} -> 18:50
A88: 43640 | B88: S9L602 | C88: H2SO4硫酸 | D88: TS99F19L602-2 | I88: 台積F8B | K88: {=SUM(IF(TYS!$C$1:$C$250=$A88,IF(TYS!$K$1:$K$250=IFERROR(LEFT($D88,FIND("-",$D88,1)-1),$D88),TYS!$L$1:$L$250,0),0))} -> 10140 | L88: {=SUM(IF(TYS!$C$1:$C$250=$A88,IF(TYS!$K$1:$K$250=IFERROR(LEFT($D88,FIND("-",$D88,1)-1),$D88),TYS!$M$1:$M$250,0),0))} -> 130 | M88: {=VLOOKUP(SUM(IF(TYS!$C$1:$C$250=$A88,IF(TYS!$K$1:$K$250=IFERROR(LEFT($D88,FIND("-",$D88,1)-1),$D88),TYS!$A$1:$A$250,0),0)),TYS!$A:$I,8,FALSE)} -> 12:20 | N88: {=VLOOKUP(SUM(IF(TYS!$C$1:$C$250=$A88,IF(TYS!$K$1:$K$250=IFERROR(LEFT($D88,FIND("-",$D88,1)-1),$D88),TYS!$A$1:$A$250,0),0)),TYS!$A:$I,9,FALSE)} -> 17:00
A89: 43638 | B89: S9L604 | C89: H2SO4硫酸 | D89: TS99F19L604-2 | I89: 力積電P1 | K89: {=SUM(IF(TYS!$C$1:$C$250=$A89,IF(TYS!$K$1:$K$250=IFERROR(LEFT($D89,FIND("-",$D89,1)-1),$D89),TYS!$L$1:$L$250,0),0))} -> 10250 | L89: {=SUM(IF(TYS!$C$1:$C$250=$A89,IF(TYS!$K$1:$K$250=IFERROR(LEFT($D89,FIND("-",$D89,1)-1),$D89),TYS!$M$1:$M$250,0),0))} -> 2520 | M89: {=VLOOKUP(SUM(IF(TYS!$C$1:$C$250=$A89,IF(TYS!$K$1:$K$250=IFERROR(LEFT($D89,FIND("-",$D89,1)-1),$D89),TYS!$A$1:$A$250,0),0)),TYS!$A:$I,8,FALSE)} -> 08:20 | N89: {=VLOOKUP(SUM(IF(TYS!$C$1:$C$250=$A89,IF(TYS!$K$1:$K$250=IFERROR(LEFT($D89,FIND("-",$D89,1)-1),$D89),TYS!$A$1:$A$250,0),0)),TYS!$A:$I,9,FALSE)} -> 11:55
...
