Workbook

Sheet METAL (2)
D2: DATE | E2: ='METAL RAW DATA'!E2 -> 0
B3: ICP- MS 金屬 R&amp;R測試 | D3: A | E3: ='METAL RAW DATA'!E3 -> 0
D4: B | E4: ='METAL RAW DATA'!E4 -> 0
B6: 技師別 | C6: A | D6: A | E6: A | F6: A | G6: A | H6: A | I6: A | J6: A | K6: A | L6: A | M6: A | N6: A | O6: A | P6: A | Q6: A | R6: A | S6: A | T6: A | U6: A | V6: A
B7: N1 ~ N2 | C7: N1 | D7: N1 | E7: N1 | F7: N1 | G7: N1 | H7: N1 | I7: N1 | J7: N1 | K7: N1 | L7: N1 | M7: N2 | N7: N2 | O7: N2 | P7: N2 | Q7: N2 | R7: N2 | S7: N2 | T7: N2 | U7: N2 | V7: N2
B8: Na | C8: ='METAL RAW DATA'!C8 -> 0 | D8: ='METAL RAW DATA'!D8 -> 0 | E8: ='METAL RAW DATA'!E8 -> 0 | F8: ='METAL RAW DATA'!F8 -> 0 | G8: ='METAL RAW DATA'!G8 -> 0 | H8: ='METAL RAW DATA'!H8 -> 0 | I8: ='METAL RAW DATA'!I8 -> 0 | J8: ='METAL RAW DATA'!J8 -> 0 | ... V8: ='METAL RAW DATA'!V8 -> 0
B9: Mg | C9: ='METAL RAW DATA'!C9 -> 0 | D9: ='METAL RAW DATA'!D9 -> 0 | E9: ='METAL RAW DATA'!E9 -> 0 | F9: ='METAL RAW DATA'!F9 -> 0 | G9: ='METAL RAW DATA'!G9 -> 0 | H9: ='METAL RAW DATA'!H9 -> 0 | I9: ='METAL RAW DATA'!I9 -> 0 | J9: ='METAL RAW DATA'!J9 -> 0 | ... V9: ='METAL RAW DATA'!V9 -> 0
B10: Al | C10: ='METAL RAW DATA'!C10 -> 0 | D10: ='METAL RAW DATA'!D10 -> 0 | E10: ='METAL RAW DATA'!E10 -> 0 | F10: ='METAL RAW DATA'!F10 -> 0 | G10: ='METAL RAW DATA'!G10 -> 0 | H10: ='METAL RAW DATA'!H10 -> 0 | I10: ='METAL RAW DATA'!I10 -> 0 | J10: ='METAL RAW DATA'!J10 -> 0 | ... V10: ='METAL RAW DATA'!V10 -> 0
B11: K | C11: ='METAL RAW DATA'!C11 -> 0 | D11: ='METAL RAW DATA'!D11 -> 0 | E11: ='METAL RAW DATA'!E11 -> 0 | F11: ='METAL RAW DATA'!F11 -> 0 | G11: ='METAL RAW DATA'!G11 -> 0 | H11: ='METAL RAW DATA'!H11 -> 0 | I11: ='METAL RAW DATA'!I11 -> 0 | J11: ='METAL RAW DATA'!J11 -> 0 | ... V11: ='METAL RAW DATA'!V11 -> 0
B12: Ca | C12: ='METAL RAW DATA'!C12 -> 0 | D12: ='METAL RAW DATA'!D12 -> 0 | E12: ='METAL RAW DATA'!E12 -> 0 | F12: ='METAL RAW DATA'!F12 -> 0 | G12: ='METAL RAW DATA'!G12 -> 0 | H12: ='METAL RAW DATA'!H12 -> 0 | I12: ='METAL RAW DATA'!I12 -> 0 | J12: ='METAL RAW DATA'!J12 -> 0 | ... V12: ='METAL RAW DATA'!V12 -> 0
B13: Cr | C13: ='METAL RAW DATA'!C13 -> 0 | D13: ='METAL RAW DATA'!D13 -> 0 | E13: ='METAL RAW DATA'!E13 -> 0 | F13: ='METAL RAW DATA'!F13 -> 0 | G13: ='METAL RAW DATA'!G13 -> 0 | H13: ='METAL RAW DATA'!H13 -> 0 | I13: ='METAL RAW DATA'!I13 -> 0 | J13: ='METAL RAW DATA'!J13 -> 0 | ... V13: ='METAL RAW DATA'!V13 -> 0
B14: Mn | C14: ='METAL RAW DATA'!C14 -> 0 | D14: ='METAL RAW DATA'!D14 -> 0 | E14: ='METAL RAW DATA'!E14 -> 0 | F14: ='METAL RAW DATA'!F14 -> 0 | G14: ='METAL RAW DATA'!G14 -> 0 | H14: ='METAL RAW DATA'!H14 -> 0 | I14: ='METAL RAW DATA'!I14 -> 0 | J14: ='METAL RAW DATA'!J14 -> 0 | ... V14: ='METAL RAW DATA'!V14 -> 0
B15: Fe | C15: ='METAL RAW DATA'!C15 -> 0 | D15: ='METAL RAW DATA'!D15 -> 0 | E15: ='METAL RAW DATA'!E15 -> 0 | F15: ='METAL RAW DATA'!F15 -> 0 | G15: ='METAL RAW DATA'!G15 -> 0 | H15: ='METAL RAW DATA'!H15 -> 0 | I15: ='METAL RAW DATA'!I15 -> 0 | J15: ='METAL RAW DATA'!J15 -> 0 | ... V15: ='METAL RAW DATA'!V15 -> 0
B16: Ni | C16: ='METAL RAW DATA'!C16 -> 0 | D16: ='METAL RAW DATA'!D16 -> 0 | E16: ='METAL RAW DATA'!E16 -> 0 | F16: ='METAL RAW DATA'!F16 -> 0 | G16: ='METAL RAW DATA'!G16 -> 0 | H16: ='METAL RAW DATA'!H16 -> 0 | I16: ='METAL RAW DATA'!I16 -> 0 | J16: ='METAL RAW DATA'!J16 -> 0 | ... V16: ='METAL RAW DATA'!V16 -> 0
B17: Co | C17: ='METAL RAW DATA'!C17 -> 0 | D17: ='METAL RAW DATA'!D17 -> 0 | E17: ='METAL RAW DATA'!E17 -> 0 | F17: ='METAL RAW DATA'!F17 -> 0 | G17: ='METAL RAW DATA'!G17 -> 0 | H17: ='METAL RAW DATA'!H17 -> 0 | I17: ='METAL RAW DATA'!I17 -> 0 | J17: ='METAL RAW DATA'!J17 -> 0 | ... V17: ='METAL RAW DATA'!V17 -> 0
B18: Cu | C18: ='METAL RAW DATA'!C18 -> 0 | D18: ='METAL RAW DATA'!D18 -> 0 | E18: ='METAL RAW DATA'!E18 -> 0 | F18: ='METAL RAW DATA'!F18 -> 0 | G18: ='METAL RAW DATA'!G18 -> 0 | H18: ='METAL RAW DATA'!H18 -> 0 | I18: ='METAL RAW DATA'!I18 -> 0 | J18: ='METAL RAW DATA'!J18 -> 0 | ... V18: ='METAL RAW DATA'!V18 -> 0
B19: Zn | C19: ='METAL RAW DATA'!C19 -> 0 | D19: ='METAL RAW DATA'!D19 -> 0 | E19: ='METAL RAW DATA'!E19 -> 0 | F19: ='METAL RAW DATA'!F19 -> 0 | G19: ='METAL RAW DATA'!G19 -> 0 | H19: ='METAL RAW DATA'!H19 -> 0 | I19: ='METAL RAW DATA'!I19 -> 0 | J19: ='METAL RAW DATA'!J19 -> 0 | ... V19: ='METAL RAW DATA'!V19 -> 0
B20: Pb | C20: ='METAL RAW DATA'!C20 -> 0 | D20: ='METAL RAW DATA'!D20 -> 0 | E20: ='METAL RAW DATA'!E20 -> 0 | F20: ='METAL RAW DATA'!F20 -> 0 | G20: ='METAL RAW DATA'!G20 -> 0 | H20: ='METAL RAW DATA'!H20 -> 0 | I20: ='METAL RAW DATA'!I20 -> 0 | J20: ='METAL RAW DATA'!J20 -> 0 | ... V20: ='METAL RAW DATA'!V20 -> 0
B23: 技師別 | C23: B | D23: B | E23: B | F23: B | G23: B | H23: B | I23: B | J23: B | K23: B | L23: B | M23: B | N23: B | O23: B | P23: B | Q23: B | R23: B | S23: B | T23: B | U23: B | V23: B
B24: N1 ~ N2 | C24: N1 | D24: N1 | E24: N1 | F24: N1 | G24: N1 | H24: N1 | I24: N1 | J24: N1 | K24: N1 | L24: N1 | M24: N2 | N24: N2 | O24: N2 | P24: N2 | Q24: N2 | R24: N2 | S24: N2 | T24: N2 | U24: N2 | V24: N2
B25: Na | C25: ='METAL RAW DATA'!W8 -> 0 | D25: ='METAL RAW DATA'!X8 -> 0 | E25: ='METAL RAW DATA'!Y8 -> 0 | F25: ='METAL RAW DATA'!Z8 -> 0 | G25: ='METAL RAW DATA'!AA8 -> 0 | H25: ='METAL RAW DATA'!AB8 -> 0 | I25: ='METAL RAW DATA'!AC8 -> 0 | J25: ='METAL RAW DATA'!AD8 -> 0 | ... V25: ='METAL RAW DATA'!AP8 -> 0
B26: Mg | C26: ='METAL RAW DATA'!W9 -> 0 | D26: ='METAL RAW DATA'!X9 -> 0 | E26: ='METAL RAW DATA'!Y9 -> 0 | F26: ='METAL RAW DATA'!Z9 -> 0 | G26: ='METAL RAW DATA'!AA9 -> 0 | H26: ='METAL RAW DATA'!AB9 -> 0 | I26: ='METAL RAW DATA'!AC9 -> 0 | J26: ='METAL RAW DATA'!AD9 -> 0 | ... V26: ='METAL RAW DATA'!AP9 -> 0
B27: Al | C27: ='METAL RAW DATA'!W10 -> 0 | D27: ='METAL RAW DATA'!X10 -> 0 | E27: ='METAL RAW DATA'!Y10 -> 0 | F27: ='METAL RAW DATA'!Z10 -> 0 | G27: ='METAL RAW DATA'!AA10 -> 0 | H27: ='METAL RAW DATA'!AB10 -> 0 | I27: ='METAL RAW DATA'!AC10 -> 0 | J27: ='METAL RAW DATA'!AD10 -> 0 | ... V27: ='METAL RAW DATA'!AP10 -> 0
B28: K | C28: ='METAL RAW DATA'!W11 -> 0 | D28: ='METAL RAW DATA'!X11 -> 0 | E28: ='METAL RAW DATA'!Y11 -> 0 | F28: ='METAL RAW DATA'!Z11 -> 0 | G28: ='METAL RAW DATA'!AA11 -> 0 | H28: ='METAL RAW DATA'!AB11 -> 0 | I28: ='METAL RAW DATA'!AC11 -> 0 | J28: ='METAL RAW DATA'!AD11 -> 0 | ... V28: ='METAL RAW DATA'!AP11 -> 0
B29: Ca | C29: ='METAL RAW DATA'!W12 -> 0 | D29: ='METAL RAW DATA'!X12 -> 0 | E29: ='METAL RAW DATA'!Y12 -> 0 | F29: ='METAL RAW DATA'!Z12 -> 0 | G29: ='METAL RAW DATA'!AA12 -> 0 | H29: ='METAL RAW DATA'!AB12 -> 0 | I29: ='METAL RAW DATA'!AC12 -> 0 | J29: ='METAL RAW DATA'!AD12 -> 0 | ... V29: ='METAL RAW DATA'!AP12 -> 0
B30: Cr | C30: ='METAL RAW DATA'!W13 -> 0 | D30: ='METAL RAW DATA'!X13 -> 0 | E30: ='METAL RAW DATA'!Y13 -> 0 | F30: ='METAL RAW DATA'!Z13 -> 0 | G30: ='METAL RAW DATA'!AA13 -> 0 | H30: ='METAL RAW DATA'!AB13 -> 0 | I30: ='METAL RAW DATA'!AC13 -> 0 | J30: ='METAL RAW DATA'!AD13 -> 0 | ... V30: ='METAL RAW DATA'!AP13 -> 0
B31: Mn | C31: ='METAL RAW DATA'!W14 -> 0 | D31: ='METAL RAW DATA'!X14 -> 0 | E31: ='METAL RAW DATA'!Y14 -> 0 | F31: ='METAL RAW DATA'!Z14 -> 0 | G31: ='METAL RAW DATA'!AA14 -> 0 | H31: ='METAL RAW DATA'!AB14 -> 0 | I31: ='METAL RAW DATA'!AC14 -> 0 | J31: ='METAL RAW DATA'!AD14 -> 0 | ... V31: ='METAL RAW DATA'!AP14 -> 0
B32: Fe | C32: ='METAL RAW DATA'!W15 -> 0 | D32: ='METAL RAW DATA'!X15 -> 0 | E32: ='METAL RAW DATA'!Y15 -> 0 | F32: ='METAL RAW DATA'!Z15 -> 0 | G32: ='METAL RAW DATA'!AA15 -> 0 | H32: ='METAL RAW DATA'!AB15 -> 0 | I32: ='METAL RAW DATA'!AC15 -> 0 | J32: ='METAL RAW DATA'!AD15 -> 0 | ... V32: ='METAL RAW DATA'!AP15 -> 0
B33: Ni | C33: ='METAL RAW DATA'!W16 -> 0 | D33: ='METAL RAW DATA'!X16 -> 0 | E33: ='METAL RAW DATA'!Y16 -> 0 | F33: ='METAL RAW DATA'!Z16 -> 0 | G33: ='METAL RAW DATA'!AA16 -> 0 | H33: ='METAL RAW DATA'!AB16 -> 0 | I33: ='METAL RAW DATA'!AC16 -> 0 | J33: ='METAL RAW DATA'!AD16 -> 0 | ... V33: ='METAL RAW DATA'!AP16 -> 0
B34: Co | C34: ='METAL RAW DATA'!W17 -> 0 | D34: ='METAL RAW DATA'!X17 -> 0 | E34: ='METAL RAW DATA'!Y17 -> 0 | F34: ='METAL RAW DATA'!Z17 -> 0 | G34: ='METAL RAW DATA'!AA17 -> 0 | H34: ='METAL RAW DATA'!AB17 -> 0 | I34: ='METAL RAW DATA'!AC17 -> 0 | J34: ='METAL RAW DATA'!AD17 -> 0 | ... V34: ='METAL RAW DATA'!AP17 -> 0
B35: Cu | C35: ='METAL RAW DATA'!W18 -> 0 | D35: ='METAL RAW DATA'!X18 -> 0 | E35: ='METAL RAW DATA'!Y18 -> 0 | F35: ='METAL RAW DATA'!Z18 -> 0 | G35: ='METAL RAW DATA'!AA18 -> 0 | H35: ='METAL RAW DATA'!AB18 -> 0 | I35: ='METAL RAW DATA'!AC18 -> 0 | J35: ='METAL RAW DATA'!AD18 -> 0 | ... V35: ='METAL RAW DATA'!AP18 -> 0
B36: Zn | C36: ='METAL RAW DATA'!W19 -> 0 | D36: ='METAL RAW DATA'!X19 -> 0 | E36: ='METAL RAW DATA'!Y19 -> 0 | F36: ='METAL RAW DATA'!Z19 -> 0 | G36: ='METAL RAW DATA'!AA19 -> 0 | H36: ='METAL RAW DATA'!AB19 -> 0 | I36: ='METAL RAW DATA'!AC19 -> 0 | J36: ='METAL RAW DATA'!AD19 -> 0 | ... V36: ='METAL RAW DATA'!AP19 -> 0
B37: Pb | C37: ='METAL RAW DATA'!W20 -> 0 | D37: ='METAL RAW DATA'!X20 -> 0 | E37: ='METAL RAW DATA'!Y20 -> 0 | F37: ='METAL RAW DATA'!Z20 -> 0 | G37: ='METAL RAW DATA'!AA20 -> 0 | H37: ='METAL RAW DATA'!AB20 -> 0 | I37: ='METAL RAW DATA'!AC20 -> 0 | J37: ='METAL RAW DATA'!AD20 -> 0 | ... V37: ='METAL RAW DATA'!AP20 -> 0

Sheet METAL RAW DATA
B2: H2SO4 | D2: DATE
B3: ICP- MS 金屬 R-R測試 | D3: A
B4: 測定日期 | D4: B
B5: 測定項目
B6: 技師別 | C6: A | D6: A | E6: A | F6: A | G6: A | H6: A | I6: A | J6: A | K6: A | L6: A | M6: A | N6: A | O6: A | P6: A | Q6: A | R6: A | S6: A | T6: A | U6: A | V6: A | W6: A | X6: A | Y6: A | Z6: A | AA6: A | AB6: A | AC6: A | AD6: A | AE6: A | AF6: A | AG6: B | AH6: B | AI6: B | AJ6: B | AK6: B | AL6: B | AM6: B | AN6: B | AO6: B | AP6: B
B7: N1 | C7: N1 | D7: N1 | E7: N1 | F7: N1 | G7: N1 | H7: N1 | I7: N1 | J7: N1 | K7: N1 | L7: N1 | M7: N1 | N7: N1 | O7: N1 | P7: N1 | Q7: N1 | R7: N1 | S7: N1 | T7: N1 | U7: N1 | V7: N1 | W7: N1 | X7: N1 | Y7: N1 | Z7: N1 | AA7: N1 | AB7: N1 | AC7: N1 | AD7: N1 | AE7: N1 | AF7: N1 | AG7: N2 | AH7: N2 | AI7: N2 | AJ7: N2 | AK7: N2 | AL7: N2 | AM7: N2 | AN7: N2 | AO7: N2 | AP7: N2
B8: Na
B9: Mg
B10: Al
B11: K
B12: Ca
B13: Cr
B14: Mn
B15: Fe
B16: Ni
B17: Co
B18: Cu
B19: Zn
B20: Pb
B22: 技師別 | C22: B | D22: B | E22: B | F22: B | G22: B | H22: B | I22: B | J22: B | K22: B | L22: B | M22: B | N22: B | O22: B | P22: B | Q22: B | R22: B | S22: B | T22: B | U22: B | V22: B | W22: B | X22: B | Y22: B | Z22: B | AA22: B | AB22: B | AC22: B | AD22: B | AE22: B | AF22: B
B23: N2 | C23: N2 | D23: N2 | E23: N2 | F23: N2 | G23: N2 | H23: N2 | I23: N2 | J23: N2 | K23: N2 | L23: N2 | M23: N2 | N23: N2 | O23: N2 | P23: N2 | Q23: N2 | R23: N2 | S23: N2 | T23: N2 | U23: N2 | V23: N2 | W23: N2 | X23: N2 | Y23: N2 | Z23: N2 | AA23: N2 | AB23: N2 | AC23: N2 | AD23: N2 | AE23: N2 | AF23: N2
B24: Na
B25: Mg
B26: Al
B27: K
B28: Ca
B29: Cr
B30: Mn
B31: Fe
B32: Ni
B33: Co
B34: Cu
B35: Zn
B36: Pb
B38: 技師別 | C38: C | D38: C | E38: C | F38: C | G38: C | H38: C | I38: C | J38: C | K38: C | L38: C | M38: C | N38: C | O38: C | P38: C | Q38: C | R38: C | S38: C | T38: C | U38: C | V38: C | W38: C | X38: C | Y38: C | Z38: C | AA38: C | AB38: C | AC38: C | AD38: C | AE38: C | AF38: C
B39: N3 | C39: N3 | D39: N3 | E39: N3 | F39: N3 | G39: N3 | H39: N3 | I39: N3 | J39: N3 | K39: N3 | L39: N3 | M39: N3 | N39: N3 | O39: N3 | P39: N3 | Q39: N3 | R39: N3 | S39: N3 | T39: N3 | U39: N3 | V39: N3 | W39: N3 | X39: N3 | Y39: N3 | Z39: N3 | AA39: N3 | AB39: N3 | AC39: N3 | AD39: N3 | AE39: N3 | AF39: N3
B40: Na
B41: Mg
B42: Al
B43: K
...
