Workbook

Sheet METAL (2)
D2: DATE | E2: ='METAL RAW DATA'!E2 -> 20180831
B3: ICP- MS 金屬 R-R測試 | D3: A | E3: ='METAL RAW DATA'!E3 -> 宋碧珍
D4: B | E4: ='METAL RAW DATA'!E4 -> 徐英明
D5: C | E5: ='METAL RAW DATA'!E5 -> XXXX
B6: 技師別 | C6: A | D6: A | E6: A | F6: A | G6: A | H6: A | I6: A | J6: A | K6: A | L6: A | M6: A | N6: A | O6: A | P6: A | Q6: A | R6: A | S6: A | T6: A | U6: A | V6: A | W6: A | X6: A | Y6: A | Z6: A | AA6: A | AB6: A | AC6: A | AD6: A | AE6: A | AF6: A
B7: N1 | C7: N1 | D7: N1 | E7: N1 | F7: N1 | G7: N1 | H7: N1 | I7: N1 | J7: N1 | K7: N1 | L7: N1 | M7: N1 | N7: N1 | O7: N1 | P7: N1 | Q7: N1 | R7: N1 | S7: N1 | T7: N1 | U7: N1 | V7: N1 | W7: N1 | X7: N1 | Y7: N1 | Z7: N1 | AA7: N1 | AB7: N1 | AC7: N1 | AD7: N1 | AE7: N1 | AF7: N1
B8: Na | C8: ='METAL RAW DATA'!C8 -> 0 | D8: ='METAL RAW DATA'!D8 -> 0 | E8: ='METAL RAW DATA'!E8 -> 0 | F8: ='METAL RAW DATA'!F8 -> 0 | G8: ='METAL RAW DATA'!G8 -> 0 | H8: ='METAL RAW DATA'!H8 -> 0 | I8: ='METAL RAW DATA'!I8 -> 0 | J8: ='METAL RAW DATA'!J8 -> 0 | ... AF8: ='METAL RAW DATA'!AF8 -> 0
B9: Mg | C9: ='METAL RAW DATA'!C9 -> 0 | D9: ='METAL RAW DATA'!D9 -> 0 | E9: ='METAL RAW DATA'!E9 -> 0 | F9: ='METAL RAW DATA'!F9 -> 0 | G9: ='METAL RAW DATA'!G9 -> 0 | H9: ='METAL RAW DATA'!H9 -> 0 | I9: ='METAL RAW DATA'!I9 -> 0 | J9: ='METAL RAW DATA'!J9 -> 0 | ... AF9: ='METAL RAW DATA'!AF9 -> 0
B10: Al | C10: ='METAL RAW DATA'!C10 -> 0 | D10: ='METAL RAW DATA'!D10 -> 0 | E10: ='METAL RAW DATA'!E10 -> 0 | F10: ='METAL RAW DATA'!F10 -> 0 | G10: ='METAL RAW DATA'!G10 -> 0 | H10: ='METAL RAW DATA'!H10 -> 0 | I10: ='METAL RAW DATA'!I10 -> 0 | J10: ='METAL RAW DATA'!J10 -> 0 | ... AF10: ='METAL RAW DATA'!AF10 -> 0
B11: K | C11: ='METAL RAW DATA'!C11 -> 0 | D11: ='METAL RAW DATA'!D11 -> 0 | E11: ='METAL RAW DATA'!E11 -> 0 | F11: ='METAL RAW DATA'!F11 -> 0 | G11: ='METAL RAW DATA'!G11 -> 0 | H11: ='METAL RAW DATA'!H11 -> 0 | I11: ='METAL RAW DATA'!I11 -> 0 | J11: ='METAL RAW DATA'!J11 -> 0 | ... AF11: ='METAL RAW DATA'!AF11 -> 0
B12: Ca | C12: ='METAL RAW DATA'!C12 -> 0 | D12: ='METAL RAW DATA'!D12 -> 0 | E12: ='METAL RAW DATA'!E12 -> 0 | F12: ='METAL RAW DATA'!F12 -> 0 | G12: ='METAL RAW DATA'!G12 -> 0 | H12: ='METAL RAW DATA'!H12 -> 0 | I12: ='METAL RAW DATA'!I12 -> 0 | J12: ='METAL RAW DATA'!J12 -> 0 | ... AF12: ='METAL RAW DATA'!AF12 -> 0
B13: Cr | C13: ='METAL RAW DATA'!C13 -> 0 | D13: ='METAL RAW DATA'!D13 -> 0 | E13: ='METAL RAW DATA'!E13 -> 0 | F13: ='METAL RAW DATA'!F13 -> 0 | G13: ='METAL RAW DATA'!G13 -> 0 | H13: ='METAL RAW DATA'!H13 -> 0 | I13: ='METAL RAW DATA'!I13 -> 0 | J13: ='METAL RAW DATA'!J13 -> 0 | ... AF13: ='METAL RAW DATA'!AF13 -> 0
B14: Mn | C14: ='METAL RAW DATA'!C14 -> 0 | D14: ='METAL RAW DATA'!D14 -> 0 | E14: ='METAL RAW DATA'!E14 -> 0 | F14: ='METAL RAW DATA'!F14 -> 0 | G14: ='METAL RAW DATA'!G14 -> 0 | H14: ='METAL RAW DATA'!H14 -> 0 | I14: ='METAL RAW DATA'!I14 -> 0 | J14: ='METAL RAW DATA'!J14 -> 0 | ... AF14: ='METAL RAW DATA'!AF14 -> 0
B15: Fe | C15: ='METAL RAW DATA'!C15 -> 0 | D15: ='METAL RAW DATA'!D15 -> 0 | E15: ='METAL RAW DATA'!E15 -> 0 | F15: ='METAL RAW DATA'!F15 -> 0 | G15: ='METAL RAW DATA'!G15 -> 0 | H15: ='METAL RAW DATA'!H15 -> 0 | I15: ='METAL RAW DATA'!I15 -> 0 | J15: ='METAL RAW DATA'!J15 -> 0 | ... AF15: ='METAL RAW DATA'!AF15 -> 0
B16: Ni | C16: ='METAL RAW DATA'!C16 -> 0 | D16: ='METAL RAW DATA'!D16 -> 0 | E16: ='METAL RAW DATA'!E16 -> 0 | F16: ='METAL RAW DATA'!F16 -> 0 | G16: ='METAL RAW DATA'!G16 -> 0 | H16: ='METAL RAW DATA'!H16 -> 0 | I16: ='METAL RAW DATA'!I16 -> 0 | J16: ='METAL RAW DATA'!J16 -> 0 | ... AF16: ='METAL RAW DATA'!AF16 -> 0
B17: Co | C17: ='METAL RAW DATA'!C17 -> 0 | D17: ='METAL RAW DATA'!D17 -> 0 | E17: ='METAL RAW DATA'!E17 -> 0 | F17: ='METAL RAW DATA'!F17 -> 0 | G17: ='METAL RAW DATA'!G17 -> 0 | H17: ='METAL RAW DATA'!H17 -> 0 | I17: ='METAL RAW DATA'!I17 -> 0 | J17: ='METAL RAW DATA'!J17 -> 0 | ... AF17: ='METAL RAW DATA'!AF17 -> 0
B18: Cu | C18: ='METAL RAW DATA'!C18 -> 0 | D18: ='METAL RAW DATA'!D18 -> 0 | E18: ='METAL RAW DATA'!E18 -> 0 | F18: ='METAL RAW DATA'!F18 -> 0 | G18: ='METAL RAW DATA'!G18 -> 0 | H18: ='METAL RAW DATA'!H18 -> 0 | I18: ='METAL RAW DATA'!I18 -> 0 | J18: ='METAL RAW DATA'!J18 -> 0 | ... AF18: ='METAL RAW DATA'!AF18 -> 0
B19: Zn | C19: ='METAL RAW DATA'!C19 -> 0 | D19: ='METAL RAW DATA'!D19 -> 0 | E19: ='METAL RAW DATA'!E19 -> 0 | F19: ='METAL RAW DATA'!F19 -> 0 | G19: ='METAL RAW DATA'!G19 -> 0 | H19: ='METAL RAW DATA'!H19 -> 0 | I19: ='METAL RAW DATA'!I19 -> 0 | J19: ='METAL RAW DATA'!J19 -> 0 | ... AF19: ='METAL RAW DATA'!AF19 -> 0
B20: Pb | C20: ='METAL RAW DATA'!C20 -> 0 | D20: ='METAL RAW DATA'!D20 -> 0 | E20: ='METAL RAW DATA'!E20 -> 0 | F20: ='METAL RAW DATA'!F20 -> 0 | G20: ='METAL RAW DATA'!G20 -> 0 | H20: ='METAL RAW DATA'!H20 -> 0 | I20: ='METAL RAW DATA'!I20 -> 0 | J20: ='METAL RAW DATA'!J20 -> 0 | ... AF20: ='METAL RAW DATA'!AF20 -> 0
B22: 技師別 | C22: B | D22: B | E22: B | F22: B | G22: B | H22: B | I22: B | J22: B | K22: B | L22: B | M22: B | N22: B | O22: B | P22: B | Q22: B | R22: B | S22: B | T22: B | U22: B | V22: B | W22: B | X22: B | Y22: B | Z22: B | AA22: B | AB22: B | AC22: B | AD22: B | AE22: B | AF22: B
B23: N2 | C23: N2 | D23: N2 | E23: N2 | F23: N2 | G23: N2 | H23: N2 | I23: N2 | J23: N2 | K23: N2 | L23: N2 | M23: N2 | N23: N2 | O23: N2 | P23: N2 | Q23: N2 | R23: N2 | S23: N2 | T23: N2 | U23: N2 | V23: N2 | W23: N2 | X23: N2 | Y23: N2 | Z23: N2 | AA23: N2 | AB23: N2 | AC23: N2 | AD23: N2 | AE23: N2 | AF23: N2
B24: Na | C24: ='METAL RAW DATA'!C24 -> 0 | D24: ='METAL RAW DATA'!D24 -> 0 | E24: ='METAL RAW DATA'!E24 -> 0 | F24: ='METAL RAW DATA'!F24 -> 0 | G24: ='METAL RAW DATA'!G24 -> 0 | H24: ='METAL RAW DATA'!H24 -> 0 | I24: ='METAL RAW DATA'!I24 -> 0 | J24: ='METAL RAW DATA'!J24 -> 0 | ... AF24: ='METAL RAW DATA'!AF24 -> 0
B25: Mg | C25: ='METAL RAW DATA'!C25 -> 0 | D25: ='METAL RAW DATA'!D25 -> 0 | E25: ='METAL RAW DATA'!E25 -> 0 | F25: ='METAL RAW DATA'!F25 -> 0 | G25: ='METAL RAW DATA'!G25 -> 0 | H25: ='METAL RAW DATA'!H25 -> 0 | I25: ='METAL RAW DATA'!I25 -> 0 | J25: ='METAL RAW DATA'!J25 -> 0 | ... AF25: ='METAL RAW DATA'!AF25 -> 0
B26: Al | C26: ='METAL RAW DATA'!C26 -> 0 | D26: ='METAL RAW DATA'!D26 -> 0 | E26: ='METAL RAW DATA'!E26 -> 0 | F26: ='METAL RAW DATA'!F26 -> 0 | G26: ='METAL RAW DATA'!G26 -> 0 | H26: ='METAL RAW DATA'!H26 -> 0 | I26: ='METAL RAW DATA'!I26 -> 0 | J26: ='METAL RAW DATA'!J26 -> 0 | ... AF26: ='METAL RAW DATA'!AF26 -> 0
B27: K | C27: ='METAL RAW DATA'!C27 -> 0 | D27: ='METAL RAW DATA'!D27 -> 0 | E27: ='METAL RAW DATA'!E27 -> 0 | F27: ='METAL RAW DATA'!F27 -> 0 | G27: ='METAL RAW DATA'!G27 -> 0 | H27: ='METAL RAW DATA'!H27 -> 0 | I27: ='METAL RAW DATA'!I27 -> 0 | J27: ='METAL RAW DATA'!J27 -> 0 | ... AF27: ='METAL RAW DATA'!AF27 -> 0
B28: Ca | C28: ='METAL RAW DATA'!C28 -> 0 | D28: ='METAL RAW DATA'!D28 -> 0 | E28: ='METAL RAW DATA'!E28 -> 0 | F28: ='METAL RAW DATA'!F28 -> 0 | G28: ='METAL RAW DATA'!G28 -> 0 | H28: ='METAL RAW DATA'!H28 -> 0 | I28: ='METAL RAW DATA'!I28 -> 0 | J28: ='METAL RAW DATA'!J28 -> 0 | ... AF28: ='METAL RAW DATA'!AF28 -> 0
B29: Cr | C29: ='METAL RAW DATA'!C29 -> 0 | D29: ='METAL RAW DATA'!D29 -> 0 | E29: ='METAL RAW DATA'!E29 -> 0 | F29: ='METAL RAW DATA'!F29 -> 0 | G29: ='METAL RAW DATA'!G29 -> 0 | H29: ='METAL RAW DATA'!H29 -> 0 | I29: ='METAL RAW DATA'!I29 -> 0 | J29: ='METAL RAW DATA'!J29 -> 0 | ... AF29: ='METAL RAW DATA'!AF29 -> 0
B30: Mn | C30: ='METAL RAW DATA'!C30 -> 0 | D30: ='METAL RAW DATA'!D30 -> 0 | E30: ='METAL RAW DATA'!E30 -> 0 | F30: ='METAL RAW DATA'!F30 -> 0 | G30: ='METAL RAW DATA'!G30 -> 0 | H30: ='METAL RAW DATA'!H30 -> 0 | I30: ='METAL RAW DATA'!I30 -> 0 | J30: ='METAL RAW DATA'!J30 -> 0 | ... AF30: ='METAL RAW DATA'!AF30 -> 0
B31: Fe | C31: ='METAL RAW DATA'!C31 -> 0 | D31: ='METAL RAW DATA'!D31 -> 0 | E31: ='METAL RAW DATA'!E31 -> 0 | F31: ='METAL RAW DATA'!F31 -> 0 | G31: ='METAL RAW DATA'!G31 -> 0 | H31: ='METAL RAW DATA'!H31 -> 0 | I31: ='METAL RAW DATA'!I31 -> 0 | J31: ='METAL RAW DATA'!J31 -> 0 | ... AF31: ='METAL RAW DATA'!AF31 -> 0
B32: Ni | C32: ='METAL RAW DATA'!C32 -> 0 | D32: ='METAL RAW DATA'!D32 -> 0 | E32: ='METAL RAW DATA'!E32 -> 0 | F32: ='METAL RAW DATA'!F32 -> 0 | G32: ='METAL RAW DATA'!G32 -> 0 | H32: ='METAL RAW DATA'!H32 -> 0 | I32: ='METAL RAW DATA'!I32 -> 0 | J32: ='METAL RAW DATA'!J32 -> 0 | ... AF32: ='METAL RAW DATA'!AF32 -> 0
B33: Co | C33: ='METAL RAW DATA'!C33 -> 0 | D33: ='METAL RAW DATA'!D33 -> 0 | E33: ='METAL RAW DATA'!E33 -> 0 | F33: ='METAL RAW DATA'!F33 -> 0 | G33: ='METAL RAW DATA'!G33 -> 0 | H33: ='METAL RAW DATA'!H33 -> 0 | I33: ='METAL RAW DATA'!I33 -> 0 | J33: ='METAL RAW DATA'!J33 -> 0 | ... AF33: ='METAL RAW DATA'!AF33 -> 0
B34: Cu | C34: ='METAL RAW DATA'!C34 -> 0 | D34: ='METAL RAW DATA'!D34 -> 0 | E34: ='METAL RAW DATA'!E34 -> 0 | F34: ='METAL RAW DATA'!F34 -> 0 | G34: ='METAL RAW DATA'!G34 -> 0 | H34: ='METAL RAW DATA'!H34 -> 0 | I34: ='METAL RAW DATA'!I34 -> 0 | J34: ='METAL RAW DATA'!J34 -> 0 | ... AF34: ='METAL RAW DATA'!AF34 -> 0
B35: Zn | C35: ='METAL RAW DATA'!C35 -> 0 | D35: ='METAL RAW DATA'!D35 -> 0 | E35: ='METAL RAW DATA'!E35 -> 0 | F35: ='METAL RAW DATA'!F35 -> 0 | G35: ='METAL RAW DATA'!G35 -> 0 | H35: ='METAL RAW DATA'!H35 -> 0 | I35: ='METAL RAW DATA'!I35 -> 0 | J35: ='METAL RAW DATA'!J35 -> 0 | ... AF35: ='METAL RAW DATA'!AF35 -> 0
B36: Pb | C36: ='METAL RAW DATA'!C36 -> 0 | D36: ='METAL RAW DATA'!D36 -> 0 | E36: ='METAL RAW DATA'!E36 -> 0 | F36: ='METAL RAW DATA'!F36 -> 0 | G36: ='METAL RAW DATA'!G36 -> 0 | H36: ='METAL RAW DATA'!H36 -> 0 | I36: ='METAL RAW DATA'!I36 -> 0 | J36: ='METAL RAW DATA'!J36 -> 0 | ... AF36: ='METAL RAW DATA'!AF36 -> 0
B38: 技師別 | C38: C | D38: C | E38: C | F38: C | G38: C | H38: C | I38: C | J38: C | K38: C | L38: C | M38: C | N38: C | O38: C | P38: C | Q38: C | R38: C | S38: C | T38: C | U38: C | V38: C | W38: C | X38: C | Y38: C | Z38: C | AA38: C | AB38: C | AC38: C | AD38: C | AE38: C | AF38: C
B39: N3 | C39: N3 | D39: N3 | E39: N3 | F39: N3 | G39: N3 | H39: N3 | I39: N3 | J39: N3 | K39: N3 | L39: N3 | M39: N3 | N39: N3 | O39: N3 | P39: N3 | Q39: N3 | R39: N3 | S39: N3 | T39: N3 | U39: N3 | V39: N3 | W39: N3 | X39: N3 | Y39: N3 | Z39: N3 | AA39: N3 | AB39: N3 | AC39: N3 | AD39: N3 | AE39: N3 | AF39: N3
B40: Na | C40: ='METAL RAW DATA'!C40 -> 0 | D40: ='METAL RAW DATA'!D40 -> 0 | E40: ='METAL RAW DATA'!E40 -> 0 | F40: ='METAL RAW DATA'!F40 -> 0 | G40: ='METAL RAW DATA'!G40 -> 0 | H40: ='METAL RAW DATA'!H40 -> 0 | I40: ='METAL RAW DATA'!I40 -> 0 | J40: ='METAL RAW DATA'!J40 -> 0 | ... AF40: ='METAL RAW DATA'!AF40 -> 0
B41: Mg | C41: ='METAL RAW DATA'!C41 -> 0 | D41: ='METAL RAW DATA'!D41 -> 0 | E41: ='METAL RAW DATA'!E41 -> 0 | F41: ='METAL RAW DATA'!F41 -> 0 | G41: ='METAL RAW DATA'!G41 -> 0 | H41: ='METAL RAW DATA'!H41 -> 0 | I41: ='METAL RAW DATA'!I41 -> 0 | J41: ='METAL RAW DATA'!J41 -> 0 | ... AF41: ='METAL RAW DATA'!AF41 -> 0
B42: Al | C42: ='METAL RAW DATA'!C42 -> 0 | D42: ='METAL RAW DATA'!D42 -> 0 | E42: ='METAL RAW DATA'!E42 -> 0 | F42: ='METAL RAW DATA'!F42 -> 0 | G42: ='METAL RAW DATA'!G42 -> 0 | H42: ='METAL RAW DATA'!H42 -> 0 | I42: ='METAL RAW DATA'!I42 -> 0 | J42: ='METAL RAW DATA'!J42 -> 0 | ... AF42: ='METAL RAW DATA'!AF42 -> 0
B43: K | C43: ='METAL RAW DATA'!C43 -> 0 | D43: ='METAL RAW DATA'!D43 -> 0 | E43: ='METAL RAW DATA'!E43 -> 0 | F43: ='METAL RAW DATA'!F43 -> 0 | G43: ='METAL RAW DATA'!G43 -> 0 | H43: ='METAL RAW DATA'!H43 -> 0 | I43: ='METAL RAW DATA'!I43 -> 0 | J43: ='METAL RAW DATA'!J43 -> 0 | ... AF43: ='METAL RAW DATA'!AF43 -> 0
...

Sheet METAL RAW DATA
B2: H2SO4 | D2: DATE | E2: 20180831
B3: ICP- MS 金屬 Ｒ-Ｒ測試 | D3: A | E3: 宋碧珍
D4: B | E4: 徐英明
D5: C | E5: XXXX
B6: 技師別 | C6: A | D6: A | E6: A | F6: A | G6: A | H6: A | I6: A | J6: A | K6: A | L6: A | M6: A | N6: A | O6: A | P6: A | Q6: A | R6: A | S6: A | T6: A | U6: A | V6: A | W6: A | X6: A | Y6: A | Z6: A | AA6: A | AB6: A | AC6: A | AD6: A | AE6: A | AF6: A
B7: N1 | C7: N1 | D7: N1 | E7: N1 | F7: N1 | G7: N1 | H7: N1 | I7: N1 | J7: N1 | K7: N1 | L7: N1 | M7: N1 | N7: N1 | O7: N1 | P7: N1 | Q7: N1 | R7: N1 | S7: N1 | T7: N1 | U7: N1 | V7: N1 | W7: N1 | X7: N1 | Y7: N1 | Z7: N1 | AA7: N1 | AB7: N1 | AC7: N1 | AD7: N1 | AE7: N1 | AF7: N1
B8: Na
B9: Mg
B10: Al
B11: K
B12: Ca
B13: Cr
B14: Mn
B15: Fe
B16: Ni
B17: Co
B18: Cu
B19: Zn
B20: Pb
B22: 技師別 | C22: B | D22: B | E22: B | F22: B | G22: B | H22: B | I22: B | J22: B | K22: B | L22: B | M22: B | N22: B | O22: B | P22: B | Q22: B | R22: B | S22: B | T22: B | U22: B | V22: B | W22: B | X22: B | Y22: B | Z22: B | AA22: B | AB22: B | AC22: B | AD22: B | AE22: B | AF22: B
B23: N2 | C23: N2 | D23: N2 | E23: N2 | F23: N2 | G23: N2 | H23: N2 | I23: N2 | J23: N2 | K23: N2 | L23: N2 | M23: N2 | N23: N2 | O23: N2 | P23: N2 | Q23: N2 | R23: N2 | S23: N2 | T23: N2 | U23: N2 | V23: N2 | W23: N2 | X23: N2 | Y23: N2 | Z23: N2 | AA23: N2 | AB23: N2 | AC23: N2 | AD23: N2 | AE23: N2 | AF23: N2
B24: Na
B25: Mg
B26: Al
B27: K
B28: Ca
B29: Cr
B30: Mn
B31: Fe
B32: Ni
B33: Co
B34: Cu
B35: Zn
B36: Pb
B38: 技師別 | C38: C | D38: C | E38: C | F38: C | G38: C | H38: C | I38: C | J38: C | K38: C | L38: C | M38: C | N38: C | O38: C | P38: C | Q38: C | R38: C | S38: C | T38: C | U38: C | V38: C | W38: C | X38: C | Y38: C | Z38: C | AA38: C | AB38: C | AC38: C | AD38: C | AE38: C | AF38: C
B39: N3 | C39: N3 | D39: N3 | E39: N3 | F39: N3 | G39: N3 | H39: N3 | I39: N3 | J39: N3 | K39: N3 | L39: N3 | M39: N3 | N39: N3 | O39: N3 | P39: N3 | Q39: N3 | R39: N3 | S39: N3 | T39: N3 | U39: N3 | V39: N3 | W39: N3 | X39: N3 | Y39: N3 | Z39: N3 | AA39: N3 | AB39: N3 | AC39: N3 | AD39: N3 | AE39: N3 | AF39: N3
B40: Na
B41: Mg
B42: Al
B43: K
...

Sheet Na
F1: ='METAL RAW DATA'!B3 -> ICP- MS 金屬 Ｒ-Ｒ測試
B3: ITEM | C3: ='METAL RAW DATA'!B8 -> Na | F3: DATE | G3: ='METAL RAW DATA'!E2 -> 20180831 | L3: NDC= | M3: =1.41*(0.02/D70) -> #DIV/0!
F4: 儀 器 | G4: ='METAL RAW DATA'!B3 -> ICP- MS 金屬 Ｒ-Ｒ測試
D5: 1 | E5: 2 | F5: 3 | G5: 4 | H5: 5 | I5: 6 | J5: 7 | K5: 8 | L5: 9 | M5: 10 | O5: AVE
B6: A | D6: ='METAL RAW DATA'!C8 -> 0 | E6: ='METAL RAW DATA'!D8 -> 0 | F6: ='METAL RAW DATA'!E8 -> 0 | G6: ='METAL RAW DATA'!F8 -> 0 | H6: ='METAL RAW DATA'!G8 -> 0 | I6: ='METAL RAW DATA'!H8 -> 0 | J6: ='METAL RAW DATA'!I8 -> 0 | K6: ='METAL RAW DATA'!J8 -> 0 | ... M6: ='METAL RAW DATA'!L8 -> 0 | O6: =SUM(D6:M6)/10 -> 0
B7: A | D7: ='METAL RAW DATA'!M8 -> 0 | E7: ='METAL RAW DATA'!N8 -> 0 | F7: ='METAL RAW DATA'!O8 -> 0 | G7: ='METAL RAW DATA'!P8 -> 0 | H7: ='METAL RAW DATA'!Q8 -> 0 | I7: ='METAL RAW DATA'!R8 -> 0 | J7: ='METAL RAW DATA'!S8 -> 0 | K7: ='METAL RAW DATA'!T8 -> 0 | ... M7: ='METAL RAW DATA'!V8 -> 0 | O7: =SUM(D7:M7)/10 -> 0
B8: A | D8: ='METAL RAW DATA'!W8 -> 0 | E8: ='METAL RAW DATA'!X8 -> 0 | F8: ='METAL RAW DATA'!Y8 -> 0 | G8: ='METAL RAW DATA'!Z8 -> 0 | H8: ='METAL RAW DATA'!AA8 -> 0 | I8: ='METAL RAW DATA'!AB8 -> 0 | J8: ='METAL RAW DATA'!AC8 -> 0 | K8: ='METAL RAW DATA'!AD8 -> 0 | ... M8: ='METAL RAW DATA'!AF8 -> 0 | O8: =SUM(D8:M8)/10 -> 0
B9: AVE | D9: =AVERAGE(D6:D8) -> 0 | E9: =AVERAGE(E6:E8) -> 0 | F9: =AVERAGE(F6:F8) -> 0 | G9: =AVERAGE(G6:G8) -> 0 | H9: =AVERAGE(H6:H8) -> 0 | I9: =AVERAGE(I6:I8) -> 0 | J9: =AVERAGE(J6:J8) -> 0 | K9: =AVERAGE(K6:K7:K8) -> 0 | L9: =AVERAGE(L6:L8) -> 0 | M9: =AVERAGE(M6:M8) -> 0 | N9: Xa | O9: =AVERAGE(O6:O8) -> 0
B10: RANGE | D10: =MAX(D6:D8)-MIN(D6:D8) -> 0 | E10: =MAX(E6:E8)-MIN(E6:E8) -> 0 | F10: =MAX(F6:F8)-MIN(F6:F7) -> 0 | G10: =MAX(G6:G8)-MIN(G6:G8) -> 0 | H10: =MAX(H6:H8)-MIN(H6:H8) -> 0 | I10: =MAX(I6:I8)-MIN(I6:I8) -> 0 | J10: =MAX(J6:J8)-MIN(J6:J8) -> 0 | K10: =MAX(K6:K8)-MIN(K6:K8) -> 0 | L10: =MAX(L6:L8)-MIN(L6:L8) -> 0 | M10: =MAX(M6:M8)-MIN(M6:M8) -> 0 | N10: Ra | O10: =SUM(D10:M10)/10 -> 0
B11: B | D11: ='METAL RAW DATA'!C24 -> 0 | E11: ='METAL RAW DATA'!D24 -> 0 | F11: ='METAL RAW DATA'!E24 -> 0 | G11: ='METAL RAW DATA'!F24 -> 0 | H11: ='METAL RAW DATA'!G24 -> 0 | I11: ='METAL RAW DATA'!H24 -> 0 | J11: ='METAL RAW DATA'!I24 -> 0 | K11: ='METAL RAW DATA'!J24 -> 0 | ... M11: ='METAL RAW DATA'!L24 -> 0 | O11: =SUM(D11:M11)/10 -> 0
B12: B | D12: ='METAL RAW DATA'!M24 -> 0 | E12: ='METAL RAW DATA'!N24 -> 0 | F12: ='METAL RAW DATA'!O24 -> 0 | G12: ='METAL RAW DATA'!P24 -> 0 | H12: ='METAL RAW DATA'!Q24 -> 0 | I12: ='METAL RAW DATA'!R24 -> 0 | J12: ='METAL RAW DATA'!S24 -> 0 | K12: ='METAL RAW DATA'!T24 -> 0 | ... M12: ='METAL RAW DATA'!V24 -> 0 | O12: =SUM(D12:M12)/10 -> 0
B13: B | D13: ='METAL RAW DATA'!W24 -> 0 | E13: ='METAL RAW DATA'!X24 -> 0 | F13: ='METAL RAW DATA'!Y24 -> 0 | G13: ='METAL RAW DATA'!Z24 -> 0 | H13: ='METAL RAW DATA'!AA24 -> 0 | I13: ='METAL RAW DATA'!AB24 -> 0 | J13: ='METAL RAW DATA'!AC24 -> 0 | K13: ='METAL RAW DATA'!AD24 -> 0 | ... M13: ='METAL RAW DATA'!AF24 -> 0 | O13: =SUM(D13:M13)/10 -> 0
B14: AVE | D14: =AVERAGE(D11:D13) -> 0 | E14: =AVERAGE(E11:E13) -> 0 | F14: =AVERAGE(F11:F13) -> 0 | G14: =AVERAGE(G11:G13) -> 0 | H14: =AVERAGE(H11:H13) -> 0 | I14: =AVERAGE(I11:I13) -> 0 | J14: =AVERAGE(J11:J13) -> 0 | K14: =AVERAGE(K11:K13) -> 0 | ... M14: =AVERAGE(M11:M13) -> 0 | N14: Xb | O14: =SUM(D14:M14)/10 -> 0
B15: RANGE | D15: =MAX(D11:D13)-MIN(D11:D13) -> 0 | E15: =MAX(E11:E13)-MIN(E11:E13) -> 0 | F15: =MAX(F11:F13)-MIN(F11:F13) -> 0 | G15: =MAX(G11:G13)-MIN(G11:G13) -> 0 | H15: =MAX(H11:H13)-MIN(H11:H13) -> 0 | I15: =MAX(I11:I13)-MIN(I11:I13) -> 0 | J15: =MAX(J11:J13)-MIN(J11:J13) -> 0 | K15: =MAX(K11:K13)-MIN(K11:K13) -> 0 | ... M15: =MAX(M11:M13)-MIN(M11:M13) -> 0 | N15: Rb | O15: =SUM(D15:M15)/10 -> 0
B16: C | D16: ='METAL RAW DATA'!C40 -> 0 | E16: ='METAL RAW DATA'!D40 -> 0 | F16: ='METAL RAW DATA'!E40 -> 0 | G16: ='METAL RAW DATA'!F40 -> 0 | H16: ='METAL RAW DATA'!G40 -> 0 | I16: ='METAL RAW DATA'!H40 -> 0 | J16: ='METAL RAW DATA'!I40 -> 0 | K16: ='METAL RAW DATA'!J40 -> 0 | ... M16: ='METAL RAW DATA'!L40 -> 0 | O16: =SUM(D16:M16)/10 -> 0
B17: C | D17: ='METAL RAW DATA'!M40 -> 0 | E17: ='METAL RAW DATA'!N40 -> 0 | F17: ='METAL RAW DATA'!O40 -> 0 | G17: ='METAL RAW DATA'!P40 -> 0 | H17: ='METAL RAW DATA'!Q40 -> 0 | I17: ='METAL RAW DATA'!R40 -> 0 | J17: ='METAL RAW DATA'!S40 -> 0 | K17: ='METAL RAW DATA'!T40 -> 0 | ... M17: ='METAL RAW DATA'!V40 -> 0 | O17: =SUM(D17:M17)/10 -> 0
B18: C | D18: ='METAL RAW DATA'!W40 -> 0 | E18: ='METAL RAW DATA'!X40 -> 0 | F18: ='METAL RAW DATA'!Y40 -> 0 | G18: ='METAL RAW DATA'!Z40 -> 0 | H18: ='METAL RAW DATA'!AA40 -> 0 | I18: ='METAL RAW DATA'!AB40 -> 0 | J18: ='METAL RAW DATA'!AC40 -> 0 | K18: ='METAL RAW DATA'!AD40 -> 0 | ... M18: ='METAL RAW DATA'!AF40 -> 0 | O18: =SUM(D18:M18)/10 -> 0
B19: AVE | D19: =AVERAGE(D16:D18) -> 0 | E19: =AVERAGE(E16:E18) -> 0 | F19: =AVERAGE(F16:F18) -> 0 | G19: =AVERAGE(G16:G18) -> 0 | H19: =AVERAGE(H16:H18) -> 0 | I19: =AVERAGE(I16:I18) -> 0 | J19: =AVERAGE(J16:J18) -> 0 | K19: =AVERAGE(K16:K18) -> 0 | ... M19: =AVERAGE(M16:M18) -> 0 | N19: Xc | O19: =SUM(D19:M19)/10 -> 0
B20: RANGE | D20: =MAX(D16:D18)-MIN(D16:D18) -> 0 | E20: =MAX(E16:E18)-MIN(E16:E18) -> 0 | F20: =MAX(F16:F18)-MIN(F16:F18) -> 0 | G20: =MAX(G16:G18)-MIN(G16:G18) -> 0 | H20: =MAX(H16:H18)-MIN(H16:H18) -> 0 | I20: =MAX(I16:I18)-MIN(I16:I18) -> 0 | J20: =MAX(J16:J18)-MIN(J16:J18) -> 0 | K20: =MAX(K16:K18)-MIN(K16:K18) -> 0 | ... M20: =MAX(M16:M18)-MIN(M16:M18) -> 0 | N20: Rc | O20: =SUM(D20:M20)/10 -> 0
B21: PART | N21: X | O21: =(O14+O9+O19)/3 -> 0
B22: AVE | C22: Xp | D22: =(D14+D9+D19)/3 -> 0 | E22: =(E14+E9+E19)/3 -> 0 | F22: =(F14+F9+F19)/3 -> 0 | G22: =(G14+G9+G19)/3 -> 0 | H22: =(H14+H9+H19)/3 -> 0 | I22: =(I14+I9+I19)/3 -> 0 | J22: =(J14+J9+J19)/3 -> 0 | K22: =(K14+K9+K19)/3 -> 0 | ... M22: =(M14+M9+M19)/3 -> 0 | N22: Rp | O22: =MAX(A22:M22)-MIN(A22:M22) -> 0
B23: R=(Ra+Rb)/2 | N23: R | O23: =(O15+O10+O20)/3 -> 0
B24: Max X-MaxB=X diff | N24: X diff | O24: =MAX(O9,O14,O19)-MIN(O9,O14,O19) -> 0
B26: R*D4=UCLR | O26: =O23*3.27 -> 0
B27: R*D3=LCLR | O27: =P23*0 -> 0
B29: Gage Repeatability and Reproducibility Report
E30: =G4 -> ICP- MS 金屬 Ｒ-Ｒ測試 | I30: Gage Nane | K30: ASSAY R&R | N30: Date: | O30: ='METAL RAW DATA'!E2 -> 20180831
B31: Part No.and Name | I31: Gage No | N31: performed by
B32: Characteristics: | I32: Gage Type: | K32: METAL
B33: Specification:
E34: R= | F34: =O23 -> 0 | G34: x diff= | H34: =O24 -> 0 | I34: Rp= | K34: =O22 -> 0
B35: From date sheet: | I35: %Total Variation(TV)
E36: n= | F36: 3 | G36: test= | H36: 10
B37: Measurement Unit Analysis
B38: Repeatability-Equipment Variation(EV) | D38: EV = | E38: R × K1 | G38: Trials | H38: K1 | I38: %EV=100(EV/TV)
D39: =F34 -> 0 | E39: * | F39: =H40 -> 0.5908 | G39: 2 | H39: 0.8862 | I39: =100*(D40/D58) -> #DIV/0! | K39: %
B40: = | D40: =D39*F39 -> 0 | G40: 3 | H40: 0.5908
B41: 重複性-設備變異
B42: Reproducibity-Appraiser Variation(AV) | D42: AV= | E42: √【（Xdiff X K2）2-（EV2/nr）】 | I42: %AV=100(AV/TV)
I43: =100*(E44/D58) -> #DIV/0! | K43: %
...

Sheet Mg
F1: ='METAL RAW DATA'!B3 -> ICP- MS 金屬 Ｒ-Ｒ測試
B3: ITEM | C3: ='METAL RAW DATA'!B9 -> Mg | F3: DATE | G3: ='METAL RAW DATA'!E2 -> 20180831 | L3: NDC= | M3: =1.41*(0.01/D70) -> #DIV/0!
F4: 儀 器 | G4: ='METAL RAW DATA'!B3 -> ICP- MS 金屬 Ｒ-Ｒ測試
D5: 1 | E5: 2 | F5: 3 | G5: 4 | H5: 5 | I5: 6 | J5: 7 | K5: 8 | L5: 9 | M5: 10 | O5: AVE
B6: A | D6: ='METAL RAW DATA'!C9 -> 0 | E6: ='METAL RAW DATA'!D9 -> 0 | F6: ='METAL RAW DATA'!E9 -> 0 | G6: ='METAL RAW DATA'!F9 -> 0 | H6: ='METAL RAW DATA'!G9 -> 0 | I6: ='METAL RAW DATA'!H9 -> 0 | J6: ='METAL RAW DATA'!I9 -> 0 | K6: ='METAL RAW DATA'!J9 -> 0 | ... M6: ='METAL RAW DATA'!L9 -> 0 | O6: =SUM(D6:M6)/10 -> 0
B7: A | D7: ='METAL RAW DATA'!M9 -> 0 | E7: ='METAL RAW DATA'!N9 -> 0 | F7: ='METAL RAW DATA'!O9 -> 0 | G7: ='METAL RAW DATA'!P9 -> 0 | H7: ='METAL RAW DATA'!Q9 -> 0 | I7: ='METAL RAW DATA'!R9 -> 0 | J7: ='METAL RAW DATA'!S9 -> 0 | K7: ='METAL RAW DATA'!T9 -> 0 | ... M7: ='METAL RAW DATA'!V9 -> 0 | O7: =SUM(D7:M7)/10 -> 0
B8: A | D8: ='METAL RAW DATA'!W9 -> 0 | E8: ='METAL RAW DATA'!X9 -> 0 | F8: ='METAL RAW DATA'!Y9 -> 0 | G8: ='METAL RAW DATA'!Z9 -> 0 | H8: ='METAL RAW DATA'!AA9 -> 0 | I8: ='METAL RAW DATA'!AB9 -> 0 | J8: ='METAL RAW DATA'!AC9 -> 0 | K8: ='METAL RAW DATA'!AD9 -> 0 | ... M8: ='METAL RAW DATA'!AF9 -> 0 | O8: =SUM(D8:M8)/10 -> 0
B9: AVE | D9: =AVERAGE(D6:D8) -> 0 | E9: =AVERAGE(E6:E8) -> 0 | F9: =AVERAGE(F6:F8) -> 0 | G9: =AVERAGE(G6:G8) -> 0 | H9: =AVERAGE(H6:H8) -> 0 | I9: =AVERAGE(I6:I8) -> 0 | J9: =AVERAGE(J6:J8) -> 0 | K9: =AVERAGE(K6:K8) -> 0 | ... M9: =AVERAGE(M6:M8) -> 0 | N9: Xa | O9: =AVERAGE(O6:O8) -> 0
B10: RANGE | D10: =MAX(D6:D8)-MIN(D6:D8) -> 0 | E10: =MAX(E6:E8)-MIN(E6:E8) -> 0 | F10: =MAX(F6:F8)-MIN(F6:F8) -> 0 | G10: =MAX(G6:G8)-MIN(G6:G8) -> 0 | H10: =MAX(H6:H8)-MIN(H6:H8) -> 0 | I10: =MAX(I6:I8)-MIN(I6:I8) -> 0 | J10: =MAX(J6:J8)-MIN(J6:J8) -> 0 | K10: =MAX(K6:K8)-MIN(K6:K8) -> 0 | ... M10: =MAX(M6:M8)-MIN(M6:M8) -> 0 | N10: Ra | O10: =SUM(D10:M10)/8 -> 0
B11: B | D11: ='METAL RAW DATA'!C25 -> 0 | E11: ='METAL RAW DATA'!D25 -> 0 | F11: ='METAL RAW DATA'!E25 -> 0 | G11: ='METAL RAW DATA'!F25 -> 0 | H11: ='METAL RAW DATA'!G25 -> 0 | I11: ='METAL RAW DATA'!H25 -> 0 | J11: ='METAL RAW DATA'!I25 -> 0 | K11: ='METAL RAW DATA'!J25 -> 0 | ... M11: ='METAL RAW DATA'!L25 -> 0 | O11: =SUM(D11:M11)/10 -> 0
B12: B | D12: ='METAL RAW DATA'!M25 -> 0 | E12: ='METAL RAW DATA'!N25 -> 0 | F12: ='METAL RAW DATA'!O25 -> 0 | G12: ='METAL RAW DATA'!P25 -> 0 | H12: ='METAL RAW DATA'!Q25 -> 0 | I12: ='METAL RAW DATA'!R25 -> 0 | J12: ='METAL RAW DATA'!S25 -> 0 | K12: ='METAL RAW DATA'!T25 -> 0 | ... M12: ='METAL RAW DATA'!V25 -> 0 | O12: =SUM(D12:M12)/10 -> 0
B13: B | D13: ='METAL RAW DATA'!W25 -> 0 | E13: ='METAL RAW DATA'!X25 -> 0 | F13: ='METAL RAW DATA'!Y25 -> 0 | G13: ='METAL RAW DATA'!Z25 -> 0 | H13: ='METAL RAW DATA'!AA25 -> 0 | I13: ='METAL RAW DATA'!AB25 -> 0 | J13: ='METAL RAW DATA'!AC25 -> 0 | K13: ='METAL RAW DATA'!AD25 -> 0 | ... M13: ='METAL RAW DATA'!AF25 -> 0 | O13: =SUM(D13:M13)/10 -> 0
B14: AVE | D14: =AVERAGE(D11:D13) -> 0 | E14: =AVERAGE(E11:E13) -> 0 | F14: =AVERAGE(F11:F13) -> 0 | G14: =AVERAGE(G11:G13) -> 0 | H14: =AVERAGE(H11:H13) -> 0 | I14: =AVERAGE(I11:I13) -> 0 | J14: =AVERAGE(J11:J13) -> 0 | K14: =AVERAGE(K11:K13) -> 0 | ... M14: =AVERAGE(M11:M13) -> 0 | N14: Xb | O14: =SUM(D14:M14)/10 -> 0
B15: RANGE | D15: =MAX(D11:D13)-MIN(D11:D13) -> 0 | E15: =MAX(E11:E13)-MIN(E11:E13) -> 0 | F15: =MAX(F11:F13)-MIN(F11:F13) -> 0 | G15: =MAX(G11:G13)-MIN(G11:G13) -> 0 | H15: =MAX(H11:H13)-MIN(H11:H13) -> 0 | I15: =MAX(I11:I13)-MIN(I11:I13) -> 0 | J15: =MAX(J11:J13)-MIN(J11:J13) -> 0 | K15: =MAX(K11:K13)-MIN(K11:K13) -> 0 | ... M15: =MAX(M11:M13)-MIN(M11:M13) -> 0 | N15: Rb | O15: =SUM(D15:M15)/10 -> 0
B16: C | D16: ='METAL RAW DATA'!C41 -> 0 | E16: ='METAL RAW DATA'!D41 -> 0 | F16: ='METAL RAW DATA'!E41 -> 0 | G16: ='METAL RAW DATA'!F41 -> 0 | H16: ='METAL RAW DATA'!G41 -> 0 | I16: ='METAL RAW DATA'!H41 -> 0 | J16: ='METAL RAW DATA'!I41 -> 0 | K16: ='METAL RAW DATA'!J41 -> 0 | ... M16: ='METAL RAW DATA'!L41 -> 0 | O16: =SUM(D16:M16)/10 -> 0
B17: C | D17: ='METAL RAW DATA'!M41 -> 0 | E17: ='METAL RAW DATA'!N41 -> 0 | F17: ='METAL RAW DATA'!O41 -> 0 | G17: ='METAL RAW DATA'!P41 -> 0 | H17: ='METAL RAW DATA'!Q41 -> 0 | I17: ='METAL RAW DATA'!R41 -> 0 | J17: ='METAL RAW DATA'!S41 -> 0 | K17: ='METAL RAW DATA'!T41 -> 0 | ... M17: ='METAL RAW DATA'!V41 -> 0 | O17: =SUM(D17:M17)/10 -> 0
B18: C | D18: ='METAL RAW DATA'!W41 -> 0 | E18: ='METAL RAW DATA'!X41 -> 0 | F18: ='METAL RAW DATA'!Y41 -> 0 | G18: ='METAL RAW DATA'!Z41 -> 0 | H18: ='METAL RAW DATA'!AA41 -> 0 | I18: ='METAL RAW DATA'!AB41 -> 0 | J18: ='METAL RAW DATA'!AC41 -> 0 | K18: ='METAL RAW DATA'!AD41 -> 0 | ... M18: ='METAL RAW DATA'!AF41 -> 0 | O18: =SUM(D18:M18)/10 -> 0
B19: AVE | D19: =AVERAGE(D16:D18) -> 0 | E19: =AVERAGE(E16:E18) -> 0 | F19: =AVERAGE(F16:F18) -> 0 | G19: =AVERAGE(G16:G18) -> 0 | H19: =AVERAGE(H16:H18) -> 0 | I19: =AVERAGE(I16:I18) -> 0 | J19: =AVERAGE(J16:J18) -> 0 | K19: =AVERAGE(K16:K18) -> 0 | ... M19: =AVERAGE(M16:M18) -> 0 | N19: Xc | O19: =SUM(D19:M19)/10 -> 0
B20: RANGE | D20: =MAX(D16:D18)-MIN(D16:D18) -> 0 | E20: =MAX(E16:E18)-MIN(E16:E18) -> 0 | F20: =MAX(F16:F18)-MIN(F16:F18) -> 0 | G20: =MAX(G16:G18)-MIN(G16:G18) -> 0 | H20: =MAX(H16:H18)-MIN(H16:H18) -> 0 | I20: =MAX(I16:I18)-MIN(I16:I18) -> 0 | J20: =MAX(J16:J18)-MIN(J16:J18) -> 0 | K20: =MAX(K16:K18)-MIN(K16:K18) -> 0 | ... M20: =MAX(M16:M18)-MIN(M16:M18) -> 0 | N20: Rc | O20: =SUM(D20:M20)/10 -> 0
B21: PART | N21: X | O21: =(O14+O9+O19)/3 -> 0
B22: AVE | C22: Xp | D22: =(D14+D9)/2 -> 0 | E22: =(E14+E9)/2 -> 0 | F22: =(F14+F9)/2 -> 0 | G22: =(G14+G9)/2 -> 0 | H22: =(H14+H9)/2 -> 0 | I22: =(I14+I9)/2 -> 0 | J22: =(J14+J9)/2 -> 0 | K22: =(K14+K9)/2 -> 0 | ... M22: =(M14+M9)/2 -> 0 | N22: Rp | O22: =MAX(A22:M22)-MIN(A22:M22) -> 0
B23: R=(Ra+Rb)/2 | N23: R | O23: =(O15+O10+O20)/3 -> 0
B24: Max X-MaxB=X diff | N24: X diff | O24: =MAX(O9,O14,O19)-MIN(O9,O14,O19) -> 0
B26: R*D4=UCLR | O26: =O23*3.27 -> 0
B27: R*D3=LCLR | O27: =O23*0 -> 0
B29: Gage Repeatability and Reproducibility Report
E30: =G4 -> ICP- MS 金屬 Ｒ-Ｒ測試 | I30: Gage Nane | K30: ASSAY R&R | N30: Date: | O30: ='METAL RAW DATA'!E2 -> 20180831
B31: Part No.and Name | I31: Gage No | N31: performed by
B32: Characteristics: | I32: Gage Type: | K32: METAL
B33: Specification:
E34: R= | F34: =O23 -> 0 | G34: x diff= | H34: =O24 -> 0 | I34: Rp= | K34: =O22 -> 0
B35: From date sheet: | I35: %Total Variation(TV)
E36: n= | F36: 3 | G36: test= | H36: 10
B37: Measurement Unit Analysis
B38: Repeatability-Equipment Variation(EV) | D38: EV = | E38: R × K1 | G38: Trials | H38: K1 | I38: %EV=100(EV/TV)
D39: =F34 -> 0 | E39: * | F39: =H40 -> 0.5908 | G39: 2 | H39: 0.8862 | I39: =100*(D40/D58) -> #DIV/0! | K39: %
B40: = | D40: =D39*F39 -> 0 | G40: 3 | H40: 0.5908
B41: 重複性-設備變異
B42: Reproducibity-Appraiser Variation(AV) | D42: AV= | E42: √【（Xdiff X K2）2-（EV2/nr）】 | I42: %AV=100(AV/TV)
I43: =100*(E44/D58) -> #DIV/0! | K43: %
...

Sheet K
F1: ='METAL RAW DATA'!B3 -> ICP- MS 金屬 Ｒ-Ｒ測試
B3: ITEM | C3: ='METAL RAW DATA'!B11 -> K | F3: DATE | G3: ='METAL RAW DATA'!E2 -> 20180831 | L3: NDC= | M3: =1.41*(0.01/D70) -> #DIV/0!
F4: 儀 器 | G4: ='METAL RAW DATA'!B3 -> ICP- MS 金屬 Ｒ-Ｒ測試
D5: 1 | E5: 2 | F5: 3 | G5: 4 | H5: 5 | I5: 6 | J5: 7 | K5: 8 | L5: 9 | M5: 10 | O5: AVE
B6: A | D6: ='METAL RAW DATA'!C11 -> 0 | E6: ='METAL RAW DATA'!D11 -> 0 | F6: ='METAL RAW DATA'!E11 -> 0 | G6: ='METAL RAW DATA'!F11 -> 0 | H6: ='METAL RAW DATA'!G11 -> 0 | I6: ='METAL RAW DATA'!H11 -> 0 | J6: ='METAL RAW DATA'!I11 -> 0 | K6: ='METAL RAW DATA'!J11 -> 0 | ... M6: ='METAL RAW DATA'!L11 -> 0 | O6: =SUM(D6:M6)/10 -> 0
B7: A | D7: ='METAL RAW DATA'!M11 -> 0 | E7: ='METAL RAW DATA'!N11 -> 0 | F7: ='METAL RAW DATA'!O11 -> 0 | G7: ='METAL RAW DATA'!P11 -> 0 | H7: ='METAL RAW DATA'!Q11 -> 0 | I7: ='METAL RAW DATA'!R11 -> 0 | J7: ='METAL RAW DATA'!S11 -> 0 | K7: ='METAL RAW DATA'!T11 -> 0 | ... M7: ='METAL RAW DATA'!V11 -> 0 | O7: =SUM(D7:M7)/10 -> 0
B8: A | D8: ='METAL RAW DATA'!W11 -> 0 | E8: ='METAL RAW DATA'!X11 -> 0 | F8: ='METAL RAW DATA'!Y11 -> 0 | G8: ='METAL RAW DATA'!Z11 -> 0 | H8: ='METAL RAW DATA'!AA11 -> 0 | I8: ='METAL RAW DATA'!AB11 -> 0 | J8: ='METAL RAW DATA'!AC11 -> 0 | K8: ='METAL RAW DATA'!AD11 -> 0 | ... M8: ='METAL RAW DATA'!AF11 -> 0 | O8: =SUM(D8:M8)/10 -> 0
B9: AVE | D9: =AVERAGE(D6:D7) -> 0 | E9: =AVERAGE(E6:E7) -> 0 | F9: =AVERAGE(F6:F7) -> 0 | G9: =AVERAGE(G6:G7) -> 0 | H9: =AVERAGE(H6:H7) -> 0 | I9: =AVERAGE(I6:I7) -> 0 | J9: =AVERAGE(J6:J7) -> 0 | K9: =AVERAGE(K6:K7) -> 0 | ... M9: =AVERAGE(M6:M7) -> 0 | N9: Xa | O9: =AVERAGE(O6:O8) -> 0
B10: RANGE | D10: =MAX(D6:D7)-MIN(D6:D7) -> 0 | E10: =MAX(E6:E7)-MIN(E6:E7) -> 0 | F10: =MAX(F6:F7)-MIN(F6:F7) -> 0 | G10: =MAX(G6:G7)-MIN(G6:G7) -> 0 | H10: =MAX(H6:H7)-MIN(H6:H7) -> 0 | I10: =MAX(I6:I7)-MIN(I6:I7) -> 0 | J10: =MAX(J6:J7)-MIN(J6:J7) -> 0 | K10: =MAX(K6:K7)-MIN(K6:K7) -> 0 | ... M10: =MAX(M6:M7)-MIN(M6:M7) -> 0 | N10: Ra | O10: =SUM(D10:M10)/10 -> 0
B11: B | D11: ='METAL RAW DATA'!C27 -> 0 | E11: ='METAL RAW DATA'!D27 -> 0 | F11: ='METAL RAW DATA'!E27 -> 0 | G11: ='METAL RAW DATA'!F27 -> 0 | H11: ='METAL RAW DATA'!G27 -> 0 | I11: ='METAL RAW DATA'!H27 -> 0 | J11: ='METAL RAW DATA'!I27 -> 0 | K11: ='METAL RAW DATA'!J27 -> 0 | L11: ='METAL RAW DATA'!J27 -> 0 | M11: ='METAL RAW DATA'!L27 -> 0 | O11: =SUM(D11:M11)/10 -> 0
B12: B | D12: ='METAL RAW DATA'!M27 -> 0 | E12: ='METAL RAW DATA'!N27 -> 0 | F12: ='METAL RAW DATA'!O27 -> 0 | G12: ='METAL RAW DATA'!P27 -> 0 | H12: ='METAL RAW DATA'!Q27 -> 0 | I12: ='METAL RAW DATA'!R27 -> 0 | J12: ='METAL RAW DATA'!S27 -> 0 | K12: ='METAL RAW DATA'!T27 -> 0 | ... M12: ='METAL RAW DATA'!V27 -> 0 | O12: =SUM(D12:M12)/10 -> 0
B13: B | D13: ='METAL RAW DATA'!W27 -> 0 | E13: ='METAL RAW DATA'!X27 -> 0 | F13: ='METAL RAW DATA'!Y27 -> 0 | G13: ='METAL RAW DATA'!Z27 -> 0 | H13: ='METAL RAW DATA'!AA27 -> 0 | I13: ='METAL RAW DATA'!AB27 -> 0 | J13: ='METAL RAW DATA'!AC27 -> 0 | K13: ='METAL RAW DATA'!AD27 -> 0 | ... M13: ='METAL RAW DATA'!AF27 -> 0 | O13: =SUM(D13:M13)/10 -> 0
B14: AVE | D14: =AVERAGE(D11:D13) -> 0 | E14: =AVERAGE(E11:E13) -> 0 | F14: =AVERAGE(F11:F13) -> 0 | G14: =AVERAGE(G11:G13) -> 0 | H14: =AVERAGE(H11:H13) -> 0 | I14: =AVERAGE(I11:I13) -> 0 | J14: =AVERAGE(J11:J13) -> 0 | K14: =AVERAGE(K11:K13) -> 0 | ... M14: =AVERAGE(M11:M13) -> 0 | N14: Xb | O14: =SUM(D14:M14)/10 -> 0
B15: RANGE | D15: =MAX(D11:D13)-MIN(D11:D13) -> 0 | E15: =MAX(E11:E13)-MIN(E11:E13) -> 0 | F15: =MAX(F11:F13)-MIN(F11:F13) -> 0 | G15: =MAX(G11:G13)-MIN(G11:G13) -> 0 | H15: =MAX(H11:H13)-MIN(H11:H13) -> 0 | I15: =MAX(I11:I13)-MIN(I11:I13) -> 0 | J15: =MAX(J11:J13)-MIN(J11:J13) -> 0 | K15: =MAX(K11:K13)-MIN(K11:K13) -> 0 | ... M15: =MAX(M11:M13)-MIN(M11:M13) -> 0 | N15: Rb | O15: =SUM(D15:M15)/10 -> 0
B16: C | D16: ='METAL RAW DATA'!C43 -> 0 | E16: ='METAL RAW DATA'!D43 -> 0 | F16: ='METAL RAW DATA'!E43 -> 0 | G16: ='METAL RAW DATA'!F43 -> 0 | H16: ='METAL RAW DATA'!G43 -> 0 | I16: ='METAL RAW DATA'!H43 -> 0 | J16: ='METAL RAW DATA'!I43 -> 0 | K16: ='METAL RAW DATA'!J43 -> 0 | ... M16: ='METAL RAW DATA'!L43 -> 0 | O16: =SUM(D16:M16)/10 -> 0
B17: C | D17: ='METAL RAW DATA'!M43 -> 0 | E17: ='METAL RAW DATA'!N43 -> 0 | F17: ='METAL RAW DATA'!O43 -> 0 | G17: ='METAL RAW DATA'!P43 -> 0 | H17: ='METAL RAW DATA'!Q43 -> 0 | I17: ='METAL RAW DATA'!R43 -> 0 | J17: ='METAL RAW DATA'!S43 -> 0 | K17: ='METAL RAW DATA'!T43 -> 0 | ... M17: ='METAL RAW DATA'!V43 -> 0 | O17: =SUM(D17:M17)/10 -> 0
B18: C | D18: ='METAL RAW DATA'!W43 -> 0 | E18: ='METAL RAW DATA'!X43 -> 0 | F18: ='METAL RAW DATA'!Y43 -> 0 | G18: ='METAL RAW DATA'!Z43 -> 0 | H18: ='METAL RAW DATA'!AA43 -> 0 | I18: ='METAL RAW DATA'!AB43 -> 0 | J18: ='METAL RAW DATA'!AC43 -> 0 | K18: ='METAL RAW DATA'!AD43 -> 0 | ... M18: ='METAL RAW DATA'!AF43 -> 0 | O18: =SUM(D18:M18)/10 -> 0
B19: AVE | D19: =AVERAGE(D16:D18) -> 0 | E19: =AVERAGE(E16:E18) -> 0 | F19: =AVERAGE(F16:F18) -> 0 | G19: =AVERAGE(G16:G18) -> 0 | H19: =AVERAGE(H16:H18) -> 0 | I19: =AVERAGE(I16:I18) -> 0 | J19: =AVERAGE(J16:J18) -> 0 | K19: =AVERAGE(K16:K18) -> 0 | ... M19: =AVERAGE(M16:M18) -> 0 | N19: Xc | O19: =SUM(D19:M19)/10 -> 0
B20: RANGE | D20: =MAX(D16:D18)-MIN(D16:D18) -> 0 | E20: =MAX(E16:E18)-MIN(E16:E18) -> 0 | F20: =MAX(F16:F18)-MIN(F16:F18) -> 0 | G20: =MAX(G16:G18)-MIN(G16:G18) -> 0 | H20: =MAX(H16:H18)-MIN(H16:H18) -> 0 | I20: =MAX(I16:I18)-MIN(I16:I18) -> 0 | J20: =MAX(J16:J18)-MIN(J16:J18) -> 0 | K20: =MAX(K16:K18)-MIN(K16:K18) -> 0 | ... M20: =MAX(M16:M18)-MIN(M16:M18) -> 0 | N20: Rc | O20: =SUM(D20:M20)/10 -> 0
B21: PART | N21: X | O21: =(O14+O9+O19)/3 -> 0
B22: AVE | C22: Xp | D22: =(D14+D9)/2 -> 0 | E22: =(E14+E9)/2 -> 0 | F22: =(F14+F9)/2 -> 0 | G22: =(G14+G9)/2 -> 0 | H22: =(H14+H9)/2 -> 0 | I22: =(I14+I9)/2 -> 0 | J22: =(J14+J9)/2 -> 0 | K22: =(K14+K9)/2 -> 0 | ... M22: =(M14+M9)/2 -> 0 | N22: Rp | O22: =MAX(A22:M22)-MIN(A22:M22) -> 0
B23: R=(Ra+Rb)/2 | N23: R | O23: =(O15+O10+O20)/3 -> 0
B24: Max X-MaxB=X diff | N24: X diff | O24: =MAX(O9,O14,O19)-MIN(O9,O14,O19) -> 0
B26: R*D4=UCLR | O26: =O23*3.27 -> 0
B27: R*D3=LCLR | O27: =O23*0 -> 0
B29: Gage Repeatability and Reproducibility Report
E30: =G4 -> ICP- MS 金屬 Ｒ-Ｒ測試 | I30: Gage Nane | K30: ASSAY R&R | N30: Date: | O30: ='METAL RAW DATA'!E2 -> 20180831
B31: Part No.and Name | I31: Gage No | N31: performed by
B32: Characteristics: | I32: Gage Type: | K32: METAL
B33: Specification:
E34: R= | F34: =O23 -> 0 | G34: x diff= | H34: =O24 -> 0 | I34: Rp= | K34: =O22 -> 0
B35: From date sheet: | I35: %Total Variation(TV)
E36: n= | F36: 3 | G36: test= | H36: 10
B37: Measurement Unit Analysis
B38: Repeatability-Equipment Variation(EV) | D38: EV = | E38: R × K1 | G38: Trials | H38: K1 | I38: %EV=100(EV/TV)
D39: =F34 -> 0 | E39: * | F39: =H40 -> 0.5908 | G39: 2 | H39: 0.8862 | I39: =100*(D40/D58) -> #DIV/0! | K39: %
B40: = | D40: =D39*F39 -> 0 | G40: 3 | H40: 0.5908
B41: 重複性-設備變異
B42: Reproducibity-Appraiser Variation(AV) | D42: AV= | E42: √【（Xdiff X K2）2-（EV2/nr）】 | I42: %AV=100(AV/TV)
I43: =100*(E44/D58) -> #DIV/0! | K43: %
...

Sheet AL
F1: ='METAL RAW DATA'!B3 -> ICP- MS 金屬 Ｒ-Ｒ測試
B3: ITEM | C3: ='METAL RAW DATA'!B10 -> Al | F3: DATE | G3: ='METAL RAW DATA'!E2 -> 20180831 | L3: NDC= | M3: =1.41*(0.02/D70) -> #DIV/0!
F4: 儀 器 | G4: ='METAL RAW DATA'!B3 -> ICP- MS 金屬 Ｒ-Ｒ測試
D5: 1 | E5: 2 | F5: 3 | G5: 4 | H5: 5 | I5: 6 | J5: 7 | K5: 8 | L5: 9 | M5: 10 | O5: AVE
B6: A | D6: ='METAL RAW DATA'!C10 -> 0 | E6: ='METAL RAW DATA'!D10 -> 0 | F6: ='METAL RAW DATA'!E10 -> 0 | G6: ='METAL RAW DATA'!F10 -> 0 | H6: ='METAL RAW DATA'!G10 -> 0 | I6: ='METAL RAW DATA'!H10 -> 0 | J6: ='METAL RAW DATA'!I10 -> 0 | K6: ='METAL RAW DATA'!J10 -> 0 | ... M6: ='METAL RAW DATA'!L10 -> 0 | O6: =SUM(D6:M6)/10 -> 0
B7: A | D7: ='METAL RAW DATA'!M10 -> 0 | E7: ='METAL RAW DATA'!N10 -> 0 | F7: ='METAL RAW DATA'!O10 -> 0 | G7: ='METAL RAW DATA'!P10 -> 0 | H7: ='METAL RAW DATA'!Q10 -> 0 | I7: ='METAL RAW DATA'!R10 -> 0 | J7: ='METAL RAW DATA'!S10 -> 0 | K7: ='METAL RAW DATA'!T10 -> 0 | ... M7: ='METAL RAW DATA'!V10 -> 0 | O7: =SUM(D7:M7)/10 -> 0
B8: A | D8: ='METAL RAW DATA'!W10 -> 0 | E8: ='METAL RAW DATA'!X10 -> 0 | F8: ='METAL RAW DATA'!Y10 -> 0 | G8: ='METAL RAW DATA'!Z10 -> 0 | H8: ='METAL RAW DATA'!AA10 -> 0 | I8: ='METAL RAW DATA'!AB10 -> 0 | J8: ='METAL RAW DATA'!AC10 -> 0 | K8: ='METAL RAW DATA'!AD10 -> 0 | ... M8: ='METAL RAW DATA'!AF10 -> 0 | O8: =SUM(D8:M8)/10 -> 0
B9: AVE | D9: =AVERAGE(D6:D7) -> 0 | E9: =AVERAGE(E6:E7) -> 0 | F9: =AVERAGE(F6:F7) -> 0 | G9: =AVERAGE(G6:G7) -> 0 | H9: =AVERAGE(H6:H7) -> 0 | I9: =AVERAGE(I6:I7) -> 0 | J9: =AVERAGE(J6:J7) -> 0 | K9: =AVERAGE(K6:K7) -> 0 | ... M9: =AVERAGE(M6:M7) -> 0 | N9: Xa | O9: =AVERAGE(O6:O8) -> 0
B10: RANGE | D10: =MAX(D6:D7)-MIN(D6:D7) -> 0 | E10: =MAX(E6:E7)-MIN(E6:E7) -> 0 | F10: =MAX(F6:F7)-MIN(F6:F7) -> 0 | G10: =MAX(G6:G7)-MIN(G6:G7) -> 0 | H10: =MAX(H6:H7)-MIN(H6:H7) -> 0 | I10: =MAX(I6:I7)-MIN(I6:I7) -> 0 | J10: =MAX(J6:J7)-MIN(J6:J7) -> 0 | K10: =MAX(K6:K7)-MIN(K6:K7) -> 0 | ... M10: =MAX(M6:M7)-MIN(M6:M7) -> 0 | N10: Ra | O10: =SUM(D10:M10)/10 -> 0
B11: B | D11: ='METAL RAW DATA'!C26 -> 0 | E11: ='METAL RAW DATA'!D26 -> 0 | F11: ='METAL RAW DATA'!E26 -> 0 | G11: ='METAL RAW DATA'!F26 -> 0 | H11: ='METAL RAW DATA'!G26 -> 0 | I11: ='METAL RAW DATA'!H26 -> 0 | J11: ='METAL RAW DATA'!I26 -> 0 | K11: ='METAL RAW DATA'!J26 -> 0 | ... M11: ='METAL RAW DATA'!L26 -> 0 | O11: =SUM(D11:M11)/10 -> 0
B12: B | D12: ='METAL RAW DATA'!M26 -> 0 | E12: ='METAL RAW DATA'!N26 -> 0 | F12: ='METAL RAW DATA'!O26 -> 0 | G12: ='METAL RAW DATA'!P26 -> 0 | H12: ='METAL RAW DATA'!Q26 -> 0 | I12: ='METAL RAW DATA'!R26 -> 0 | J12: ='METAL RAW DATA'!S26 -> 0 | K12: ='METAL RAW DATA'!T26 -> 0 | ... M12: ='METAL RAW DATA'!V26 -> 0 | O12: =SUM(D12:M12)/10 -> 0
B13: B | D13: ='METAL RAW DATA'!W26 -> 0 | E13: ='METAL RAW DATA'!X26 -> 0 | F13: ='METAL RAW DATA'!Y26 -> 0 | G13: ='METAL RAW DATA'!Z26 -> 0 | H13: ='METAL RAW DATA'!AA26 -> 0 | I13: ='METAL RAW DATA'!AB26 -> 0 | J13: ='METAL RAW DATA'!AC26 -> 0 | K13: ='METAL RAW DATA'!AD26 -> 0 | ... M13: ='METAL RAW DATA'!AF26 -> 0 | O13: =SUM(D13:M13)/10 -> 0
B14: AVE | D14: =AVERAGE(D11:D12) -> 0 | E14: =AVERAGE(E11:E12) -> 0 | F14: =AVERAGE(F11:F12) -> 0 | G14: =AVERAGE(G11:G12) -> 0 | H14: =AVERAGE(H11:H12) -> 0 | I14: =AVERAGE(I11:I12) -> 0 | J14: =AVERAGE(J11:J12) -> 0 | K14: =AVERAGE(K11:K12) -> 0 | ... M14: =AVERAGE(M11:M12) -> 0 | N14: Xb | O14: =SUM(D14:M14)/10 -> 0
B15: RANGE | D15: =MAX(D11:D12)-MIN(D11:D12) -> 0 | E15: =MAX(E11:E12)-MIN(E11:E12) -> 0 | F15: =MAX(F11:F12)-MIN(F11:F12) -> 0 | G15: =MAX(G11:G12)-MIN(G11:G12) -> 0 | H15: =MAX(H11:H12)-MIN(H11:H12) -> 0 | I15: =MAX(I11:I12)-MIN(I11:I12) -> 0 | J15: =MAX(J11:J12)-MIN(J11:J12) -> 0 | K15: =MAX(K11:K12)-MIN(K11:K12) -> 0 | ... M15: =MAX(M11:M12)-MIN(M11:M12) -> 0 | N15: Rb | O15: =SUM(D15:M15)/10 -> 0
B16: C | D16: ='METAL RAW DATA'!C42 -> 0 | E16: ='METAL RAW DATA'!D42 -> 0 | F16: ='METAL RAW DATA'!E42 -> 0 | G16: ='METAL RAW DATA'!F42 -> 0 | H16: ='METAL RAW DATA'!G42 -> 0 | I16: ='METAL RAW DATA'!H42 -> 0 | J16: ='METAL RAW DATA'!I42 -> 0 | K16: ='METAL RAW DATA'!J42 -> 0 | ... M16: ='METAL RAW DATA'!L42 -> 0 | O16: =SUM(D16:M16)/10 -> 0
B17: C | D17: ='METAL RAW DATA'!M42 -> 0 | E17: ='METAL RAW DATA'!N42 -> 0 | F17: ='METAL RAW DATA'!O42 -> 0 | G17: ='METAL RAW DATA'!P42 -> 0 | H17: ='METAL RAW DATA'!Q42 -> 0 | I17: ='METAL RAW DATA'!R42 -> 0 | J17: ='METAL RAW DATA'!S42 -> 0 | K17: ='METAL RAW DATA'!T42 -> 0 | ... M17: ='METAL RAW DATA'!V42 -> 0 | O17: =SUM(D17:M17)/10 -> 0
B18: C | D18: ='METAL RAW DATA'!W42 -> 0 | E18: ='METAL RAW DATA'!X42 -> 0 | F18: ='METAL RAW DATA'!Y42 -> 0 | G18: ='METAL RAW DATA'!Z42 -> 0 | H18: ='METAL RAW DATA'!AA42 -> 0 | I18: ='METAL RAW DATA'!AB42 -> 0 | J18: ='METAL RAW DATA'!AC42 -> 0 | K18: ='METAL RAW DATA'!AD42 -> 0 | ... M18: ='METAL RAW DATA'!AF42 -> 0 | O18: =SUM(D18:M18)/10 -> 0
B19: AVE | D19: =AVERAGE(D16:D18) -> 0 | E19: =AVERAGE(E16:E18) -> 0 | F19: =AVERAGE(F16:F18) -> 0 | G19: =AVERAGE(G16:G18) -> 0 | H19: =AVERAGE(H16:H18) -> 0 | I19: =AVERAGE(I16:I18) -> 0 | J19: =AVERAGE(J16:J18) -> 0 | K19: =AVERAGE(K16:K18) -> 0 | ... M19: =AVERAGE(M16:M18) -> 0 | N19: Xc | O19: =SUM(D19:M19)/10 -> 0
B20: RANGE | D20: =MAX(D16:D18)-MIN(D16:D18) -> 0 | E20: =MAX(E16:E18)-MIN(E16:E18) -> 0 | F20: =MAX(F16:F18)-MIN(F16:F18) -> 0 | G20: =MAX(G16:G18)-MIN(G16:G18) -> 0 | H20: =MAX(H16:H18)-MIN(H16:H18) -> 0 | I20: =MAX(I16:I18)-MIN(I16:I18) -> 0 | J20: =MAX(J16:J18)-MIN(J16:J18) -> 0 | K20: =MAX(K16:K18)-MIN(K16:K18) -> 0 | ... M20: =MAX(M16:M18)-MIN(M16:M18) -> 0 | N20: Rc | O20: =SUM(D20:M20)/10 -> 0
B21: PART | N21: X | O21: =(O14+O9+O19)/3 -> 0
B22: AVE | C22: Xp | D22: =(D14+D9)/2 -> 0 | E22: =(E14+E9)/2 -> 0 | F22: =(F14+F9)/2 -> 0 | G22: =(G14+G9)/2 -> 0 | H22: =(H14+H9)/2 -> 0 | I22: =(I14+I9)/2 -> 0 | J22: =(J14+J9)/2 -> 0 | K22: =(K14+K9)/2 -> 0 | ... M22: =(M14+M9)/2 -> 0 | N22: Rp | O22: =MAX(A22:M22)-MIN(A22:M22) -> 0
B23: R=(Ra+Rb)/2 | N23: R | O23: =(O15+O10+O20)/3 -> 0
B24: Max X-MaxB=X diff | N24: X diff | O24: =MAX(O9,O14,O19)-MIN(O9,O14,O19) -> 0
B26: R*D4=UCLR | O26: =O23*3.27 -> 0
B27: R*D3=LCLR | O27: =O23*0 -> 0
B29: Gage Repeatability and Reproducibility Report
E30: =G4 -> ICP- MS 金屬 Ｒ-Ｒ測試 | I30: Gage Nane | K30: ASSAY R&R | N30: Date: | O30: ='METAL RAW DATA'!E2 -> 20180831
B31: Part No.and Name | I31: Gage No | N31: performed by
B32: Characteristics: | I32: Gage Type: | K32: METAL
B33: Specification:
E34: R= | F34: =O23 -> 0 | G34: x diff= | H34: =O24 -> 0 | I34: Rp= | K34: =O22 -> 0
B35: From date sheet: | I35: %Total Variation(TV)
E36: n= | F36: 3 | G36: test= | H36: 10
B37: Measurement Unit Analysis
B38: Repeatability-Equipment Variation(EV) | D38: EV = | E38: R × K1 | G38: Trials | H38: K1 | I38: %EV=100(EV/TV)
D39: =F34 -> 0 | E39: * | F39: =H40 -> 0.5908 | G39: 2 | H39: 0.8862 | I39: =100*(D40/D58) -> #DIV/0! | K39: %
B40: = | D40: =D39*F39 -> 0 | G40: 3 | H40: 0.5908
B41: 重複性-設備變異
B42: Reproducibity-Appraiser Variation(AV) | D42: AV= | E42: √【（Xdiff X K2）2-（EV2/nr）】 | I42: %AV=100(AV/TV)
I43: =100*(E44/D58) -> #DIV/0! | K43: %
...

Sheet Ca
F1: ='METAL RAW DATA'!B3 -> ICP- MS 金屬 Ｒ-Ｒ測試
B3: ITEM | C3: ='METAL RAW DATA'!B12 -> Ca | F3: DATE | G3: ='METAL RAW DATA'!E2 -> 20180831 | L3: NDC= | M3: =1.41*(0.02/D70) -> #DIV/0!
F4: 儀 器 | G4: ='METAL RAW DATA'!B3 -> ICP- MS 金屬 Ｒ-Ｒ測試
D5: 1 | E5: 2 | F5: 3 | G5: 4 | H5: 5 | I5: 6 | J5: 7 | K5: 8 | L5: 9 | M5: 10 | O5: AVE
B6: A | D6: ='METAL RAW DATA'!C12 -> 0 | E6: ='METAL RAW DATA'!D12 -> 0 | F6: ='METAL RAW DATA'!E12 -> 0 | G6: ='METAL RAW DATA'!F12 -> 0 | H6: ='METAL RAW DATA'!G12 -> 0 | I6: ='METAL RAW DATA'!H12 -> 0 | J6: ='METAL RAW DATA'!I12 -> 0 | K6: ='METAL RAW DATA'!J12 -> 0 | ... M6: ='METAL RAW DATA'!L12 -> 0 | O6: =SUM(D6:M6)/10 -> 0
B7: A | D7: ='METAL RAW DATA'!M12 -> 0 | E7: ='METAL RAW DATA'!N12 -> 0 | F7: ='METAL RAW DATA'!O12 -> 0 | G7: ='METAL RAW DATA'!P12 -> 0 | H7: ='METAL RAW DATA'!Q12 -> 0 | I7: ='METAL RAW DATA'!R12 -> 0 | J7: ='METAL RAW DATA'!S12 -> 0 | K7: ='METAL RAW DATA'!T12 -> 0 | ... M7: ='METAL RAW DATA'!V12 -> 0 | O7: =SUM(D7:M7)/10 -> 0
B8: A | D8: ='METAL RAW DATA'!W12 -> 0 | E8: ='METAL RAW DATA'!X12 -> 0 | F8: ='METAL RAW DATA'!Y12 -> 0 | G8: ='METAL RAW DATA'!Z12 -> 0 | H8: ='METAL RAW DATA'!AA12 -> 0 | I8: ='METAL RAW DATA'!AB12 -> 0 | J8: ='METAL RAW DATA'!AC12 -> 0 | K8: ='METAL RAW DATA'!AD12 -> 0 | ... M8: ='METAL RAW DATA'!AF12 -> 0 | O8: =SUM(D8:M8)/10 -> 0
B9: AVE | D9: =AVERAGE(D6:D7) -> 0 | E9: =AVERAGE(E6:E7) -> 0 | F9: =AVERAGE(F6:F7) -> 0 | G9: =AVERAGE(G6:G7) -> 0 | H9: =AVERAGE(H6:H7) -> 0 | I9: =AVERAGE(I6:I7) -> 0 | J9: =AVERAGE(J6:J7) -> 0 | K9: =AVERAGE(K6:K7) -> 0 | ... M9: =AVERAGE(M6:M7) -> 0 | N9: Xa | O9: =AVERAGE(O6:O8) -> 0
B10: RANGE | D10: =MAX(D6:D7)-MIN(D6:D7) -> 0 | E10: =MAX(E6:E7)-MIN(E6:E7) -> 0 | F10: =MAX(F6:F7)-MIN(F6:F7) -> 0 | G10: =MAX(G6:G7)-MIN(G6:G7) -> 0 | H10: =MAX(H6:H7)-MIN(H6:H7) -> 0 | I10: =MAX(I6:I7)-MIN(I6:I7) -> 0 | J10: =MAX(J6:J7)-MIN(J6:J7) -> 0 | K10: =MAX(K6:K7)-MIN(K6:K7) -> 0 | ... M10: =MAX(M6:M7)-MIN(M6:M7) -> 0 | N10: Ra | O10: =SUM(D10:M10)/10 -> 0
B11: B | D11: ='METAL RAW DATA'!C28 -> 0 | E11: ='METAL RAW DATA'!D28 -> 0 | F11: ='METAL RAW DATA'!E28 -> 0 | G11: ='METAL RAW DATA'!F28 -> 0 | H11: ='METAL RAW DATA'!G28 -> 0 | I11: ='METAL RAW DATA'!H28 -> 0 | J11: ='METAL RAW DATA'!I28 -> 0 | K11: ='METAL RAW DATA'!J28 -> 0 | ... M11: ='METAL RAW DATA'!L28 -> 0 | O11: =SUM(D11:M11)/10 -> 0
B12: B | D12: ='METAL RAW DATA'!M28 -> 0 | E12: ='METAL RAW DATA'!N28 -> 0 | F12: ='METAL RAW DATA'!O28 -> 0 | G12: ='METAL RAW DATA'!P28 -> 0 | H12: ='METAL RAW DATA'!Q28 -> 0 | I12: ='METAL RAW DATA'!R28 -> 0 | J12: ='METAL RAW DATA'!S28 -> 0 | K12: ='METAL RAW DATA'!T28 -> 0 | ... M12: ='METAL RAW DATA'!V28 -> 0 | O12: =SUM(D12:M12)/10 -> 0
B13: B | D13: ='METAL RAW DATA'!W28 -> 0 | E13: ='METAL RAW DATA'!X28 -> 0 | F13: ='METAL RAW DATA'!Y28 -> 0 | G13: ='METAL RAW DATA'!Z28 -> 0 | H13: ='METAL RAW DATA'!AA28 -> 0 | I13: ='METAL RAW DATA'!AB28 -> 0 | J13: ='METAL RAW DATA'!AC28 -> 0 | K13: ='METAL RAW DATA'!AD28 -> 0 | ... M13: ='METAL RAW DATA'!AF28 -> 0 | O13: =SUM(D13:M13)/10 -> 0
B14: AVE | D14: =AVERAGE(D11:D12)/10 -> 0 | E14: =AVERAGE(E11:E12) -> 0 | F14: =AVERAGE(F11:F12) -> 0 | G14: =AVERAGE(G11:G12) -> 0 | H14: =AVERAGE(H11:H12) -> 0 | I14: =AVERAGE(I11:I12) -> 0 | J14: =AVERAGE(J11:J12) -> 0 | K14: =AVERAGE(K11:K12) -> 0 | L14: =AVERAGE(L11:L12) -> 0 | M14: =AVERAGE(M11:M12) -> 0 | N14: Xb | O14: =SUM(D14:M14)/10 -> 0
B15: RANGE | D15: =MAX(D11:D12)-MIN(D11:D12) -> 0 | E15: =MAX(E11:E12)-MIN(E11:E12) -> 0 | F15: =MAX(F11:F12)-MIN(F11:F12) -> 0 | G15: =MAX(G11:G12)-MIN(G11:G12) -> 0 | H15: =MAX(H11:H12)-MIN(H11:H12) -> 0 | I15: =MAX(I11:I12)-MIN(I11:I12) -> 0 | J15: =MAX(J11:J12)-MIN(J11:J12) -> 0 | K15: =MAX(K11:K12)-MIN(K11:K12) -> 0 | ... M15: =MAX(M11:M12)-MIN(M11:M12) -> 0 | N15: Rb | O15: =SUM(D15:M15)/10 -> 0
B16: C | D16: ='METAL RAW DATA'!C44 -> 0 | E16: ='METAL RAW DATA'!D44 -> 0 | F16: ='METAL RAW DATA'!E44 -> 0 | G16: ='METAL RAW DATA'!F44 -> 0 | H16: ='METAL RAW DATA'!G44 -> 0 | I16: ='METAL RAW DATA'!H44 -> 0 | J16: ='METAL RAW DATA'!I44 -> 0 | K16: ='METAL RAW DATA'!J44 -> 0 | ... M16: ='METAL RAW DATA'!L44 -> 0 | O16: =SUM(D16:M16)/10 -> 0
B17: C | D17: ='METAL RAW DATA'!M44 -> 0 | E17: ='METAL RAW DATA'!N44 -> 0 | F17: ='METAL RAW DATA'!O44 -> 0 | G17: ='METAL RAW DATA'!P44 -> 0 | H17: ='METAL RAW DATA'!Q44 -> 0 | I17: ='METAL RAW DATA'!R44 -> 0 | J17: ='METAL RAW DATA'!S44 -> 0 | K17: ='METAL RAW DATA'!T44 -> 0 | ... M17: ='METAL RAW DATA'!V44 -> 0 | O17: =SUM(D17:M17)/10 -> 0
B18: C | D18: ='METAL RAW DATA'!W44 -> 0 | E18: ='METAL RAW DATA'!X44 -> 0 | F18: ='METAL RAW DATA'!Y44 -> 0 | G18: ='METAL RAW DATA'!Z44 -> 0 | H18: ='METAL RAW DATA'!AA44 -> 0 | I18: ='METAL RAW DATA'!AB44 -> 0 | J18: ='METAL RAW DATA'!AC44 -> 0 | K18: ='METAL RAW DATA'!AD44 -> 0 | ... M18: ='METAL RAW DATA'!AF44 -> 0 | O18: =SUM(D18:M18)/10 -> 0
B19: AVE | D19: =AVERAGE(D16:D17) -> 0 | E19: =AVERAGE(E16:E17) -> 0 | F19: =AVERAGE(F16:F17) -> 0 | G19: =AVERAGE(G16:G17) -> 0 | H19: =AVERAGE(H16:H17) -> 0 | I19: =AVERAGE(I16:I17) -> 0 | J19: =AVERAGE(J16:J17) -> 0 | K19: =AVERAGE(K16:K17) -> 0 | ... M19: =AVERAGE(M16:M17) -> 0 | N19: Xc | O19: =SUM(D19:M19)/10 -> 0
B20: RANGE | D20: =MAX(D16:D17)-MIN(D16:D17) -> 0 | E20: =MAX(E16:E17)-MIN(E16:E17) -> 0 | F20: =MAX(F16:F17)-MIN(F16:F17) -> 0 | G20: =MAX(G16:G17)-MIN(G16:G17) -> 0 | H20: =MAX(H16:H17)-MIN(H16:H17) -> 0 | I20: =MAX(I16:I17)-MIN(I16:I17) -> 0 | J20: =MAX(J16:J17)-MIN(J16:J17) -> 0 | K20: =MAX(K16:K17)-MIN(K16:K17) -> 0 | ... M20: =MAX(M16:M17)-MIN(M16:M17) -> 0 | N20: Rc | O20: =SUM(D20:M20)/10 -> 0
B21: PART | N21: X | O21: =(O14+O9+O19)/3 -> 0
B22: AVE | C22: Xp | D22: =(D14+D9)/2 -> 0 | E22: =(E14+E9)/2 -> 0 | F22: =(F14+F9)/2 -> 0 | G22: =(G14+G9)/2 -> 0 | H22: =(H14+H9)/2 -> 0 | I22: =(I14+I9)/2 -> 0 | J22: =(J14+J9)/2 -> 0 | K22: =(K14+K9)/2 -> 0 | ... M22: =(M14+M9)/2 -> 0 | N22: Rp | O22: =MAX(A22:M22)-MIN(A22:M22) -> 0
B23: R=(Ra+Rb)/2 | N23: R | O23: =(O15+O10+O20)/3 -> 0
B24: Max X-MaxB=X diff | N24: X diff | O24: =MAX(O9,O14,O19)-MIN(O9,O14,O19) -> 0
B26: R*D4=UCLR | O26: =O23*3.27 -> 0
B27: R*D3=LCLR | O27: =O23*0 -> 0
B29: Gage Repeatability and Reproducibility Report
E30: =G4 -> ICP- MS 金屬 Ｒ-Ｒ測試 | I30: Gage Nane | K30: ASSAY R&R | N30: Date: | O30: ='METAL RAW DATA'!E2 -> 20180831
B31: Part No.and Name | I31: Gage No | N31: performed by
B32: Characteristics: | I32: Gage Type: | K32: METAL
B33: Specification:
E34: R= | F34: =O23 -> 0 | G34: x diff= | H34: =O24 -> 0 | I34: Rp= | K34: =O22 -> 0
B35: From date sheet: | I35: %Total Variation(TV)
E36: n= | F36: 3 | G36: test= | H36: 10
B37: Measurement Unit Analysis
B38: Repeatability-Equipment Variation(EV) | D38: EV = | E38: R × K1 | G38: Trials | H38: K1 | I38: %EV=100(EV/TV)
D39: =F34 -> 0 | E39: * | F39: =H40 -> 0.5908 | G39: 2 | H39: 0.8862 | I39: =100*(D40/D58) -> #DIV/0! | K39: %
B40: = | D40: =D39*F39 -> 0 | G40: 3 | H40: 0.5908
B41: 重複性-設備變異
B42: Reproducibity-Appraiser Variation(AV) | D42: AV= | E42: √【（Xdiff X K2）2-（EV2/nr）】 | I42: %AV=100(AV/TV)
I43: =100*(E44/D58) -> #DIV/0! | K43: %
...

Sheet Cr
F1: ='METAL RAW DATA'!B3 -> ICP- MS 金屬 Ｒ-Ｒ測試
B3: ITEM | C3: ='METAL RAW DATA'!B13 -> Cr | F3: DATE | G3: ='METAL RAW DATA'!E2 -> 20180831 | L3: NDC= | M3: =1.41*(0.01/D70) -> #DIV/0!
F4: 儀 器 | G4: ='METAL RAW DATA'!B3 -> ICP- MS 金屬 Ｒ-Ｒ測試
D5: 1 | E5: 2 | F5: 3 | G5: 4 | H5: 5 | I5: 6 | J5: 7 | K5: 8 | L5: 9 | M5: 10 | O5: AVE
B6: A | D6: ='METAL RAW DATA'!C13 -> 0 | E6: ='METAL RAW DATA'!D13 -> 0 | F6: ='METAL RAW DATA'!E13 -> 0 | G6: ='METAL RAW DATA'!F13 -> 0 | H6: ='METAL RAW DATA'!G13 -> 0 | I6: ='METAL RAW DATA'!H13 -> 0 | J6: ='METAL RAW DATA'!I13 -> 0 | K6: ='METAL RAW DATA'!J13 -> 0 | ... M6: ='METAL RAW DATA'!L13 -> 0 | O6: =SUM(D6:M6)/10 -> 0
B7: A | D7: ='METAL RAW DATA'!M13 -> 0 | E7: ='METAL RAW DATA'!N13 -> 0 | F7: ='METAL RAW DATA'!O13 -> 0 | G7: ='METAL RAW DATA'!P13 -> 0 | H7: ='METAL RAW DATA'!Q13 -> 0 | I7: ='METAL RAW DATA'!R13 -> 0 | J7: ='METAL RAW DATA'!S13 -> 0 | K7: ='METAL RAW DATA'!T13 -> 0 | ... M7: ='METAL RAW DATA'!V13 -> 0 | O7: =SUM(D7:M7)/10 -> 0
B8: A | D8: ='METAL RAW DATA'!W13 -> 0 | E8: ='METAL RAW DATA'!X13 -> 0 | F8: ='METAL RAW DATA'!Y13 -> 0 | G8: ='METAL RAW DATA'!Z13 -> 0 | H8: ='METAL RAW DATA'!AA13 -> 0 | I8: ='METAL RAW DATA'!AB13 -> 0 | J8: ='METAL RAW DATA'!AC13 -> 0 | K8: ='METAL RAW DATA'!AD13 -> 0 | ... M8: ='METAL RAW DATA'!AF13 -> 0 | O8: =SUM(D8:M8)/10 -> 0
B9: AVE | D9: =AVERAGE(D6:D8) -> 0 | E9: =AVERAGE(E6:E8) -> 0 | F9: =AVERAGE(F6:F8) -> 0 | G9: =AVERAGE(G6:G8) -> 0 | H9: =AVERAGE(H6:H8) -> 0 | I9: =AVERAGE(I6:I8) -> 0 | J9: =AVERAGE(J6:J8) -> 0 | K9: =AVERAGE(K6:K8) -> 0 | ... M9: =AVERAGE(M6:M8) -> 0 | N9: Xa | O9: =AVERAGE(O6:O8) -> 0
B10: RANGE | D10: =MAX(D6:D8)-MIN(D6:D8) -> 0 | E10: =MAX(E6:E8)-MIN(E6:E8) -> 0 | F10: =MAX(F6:F8)-MIN(F6:F8) -> 0 | G10: =MAX(G6:G8)-MIN(G6:G8) -> 0 | H10: =MAX(H6:H8)-MIN(H6:H8) -> 0 | I10: =MAX(I6:I8)-MIN(I6:I8) -> 0 | J10: =MAX(J6:J8)-MIN(J6:J8) -> 0 | K10: =MAX(K6:K8)-MIN(K6:K8) -> 0 | ... M10: =MAX(M6:M8)-MIN(M6:M8) -> 0 | N10: Ra | O10: =SUM(D10:M10)/10 -> 0
B11: B | D11: ='METAL RAW DATA'!C29 -> 0 | E11: ='METAL RAW DATA'!D29 -> 0 | F11: ='METAL RAW DATA'!E29 -> 0 | G11: ='METAL RAW DATA'!F29 -> 0 | H11: ='METAL RAW DATA'!G29 -> 0 | I11: ='METAL RAW DATA'!H29 -> 0 | J11: ='METAL RAW DATA'!I29 -> 0 | K11: ='METAL RAW DATA'!J29 -> 0 | ... M11: ='METAL RAW DATA'!L29 -> 0 | O11: =SUM(D11:M11)/10 -> 0
B12: B | D12: ='METAL RAW DATA'!M29 -> 0 | E12: ='METAL RAW DATA'!N29 -> 0 | F12: ='METAL RAW DATA'!O29 -> 0 | G12: ='METAL RAW DATA'!P29 -> 0 | H12: ='METAL RAW DATA'!Q29 -> 0 | I12: ='METAL RAW DATA'!R29 -> 0 | J12: ='METAL RAW DATA'!S29 -> 0 | K12: ='METAL RAW DATA'!T29 -> 0 | ... M12: ='METAL RAW DATA'!V29 -> 0 | O12: =SUM(D12:M12)/10 -> 0
B13: B | D13: ='METAL RAW DATA'!W29 -> 0 | E13: ='METAL RAW DATA'!X29 -> 0 | F13: ='METAL RAW DATA'!Y29 -> 0 | G13: ='METAL RAW DATA'!Z29 -> 0 | H13: ='METAL RAW DATA'!AA29 -> 0 | I13: ='METAL RAW DATA'!AB29 -> 0 | J13: ='METAL RAW DATA'!AC29 -> 0 | K13: ='METAL RAW DATA'!AD29 -> 0 | ... M13: ='METAL RAW DATA'!AF29 -> 0 | O13: =SUM(D13:M13)/10 -> 0
B14: AVE | D14: =AVERAGE(D11:D13) -> 0 | E14: =AVERAGE(E11:E13) -> 0 | F14: =AVERAGE(F11:F13) -> 0 | G14: =AVERAGE(G11:G13) -> 0 | H14: =AVERAGE(H11:H13) -> 0 | I14: =AVERAGE(I11:I13) -> 0 | J14: =AVERAGE(J11:J13) -> 0 | K14: =AVERAGE(K11:K13) -> 0 | ... M14: =AVERAGE(M11:M13) -> 0 | N14: Xb | O14: =SUM(D14:M14)/10 -> 0
B15: RANGE | D15: =MAX(D11:D13)-MIN(D11:D13) -> 0 | E15: =MAX(E11:E13)-MIN(E11:E13) -> 0 | F15: =MAX(F11:F13)-MIN(F11:F13) -> 0 | G15: =MAX(G11:G13)-MIN(G11:G13) -> 0 | H15: =MAX(H11:H13)-MIN(H11:H13) -> 0 | I15: =MAX(I11:I13)-MIN(I11:I13) -> 0 | J15: =MAX(J11:J13)-MIN(J11:J13) -> 0 | K15: =MAX(K11:K13)-MIN(K11:K13) -> 0 | ... M15: =MAX(M11:M13)-MIN(M11:M13) -> 0 | N15: Rb | O15: =SUM(D15:M15)/10 -> 0
B16: C | D16: ='METAL RAW DATA'!C45 -> 0 | E16: ='METAL RAW DATA'!D45 -> 0 | F16: ='METAL RAW DATA'!E45 -> 0 | G16: ='METAL RAW DATA'!F45 -> 0 | H16: ='METAL RAW DATA'!G45 -> 0 | I16: ='METAL RAW DATA'!H45 -> 0 | J16: ='METAL RAW DATA'!I45 -> 0 | K16: ='METAL RAW DATA'!J45 -> 0 | ... M16: ='METAL RAW DATA'!L45 -> 0 | O16: =SUM(D16:M16)/10 -> 0
B17: C | D17: ='METAL RAW DATA'!M45 -> 0 | E17: ='METAL RAW DATA'!N45 -> 0 | F17: ='METAL RAW DATA'!O45 -> 0 | G17: ='METAL RAW DATA'!P45 -> 0 | H17: ='METAL RAW DATA'!Q45 -> 0 | I17: ='METAL RAW DATA'!R45 -> 0 | J17: ='METAL RAW DATA'!S45 -> 0 | K17: ='METAL RAW DATA'!T45 -> 0 | ... M17: ='METAL RAW DATA'!V45 -> 0 | O17: =SUM(D17:M17)/10 -> 0
B18: C | D18: ='METAL RAW DATA'!W45 -> 0 | E18: ='METAL RAW DATA'!X45 -> 0 | F18: ='METAL RAW DATA'!Y45 -> 0 | G18: ='METAL RAW DATA'!Z45 -> 0 | H18: ='METAL RAW DATA'!AA45 -> 0 | I18: ='METAL RAW DATA'!AB45 -> 0 | J18: ='METAL RAW DATA'!AC45 -> 0 | K18: ='METAL RAW DATA'!AD45 -> 0 | ... M18: ='METAL RAW DATA'!AF45 -> 0 | O18: =SUM(D18:M18)/10 -> 0
B19: AVE | D19: =AVERAGE(D16:D18) -> 0 | E19: =AVERAGE(E16:E18) -> 0 | F19: =AVERAGE(F16:F18) -> 0 | G19: =AVERAGE(G16:G18) -> 0 | H19: =AVERAGE(H16:H18) -> 0 | I19: =AVERAGE(I16:I18) -> 0 | J19: =AVERAGE(J16:J18) -> 0 | K19: =AVERAGE(K16:K18) -> 0 | ... M19: =AVERAGE(M16:M18) -> 0 | N19: Xc | O19: =SUM(D19:M19)/10 -> 0
B20: RANGE | D20: =MAX(D16:D18)-MIN(D16:D18) -> 0 | E20: =MAX(E16:E18)-MIN(E16:E18) -> 0 | F20: =MAX(F16:F18)-MIN(F16:F18) -> 0 | G20: =MAX(G16:G18)-MIN(G16:G18) -> 0 | H20: =MAX(H16:H18)-MIN(H16:H18) -> 0 | I20: =MAX(I16:I18)-MIN(I16:I18) -> 0 | J20: =MAX(J16:J18)-MIN(J16:J18) -> 0 | K20: =MAX(K16:K18)-MIN(K16:K18) -> 0 | ... M20: =MAX(M16:M18)-MIN(M16:M18) -> 0 | N20: Rc | O20: =SUM(D20:M20)/10 -> 0
B21: PART | N21: X | O21: =(O14+O9+O19)/3 -> 0
B22: AVE | C22: Xp | D22: =(D14+D9)/2 -> 0 | E22: =(E14+E9)/2 -> 0 | F22: =(F14+F9)/2 -> 0 | G22: =(G14+G9)/2 -> 0 | H22: =(H14+H9)/2 -> 0 | I22: =(I14+I9)/2 -> 0 | J22: =(J14+J9)/2 -> 0 | K22: =(K14+K9)/2 -> 0 | ... M22: =(M14+M9)/2 -> 0 | N22: Rp | O22: =MAX(A22:M22)-MIN(A22:M22) -> 0
B23: R=(Ra+Rb)/2 | N23: R | O23: =(O15+O10+O20)/3 -> 0
B24: Max X-MaxB=X diff | N24: X diff | O24: =MAX(O9,O14,O19)-MIN(O9,O14,O19) -> 0
B26: R*D4=UCLR | O26: =O23*3.27 -> 0
B27: R*D3=LCLR | O27: =O23*0 -> 0
B29: Gage Repeatability and Reproducibility Report
E30: =G4 -> ICP- MS 金屬 Ｒ-Ｒ測試 | I30: Gage Nane | K30: ASSAY R&R | N30: Date: | O30: ='METAL RAW DATA'!E2 -> 20180831
B31: Part No.and Name | I31: Gage No | N31: performed by
B32: Characteristics: | I32: Gage Type: | K32: METAL
B33: Specification:
E34: R= | F34: =O23 -> 0 | G34: x diff= | H34: =O24 -> 0 | I34: Rp= | K34: =O22 -> 0
B35: From date sheet: | I35: %Total Variation(TV)
E36: n= | F36: 3 | G36: test= | H36: 10
B37: Measurement Unit Analysis
B38: Repeatability-Equipment Variation(EV) | D38: EV = | E38: R × K1 | G38: Trials | H38: K1 | I38: %EV=100(EV/TV)
D39: =F34 -> 0 | E39: * | F39: =H40 -> 0.5908 | G39: 2 | H39: 0.8862 | I39: =100*(D40/D58) -> #DIV/0! | K39: %
B40: = | D40: =D39*F39 -> 0 | G40: 3 | H40: 0.5908
B41: 重複性-設備變異
B42: Reproducibity-Appraiser Variation(AV) | D42: AV= | E42: √【（Xdiff X K2）2-（EV2/nr）】 | I42: %AV=100(AV/TV)
I43: =100*(E44/D58) -> #DIV/0! | K43: %
...

Sheet Mn
F1: ='METAL RAW DATA'!B3 -> ICP- MS 金屬 Ｒ-Ｒ測試
B3: ITEM | C3: ='METAL RAW DATA'!B14 -> Mn | F3: DATE | G3: ='METAL RAW DATA'!E2 -> 20180831 | L3: NDC= | M3: =1.41*(0.01/D70) -> #DIV/0!
F4: 儀 器 | G4: ='METAL RAW DATA'!B3 -> ICP- MS 金屬 Ｒ-Ｒ測試
D5: 1 | E5: 2 | F5: 3 | G5: 4 | H5: 5 | I5: 6 | J5: 7 | K5: 8 | L5: 9 | M5: 10 | O5: AVE
B6: A | D6: ='METAL RAW DATA'!C14 -> 0 | E6: ='METAL RAW DATA'!D14 -> 0 | F6: ='METAL RAW DATA'!E14 -> 0 | G6: ='METAL RAW DATA'!F14 -> 0 | H6: ='METAL RAW DATA'!G14 -> 0 | I6: ='METAL RAW DATA'!H14 -> 0 | J6: ='METAL RAW DATA'!I14 -> 0 | K6: ='METAL RAW DATA'!J14 -> 0 | ... M6: ='METAL RAW DATA'!L14 -> 0 | O6: =SUM(D6:M6)/10 -> 0
B7: A | D7: ='METAL RAW DATA'!M14 -> 0 | E7: ='METAL RAW DATA'!N14 -> 0 | F7: ='METAL RAW DATA'!O14 -> 0 | G7: ='METAL RAW DATA'!P14 -> 0 | H7: ='METAL RAW DATA'!Q14 -> 0 | I7: ='METAL RAW DATA'!R14 -> 0 | J7: ='METAL RAW DATA'!S14 -> 0 | K7: ='METAL RAW DATA'!T14 -> 0 | ... M7: ='METAL RAW DATA'!V14 -> 0 | O7: =SUM(D7:M7)/10 -> 0
B8: A | D8: ='METAL RAW DATA'!W14 -> 0 | E8: ='METAL RAW DATA'!X14 -> 0 | F8: ='METAL RAW DATA'!Y14 -> 0 | G8: ='METAL RAW DATA'!Z14 -> 0 | H8: ='METAL RAW DATA'!AA14 -> 0 | I8: ='METAL RAW DATA'!AB14 -> 0 | J8: ='METAL RAW DATA'!AC14 -> 0 | K8: ='METAL RAW DATA'!AD14 -> 0 | ... M8: ='METAL RAW DATA'!AF14 -> 0 | O8: =SUM(D8:M8)/10 -> 0
B9: AVE | D9: =AVERAGE(D6:D8) -> 0 | E9: =AVERAGE(E6:E8) -> 0 | F9: =AVERAGE(F6:F8) -> 0 | G9: =AVERAGE(G6:G8) -> 0 | H9: =AVERAGE(H6:H8) -> 0 | I9: =AVERAGE(I6:I8) -> 0 | J9: =AVERAGE(J6:J8) -> 0 | K9: =AVERAGE(K6:K8) -> 0 | ... M9: =AVERAGE(M6:M8) -> 0 | N9: Xa | O9: =AVERAGE(O6:O8) -> 0
B10: RANGE | D10: =MAX(D6:D8)-MIN(D6:D8) -> 0 | E10: =MAX(E6:E8)-MIN(E6:E8) -> 0 | F10: =MAX(F6:F8)-MIN(F6:F8) -> 0 | G10: =MAX(G6:G8)-MIN(G6:G8) -> 0 | H10: =MAX(H6:H8)-MIN(H6:H8) -> 0 | I10: =MAX(I6:I8)-MIN(I6:I8) -> 0 | J10: =MAX(J6:J8)-MIN(J6:J8) -> 0 | K10: =MAX(K6:K8)-MIN(K6:K8) -> 0 | ... M10: =MAX(M6:M8)-MIN(M6:M8) -> 0 | N10: Ra | O10: =SUM(D10:M10)/10 -> 0
B11: B | D11: ='METAL RAW DATA'!C30 -> 0 | E11: ='METAL RAW DATA'!D30 -> 0 | F11: ='METAL RAW DATA'!E30 -> 0 | G11: ='METAL RAW DATA'!F30 -> 0 | H11: ='METAL RAW DATA'!G30 -> 0 | I11: ='METAL RAW DATA'!H30 -> 0 | J11: ='METAL RAW DATA'!I30 -> 0 | K11: ='METAL RAW DATA'!J30 -> 0 | ... M11: ='METAL RAW DATA'!L30 -> 0 | O11: =SUM(D11:M11)/10 -> 0
B12: B | D12: ='METAL RAW DATA'!M30 -> 0 | E12: ='METAL RAW DATA'!N30 -> 0 | F12: ='METAL RAW DATA'!O30 -> 0 | G12: ='METAL RAW DATA'!P30 -> 0 | H12: ='METAL RAW DATA'!Q30 -> 0 | I12: ='METAL RAW DATA'!R30 -> 0 | J12: ='METAL RAW DATA'!S30 -> 0 | K12: ='METAL RAW DATA'!T30 -> 0 | ... M12: ='METAL RAW DATA'!V30 -> 0 | O12: =SUM(D12:M12)/10 -> 0
B13: B | D13: ='METAL RAW DATA'!W30 -> 0 | E13: ='METAL RAW DATA'!X30 -> 0 | F13: ='METAL RAW DATA'!Y30 -> 0 | G13: ='METAL RAW DATA'!Z30 -> 0 | H13: ='METAL RAW DATA'!AA30 -> 0 | I13: ='METAL RAW DATA'!AB30 -> 0 | J13: ='METAL RAW DATA'!AC30 -> 0 | K13: ='METAL RAW DATA'!AD30 -> 0 | ... M13: ='METAL RAW DATA'!AF30 -> 0 | O13: =SUM(C13:M13)/10 -> 0
B14: AVE | D14: =AVERAGE(D11:D13) -> 0 | E14: =AVERAGE(E11:E13) -> 0 | F14: =AVERAGE(F11:F13) -> 0 | G14: =AVERAGE(G11:G13) -> 0 | H14: =AVERAGE(H11:H13) -> 0 | I14: =AVERAGE(I11:I13) -> 0 | J14: =AVERAGE(J11:J13) -> 0 | K14: =AVERAGE(K11:K13) -> 0 | ... M14: =AVERAGE(M11:M13) -> 0 | N14: Xb | O14: =SUM(D14:M14)/10 -> 0
B15: RANGE | D15: =MAX(D11:D13)-MIN(D11:D13) -> 0 | E15: =MAX(E11:E13)-MIN(E11:E13) -> 0 | F15: =MAX(F11:F13)-MIN(F11:F13) -> 0 | G15: =MAX(G11:G13)-MIN(G11:G13) -> 0 | H15: =MAX(H11:H13)-MIN(H11:H13) -> 0 | I15: =MAX(I11:I13)-MIN(I11:I13) -> 0 | J15: =MAX(J11:J13)-MIN(J11:J13) -> 0 | K15: =MAX(K11:K13)-MIN(K11:K13) -> 0 | ... M15: =MAX(M11:M13)-MIN(M11:M13) -> 0 | N15: Rb | O15: =SUM(D15:M15)/10 -> 0
