Workbook

Sheet METAL RAW DATA
C1: IPA-M13 | F1: DATE | G1: 20231226
C2: ICP- MS 金屬 R-R測試 | F2: A | G2: 賴俊顏
F3: B
F4: C
C6: 分析師A | D6: 23 Na [ 1 ] | E6: 24 Mg [ 1 ] | F6: 27 Al [ 1 ] | G6: 39 K [ 1 ] | H6: 40 Ca [ 1 ] | I6: 52 Cr [ 1 ] | J6: 55 Mn [ 1 ] | K6: 56 Fe [ 1 ] | L6: 58 Ni [ 1 ] | M6: 59 Co [ 1 ] | N6: 63 Cu [ 1 ] | O6: 66 Zn [ 2 ] | P6: 208 Pb [ 2 ]
C7: R1-1
C8: R1-2
C9: R1-3
C10: R2-1
C11: R2-2
C12: R2-3
C13: R3-1
C14: R3-2
C15: R3-3
C16: R4-1
C17: R4-2
C18: R4-3
... C21: R5-3
C23: 分析師B | D23: 23 Na [ 1 ] | E23: 24 Mg [ 1 ] | F23: 27 Al [ 1 ] | G23: 39 K [ 1 ] | H23: 40 Ca [ 1 ] | I23: 52 Cr [ 1 ] | J23: 55 Mn [ 1 ] | K23: 56 Fe [ 1 ] | L23: 58 Ni [ 1 ] | M23: 59 Co [ 1 ] | N23: 63 Cu [ 1 ] | O23: 66 Zn [ 2 ] | P23: 208 Pb [ 2 ]
C24: R1-1
C25: R1-2
C26: R1-3
C27: R2-1
C28: R2-2
C29: R2-3
C30: R3-1
C31: R3-2
C32: R3-3
C33: R4-1
C34: R4-2
C35: R4-3
... C38: R5-3
C40: 分析師C | D40: 23 Na [ 1 ] | E40: 24 Mg [ 1 ] | F40: 27 Al [ 1 ] | G40: 39 K [ 1 ] | H40: 40 Ca [ 1 ] | I40: 52 Cr [ 1 ] | J40: 55 Mn [ 1 ] | K40: 56 Fe [ 1 ] | L40: 58 Ni [ 1 ] | M40: 59 Co [ 1 ] | N40: 63 Cu [ 1 ] | O40: 66 Zn [ 2 ] | P40: 208 Pb [ 2 ]
C41: R1-1
C42: R1-2
C43: R1-3
C44: R2-1
C45: R2-2
C46: R2-3
C47: R3-1
...

Sheet Na
B3: ITEM | C3: Na | F3: DATE | G3: ='METAL RAW DATA'!G1 -> 20231226 | L3: NDC= | M3: =1.41*(D54/D70) -> #DIV/0!
F4: 儀 器 | G4: ='METAL RAW DATA'!C2 -> ICP- MS 金屬 R-R測試
D5: 1 | E5: 2 | F5: 3 | G5: 4 | H5: 5 | J5: AVE
B6: 分析師A | C6: N1 | D6: ='METAL RAW DATA'!D7 -> 0 | E6: ='METAL RAW DATA'!D10 -> 0 | F6: ='METAL RAW DATA'!D13 -> 0 | G6: ='METAL RAW DATA'!D16 -> 0 | H6: ='METAL RAW DATA'!D19 -> 0 | J6: =AVERAGE(D6:H6) -> 0
B7: 分析師A | C7: N2 | D7: ='METAL RAW DATA'!D8 -> 0 | E7: ='METAL RAW DATA'!D11 -> 0 | F7: ='METAL RAW DATA'!D14 -> 0 | G7: ='METAL RAW DATA'!D17 -> 0 | H7: ='METAL RAW DATA'!D20 -> 0 | J7: =AVERAGE(D7:H7) -> 0
B8: 分析師A | C8: N3 | D8: ='METAL RAW DATA'!D9 -> 0 | E8: ='METAL RAW DATA'!D12 -> 0 | F8: ='METAL RAW DATA'!D15 -> 0 | G8: ='METAL RAW DATA'!D18 -> 0 | H8: ='METAL RAW DATA'!D21 -> 0 | J8: =AVERAGE(D8:H8) -> 0
B9: AVE | D9: =AVERAGE(D6:D8) -> 0 | E9: =AVERAGE(E6:E8) -> 0 | F9: =AVERAGE(F6:F8) -> 0 | G9: =AVERAGE(G6:G8) -> 0 | H9: =AVERAGE(H6:H8) -> 0 | I9: Xa | J9: =AVERAGE(D9:H9) -> 0
B10: RANGE | D10: =MAX(D6:D8)-MIN(D6:D8) -> 0 | E10: =MAX(E6:E8)-MIN(E6:E8) -> 0 | F10: =MAX(F6:F8)-MIN(F6:F8) -> 0 | G10: =MAX(G6:G8)-MIN(G6:G8) -> 0 | H10: =MAX(H6:H8)-MIN(H6:H8) -> 0 | I10: Ra | J10: =AVERAGE(D10:H10) -> 0
B11: 分析師B | C11: N1 | D11: ='METAL RAW DATA'!D24 -> 0 | E11: ='METAL RAW DATA'!D27 -> 0 | F11: ='METAL RAW DATA'!D30 -> 0 | G11: ='METAL RAW DATA'!D33 -> 0 | H11: ='METAL RAW DATA'!D36 -> 0 | J11: =AVERAGE(D11:H11) -> 0
B12: 分析師B | C12: N2 | D12: ='METAL RAW DATA'!D25 -> 0 | E12: ='METAL RAW DATA'!D28 -> 0 | F12: ='METAL RAW DATA'!D31 -> 0 | G12: ='METAL RAW DATA'!D34 -> 0 | H12: ='METAL RAW DATA'!D37 -> 0 | J12: =AVERAGE(D12:H12) -> 0
B13: 分析師B | C13: N3 | D13: ='METAL RAW DATA'!D26 -> 0 | E13: ='METAL RAW DATA'!D29 -> 0 | F13: ='METAL RAW DATA'!D32 -> 0 | G13: ='METAL RAW DATA'!D35 -> 0 | H13: ='METAL RAW DATA'!D38 -> 0 | J13: =AVERAGE(D13:H13) -> 0
B14: AVE | D14: =AVERAGE(D11:D13) -> 0 | E14: =AVERAGE(E11:E13) -> 0 | F14: =AVERAGE(F11:F13) -> 0 | G14: =AVERAGE(G11:G13) -> 0 | H14: =AVERAGE(H11:H13) -> 0 | I14: Xb | J14: =AVERAGE(D14:H14) -> 0
B15: RANGE | D15: =MAX(D11:D13)-MIN(D11:D13) -> 0 | E15: =MAX(E11:E13)-MIN(E11:E13) -> 0 | F15: =MAX(F11:F13)-MIN(F11:F13) -> 0 | G15: =MAX(G11:G13)-MIN(G11:G13) -> 0 | H15: =MAX(H11:H13)-MIN(H11:H13) -> 0 | I15: Rb | J15: =AVERAGE(D15:H15) -> 0
B16: 分析師C | C16: N1 | D16: ='METAL RAW DATA'!D41 -> 0 | E16: ='METAL RAW DATA'!D44 -> 0 | F16: ='METAL RAW DATA'!D47 -> 0 | G16: ='METAL RAW DATA'!D50 -> 0 | H16: ='METAL RAW DATA'!D53 -> 0 | J16: =AVERAGE(D16:H16) -> 0
B17: 分析師C | C17: N2 | D17: ='METAL RAW DATA'!D42 -> 0 | E17: ='METAL RAW DATA'!D45 -> 0 | F17: ='METAL RAW DATA'!D48 -> 0 | G17: ='METAL RAW DATA'!D51 -> 0 | H17: ='METAL RAW DATA'!D54 -> 0 | J17: =AVERAGE(D17:H17) -> 0
B18: 分析師C | C18: N3 | D18: ='METAL RAW DATA'!D43 -> 0 | E18: ='METAL RAW DATA'!D46 -> 0 | F18: ='METAL RAW DATA'!D49 -> 0 | G18: ='METAL RAW DATA'!D52 -> 0 | H18: ='METAL RAW DATA'!D55 -> 0 | J18: =AVERAGE(D18:H18) -> 0
B19: AVE | D19: =AVERAGE(D16:D18) -> 0 | E19: =AVERAGE(E16:E18) -> 0 | F19: =AVERAGE(F16:F18) -> 0 | G19: =AVERAGE(G16:G18) -> 0 | H19: =AVERAGE(H16:H18) -> 0 | I19: Xa | J19: =AVERAGE(D19:H19) -> 0
B20: RANGE | D20: =MAX(D16:D18)-MIN(D16:D18) -> 0 | E20: =MAX(E16:E18)-MIN(E16:E18) -> 0 | F20: =MAX(F16:F18)-MIN(F16:F18) -> 0 | G20: =MAX(G16:G18)-MIN(G16:G18) -> 0 | H20: =MAX(H16:H18)-MIN(H16:H18) -> 0 | I20: Ra | J20: =AVERAGE(D20:H20) -> 0
B21: PART | I21: X | J21: =(J14+J9+J19)/3 -> 0
B22: AVE | C22: Xp | D22: =(D14+D9+D19)/3 -> 0 | E22: =(E14+E9+E19)/3 -> 0 | F22: =(F14+F9+F19)/3 -> 0 | G22: =(G14+G9+G19)/3 -> 0 | H22: =(H14+H9+H19)/3 -> 0 | I22: Rp | J22: =MAX(D22:H22)-MIN(D22:H22) -> 0
B23: R=(Ra+Rb+Rc)/3 | I23: R | J23: =(J15+J10+J20)/3 -> 0
B24: Max X-MaxB=X diff | I24: X diff | J24: =MAX(J9,J14,J19)-MIN(J9,J14,J19) -> 0
B26: R*D4=UCLR | J26: =J23*3.27 -> 0
B27: R*D3=LCLR | J27: =J23*0 -> 0
B29: Gage Repeatability and Reproducibility Report
E30: =G4 -> ICP- MS 金屬 R-R測試 | I30: Gage Nane | K30: ASSAY R&R | N30: Date: | O30: ='METAL RAW DATA'!#REF! -> #REF!
B31: Part No.and Name | I31: Gage No | N31: performed by
B32: Characteristics: | I32: Gage Type: | K32: METAL
B33: Specification:
E34: R= | F34: =J23 -> 0 | G34: x diff= | H34: =J24 -> 0 | I34: Rp= | K34: =J22 -> 0
B35: From date sheet: | I35: %Total Variation(TV)
E36: 操作人數(m=) | F36: 3 | G36: 重複測量(r=) | H36: 3 | I36: 測量樣品數(n=) | J36: 5
B37: Measurement Unit Analysis
B38: Repeatability-Equipment Variation(EV) | D38: EV = | E38: R × K1 | G38: Trials | H38: K1 | I38: %EV=100(EV/TV)
D39: =F34 -> 0 | E39: * | F39: =H40 -> 0.5908 | G39: 2 | H39: 0.8862 | I39: =100*(D40/D58) -> #DIV/0! | K39: %
B40: = | D40: =D39*F39 -> 0 | G40: 3 | H40: 0.5908
B41: 重複性-設備變異
B42: Reproducibity-Appraiser Variation(AV) | D42: AV= | E42: √【（Xdiff X K2）2-（EV2/nr）】 | I42: %AV=100(AV/TV)
I43: =100*(E44/D58) -> #DIV/0! | K43: %
D44: = | E44: =D66 -> 0
...

Sheet Mg
B3: ITEM | C3: Mg | F3: DATE | G3: ='METAL RAW DATA'!G1 -> 20231226 | L3: NDC= | M3: =1.41*(D54/D70) -> #DIV/0!
F4: 儀 器 | G4: ='METAL RAW DATA'!C2 -> ICP- MS 金屬 R-R測試
D5: 1 | E5: 2 | F5: 3 | G5: 4 | H5: 5 | J5: AVE
B6: 分析師A | C6: N1 | D6: ='METAL RAW DATA'!E7 -> 0 | E6: ='METAL RAW DATA'!E10 -> 0 | F6: ='METAL RAW DATA'!E13 -> 0 | G6: ='METAL RAW DATA'!E16 -> 0 | H6: ='METAL RAW DATA'!E19 -> 0 | J6: =AVERAGE(D6:H6) -> 0
B7: 分析師A | C7: N2 | D7: ='METAL RAW DATA'!E8 -> 0 | E7: ='METAL RAW DATA'!E11 -> 0 | F7: ='METAL RAW DATA'!E14 -> 0 | G7: ='METAL RAW DATA'!E17 -> 0 | H7: ='METAL RAW DATA'!E20 -> 0 | J7: =AVERAGE(D7:H7) -> 0
B8: 分析師A | C8: N3 | D8: ='METAL RAW DATA'!E9 -> 0 | E8: ='METAL RAW DATA'!E12 -> 0 | F8: ='METAL RAW DATA'!E15 -> 0 | G8: ='METAL RAW DATA'!E18 -> 0 | H8: ='METAL RAW DATA'!E21 -> 0 | J8: =AVERAGE(D8:H8) -> 0
B9: AVE | D9: =AVERAGE(D6:D8) -> 0 | E9: =AVERAGE(E6:E8) -> 0 | F9: =AVERAGE(F6:F8) -> 0 | G9: =AVERAGE(G6:G8) -> 0 | H9: =AVERAGE(H6:H8) -> 0 | I9: Xa | J9: =AVERAGE(D9:H9) -> 0
B10: RANGE | D10: =MAX(D6:D8)-MIN(D6:D8) -> 0 | E10: =MAX(E6:E8)-MIN(E6:E8) -> 0 | F10: =MAX(F6:F8)-MIN(F6:F8) -> 0 | G10: =MAX(G6:G8)-MIN(G6:G8) -> 0 | H10: =MAX(H6:H8)-MIN(H6:H8) -> 0 | I10: Ra | J10: =AVERAGE(D10:H10) -> 0
B11: 分析師B | C11: N1 | D11: ='METAL RAW DATA'!E24 -> 0 | E11: ='METAL RAW DATA'!E27 -> 0 | F11: ='METAL RAW DATA'!E30 -> 0 | G11: ='METAL RAW DATA'!E33 -> 0 | H11: ='METAL RAW DATA'!E36 -> 0 | J11: =AVERAGE(D11:H11) -> 0
B12: 分析師B | C12: N2 | D12: ='METAL RAW DATA'!E25 -> 0 | E12: ='METAL RAW DATA'!E28 -> 0 | F12: ='METAL RAW DATA'!E31 -> 0 | G12: ='METAL RAW DATA'!E34 -> 0 | H12: ='METAL RAW DATA'!E37 -> 0 | J12: =AVERAGE(D12:H12) -> 0
B13: 分析師B | C13: N3 | D13: ='METAL RAW DATA'!E26 -> 0 | E13: ='METAL RAW DATA'!E29 -> 0 | F13: ='METAL RAW DATA'!E32 -> 0 | G13: ='METAL RAW DATA'!E35 -> 0 | H13: ='METAL RAW DATA'!E38 -> 0 | J13: =AVERAGE(D13:H13) -> 0
B14: AVE | D14: =AVERAGE(D11:D13) -> 0 | E14: =AVERAGE(E11:E13) -> 0 | F14: =AVERAGE(F11:F13) -> 0 | G14: =AVERAGE(G11:G13) -> 0 | H14: =AVERAGE(H11:H13) -> 0 | I14: Xb | J14: =AVERAGE(D14:H14) -> 0
B15: RANGE | D15: =MAX(D11:D13)-MIN(D11:D13) -> 0 | E15: =MAX(E11:E13)-MIN(E11:E13) -> 0 | F15: =MAX(F11:F13)-MIN(F11:F13) -> 0 | G15: =MAX(G11:G13)-MIN(G11:G13) -> 0 | H15: =MAX(H11:H13)-MIN(H11:H13) -> 0 | I15: Rb | J15: =AVERAGE(D15:H15) -> 0
B16: 分析師C | C16: N1 | D16: ='METAL RAW DATA'!E41 -> 0 | E16: ='METAL RAW DATA'!E44 -> 0 | F16: ='METAL RAW DATA'!E47 -> 0 | G16: ='METAL RAW DATA'!E50 -> 0 | H16: ='METAL RAW DATA'!E53 -> 0 | J16: =AVERAGE(D16:H16) -> 0
B17: 分析師C | C17: N2 | D17: ='METAL RAW DATA'!E42 -> 0 | E17: ='METAL RAW DATA'!E45 -> 0 | F17: ='METAL RAW DATA'!E48 -> 0 | G17: ='METAL RAW DATA'!E51 -> 0 | H17: ='METAL RAW DATA'!E54 -> 0 | J17: =AVERAGE(D17:H17) -> 0
B18: 分析師C | C18: N3 | D18: ='METAL RAW DATA'!E43 -> 0 | E18: ='METAL RAW DATA'!E46 -> 0 | F18: ='METAL RAW DATA'!E49 -> 0 | G18: ='METAL RAW DATA'!E52 -> 0 | H18: ='METAL RAW DATA'!E55 -> 0 | J18: =AVERAGE(D18:H18) -> 0
B19: AVE | D19: =AVERAGE(D16:D18) -> 0 | E19: =AVERAGE(E16:E18) -> 0 | F19: =AVERAGE(F16:F18) -> 0 | G19: =AVERAGE(G16:G18) -> 0 | H19: =AVERAGE(H16:H18) -> 0 | I19: Xa | J19: =AVERAGE(D19:H19) -> 0
B20: RANGE | D20: =MAX(D16:D18)-MIN(D16:D18) -> 0 | E20: =MAX(E16:E18)-MIN(E16:E18) -> 0 | F20: =MAX(F16:F18)-MIN(F16:F18) -> 0 | G20: =MAX(G16:G18)-MIN(G16:G18) -> 0 | H20: =MAX(H16:H18)-MIN(H16:H18) -> 0 | I20: Ra | J20: =AVERAGE(D20:H20) -> 0
B21: PART | I21: X | J21: =(J14+J9+J19)/3 -> 0
B22: AVE | C22: Xp | D22: =(D14+D9+D19)/3 -> 0 | E22: =(E14+E9+E19)/3 -> 0 | F22: =(F14+F9+F19)/3 -> 0 | G22: =(G14+G9+G19)/3 -> 0 | H22: =(H14+H9+H19)/3 -> 0 | I22: Rp | J22: =MAX(D22:H22)-MIN(D22:H22) -> 0
B23: R=(Ra+Rb+Rc)/3 | I23: R | J23: =(J15+J10+J20)/3 -> 0
B24: Max X-MaxB=X diff | I24: X diff | J24: =MAX(J9,J14,J19)-MIN(J9,J14,J19) -> 0
B26: R*D4=UCLR | J26: =J23*3.27 -> 0
B27: R*D3=LCLR | J27: =J23*0 -> 0
B29: Gage Repeatability and Reproducibility Report
E30: =G4 -> ICP- MS 金屬 R-R測試 | I30: Gage Nane | K30: ASSAY R&R | N30: Date: | O30: ='METAL RAW DATA'!#REF! -> #REF!
B31: Part No.and Name | I31: Gage No | N31: performed by
B32: Characteristics: | I32: Gage Type: | K32: METAL
B33: Specification:
E34: R= | F34: =J23 -> 0 | G34: x diff= | H34: =J24 -> 0 | I34: Rp= | K34: =J22 -> 0
B35: From date sheet: | I35: %Total Variation(TV)
E36: 操作人數(m=) | F36: 3 | G36: 重複測量(r=) | H36: 3 | I36: 測量樣品數(n=) | J36: 5
B37: Measurement Unit Analysis
B38: Repeatability-Equipment Variation(EV) | D38: EV = | E38: R × K1 | G38: Trials | H38: K1 | I38: %EV=100(EV/TV)
D39: =F34 -> 0 | E39: * | F39: =H40 -> 0.5908 | G39: 2 | H39: 0.8862 | I39: =100*(D40/D58) -> #DIV/0! | K39: %
B40: = | D40: =D39*F39 -> 0 | G40: 3 | H40: 0.5908
B41: 重複性-設備變異
B42: Reproducibity-Appraiser Variation(AV) | D42: AV= | E42: √【（Xdiff X K2）2-（EV2/nr）】 | I42: %AV=100(AV/TV)
I43: =100*(E44/D58) -> #DIV/0! | K43: %
D44: = | E44: =D66 -> 0
...

Sheet Al
B3: ITEM | C3: Al | F3: DATE | G3: ='METAL RAW DATA'!G1 -> 20231226 | L3: NDC= | M3: =1.41*(D54/D70) -> #DIV/0!
F4: 儀 器 | G4: ='METAL RAW DATA'!C2 -> ICP- MS 金屬 R-R測試
D5: 1 | E5: 2 | F5: 3 | G5: 4 | H5: 5 | J5: AVE
B6: 分析師A | C6: N1 | D6: ='METAL RAW DATA'!F7 -> 0 | E6: ='METAL RAW DATA'!F10 -> 0 | F6: ='METAL RAW DATA'!F13 -> 0 | G6: ='METAL RAW DATA'!F16 -> 0 | H6: ='METAL RAW DATA'!F19 -> 0 | J6: =AVERAGE(D6:H6) -> 0
B7: 分析師A | C7: N2 | D7: ='METAL RAW DATA'!F8 -> 0 | E7: ='METAL RAW DATA'!F11 -> 0 | F7: ='METAL RAW DATA'!F14 -> 0 | G7: ='METAL RAW DATA'!F17 -> 0 | H7: ='METAL RAW DATA'!F20 -> 0 | J7: =AVERAGE(D7:H7) -> 0
B8: 分析師A | C8: N3 | D8: ='METAL RAW DATA'!F9 -> 0 | E8: ='METAL RAW DATA'!F12 -> 0 | F8: ='METAL RAW DATA'!F15 -> 0 | G8: ='METAL RAW DATA'!F18 -> 0 | H8: ='METAL RAW DATA'!F21 -> 0 | J8: =AVERAGE(D8:H8) -> 0
B9: AVE | D9: =AVERAGE(D6:D8) -> 0 | E9: =AVERAGE(E6:E8) -> 0 | F9: =AVERAGE(F6:F8) -> 0 | G9: =AVERAGE(G6:G8) -> 0 | H9: =AVERAGE(H6:H8) -> 0 | I9: Xa | J9: =AVERAGE(D9:H9) -> 0
B10: RANGE | D10: =MAX(D6:D8)-MIN(D6:D8) -> 0 | E10: =MAX(E6:E8)-MIN(E6:E8) -> 0 | F10: =MAX(F6:F8)-MIN(F6:F8) -> 0 | G10: =MAX(G6:G8)-MIN(G6:G8) -> 0 | H10: =MAX(H6:H8)-MIN(H6:H8) -> 0 | I10: Ra | J10: =AVERAGE(D10:H10) -> 0
B11: 分析師B | C11: N1 | D11: ='METAL RAW DATA'!F24 -> 0 | E11: ='METAL RAW DATA'!F27 -> 0 | F11: ='METAL RAW DATA'!F30 -> 0 | G11: ='METAL RAW DATA'!F33 -> 0 | H11: ='METAL RAW DATA'!F36 -> 0 | J11: =AVERAGE(D11:H11) -> 0
B12: 分析師B | C12: N2 | D12: ='METAL RAW DATA'!F25 -> 0 | E12: ='METAL RAW DATA'!F28 -> 0 | F12: ='METAL RAW DATA'!F31 -> 0 | G12: ='METAL RAW DATA'!F34 -> 0 | H12: ='METAL RAW DATA'!F37 -> 0 | J12: =AVERAGE(D12:H12) -> 0
B13: 分析師B | C13: N3 | D13: ='METAL RAW DATA'!F26 -> 0 | E13: ='METAL RAW DATA'!F29 -> 0 | F13: ='METAL RAW DATA'!F32 -> 0 | G13: ='METAL RAW DATA'!F35 -> 0 | H13: ='METAL RAW DATA'!F38 -> 0 | J13: =AVERAGE(D13:H13) -> 0
B14: AVE | D14: =AVERAGE(D11:D13) -> 0 | E14: =AVERAGE(E11:E13) -> 0 | F14: =AVERAGE(F11:F13) -> 0 | G14: =AVERAGE(G11:G13) -> 0 | H14: =AVERAGE(H11:H13) -> 0 | I14: Xb | J14: =AVERAGE(D14:H14) -> 0
B15: RANGE | D15: =MAX(D11:D13)-MIN(D11:D13) -> 0 | E15: =MAX(E11:E13)-MIN(E11:E13) -> 0 | F15: =MAX(F11:F13)-MIN(F11:F13) -> 0 | G15: =MAX(G11:G13)-MIN(G11:G13) -> 0 | H15: =MAX(H11:H13)-MIN(H11:H13) -> 0 | I15: Rb | J15: =AVERAGE(D15:H15) -> 0
B16: 分析師C | C16: N1 | D16: ='METAL RAW DATA'!F41 -> 0 | E16: ='METAL RAW DATA'!F44 -> 0 | F16: ='METAL RAW DATA'!F47 -> 0 | G16: ='METAL RAW DATA'!F50 -> 0 | H16: ='METAL RAW DATA'!F53 -> 0 | J16: =AVERAGE(D16:H16) -> 0
B17: 分析師C | C17: N2 | D17: ='METAL RAW DATA'!F42 -> 0 | E17: ='METAL RAW DATA'!F45 -> 0 | F17: ='METAL RAW DATA'!F48 -> 0 | G17: ='METAL RAW DATA'!F51 -> 0 | H17: ='METAL RAW DATA'!F54 -> 0 | J17: =AVERAGE(D17:H17) -> 0
B18: 分析師C | C18: N3 | D18: ='METAL RAW DATA'!F43 -> 0 | E18: ='METAL RAW DATA'!F46 -> 0 | F18: ='METAL RAW DATA'!F49 -> 0 | G18: ='METAL RAW DATA'!F52 -> 0 | H18: ='METAL RAW DATA'!F55 -> 0 | J18: =AVERAGE(D18:H18) -> 0
B19: AVE | D19: =AVERAGE(D16:D18) -> 0 | E19: =AVERAGE(E16:E18) -> 0 | F19: =AVERAGE(F16:F18) -> 0 | G19: =AVERAGE(G16:G18) -> 0 | H19: =AVERAGE(H16:H18) -> 0 | I19: Xa | J19: =AVERAGE(D19:H19) -> 0
B20: RANGE | D20: =MAX(D16:D18)-MIN(D16:D18) -> 0 | E20: =MAX(E16:E18)-MIN(E16:E18) -> 0 | F20: =MAX(F16:F18)-MIN(F16:F18) -> 0 | G20: =MAX(G16:G18)-MIN(G16:G18) -> 0 | H20: =MAX(H16:H18)-MIN(H16:H18) -> 0 | I20: Ra | J20: =AVERAGE(D20:H20) -> 0
B21: PART | I21: X | J21: =(J14+J9+J19)/3 -> 0
B22: AVE | C22: Xp | D22: =(D14+D9+D19)/3 -> 0 | E22: =(E14+E9+E19)/3 -> 0 | F22: =(F14+F9+F19)/3 -> 0 | G22: =(G14+G9+G19)/3 -> 0 | H22: =(H14+H9+H19)/3 -> 0 | I22: Rp | J22: =MAX(D22:H22)-MIN(D22:H22) -> 0
B23: R=(Ra+Rb+Rc)/3 | I23: R | J23: =(J15+J10+J20)/3 -> 0
B24: Max X-MaxB=X diff | I24: X diff | J24: =MAX(J9,J14,J19)-MIN(J9,J14,J19) -> 0
B26: R*D4=UCLR | J26: =J23*3.27 -> 0
B27: R*D3=LCLR | J27: =J23*0 -> 0
B29: Gage Repeatability and Reproducibility Report
E30: =G4 -> ICP- MS 金屬 R-R測試 | I30: Gage Nane | K30: ASSAY R&R | N30: Date: | O30: ='METAL RAW DATA'!#REF! -> #REF!
B31: Part No.and Name | I31: Gage No | N31: performed by
B32: Characteristics: | I32: Gage Type: | K32: METAL
B33: Specification:
E34: R= | F34: =J23 -> 0 | G34: x diff= | H34: =J24 -> 0 | I34: Rp= | K34: =J22 -> 0
B35: From date sheet: | I35: %Total Variation(TV)
E36: 操作人數(m=) | F36: 3 | G36: 重複測量(r=) | H36: 3 | I36: 測量樣品數(n=) | J36: 5
B37: Measurement Unit Analysis
B38: Repeatability-Equipment Variation(EV) | D38: EV = | E38: R × K1 | G38: Trials | H38: K1 | I38: %EV=100(EV/TV)
D39: =F34 -> 0 | E39: * | F39: =H40 -> 0.5908 | G39: 2 | H39: 0.8862 | I39: =100*(D40/D58) -> #DIV/0! | K39: %
B40: = | D40: =D39*F39 -> 0 | G40: 3 | H40: 0.5908
B41: 重複性-設備變異
B42: Reproducibity-Appraiser Variation(AV) | D42: AV= | E42: √【（Xdiff X K2）2-（EV2/nr）】 | I42: %AV=100(AV/TV)
I43: =100*(E44/D58) -> #DIV/0! | K43: %
D44: = | E44: =D66 -> 0
...

Sheet K
B3: ITEM | C3: K | F3: DATE | G3: ='METAL RAW DATA'!G1 -> 20231226 | L3: NDC= | M3: =1.41*(D54/D70) -> #DIV/0!
F4: 儀 器 | G4: ='METAL RAW DATA'!C2 -> ICP- MS 金屬 R-R測試
D5: 1 | E5: 2 | F5: 3 | G5: 4 | H5: 5 | J5: AVE
B6: 分析師A | C6: N1 | D6: ='METAL RAW DATA'!G7 -> 0 | E6: ='METAL RAW DATA'!G10 -> 0 | F6: ='METAL RAW DATA'!G13 -> 0 | G6: ='METAL RAW DATA'!G16 -> 0 | H6: ='METAL RAW DATA'!G19 -> 0 | J6: =AVERAGE(D6:H6) -> 0
B7: 分析師A | C7: N2 | D7: ='METAL RAW DATA'!G8 -> 0 | E7: ='METAL RAW DATA'!G11 -> 0 | F7: ='METAL RAW DATA'!G14 -> 0 | G7: ='METAL RAW DATA'!G17 -> 0 | H7: ='METAL RAW DATA'!G20 -> 0 | J7: =AVERAGE(D7:H7) -> 0
B8: 分析師A | C8: N3 | D8: ='METAL RAW DATA'!G9 -> 0 | E8: ='METAL RAW DATA'!G12 -> 0 | F8: ='METAL RAW DATA'!G15 -> 0 | G8: ='METAL RAW DATA'!G18 -> 0 | H8: ='METAL RAW DATA'!G21 -> 0 | J8: =AVERAGE(D8:H8) -> 0
B9: AVE | D9: =AVERAGE(D6:D8) -> 0 | E9: =AVERAGE(E6:E8) -> 0 | F9: =AVERAGE(F6:F8) -> 0 | G9: =AVERAGE(G6:G8) -> 0 | H9: =AVERAGE(H6:H8) -> 0 | I9: Xa | J9: =AVERAGE(D9:H9) -> 0
B10: RANGE | D10: =MAX(D6:D8)-MIN(D6:D8) -> 0 | E10: =MAX(E6:E8)-MIN(E6:E8) -> 0 | F10: =MAX(F6:F8)-MIN(F6:F8) -> 0 | G10: =MAX(G6:G8)-MIN(G6:G8) -> 0 | H10: =MAX(H6:H8)-MIN(H6:H8) -> 0 | I10: Ra | J10: =AVERAGE(D10:H10) -> 0
B11: 分析師B | C11: N1 | D11: ='METAL RAW DATA'!G24 -> 0 | E11: ='METAL RAW DATA'!G27 -> 0 | F11: ='METAL RAW DATA'!G30 -> 0 | G11: ='METAL RAW DATA'!G33 -> 0 | H11: ='METAL RAW DATA'!G36 -> 0 | J11: =AVERAGE(D11:H11) -> 0
B12: 分析師B | C12: N2 | D12: ='METAL RAW DATA'!G25 -> 0 | E12: ='METAL RAW DATA'!G28 -> 0 | F12: ='METAL RAW DATA'!G31 -> 0 | G12: ='METAL RAW DATA'!G34 -> 0 | H12: ='METAL RAW DATA'!G37 -> 0 | J12: =AVERAGE(D12:H12) -> 0
B13: 分析師B | C13: N3 | D13: ='METAL RAW DATA'!G26 -> 0 | E13: ='METAL RAW DATA'!G29 -> 0 | F13: ='METAL RAW DATA'!G32 -> 0 | G13: ='METAL RAW DATA'!G35 -> 0 | H13: ='METAL RAW DATA'!G38 -> 0 | J13: =AVERAGE(D13:H13) -> 0
B14: AVE | D14: =AVERAGE(D11:D13) -> 0 | E14: =AVERAGE(E11:E13) -> 0 | F14: =AVERAGE(F11:F13) -> 0 | G14: =AVERAGE(G11:G13) -> 0 | H14: =AVERAGE(H11:H13) -> 0 | I14: Xb | J14: =AVERAGE(D14:H14) -> 0
B15: RANGE | D15: =MAX(D11:D13)-MIN(D11:D13) -> 0 | E15: =MAX(E11:E13)-MIN(E11:E13) -> 0 | F15: =MAX(F11:F13)-MIN(F11:F13) -> 0 | G15: =MAX(G11:G13)-MIN(G11:G13) -> 0 | H15: =MAX(H11:H13)-MIN(H11:H13) -> 0 | I15: Rb | J15: =AVERAGE(D15:H15) -> 0
B16: 分析師C | C16: N1 | D16: ='METAL RAW DATA'!G41 -> 0 | E16: ='METAL RAW DATA'!G44 -> 0 | F16: ='METAL RAW DATA'!G47 -> 0 | G16: ='METAL RAW DATA'!G50 -> 0 | H16: ='METAL RAW DATA'!G53 -> 0 | J16: =AVERAGE(D16:H16) -> 0
B17: 分析師C | C17: N2 | D17: ='METAL RAW DATA'!G42 -> 0 | E17: ='METAL RAW DATA'!G45 -> 0 | F17: ='METAL RAW DATA'!G48 -> 0 | G17: ='METAL RAW DATA'!G51 -> 0 | H17: ='METAL RAW DATA'!G54 -> 0 | J17: =AVERAGE(D17:H17) -> 0
B18: 分析師C | C18: N3 | D18: ='METAL RAW DATA'!G43 -> 0 | E18: ='METAL RAW DATA'!G46 -> 0 | F18: ='METAL RAW DATA'!G49 -> 0 | G18: ='METAL RAW DATA'!G52 -> 0 | H18: ='METAL RAW DATA'!G55 -> 0 | J18: =AVERAGE(D18:H18) -> 0
B19: AVE | D19: =AVERAGE(D16:D18) -> 0 | E19: =AVERAGE(E16:E18) -> 0 | F19: =AVERAGE(F16:F18) -> 0 | G19: =AVERAGE(G16:G18) -> 0 | H19: =AVERAGE(H16:H18) -> 0 | I19: Xa | J19: =AVERAGE(D19:H19) -> 0
B20: RANGE | D20: =MAX(D16:D18)-MIN(D16:D18) -> 0 | E20: =MAX(E16:E18)-MIN(E16:E18) -> 0 | F20: =MAX(F16:F18)-MIN(F16:F18) -> 0 | G20: =MAX(G16:G18)-MIN(G16:G18) -> 0 | H20: =MAX(H16:H18)-MIN(H16:H18) -> 0 | I20: Ra | J20: =AVERAGE(D20:H20) -> 0
B21: PART | I21: X | J21: =(J14+J9+J19)/3 -> 0
B22: AVE | C22: Xp | D22: =(D14+D9+D19)/3 -> 0 | E22: =(E14+E9+E19)/3 -> 0 | F22: =(F14+F9+F19)/3 -> 0 | G22: =(G14+G9+G19)/3 -> 0 | H22: =(H14+H9+H19)/3 -> 0 | I22: Rp | J22: =MAX(D22:H22)-MIN(D22:H22) -> 0
B23: R=(Ra+Rb+Rc)/3 | I23: R | J23: =(J15+J10+J20)/3 -> 0
B24: Max X-MaxB=X diff | I24: X diff | J24: =MAX(J9,J14,J19)-MIN(J9,J14,J19) -> 0
B26: R*D4=UCLR | J26: =J23*3.27 -> 0
B27: R*D3=LCLR | J27: =J23*0 -> 0
B29: Gage Repeatability and Reproducibility Report
E30: =G4 -> ICP- MS 金屬 R-R測試 | I30: Gage Nane | K30: ASSAY R&R | N30: Date: | O30: ='METAL RAW DATA'!#REF! -> #REF!
B31: Part No.and Name | I31: Gage No | N31: performed by
B32: Characteristics: | I32: Gage Type: | K32: METAL
B33: Specification:
E34: R= | F34: =J23 -> 0 | G34: x diff= | H34: =J24 -> 0 | I34: Rp= | K34: =J22 -> 0
B35: From date sheet: | I35: %Total Variation(TV)
E36: 操作人數(m=) | F36: 3 | G36: 重複測量(r=) | H36: 3 | I36: 測量樣品數(n=) | J36: 5
B37: Measurement Unit Analysis
B38: Repeatability-Equipment Variation(EV) | D38: EV = | E38: R × K1 | G38: Trials | H38: K1 | I38: %EV=100(EV/TV)
D39: =F34 -> 0 | E39: * | F39: =H40 -> 0.5908 | G39: 2 | H39: 0.8862 | I39: =100*(D40/D58) -> #DIV/0! | K39: %
B40: = | D40: =D39*F39 -> 0 | G40: 3 | H40: 0.5908
B41: 重複性-設備變異
B42: Reproducibity-Appraiser Variation(AV) | D42: AV= | E42: √【（Xdiff X K2）2-（EV2/nr）】 | I42: %AV=100(AV/TV)
I43: =100*(E44/D58) -> #DIV/0! | K43: %
D44: = | E44: =D66 -> 0
...

Sheet Ca
B3: ITEM | C3: Ca | F3: DATE | G3: ='METAL RAW DATA'!G1 -> 20231226 | L3: NDC= | M3: =1.41*(D54/D70) -> #DIV/0!
F4: 儀 器 | G4: ='METAL RAW DATA'!C2 -> ICP- MS 金屬 R-R測試
D5: 1 | E5: 2 | F5: 3 | G5: 4 | H5: 5 | J5: AVE
B6: 分析師A | C6: N1 | D6: ='METAL RAW DATA'!H7 -> 0 | E6: ='METAL RAW DATA'!H10 -> 0 | F6: ='METAL RAW DATA'!H13 -> 0 | G6: ='METAL RAW DATA'!H16 -> 0 | H6: ='METAL RAW DATA'!H19 -> 0 | J6: =AVERAGE(D6:H6) -> 0
B7: 分析師A | C7: N2 | D7: ='METAL RAW DATA'!H8 -> 0 | E7: ='METAL RAW DATA'!H11 -> 0 | F7: ='METAL RAW DATA'!H14 -> 0 | G7: ='METAL RAW DATA'!H17 -> 0 | H7: ='METAL RAW DATA'!H20 -> 0 | J7: =AVERAGE(D7:H7) -> 0
B8: 分析師A | C8: N3 | D8: ='METAL RAW DATA'!H9 -> 0 | E8: ='METAL RAW DATA'!H12 -> 0 | F8: ='METAL RAW DATA'!H15 -> 0 | G8: ='METAL RAW DATA'!H18 -> 0 | H8: ='METAL RAW DATA'!H21 -> 0 | J8: =AVERAGE(D8:H8) -> 0
B9: AVE | D9: =AVERAGE(D6:D8) -> 0 | E9: =AVERAGE(E6:E8) -> 0 | F9: =AVERAGE(F6:F8) -> 0 | G9: =AVERAGE(G6:G8) -> 0 | H9: =AVERAGE(H6:H8) -> 0 | I9: Xa | J9: =AVERAGE(D9:H9) -> 0
B10: RANGE | D10: =MAX(D6:D8)-MIN(D6:D8) -> 0 | E10: =MAX(E6:E8)-MIN(E6:E8) -> 0 | F10: =MAX(F6:F8)-MIN(F6:F8) -> 0 | G10: =MAX(G6:G8)-MIN(G6:G8) -> 0 | H10: =MAX(H6:H8)-MIN(H6:H8) -> 0 | I10: Ra | J10: =AVERAGE(D10:H10) -> 0
B11: 分析師B | C11: N1 | D11: ='METAL RAW DATA'!H24 -> 0 | E11: ='METAL RAW DATA'!H27 -> 0 | F11: ='METAL RAW DATA'!H30 -> 0 | G11: ='METAL RAW DATA'!H33 -> 0 | H11: ='METAL RAW DATA'!H36 -> 0 | J11: =AVERAGE(D11:H11) -> 0
B12: 分析師B | C12: N2 | D12: ='METAL RAW DATA'!H25 -> 0 | E12: ='METAL RAW DATA'!H28 -> 0 | F12: ='METAL RAW DATA'!H31 -> 0 | G12: ='METAL RAW DATA'!H34 -> 0 | H12: ='METAL RAW DATA'!H37 -> 0 | J12: =AVERAGE(D12:H12) -> 0
B13: 分析師B | C13: N3 | D13: ='METAL RAW DATA'!H26 -> 0 | E13: ='METAL RAW DATA'!H29 -> 0 | F13: ='METAL RAW DATA'!H32 -> 0 | G13: ='METAL RAW DATA'!H35 -> 0 | H13: ='METAL RAW DATA'!H38 -> 0 | J13: =AVERAGE(D13:H13) -> 0
B14: AVE | D14: =AVERAGE(D11:D13) -> 0 | E14: =AVERAGE(E11:E13) -> 0 | F14: =AVERAGE(F11:F13) -> 0 | G14: =AVERAGE(G11:G13) -> 0 | H14: =AVERAGE(H11:H13) -> 0 | I14: Xb | J14: =AVERAGE(D14:H14) -> 0
B15: RANGE | D15: =MAX(D11:D13)-MIN(D11:D13) -> 0 | E15: =MAX(E11:E13)-MIN(E11:E13) -> 0 | F15: =MAX(F11:F13)-MIN(F11:F13) -> 0 | G15: =MAX(G11:G13)-MIN(G11:G13) -> 0 | H15: =MAX(H11:H13)-MIN(H11:H13) -> 0 | I15: Rb | J15: =AVERAGE(D15:H15) -> 0
B16: 分析師C | C16: N1 | D16: ='METAL RAW DATA'!H41 -> 0 | E16: ='METAL RAW DATA'!H44 -> 0 | F16: ='METAL RAW DATA'!H47 -> 0 | G16: ='METAL RAW DATA'!H50 -> 0 | H16: ='METAL RAW DATA'!H53 -> 0 | J16: =AVERAGE(D16:H16) -> 0
B17: 分析師C | C17: N2 | D17: ='METAL RAW DATA'!H42 -> 0 | E17: ='METAL RAW DATA'!H45 -> 0 | F17: ='METAL RAW DATA'!H48 -> 0 | G17: ='METAL RAW DATA'!H51 -> 0 | H17: ='METAL RAW DATA'!H54 -> 0 | J17: =AVERAGE(D17:H17) -> 0
B18: 分析師C | C18: N3 | D18: ='METAL RAW DATA'!H43 -> 0 | E18: ='METAL RAW DATA'!H46 -> 0 | F18: ='METAL RAW DATA'!H49 -> 0 | G18: ='METAL RAW DATA'!H52 -> 0 | H18: ='METAL RAW DATA'!H55 -> 0 | J18: =AVERAGE(D18:H18) -> 0
B19: AVE | D19: =AVERAGE(D16:D18) -> 0 | E19: =AVERAGE(E16:E18) -> 0 | F19: =AVERAGE(F16:F18) -> 0 | G19: =AVERAGE(G16:G18) -> 0 | H19: =AVERAGE(H16:H18) -> 0 | I19: Xa | J19: =AVERAGE(D19:H19) -> 0
B20: RANGE | D20: =MAX(D16:D18)-MIN(D16:D18) -> 0 | E20: =MAX(E16:E18)-MIN(E16:E18) -> 0 | F20: =MAX(F16:F18)-MIN(F16:F18) -> 0 | G20: =MAX(G16:G18)-MIN(G16:G18) -> 0 | H20: =MAX(H16:H18)-MIN(H16:H18) -> 0 | I20: Ra | J20: =AVERAGE(D20:H20) -> 0
B21: PART | I21: X | J21: =(J14+J9+J19)/3 -> 0
B22: AVE | C22: Xp | D22: =(D14+D9+D19)/3 -> 0 | E22: =(E14+E9+E19)/3 -> 0 | F22: =(F14+F9+F19)/3 -> 0 | G22: =(G14+G9+G19)/3 -> 0 | H22: =(H14+H9+H19)/3 -> 0 | I22: Rp | J22: =MAX(D22:H22)-MIN(D22:H22) -> 0
B23: R=(Ra+Rb+Rc)/3 | I23: R | J23: =(J15+J10+J20)/3 -> 0
B24: Max X-MaxB=X diff | I24: X diff | J24: =MAX(J9,J14,J19)-MIN(J9,J14,J19) -> 0
B26: R*D4=UCLR | J26: =J23*3.27 -> 0
B27: R*D3=LCLR | J27: =J23*0 -> 0
B29: Gage Repeatability and Reproducibility Report
E30: =G4 -> ICP- MS 金屬 R-R測試 | I30: Gage Nane | K30: ASSAY R&R | N30: Date: | O30: ='METAL RAW DATA'!#REF! -> #REF!
B31: Part No.and Name | I31: Gage No | N31: performed by
B32: Characteristics: | I32: Gage Type: | K32: METAL
B33: Specification:
E34: R= | F34: =J23 -> 0 | G34: x diff= | H34: =J24 -> 0 | I34: Rp= | K34: =J22 -> 0
B35: From date sheet: | I35: %Total Variation(TV)
E36: 操作人數(m=) | F36: 3 | G36: 重複測量(r=) | H36: 3 | I36: 測量樣品數(n=) | J36: 5
B37: Measurement Unit Analysis
B38: Repeatability-Equipment Variation(EV) | D38: EV = | E38: R × K1 | G38: Trials | H38: K1 | I38: %EV=100(EV/TV)
D39: =F34 -> 0 | E39: * | F39: =H40 -> 0.5908 | G39: 2 | H39: 0.8862 | I39: =100*(D40/D58) -> #DIV/0! | K39: %
B40: = | D40: =D39*F39 -> 0 | G40: 3 | H40: 0.5908
B41: 重複性-設備變異
B42: Reproducibity-Appraiser Variation(AV) | D42: AV= | E42: √【（Xdiff X K2）2-（EV2/nr）】 | I42: %AV=100(AV/TV)
I43: =100*(E44/D58) -> #DIV/0! | K43: %
D44: = | E44: =D66 -> 0
...

Sheet Cr
B3: ITEM | C3: Cr | F3: DATE | G3: ='METAL RAW DATA'!G1 -> 20231226 | L3: NDC= | M3: =1.41*(D54/D70) -> #DIV/0!
F4: 儀 器 | G4: ='METAL RAW DATA'!C2 -> ICP- MS 金屬 R-R測試
D5: 1 | E5: 2 | F5: 3 | G5: 4 | H5: 5 | J5: AVE
B6: 分析師A | C6: N1 | D6: ='METAL RAW DATA'!I7 -> 0 | E6: ='METAL RAW DATA'!I10 -> 0 | F6: ='METAL RAW DATA'!I13 -> 0 | G6: ='METAL RAW DATA'!I16 -> 0 | H6: ='METAL RAW DATA'!I19 -> 0 | J6: =AVERAGE(D6:H6) -> 0
B7: 分析師A | C7: N2 | D7: ='METAL RAW DATA'!I8 -> 0 | E7: ='METAL RAW DATA'!I11 -> 0 | F7: ='METAL RAW DATA'!I14 -> 0 | G7: ='METAL RAW DATA'!I17 -> 0 | H7: ='METAL RAW DATA'!I20 -> 0 | J7: =AVERAGE(D7:H7) -> 0
B8: 分析師A | C8: N3 | D8: ='METAL RAW DATA'!I9 -> 0 | E8: ='METAL RAW DATA'!I12 -> 0 | F8: ='METAL RAW DATA'!I15 -> 0 | G8: ='METAL RAW DATA'!I18 -> 0 | H8: ='METAL RAW DATA'!I21 -> 0 | J8: =AVERAGE(D8:H8) -> 0
B9: AVE | D9: =AVERAGE(D6:D8) -> 0 | E9: =AVERAGE(E6:E8) -> 0 | F9: =AVERAGE(F6:F8) -> 0 | G9: =AVERAGE(G6:G8) -> 0 | H9: =AVERAGE(H6:H8) -> 0 | I9: Xa | J9: =AVERAGE(D9:H9) -> 0
B10: RANGE | D10: =MAX(D6:D8)-MIN(D6:D8) -> 0 | E10: =MAX(E6:E8)-MIN(E6:E8) -> 0 | F10: =MAX(F6:F8)-MIN(F6:F8) -> 0 | G10: =MAX(G6:G8)-MIN(G6:G8) -> 0 | H10: =MAX(H6:H8)-MIN(H6:H8) -> 0 | I10: Ra | J10: =AVERAGE(D10:H10) -> 0
B11: 分析師B | C11: N1 | D11: ='METAL RAW DATA'!I24 -> 0 | E11: ='METAL RAW DATA'!I27 -> 0 | F11: ='METAL RAW DATA'!I30 -> 0 | G11: ='METAL RAW DATA'!I33 -> 0 | H11: ='METAL RAW DATA'!I36 -> 0 | J11: =AVERAGE(D11:H11) -> 0
B12: 分析師B | C12: N2 | D12: ='METAL RAW DATA'!I25 -> 0 | E12: ='METAL RAW DATA'!I28 -> 0 | F12: ='METAL RAW DATA'!I31 -> 0 | G12: ='METAL RAW DATA'!I34 -> 0 | H12: ='METAL RAW DATA'!I37 -> 0 | J12: =AVERAGE(D12:H12) -> 0
B13: 分析師B | C13: N3 | D13: ='METAL RAW DATA'!I26 -> 0 | E13: ='METAL RAW DATA'!I29 -> 0 | F13: ='METAL RAW DATA'!I32 -> 0 | G13: ='METAL RAW DATA'!I35 -> 0 | H13: ='METAL RAW DATA'!I38 -> 0 | J13: =AVERAGE(D13:H13) -> 0
B14: AVE | D14: =AVERAGE(D11:D13) -> 0 | E14: =AVERAGE(E11:E13) -> 0 | F14: =AVERAGE(F11:F13) -> 0 | G14: =AVERAGE(G11:G13) -> 0 | H14: =AVERAGE(H11:H13) -> 0 | I14: Xb | J14: =AVERAGE(D14:H14) -> 0
B15: RANGE | D15: =MAX(D11:D13)-MIN(D11:D13) -> 0 | E15: =MAX(E11:E13)-MIN(E11:E13) -> 0 | F15: =MAX(F11:F13)-MIN(F11:F13) -> 0 | G15: =MAX(G11:G13)-MIN(G11:G13) -> 0 | H15: =MAX(H11:H13)-MIN(H11:H13) -> 0 | I15: Rb | J15: =AVERAGE(D15:H15) -> 0
B16: 分析師C | C16: N1 | D16: ='METAL RAW DATA'!I41 -> 0 | E16: ='METAL RAW DATA'!I44 -> 0 | F16: ='METAL RAW DATA'!I47 -> 0 | G16: ='METAL RAW DATA'!I50 -> 0 | H16: ='METAL RAW DATA'!I53 -> 0 | J16: =AVERAGE(D16:H16) -> 0
B17: 分析師C | C17: N2 | D17: ='METAL RAW DATA'!I42 -> 0 | E17: ='METAL RAW DATA'!I45 -> 0 | F17: ='METAL RAW DATA'!I48 -> 0 | G17: ='METAL RAW DATA'!I51 -> 0 | H17: ='METAL RAW DATA'!I54 -> 0 | J17: =AVERAGE(D17:H17) -> 0
B18: 分析師C | C18: N3 | D18: ='METAL RAW DATA'!I43 -> 0 | E18: ='METAL RAW DATA'!I46 -> 0 | F18: ='METAL RAW DATA'!I49 -> 0 | G18: ='METAL RAW DATA'!I52 -> 0 | H18: ='METAL RAW DATA'!I55 -> 0 | J18: =AVERAGE(D18:H18) -> 0
B19: AVE | D19: =AVERAGE(D16:D18) -> 0 | E19: =AVERAGE(E16:E18) -> 0 | F19: =AVERAGE(F16:F18) -> 0 | G19: =AVERAGE(G16:G18) -> 0 | H19: =AVERAGE(H16:H18) -> 0 | I19: Xa | J19: =AVERAGE(D19:H19) -> 0
B20: RANGE | D20: =MAX(D16:D18)-MIN(D16:D18) -> 0 | E20: =MAX(E16:E18)-MIN(E16:E18) -> 0 | F20: =MAX(F16:F18)-MIN(F16:F18) -> 0 | G20: =MAX(G16:G18)-MIN(G16:G18) -> 0 | H20: =MAX(H16:H18)-MIN(H16:H18) -> 0 | I20: Ra | J20: =AVERAGE(D20:H20) -> 0
B21: PART | I21: X | J21: =(J14+J9+J19)/3 -> 0
B22: AVE | C22: Xp | D22: =(D14+D9+D19)/3 -> 0 | E22: =(E14+E9+E19)/3 -> 0 | F22: =(F14+F9+F19)/3 -> 0 | G22: =(G14+G9+G19)/3 -> 0 | H22: =(H14+H9+H19)/3 -> 0 | I22: Rp | J22: =MAX(D22:H22)-MIN(D22:H22) -> 0
B23: R=(Ra+Rb+Rc)/3 | I23: R | J23: =(J15+J10+J20)/3 -> 0
B24: Max X-MaxB=X diff | I24: X diff | J24: =MAX(J9,J14,J19)-MIN(J9,J14,J19) -> 0
B26: R*D4=UCLR | J26: =J23*3.27 -> 0
B27: R*D3=LCLR | J27: =J23*0 -> 0
B29: Gage Repeatability and Reproducibility Report
E30: =G4 -> ICP- MS 金屬 R-R測試 | I30: Gage Nane | K30: ASSAY R&R | N30: Date: | O30: ='METAL RAW DATA'!#REF! -> #REF!
B31: Part No.and Name | I31: Gage No | N31: performed by
B32: Characteristics: | I32: Gage Type: | K32: METAL
B33: Specification:
E34: R= | F34: =J23 -> 0 | G34: x diff= | H34: =J24 -> 0 | I34: Rp= | K34: =J22 -> 0
B35: From date sheet: | I35: %Total Variation(TV)
E36: 操作人數(m=) | F36: 3 | G36: 重複測量(r=) | H36: 3 | I36: 測量樣品數(n=) | J36: 5
B37: Measurement Unit Analysis
B38: Repeatability-Equipment Variation(EV) | D38: EV = | E38: R × K1 | G38: Trials | H38: K1 | I38: %EV=100(EV/TV)
D39: =F34 -> 0 | E39: * | F39: =H40 -> 0.5908 | G39: 2 | H39: 0.8862 | I39: =100*(D40/D58) -> #DIV/0! | K39: %
B40: = | D40: =D39*F39 -> 0 | G40: 3 | H40: 0.5908
B41: 重複性-設備變異
B42: Reproducibity-Appraiser Variation(AV) | D42: AV= | E42: √【（Xdiff X K2）2-（EV2/nr）】 | I42: %AV=100(AV/TV)
I43: =100*(E44/D58) -> #DIV/0! | K43: %
D44: = | E44: =D66 -> 0
...

Sheet Mn
B3: ITEM | C3: Mn | F3: DATE | G3: ='METAL RAW DATA'!G1 -> 20231226 | L3: NDC= | M3: =1.41*(D54/D70) -> #DIV/0!
F4: 儀 器 | G4: ='METAL RAW DATA'!C2 -> ICP- MS 金屬 R-R測試
D5: 1 | E5: 2 | F5: 3 | G5: 4 | H5: 5 | J5: AVE
B6: 分析師A | C6: N1 | D6: ='METAL RAW DATA'!J7 -> 0 | E6: ='METAL RAW DATA'!J10 -> 0 | F6: ='METAL RAW DATA'!J13 -> 0 | G6: ='METAL RAW DATA'!J16 -> 0 | H6: ='METAL RAW DATA'!J19 -> 0 | J6: =AVERAGE(D6:H6) -> 0
B7: 分析師A | C7: N2 | D7: ='METAL RAW DATA'!J8 -> 0 | E7: ='METAL RAW DATA'!J11 -> 0 | F7: ='METAL RAW DATA'!J14 -> 0 | G7: ='METAL RAW DATA'!J17 -> 0 | H7: ='METAL RAW DATA'!J20 -> 0 | J7: =AVERAGE(D7:H7) -> 0
B8: 分析師A | C8: N3 | D8: ='METAL RAW DATA'!J9 -> 0 | E8: ='METAL RAW DATA'!J12 -> 0 | F8: ='METAL RAW DATA'!J15 -> 0 | G8: ='METAL RAW DATA'!J18 -> 0 | H8: ='METAL RAW DATA'!J21 -> 0 | J8: =AVERAGE(D8:H8) -> 0
B9: AVE | D9: =AVERAGE(D6:D8) -> 0 | E9: =AVERAGE(E6:E8) -> 0 | F9: =AVERAGE(F6:F8) -> 0 | G9: =AVERAGE(G6:G8) -> 0 | H9: =AVERAGE(H6:H8) -> 0 | I9: Xa | J9: =AVERAGE(D9:H9) -> 0
B10: RANGE | D10: =MAX(D6:D8)-MIN(D6:D8) -> 0 | E10: =MAX(E6:E8)-MIN(E6:E8) -> 0 | F10: =MAX(F6:F8)-MIN(F6:F8) -> 0 | G10: =MAX(G6:G8)-MIN(G6:G8) -> 0 | H10: =MAX(H6:H8)-MIN(H6:H8) -> 0 | I10: Ra | J10: =AVERAGE(D10:H10) -> 0
B11: 分析師B | C11: N1 | D11: ='METAL RAW DATA'!J24 -> 0 | E11: ='METAL RAW DATA'!J27 -> 0 | F11: ='METAL RAW DATA'!J30 -> 0 | G11: ='METAL RAW DATA'!J33 -> 0 | H11: ='METAL RAW DATA'!J36 -> 0 | J11: =AVERAGE(D11:H11) -> 0
B12: 分析師B | C12: N2 | D12: ='METAL RAW DATA'!J25 -> 0 | E12: ='METAL RAW DATA'!J28 -> 0 | F12: ='METAL RAW DATA'!J31 -> 0 | G12: ='METAL RAW DATA'!J34 -> 0 | H12: ='METAL RAW DATA'!J37 -> 0 | J12: =AVERAGE(D12:H12) -> 0
B13: 分析師B | C13: N3 | D13: ='METAL RAW DATA'!J26 -> 0 | E13: ='METAL RAW DATA'!J29 -> 0 | F13: ='METAL RAW DATA'!J32 -> 0 | G13: ='METAL RAW DATA'!J35 -> 0 | H13: ='METAL RAW DATA'!J38 -> 0 | J13: =AVERAGE(D13:H13) -> 0
B14: AVE | D14: =AVERAGE(D11:D13) -> 0 | E14: =AVERAGE(E11:E13) -> 0 | F14: =AVERAGE(F11:F13) -> 0 | G14: =AVERAGE(G11:G13) -> 0 | H14: =AVERAGE(H11:H13) -> 0 | I14: Xb | J14: =AVERAGE(D14:H14) -> 0
B15: RANGE | D15: =MAX(D11:D13)-MIN(D11:D13) -> 0 | E15: =MAX(E11:E13)-MIN(E11:E13) -> 0 | F15: =MAX(F11:F13)-MIN(F11:F13) -> 0 | G15: =MAX(G11:G13)-MIN(G11:G13) -> 0 | H15: =MAX(H11:H13)-MIN(H11:H13) -> 0 | I15: Rb | J15: =AVERAGE(D15:H15) -> 0
B16: 分析師C | C16: N1 | D16: ='METAL RAW DATA'!J41 -> 0 | E16: ='METAL RAW DATA'!J44 -> 0 | F16: ='METAL RAW DATA'!J47 -> 0 | G16: ='METAL RAW DATA'!J50 -> 0 | H16: ='METAL RAW DATA'!J53 -> 0 | J16: =AVERAGE(D16:H16) -> 0
B17: 分析師C | C17: N2 | D17: ='METAL RAW DATA'!J42 -> 0 | E17: ='METAL RAW DATA'!J45 -> 0 | F17: ='METAL RAW DATA'!J48 -> 0 | G17: ='METAL RAW DATA'!J51 -> 0 | H17: ='METAL RAW DATA'!J54 -> 0 | J17: =AVERAGE(D17:H17) -> 0
B18: 分析師C | C18: N3 | D18: ='METAL RAW DATA'!J43 -> 0 | E18: ='METAL RAW DATA'!J46 -> 0 | F18: ='METAL RAW DATA'!J49 -> 0 | G18: ='METAL RAW DATA'!J52 -> 0 | H18: ='METAL RAW DATA'!J55 -> 0 | J18: =AVERAGE(D18:H18) -> 0
B19: AVE | D19: =AVERAGE(D16:D18) -> 0 | E19: =AVERAGE(E16:E18) -> 0 | F19: =AVERAGE(F16:F18) -> 0 | G19: =AVERAGE(G16:G18) -> 0 | H19: =AVERAGE(H16:H18) -> 0 | I19: Xa | J19: =AVERAGE(D19:H19) -> 0
B20: RANGE | D20: =MAX(D16:D18)-MIN(D16:D18) -> 0 | E20: =MAX(E16:E18)-MIN(E16:E18) -> 0 | F20: =MAX(F16:F18)-MIN(F16:F18) -> 0 | G20: =MAX(G16:G18)-MIN(G16:G18) -> 0 | H20: =MAX(H16:H18)-MIN(H16:H18) -> 0 | I20: Ra | J20: =AVERAGE(D20:H20) -> 0
B21: PART | I21: X | J21: =(J14+J9+J19)/3 -> 0
B22: AVE | C22: Xp | D22: =(D14+D9+D19)/3 -> 0 | E22: =(E14+E9+E19)/3 -> 0 | F22: =(F14+F9+F19)/3 -> 0 | G22: =(G14+G9+G19)/3 -> 0 | H22: =(H14+H9+H19)/3 -> 0 | I22: Rp | J22: =MAX(D22:H22)-MIN(D22:H22) -> 0
B23: R=(Ra+Rb+Rc)/3 | I23: R | J23: =(J15+J10+J20)/3 -> 0
B24: Max X-MaxB=X diff | I24: X diff | J24: =MAX(J9,J14,J19)-MIN(J9,J14,J19) -> 0
B26: R*D4=UCLR | J26: =J23*3.27 -> 0
B27: R*D3=LCLR | J27: =J23*0 -> 0
B29: Gage Repeatability and Reproducibility Report
E30: =G4 -> ICP- MS 金屬 R-R測試 | I30: Gage Nane | K30: ASSAY R&R | N30: Date: | O30: ='METAL RAW DATA'!#REF! -> #REF!
B31: Part No.and Name | I31: Gage No | N31: performed by
B32: Characteristics: | I32: Gage Type: | K32: METAL
B33: Specification:
E34: R= | F34: =J23 -> 0 | G34: x diff= | H34: =J24 -> 0 | I34: Rp= | K34: =J22 -> 0
B35: From date sheet: | I35: %Total Variation(TV)
E36: 操作人數(m=) | F36: 3 | G36: 重複測量(r=) | H36: 3 | I36: 測量樣品數(n=) | J36: 5
B37: Measurement Unit Analysis
B38: Repeatability-Equipment Variation(EV) | D38: EV = | E38: R × K1 | G38: Trials | H38: K1 | I38: %EV=100(EV/TV)
D39: =F34 -> 0 | E39: * | F39: =H40 -> 0.5908 | G39: 2 | H39: 0.8862 | I39: =100*(D40/D58) -> #DIV/0! | K39: %
B40: = | D40: =D39*F39 -> 0 | G40: 3 | H40: 0.5908
B41: 重複性-設備變異
B42: Reproducibity-Appraiser Variation(AV) | D42: AV= | E42: √【（Xdiff X K2）2-（EV2/nr）】 | I42: %AV=100(AV/TV)
I43: =100*(E44/D58) -> #DIV/0! | K43: %
D44: = | E44: =D66 -> 0
...

Sheet Fe
B3: ITEM | C3: Fe | F3: DATE | G3: ='METAL RAW DATA'!G1 -> 20231226 | L3: NDC= | M3: =1.41*(D54/D70) -> #DIV/0!
F4: 儀 器 | G4: ='METAL RAW DATA'!C2 -> ICP- MS 金屬 R-R測試
D5: 1 | E5: 2 | F5: 3 | G5: 4 | H5: 5 | J5: AVE
B6: 分析師A | C6: N1 | D6: ='METAL RAW DATA'!K7 -> 0 | E6: ='METAL RAW DATA'!K10 -> 0 | F6: ='METAL RAW DATA'!K13 -> 0 | G6: ='METAL RAW DATA'!K16 -> 0 | H6: ='METAL RAW DATA'!K19 -> 0 | J6: =AVERAGE(D6:H6) -> 0
B7: 分析師A | C7: N2 | D7: ='METAL RAW DATA'!K8 -> 0 | E7: ='METAL RAW DATA'!K11 -> 0 | F7: ='METAL RAW DATA'!K14 -> 0 | G7: ='METAL RAW DATA'!K17 -> 0 | H7: ='METAL RAW DATA'!K20 -> 0 | J7: =AVERAGE(D7:H7) -> 0
B8: 分析師A | C8: N3 | D8: ='METAL RAW DATA'!K9 -> 0 | E8: ='METAL RAW DATA'!K12 -> 0 | F8: ='METAL RAW DATA'!K15 -> 0 | G8: ='METAL RAW DATA'!K18 -> 0 | H8: ='METAL RAW DATA'!K21 -> 0 | J8: =AVERAGE(D8:H8) -> 0
B9: AVE | D9: =AVERAGE(D6:D8) -> 0 | E9: =AVERAGE(E6:E8) -> 0 | F9: =AVERAGE(F6:F8) -> 0 | G9: =AVERAGE(G6:G8) -> 0 | H9: =AVERAGE(H6:H8) -> 0 | I9: Xa | J9: =AVERAGE(D9:H9) -> 0
B10: RANGE | D10: =MAX(D6:D8)-MIN(D6:D8) -> 0 | E10: =MAX(E6:E8)-MIN(E6:E8) -> 0 | F10: =MAX(F6:F8)-MIN(F6:F8) -> 0 | G10: =MAX(G6:G8)-MIN(G6:G8) -> 0 | H10: =MAX(H6:H8)-MIN(H6:H8) -> 0 | I10: Ra | J10: =AVERAGE(D10:H10) -> 0
B11: 分析師B | C11: N1 | D11: ='METAL RAW DATA'!K24 -> 0 | E11: ='METAL RAW DATA'!K27 -> 0 | F11: ='METAL RAW DATA'!K30 -> 0 | G11: ='METAL RAW DATA'!K33 -> 0 | H11: ='METAL RAW DATA'!K36 -> 0 | J11: =AVERAGE(D11:H11) -> 0
B12: 分析師B | C12: N2 | D12: ='METAL RAW DATA'!K25 -> 0 | E12: ='METAL RAW DATA'!K28 -> 0 | F12: ='METAL RAW DATA'!K31 -> 0 | G12: ='METAL RAW DATA'!K34 -> 0 | H12: ='METAL RAW DATA'!K37 -> 0 | J12: =AVERAGE(D12:H12) -> 0
B13: 分析師B | C13: N3 | D13: ='METAL RAW DATA'!K26 -> 0 | E13: ='METAL RAW DATA'!K29 -> 0 | F13: ='METAL RAW DATA'!K32 -> 0 | G13: ='METAL RAW DATA'!K35 -> 0 | H13: ='METAL RAW DATA'!K38 -> 0 | J13: =AVERAGE(D13:H13) -> 0
B14: AVE | D14: =AVERAGE(D11:D13) -> 0 | E14: =AVERAGE(E11:E13) -> 0 | F14: =AVERAGE(F11:F13) -> 0 | G14: =AVERAGE(G11:G13) -> 0 | H14: =AVERAGE(H11:H13) -> 0 | I14: Xb | J14: =AVERAGE(D14:H14) -> 0
B15: RANGE | D15: =MAX(D11:D13)-MIN(D11:D13) -> 0 | E15: =MAX(E11:E13)-MIN(E11:E13) -> 0 | F15: =MAX(F11:F13)-MIN(F11:F13) -> 0 | G15: =MAX(G11:G13)-MIN(G11:G13) -> 0 | H15: =MAX(H11:H13)-MIN(H11:H13) -> 0 | I15: Rb | J15: =AVERAGE(D15:H15) -> 0
B16: 分析師C | C16: N1 | D16: ='METAL RAW DATA'!K41 -> 0 | E16: ='METAL RAW DATA'!K44 -> 0 | F16: ='METAL RAW DATA'!K47 -> 0 | G16: ='METAL RAW DATA'!K50 -> 0 | H16: ='METAL RAW DATA'!K53 -> 0 | J16: =AVERAGE(D16:H16) -> 0
B17: 分析師C | C17: N2 | D17: ='METAL RAW DATA'!K42 -> 0 | E17: ='METAL RAW DATA'!K45 -> 0 | F17: ='METAL RAW DATA'!K48 -> 0 | G17: ='METAL RAW DATA'!K51 -> 0 | H17: ='METAL RAW DATA'!K54 -> 0 | J17: =AVERAGE(D17:H17) -> 0
B18: 分析師C | C18: N3 | D18: ='METAL RAW DATA'!K43 -> 0 | E18: ='METAL RAW DATA'!K46 -> 0 | F18: ='METAL RAW DATA'!K49 -> 0 | G18: ='METAL RAW DATA'!K52 -> 0 | H18: ='METAL RAW DATA'!K55 -> 0 | J18: =AVERAGE(D18:H18) -> 0
B19: AVE | D19: =AVERAGE(D16:D18) -> 0 | E19: =AVERAGE(E16:E18) -> 0 | F19: =AVERAGE(F16:F18) -> 0 | G19: =AVERAGE(G16:G18) -> 0 | H19: =AVERAGE(H16:H18) -> 0 | I19: Xa | J19: =AVERAGE(D19:H19) -> 0
B20: RANGE | D20: =MAX(D16:D18)-MIN(D16:D18) -> 0 | E20: =MAX(E16:E18)-MIN(E16:E18) -> 0 | F20: =MAX(F16:F18)-MIN(F16:F18) -> 0 | G20: =MAX(G16:G18)-MIN(G16:G18) -> 0 | H20: =MAX(H16:H18)-MIN(H16:H18) -> 0 | I20: Ra | J20: =AVERAGE(D20:H20) -> 0
B21: PART | I21: X | J21: =(J14+J9+J19)/3 -> 0
B22: AVE | C22: Xp | D22: =(D14+D9+D19)/3 -> 0 | E22: =(E14+E9+E19)/3 -> 0 | F22: =(F14+F9+F19)/3 -> 0 | G22: =(G14+G9+G19)/3 -> 0 | H22: =(H14+H9+H19)/3 -> 0 | I22: Rp | J22: =MAX(D22:H22)-MIN(D22:H22) -> 0
B23: R=(Ra+Rb+Rc)/3 | I23: R | J23: =(J15+J10+J20)/3 -> 0
B24: Max X-MaxB=X diff | I24: X diff | J24: =MAX(J9,J14,J19)-MIN(J9,J14,J19) -> 0
B26: R*D4=UCLR | J26: =J23*3.27 -> 0
B27: R*D3=LCLR | J27: =J23*0 -> 0
B29: Gage Repeatability and Reproducibility Report
E30: =G4 -> ICP- MS 金屬 R-R測試 | I30: Gage Nane | K30: ASSAY R&R | N30: Date: | O30: ='METAL RAW DATA'!#REF! -> #REF!
B31: Part No.and Name | I31: Gage No | N31: performed by
B32: Characteristics: | I32: Gage Type: | K32: METAL
B33: Specification:
E34: R= | F34: =J23 -> 0 | G34: x diff= | H34: =J24 -> 0 | I34: Rp= | K34: =J22 -> 0
B35: From date sheet: | I35: %Total Variation(TV)
E36: 操作人數(m=) | F36: 3 | G36: 重複測量(r=) | H36: 3 | I36: 測量樣品數(n=) | J36: 5
B37: Measurement Unit Analysis
B38: Repeatability-Equipment Variation(EV) | D38: EV = | E38: R × K1 | G38: Trials | H38: K1 | I38: %EV=100(EV/TV)
D39: =F34 -> 0 | E39: * | F39: =H40 -> 0.5908 | G39: 2 | H39: 0.8862 | I39: =100*(D40/D58) -> #DIV/0! | K39: %
B40: = | D40: =D39*F39 -> 0 | G40: 3 | H40: 0.5908
B41: 重複性-設備變異
B42: Reproducibity-Appraiser Variation(AV) | D42: AV= | E42: √【（Xdiff X K2）2-（EV2/nr）】 | I42: %AV=100(AV/TV)
I43: =100*(E44/D58) -> #DIV/0! | K43: %
D44: = | E44: =D66 -> 0
...

Sheet Ni
B3: ITEM | C3: Fe | F3: DATE | G3: ='METAL RAW DATA'!G1 -> 20231226 | L3: NDC= | M3: =1.41*(D54/D70) -> #DIV/0!
F4: 儀 器 | G4: ='METAL RAW DATA'!C2 -> ICP- MS 金屬 R-R測試
D5: 1 | E5: 2 | F5: 3 | G5: 4 | H5: 5 | J5: AVE
B6: 分析師A | C6: N1 | D6: ='METAL RAW DATA'!L7 -> 0 | E6: ='METAL RAW DATA'!L10 -> 0 | F6: ='METAL RAW DATA'!L13 -> 0 | G6: ='METAL RAW DATA'!L16 -> 0 | H6: ='METAL RAW DATA'!L19 -> 0 | J6: =AVERAGE(D6:H6) -> 0
B7: 分析師A | C7: N2 | D7: ='METAL RAW DATA'!L8 -> 0 | E7: ='METAL RAW DATA'!L11 -> 0 | F7: ='METAL RAW DATA'!L14 -> 0 | G7: ='METAL RAW DATA'!L17 -> 0 | H7: ='METAL RAW DATA'!L20 -> 0 | J7: =AVERAGE(D7:H7) -> 0
B8: 分析師A | C8: N3 | D8: ='METAL RAW DATA'!L9 -> 0 | E8: ='METAL RAW DATA'!L12 -> 0 | F8: ='METAL RAW DATA'!L15 -> 0 | G8: ='METAL RAW DATA'!L18 -> 0 | H8: ='METAL RAW DATA'!L21 -> 0 | J8: =AVERAGE(D8:H8) -> 0
B9: AVE | D9: =AVERAGE(D6:D8) -> 0 | E9: =AVERAGE(E6:E8) -> 0 | F9: =AVERAGE(F6:F8) -> 0 | G9: =AVERAGE(G6:G8) -> 0 | H9: =AVERAGE(H6:H8) -> 0 | I9: Xa | J9: =AVERAGE(D9:H9) -> 0
B10: RANGE | D10: =MAX(D6:D8)-MIN(D6:D8) -> 0 | E10: =MAX(E6:E8)-MIN(E6:E8) -> 0 | F10: =MAX(F6:F8)-MIN(F6:F8) -> 0 | G10: =MAX(G6:G8)-MIN(G6:G8) -> 0 | H10: =MAX(H6:H8)-MIN(H6:H8) -> 0 | I10: Ra | J10: =AVERAGE(D10:H10) -> 0
B11: 分析師B | C11: N1 | D11: ='METAL RAW DATA'!L24 -> 0 | E11: ='METAL RAW DATA'!L27 -> 0 | F11: ='METAL RAW DATA'!L30 -> 0 | G11: ='METAL RAW DATA'!L33 -> 0 | H11: ='METAL RAW DATA'!L36 -> 0 | J11: =AVERAGE(D11:H11) -> 0
B12: 分析師B | C12: N2 | D12: ='METAL RAW DATA'!L25 -> 0 | E12: ='METAL RAW DATA'!L28 -> 0 | F12: ='METAL RAW DATA'!L31 -> 0 | G12: ='METAL RAW DATA'!L34 -> 0 | H12: ='METAL RAW DATA'!L37 -> 0 | J12: =AVERAGE(D12:H12) -> 0
B13: 分析師B | C13: N3 | D13: ='METAL RAW DATA'!L26 -> 0 | E13: ='METAL RAW DATA'!L29 -> 0 | F13: ='METAL RAW DATA'!L32 -> 0 | G13: ='METAL RAW DATA'!L35 -> 0 | H13: ='METAL RAW DATA'!L38 -> 0 | J13: =AVERAGE(D13:H13) -> 0
B14: AVE | D14: =AVERAGE(D11:D13) -> 0 | E14: =AVERAGE(E11:E13) -> 0 | F14: =AVERAGE(F11:F13) -> 0 | G14: =AVERAGE(G11:G13) -> 0 | H14: =AVERAGE(H11:H13) -> 0 | I14: Xb | J14: =AVERAGE(D14:H14) -> 0
B15: RANGE | D15: =MAX(D11:D13)-MIN(D11:D13) -> 0 | E15: =MAX(E11:E13)-MIN(E11:E13) -> 0 | F15: =MAX(F11:F13)-MIN(F11:F13) -> 0 | G15: =MAX(G11:G13)-MIN(G11:G13) -> 0 | H15: =MAX(H11:H13)-MIN(H11:H13) -> 0 | I15: Rb | J15: =AVERAGE(D15:H15) -> 0
B16: 分析師C | C16: N1 | D16: ='METAL RAW DATA'!L41 -> 0 | E16: ='METAL RAW DATA'!L44 -> 0 | F16: ='METAL RAW DATA'!L47 -> 0 | G16: ='METAL RAW DATA'!L50 -> 0 | H16: ='METAL RAW DATA'!L53 -> 0 | J16: =AVERAGE(D16:H16) -> 0
B17: 分析師C | C17: N2 | D17: ='METAL RAW DATA'!L42 -> 0 | E17: ='METAL RAW DATA'!L45 -> 0 | F17: ='METAL RAW DATA'!L48 -> 0 | G17: ='METAL RAW DATA'!L51 -> 0 | H17: ='METAL RAW DATA'!L54 -> 0 | J17: =AVERAGE(D17:H17) -> 0
B18: 分析師C | C18: N3 | D18: ='METAL RAW DATA'!L43 -> 0 | E18: ='METAL RAW DATA'!L46 -> 0 | F18: ='METAL RAW DATA'!L49 -> 0 | G18: ='METAL RAW DATA'!L52 -> 0 | H18: ='METAL RAW DATA'!L55 -> 0 | J18: =AVERAGE(D18:H18) -> 0
B19: AVE | D19: =AVERAGE(D16:D18) -> 0 | E19: =AVERAGE(E16:E18) -> 0 | F19: =AVERAGE(F16:F18) -> 0 | G19: =AVERAGE(G16:G18) -> 0 | H19: =AVERAGE(H16:H18) -> 0 | I19: Xa | J19: =AVERAGE(D19:H19) -> 0
B20: RANGE | D20: =MAX(D16:D18)-MIN(D16:D18) -> 0 | E20: =MAX(E16:E18)-MIN(E16:E18) -> 0 | F20: =MAX(F16:F18)-MIN(F16:F18) -> 0 | G20: =MAX(G16:G18)-MIN(G16:G18) -> 0 | H20: =MAX(H16:H18)-MIN(H16:H18) -> 0 | I20: Ra | J20: =AVERAGE(D20:H20) -> 0
B21: PART | I21: X | J21: =(J14+J9+J19)/3 -> 0
B22: AVE | C22: Xp | D22: =(D14+D9+D19)/3 -> 0 | E22: =(E14+E9+E19)/3 -> 0 | F22: =(F14+F9+F19)/3 -> 0 | G22: =(G14+G9+G19)/3 -> 0 | H22: =(H14+H9+H19)/3 -> 0 | I22: Rp | J22: =MAX(D22:H22)-MIN(D22:H22) -> 0
B23: R=(Ra+Rb+Rc)/3 | I23: R | J23: =(J15+J10+J20)/3 -> 0
B24: Max X-MaxB=X diff | I24: X diff | J24: =MAX(J9,J14,J19)-MIN(J9,J14,J19) -> 0
B26: R*D4=UCLR | J26: =J23*3.27 -> 0
B27: R*D3=LCLR | J27: =J23*0 -> 0
B29: Gage Repeatability and Reproducibility Report
E30: =G4 -> ICP- MS 金屬 R-R測試 | I30: Gage Nane | K30: ASSAY R&R | N30: Date: | O30: ='METAL RAW DATA'!#REF! -> #REF!
B31: Part No.and Name | I31: Gage No | N31: performed by
B32: Characteristics: | I32: Gage Type: | K32: METAL
B33: Specification:
E34: R= | F34: =J23 -> 0 | G34: x diff= | H34: =J24 -> 0 | I34: Rp= | K34: =J22 -> 0
B35: From date sheet: | I35: %Total Variation(TV)
E36: 操作人數(m=) | F36: 3 | G36: 重複測量(r=) | H36: 3 | I36: 測量樣品數(n=) | J36: 5
B37: Measurement Unit Analysis
B38: Repeatability-Equipment Variation(EV) | D38: EV = | E38: R × K1 | G38: Trials | H38: K1 | I38: %EV=100(EV/TV)
D39: =F34 -> 0 | E39: * | F39: =H40 -> 0.5908 | G39: 2 | H39: 0.8862 | I39: =100*(D40/D58) -> #DIV/0! | K39: %
B40: = | D40: =D39*F39 -> 0 | G40: 3 | H40: 0.5908
B41: 重複性-設備變異
B42: Reproducibity-Appraiser Variation(AV) | D42: AV= | E42: √【（Xdiff X K2）2-（EV2/nr）】 | I42: %AV=100(AV/TV)
I43: =100*(E44/D58) -> #DIV/0! | K43: %
D44: = | E44: =D66 -> 0
...

Sheet Co
B3: ITEM | C3: Co | F3: DATE | G3: ='METAL RAW DATA'!G1 -> 20231226 | L3: NDC= | M3: =1.41*(D54/D70) -> #DIV/0!
F4: 儀 器 | G4: ='METAL RAW DATA'!C2 -> ICP- MS 金屬 R-R測試
D5: 1 | E5: 2 | F5: 3 | G5: 4 | H5: 5 | J5: AVE
B6: 分析師A | C6: N1 | D6: ='METAL RAW DATA'!M7 -> 0 | E6: ='METAL RAW DATA'!M10 -> 0 | F6: ='METAL RAW DATA'!M13 -> 0 | G6: ='METAL RAW DATA'!M16 -> 0 | H6: ='METAL RAW DATA'!M19 -> 0 | J6: =AVERAGE(D6:H6) -> 0
B7: 分析師A | C7: N2 | D7: ='METAL RAW DATA'!M8 -> 0 | E7: ='METAL RAW DATA'!M11 -> 0 | F7: ='METAL RAW DATA'!M14 -> 0 | G7: ='METAL RAW DATA'!M17 -> 0 | H7: ='METAL RAW DATA'!M20 -> 0 | J7: =AVERAGE(D7:H7) -> 0
B8: 分析師A | C8: N3 | D8: ='METAL RAW DATA'!M9 -> 0 | E8: ='METAL RAW DATA'!M12 -> 0 | F8: ='METAL RAW DATA'!M15 -> 0 | G8: ='METAL RAW DATA'!M18 -> 0 | H8: ='METAL RAW DATA'!M21 -> 0 | J8: =AVERAGE(D8:H8) -> 0
B9: AVE | D9: =AVERAGE(D6:D8) -> 0 | E9: =AVERAGE(E6:E8) -> 0 | F9: =AVERAGE(F6:F8) -> 0 | G9: =AVERAGE(G6:G8) -> 0 | H9: =AVERAGE(H6:H8) -> 0 | I9: Xa | J9: =AVERAGE(D9:H9) -> 0
B10: RANGE | D10: =MAX(D6:D8)-MIN(D6:D8) -> 0 | E10: =MAX(E6:E8)-MIN(E6:E8) -> 0 | F10: =MAX(F6:F8)-MIN(F6:F8) -> 0 | G10: =MAX(G6:G8)-MIN(G6:G8) -> 0 | H10: =MAX(H6:H8)-MIN(H6:H8) -> 0 | I10: Ra | J10: =AVERAGE(D10:H10) -> 0
B11: 分析師B | C11: N1 | D11: ='METAL RAW DATA'!M24 -> 0 | E11: ='METAL RAW DATA'!M27 -> 0 | F11: ='METAL RAW DATA'!M30 -> 0 | G11: ='METAL RAW DATA'!M33 -> 0 | H11: ='METAL RAW DATA'!M36 -> 0 | J11: =AVERAGE(D11:H11) -> 0
B12: 分析師B | C12: N2 | D12: ='METAL RAW DATA'!M25 -> 0 | E12: ='METAL RAW DATA'!M28 -> 0 | F12: ='METAL RAW DATA'!M31 -> 0 | G12: ='METAL RAW DATA'!M34 -> 0 | H12: ='METAL RAW DATA'!M37 -> 0 | J12: =AVERAGE(D12:H12) -> 0
B13: 分析師B | C13: N3 | D13: ='METAL RAW DATA'!M26 -> 0 | E13: ='METAL RAW DATA'!M29 -> 0 | F13: ='METAL RAW DATA'!M32 -> 0 | G13: ='METAL RAW DATA'!M35 -> 0 | H13: ='METAL RAW DATA'!M38 -> 0 | J13: =AVERAGE(D13:H13) -> 0
B14: AVE | D14: =AVERAGE(D11:D13) -> 0 | E14: =AVERAGE(E11:E13) -> 0 | F14: =AVERAGE(F11:F13) -> 0 | G14: =AVERAGE(G11:G13) -> 0 | H14: =AVERAGE(H11:H13) -> 0 | I14: Xb | J14: =AVERAGE(D14:H14) -> 0
B15: RANGE | D15: =MAX(D11:D13)-MIN(D11:D13) -> 0 | E15: =MAX(E11:E13)-MIN(E11:E13) -> 0 | F15: =MAX(F11:F13)-MIN(F11:F13) -> 0 | G15: =MAX(G11:G13)-MIN(G11:G13) -> 0 | H15: =MAX(H11:H13)-MIN(H11:H13) -> 0 | I15: Rb | J15: =AVERAGE(D15:H15) -> 0
B16: 分析師C | C16: N1 | D16: ='METAL RAW DATA'!M41 -> 0 | E16: ='METAL RAW DATA'!M44 -> 0 | F16: ='METAL RAW DATA'!M47 -> 0 | G16: ='METAL RAW DATA'!M50 -> 0 | H16: ='METAL RAW DATA'!M53 -> 0 | J16: =AVERAGE(D16:H16) -> 0
B17: 分析師C | C17: N2 | D17: ='METAL RAW DATA'!M42 -> 0 | E17: ='METAL RAW DATA'!M45 -> 0 | F17: ='METAL RAW DATA'!M48 -> 0 | G17: ='METAL RAW DATA'!M51 -> 0 | H17: ='METAL RAW DATA'!M54 -> 0 | J17: =AVERAGE(D17:H17) -> 0
B18: 分析師C | C18: N3 | D18: ='METAL RAW DATA'!M43 -> 0 | E18: ='METAL RAW DATA'!M46 -> 0 | F18: ='METAL RAW DATA'!M49 -> 0 | G18: ='METAL RAW DATA'!M52 -> 0 | H18: ='METAL RAW DATA'!M55 -> 0 | J18: =AVERAGE(D18:H18) -> 0
B19: AVE | D19: =AVERAGE(D16:D18) -> 0 | E19: =AVERAGE(E16:E18) -> 0 | F19: =AVERAGE(F16:F18) -> 0 | G19: =AVERAGE(G16:G18) -> 0 | H19: =AVERAGE(H16:H18) -> 0 | I19: Xa | J19: =AVERAGE(D19:H19) -> 0
B20: RANGE | D20: =MAX(D16:D18)-MIN(D16:D18) -> 0 | E20: =MAX(E16:E18)-MIN(E16:E18) -> 0 | F20: =MAX(F16:F18)-MIN(F16:F18) -> 0 | G20: =MAX(G16:G18)-MIN(G16:G18) -> 0 | H20: =MAX(H16:H18)-MIN(H16:H18) -> 0 | I20: Ra | J20: =AVERAGE(D20:H20) -> 0
B21: PART | I21: X | J21: =(J14+J9+J19)/3 -> 0
B22: AVE | C22: Xp | D22: =(D14+D9+D19)/3 -> 0 | E22: =(E14+E9+E19)/3 -> 0 | F22: =(F14+F9+F19)/3 -> 0 | G22: =(G14+G9+G19)/3 -> 0 | H22: =(H14+H9+H19)/3 -> 0 | I22: Rp | J22: =MAX(D22:H22)-MIN(D22:H22) -> 0
B23: R=(Ra+Rb+Rc)/3 | I23: R | J23: =(J15+J10+J20)/3 -> 0
B24: Max X-MaxB=X diff | I24: X diff | J24: =MAX(J9,J14,J19)-MIN(J9,J14,J19) -> 0
B26: R*D4=UCLR | J26: =J23*3.27 -> 0
B27: R*D3=LCLR | J27: =J23*0 -> 0
B29: Gage Repeatability and Reproducibility Report
E30: =G4 -> ICP- MS 金屬 R-R測試 | I30: Gage Nane | K30: ASSAY R&R | N30: Date: | O30: ='METAL RAW DATA'!#REF! -> #REF!
B31: Part No.and Name | I31: Gage No | N31: performed by
B32: Characteristics: | I32: Gage Type: | K32: METAL
B33: Specification:
E34: R= | F34: =J23 -> 0 | G34: x diff= | H34: =J24 -> 0 | I34: Rp= | K34: =J22 -> 0
B35: From date sheet: | I35: %Total Variation(TV)
E36: 操作人數(m=) | F36: 3 | G36: 重複測量(r=) | H36: 3 | I36: 測量樣品數(n=) | J36: 5
B37: Measurement Unit Analysis
B38: Repeatability-Equipment Variation(EV) | D38: EV = | E38: R × K1 | G38: Trials | H38: K1 | I38: %EV=100(EV/TV)
D39: =F34 -> 0 | E39: * | F39: =H40 -> 0.5908 | G39: 2 | H39: 0.8862 | I39: =100*(D40/D58) -> #DIV/0! | K39: %
B40: = | D40: =D39*F39 -> 0 | G40: 3 | H40: 0.5908
B41: 重複性-設備變異
B42: Reproducibity-Appraiser Variation(AV) | D42: AV= | E42: √【（Xdiff X K2）2-（EV2/nr）】 | I42: %AV=100(AV/TV)
I43: =100*(E44/D58) -> #DIV/0! | K43: %
D44: = | E44: =D66 -> 0
...

Sheet Cu
B3: ITEM | C3: Cu | F3: DATE | G3: ='METAL RAW DATA'!G1 -> 20231226 | L3: NDC= | M3: =1.41*(D54/D70) -> #DIV/0!
F4: 儀 器 | G4: ='METAL RAW DATA'!C2 -> ICP- MS 金屬 R-R測試
D5: 1 | E5: 2 | F5: 3 | G5: 4 | H5: 5 | J5: AVE
B6: 分析師A | C6: N1 | D6: ='METAL RAW DATA'!N7 -> 0 | E6: ='METAL RAW DATA'!N10 -> 0 | F6: ='METAL RAW DATA'!N13 -> 0 | G6: ='METAL RAW DATA'!N16 -> 0 | H6: ='METAL RAW DATA'!N19 -> 0 | J6: =AVERAGE(D6:H6) -> 0
B7: 分析師A | C7: N2 | D7: ='METAL RAW DATA'!N8 -> 0 | E7: ='METAL RAW DATA'!N11 -> 0 | F7: ='METAL RAW DATA'!N14 -> 0 | G7: ='METAL RAW DATA'!N17 -> 0 | H7: ='METAL RAW DATA'!N20 -> 0 | J7: =AVERAGE(D7:H7) -> 0
B8: 分析師A | C8: N3 | D8: ='METAL RAW DATA'!N9 -> 0 | E8: ='METAL RAW DATA'!N12 -> 0 | F8: ='METAL RAW DATA'!N15 -> 0 | G8: ='METAL RAW DATA'!N18 -> 0 | H8: ='METAL RAW DATA'!N21 -> 0 | J8: =AVERAGE(D8:H8) -> 0
B9: AVE | D9: =AVERAGE(D6:D8) -> 0 | E9: =AVERAGE(E6:E8) -> 0 | F9: =AVERAGE(F6:F8) -> 0 | G9: =AVERAGE(G6:G8) -> 0 | H9: =AVERAGE(H6:H8) -> 0 | I9: Xa | J9: =AVERAGE(D9:H9) -> 0
B10: RANGE | D10: =MAX(D6:D8)-MIN(D6:D8) -> 0 | E10: =MAX(E6:E8)-MIN(E6:E8) -> 0 | F10: =MAX(F6:F8)-MIN(F6:F8) -> 0 | G10: =MAX(G6:G8)-MIN(G6:G8) -> 0 | H10: =MAX(H6:H8)-MIN(H6:H8) -> 0 | I10: Ra | J10: =AVERAGE(D10:H10) -> 0
B11: 分析師B | C11: N1 | D11: ='METAL RAW DATA'!N24 -> 0 | E11: ='METAL RAW DATA'!N27 -> 0 | F11: ='METAL RAW DATA'!N30 -> 0 | G11: ='METAL RAW DATA'!N33 -> 0 | H11: ='METAL RAW DATA'!N36 -> 0 | J11: =AVERAGE(D11:H11) -> 0
B12: 分析師B | C12: N2 | D12: ='METAL RAW DATA'!N25 -> 0 | E12: ='METAL RAW DATA'!N28 -> 0 | F12: ='METAL RAW DATA'!N31 -> 0 | G12: ='METAL RAW DATA'!N34 -> 0 | H12: ='METAL RAW DATA'!N37 -> 0 | J12: =AVERAGE(D12:H12) -> 0
B13: 分析師B | C13: N3 | D13: ='METAL RAW DATA'!N26 -> 0 | E13: ='METAL RAW DATA'!N29 -> 0 | F13: ='METAL RAW DATA'!N32 -> 0 | G13: ='METAL RAW DATA'!N35 -> 0 | H13: ='METAL RAW DATA'!N38 -> 0 | J13: =AVERAGE(D13:H13) -> 0
B14: AVE | D14: =AVERAGE(D11:D13) -> 0 | E14: =AVERAGE(E11:E13) -> 0 | F14: =AVERAGE(F11:F13) -> 0 | G14: =AVERAGE(G11:G13) -> 0 | H14: =AVERAGE(H11:H13) -> 0 | I14: Xb | J14: =AVERAGE(D14:H14) -> 0
B15: RANGE | D15: =MAX(D11:D13)-MIN(D11:D13) -> 0 | E15: =MAX(E11:E13)-MIN(E11:E13) -> 0 | F15: =MAX(F11:F13)-MIN(F11:F13) -> 0 | G15: =MAX(G11:G13)-MIN(G11:G13) -> 0 | H15: =MAX(H11:H13)-MIN(H11:H13) -> 0 | I15: Rb | J15: =AVERAGE(D15:H15) -> 0
B16: 分析師C | C16: N1 | D16: ='METAL RAW DATA'!N41 -> 0 | E16: ='METAL RAW DATA'!N44 -> 0 | F16: ='METAL RAW DATA'!N47 -> 0 | G16: ='METAL RAW DATA'!N50 -> 0 | H16: ='METAL RAW DATA'!N53 -> 0 | J16: =AVERAGE(D16:H16) -> 0
B17: 分析師C | C17: N2 | D17: ='METAL RAW DATA'!N42 -> 0 | E17: ='METAL RAW DATA'!N45 -> 0 | F17: ='METAL RAW DATA'!N48 -> 0 | G17: ='METAL RAW DATA'!N51 -> 0 | H17: ='METAL RAW DATA'!N54 -> 0 | J17: =AVERAGE(D17:H17) -> 0
B18: 分析師C | C18: N3 | D18: ='METAL RAW DATA'!N43 -> 0 | E18: ='METAL RAW DATA'!N46 -> 0 | F18: ='METAL RAW DATA'!N49 -> 0 | G18: ='METAL RAW DATA'!N52 -> 0 | H18: ='METAL RAW DATA'!N55 -> 0 | J18: =AVERAGE(D18:H18) -> 0
B19: AVE | D19: =AVERAGE(D16:D18) -> 0 | E19: =AVERAGE(E16:E18) -> 0 | F19: =AVERAGE(F16:F18) -> 0 | G19: =AVERAGE(G16:G18) -> 0 | H19: =AVERAGE(H16:H18) -> 0 | I19: Xa | J19: =AVERAGE(D19:H19) -> 0
B20: RANGE | D20: =MAX(D16:D18)-MIN(D16:D18) -> 0 | E20: =MAX(E16:E18)-MIN(E16:E18) -> 0 | F20: =MAX(F16:F18)-MIN(F16:F18) -> 0 | G20: =MAX(G16:G18)-MIN(G16:G18) -> 0 | H20: =MAX(H16:H18)-MIN(H16:H18) -> 0 | I20: Ra | J20: =AVERAGE(D20:H20) -> 0
B21: PART | I21: X | J21: =(J14+J9+J19)/3 -> 0
B22: AVE | C22: Xp | D22: =(D14+D9+D19)/3 -> 0 | E22: =(E14+E9+E19)/3 -> 0 | F22: =(F14+F9+F19)/3 -> 0 | G22: =(G14+G9+G19)/3 -> 0 | H22: =(H14+H9+H19)/3 -> 0 | I22: Rp | J22: =MAX(D22:H22)-MIN(D22:H22) -> 0
B23: R=(Ra+Rb+Rc)/3 | I23: R | J23: =(J15+J10+J20)/3 -> 0
B24: Max X-MaxB=X diff | I24: X diff | J24: =MAX(J9,J14,J19)-MIN(J9,J14,J19) -> 0
B26: R*D4=UCLR | J26: =J23*3.27 -> 0
B27: R*D3=LCLR | J27: =J23*0 -> 0
B29: Gage Repeatability and Reproducibility Report
E30: =G4 -> ICP- MS 金屬 R-R測試 | I30: Gage Nane | K30: ASSAY R&R | N30: Date: | O30: ='METAL RAW DATA'!#REF! -> #REF!
B31: Part No.and Name | I31: Gage No | N31: performed by
B32: Characteristics: | I32: Gage Type: | K32: METAL
B33: Specification:
E34: R= | F34: =J23 -> 0 | G34: x diff= | H34: =J24 -> 0 | I34: Rp= | K34: =J22 -> 0
B35: From date sheet: | I35: %Total Variation(TV)
E36: 操作人數(m=) | F36: 3 | G36: 重複測量(r=) | H36: 3 | I36: 測量樣品數(n=) | J36: 5
B37: Measurement Unit Analysis
B38: Repeatability-Equipment Variation(EV) | D38: EV = | E38: R × K1 | G38: Trials | H38: K1 | I38: %EV=100(EV/TV)
D39: =F34 -> 0 | E39: * | F39: =H40 -> 0.5908 | G39: 2 | H39: 0.8862 | I39: =100*(D40/D58) -> #DIV/0! | K39: %
B40: = | D40: =D39*F39 -> 0 | G40: 3 | H40: 0.5908
B41: 重複性-設備變異
B42: Reproducibity-Appraiser Variation(AV) | D42: AV= | E42: √【（Xdiff X K2）2-（EV2/nr）】 | I42: %AV=100(AV/TV)
I43: =100*(E44/D58) -> #DIV/0! | K43: %
D44: = | E44: =D66 -> 0
...

Sheet Zn
B3: ITEM | C3: Zn | F3: DATE | G3: ='METAL RAW DATA'!G1 -> 20231226 | L3: NDC= | M3: =1.41*(D54/D70) -> #DIV/0!
F4: 儀 器 | G4: ='METAL RAW DATA'!C2 -> ICP- MS 金屬 R-R測試
D5: 1 | E5: 2 | F5: 3 | G5: 4 | H5: 5 | J5: AVE
B6: 分析師A | C6: N1 | D6: ='METAL RAW DATA'!O7 -> 0 | E6: ='METAL RAW DATA'!O10 -> 0 | F6: ='METAL RAW DATA'!O13 -> 0 | G6: ='METAL RAW DATA'!O16 -> 0 | H6: ='METAL RAW DATA'!O19 -> 0 | J6: =AVERAGE(D6:H6) -> 0
B7: 分析師A | C7: N2 | D7: ='METAL RAW DATA'!O8 -> 0 | E7: ='METAL RAW DATA'!O11 -> 0 | F7: ='METAL RAW DATA'!O14 -> 0 | G7: ='METAL RAW DATA'!O17 -> 0 | H7: ='METAL RAW DATA'!O20 -> 0 | J7: =AVERAGE(D7:H7) -> 0
B8: 分析師A | C8: N3 | D8: ='METAL RAW DATA'!O9 -> 0 | E8: ='METAL RAW DATA'!O12 -> 0 | F8: ='METAL RAW DATA'!O15 -> 0 | G8: ='METAL RAW DATA'!O18 -> 0 | H8: ='METAL RAW DATA'!O21 -> 0 | J8: =AVERAGE(D8:H8) -> 0
B9: AVE | D9: =AVERAGE(D6:D8) -> 0 | E9: =AVERAGE(E6:E8) -> 0 | F9: =AVERAGE(F6:F8) -> 0 | G9: =AVERAGE(G6:G8) -> 0 | H9: =AVERAGE(H6:H8) -> 0 | I9: Xa | J9: =AVERAGE(D9:H9) -> 0
B10: RANGE | D10: =MAX(D6:D8)-MIN(D6:D8) -> 0 | E10: =MAX(E6:E8)-MIN(E6:E8) -> 0 | F10: =MAX(F6:F8)-MIN(F6:F8) -> 0 | G10: =MAX(G6:G8)-MIN(G6:G8) -> 0 | H10: =MAX(H6:H8)-MIN(H6:H8) -> 0 | I10: Ra | J10: =AVERAGE(D10:H10) -> 0
B11: 分析師B | C11: N1 | D11: ='METAL RAW DATA'!O24 -> 0 | E11: ='METAL RAW DATA'!O27 -> 0 | F11: ='METAL RAW DATA'!O30 -> 0 | G11: ='METAL RAW DATA'!O33 -> 0 | H11: ='METAL RAW DATA'!O36 -> 0 | J11: =AVERAGE(D11:H11) -> 0
B12: 分析師B | C12: N2 | D12: ='METAL RAW DATA'!O25 -> 0 | E12: ='METAL RAW DATA'!O28 -> 0 | F12: ='METAL RAW DATA'!O31 -> 0 | G12: ='METAL RAW DATA'!O34 -> 0 | H12: ='METAL RAW DATA'!O37 -> 0 | J12: =AVERAGE(D12:H12) -> 0
B13: 分析師B | C13: N3 | D13: ='METAL RAW DATA'!O26 -> 0 | E13: ='METAL RAW DATA'!O29 -> 0 | F13: ='METAL RAW DATA'!O32 -> 0 | G13: ='METAL RAW DATA'!O35 -> 0 | H13: ='METAL RAW DATA'!O38 -> 0 | J13: =AVERAGE(D13:H13) -> 0
B14: AVE | D14: =AVERAGE(D11:D13) -> 0 | E14: =AVERAGE(E11:E13) -> 0 | F14: =AVERAGE(F11:F13) -> 0 | G14: =AVERAGE(G11:G13) -> 0 | H14: =AVERAGE(H11:H13) -> 0 | I14: Xb | J14: =AVERAGE(D14:H14) -> 0
B15: RANGE | D15: =MAX(D11:D13)-MIN(D11:D13) -> 0 | E15: =MAX(E11:E13)-MIN(E11:E13) -> 0 | F15: =MAX(F11:F13)-MIN(F11:F13) -> 0 | G15: =MAX(G11:G13)-MIN(G11:G13) -> 0 | H15: =MAX(H11:H13)-MIN(H11:H13) -> 0 | I15: Rb | J15: =AVERAGE(D15:H15) -> 0
B16: 分析師C | C16: N1 | D16: ='METAL RAW DATA'!O41 -> 0 | E16: ='METAL RAW DATA'!O44 -> 0 | F16: ='METAL RAW DATA'!O47 -> 0 | G16: ='METAL RAW DATA'!O50 -> 0 | H16: ='METAL RAW DATA'!O53 -> 0 | J16: =AVERAGE(D16:H16) -> 0
B17: 分析師C | C17: N2 | D17: ='METAL RAW DATA'!O42 -> 0 | E17: ='METAL RAW DATA'!O45 -> 0 | F17: ='METAL RAW DATA'!O48 -> 0 | G17: ='METAL RAW DATA'!O51 -> 0 | H17: ='METAL RAW DATA'!O54 -> 0 | J17: =AVERAGE(D17:H17) -> 0
B18: 分析師C | C18: N3 | D18: ='METAL RAW DATA'!O43 -> 0 | E18: ='METAL RAW DATA'!O46 -> 0 | F18: ='METAL RAW DATA'!O49 -> 0 | G18: ='METAL RAW DATA'!O52 -> 0 | H18: ='METAL RAW DATA'!O55 -> 0 | J18: =AVERAGE(D18:H18) -> 0
B19: AVE | D19: =AVERAGE(D16:D18) -> 0 | E19: =AVERAGE(E16:E18) -> 0 | F19: =AVERAGE(F16:F18) -> 0 | G19: =AVERAGE(G16:G18) -> 0 | H19: =AVERAGE(H16:H18) -> 0 | I19: Xa | J19: =AVERAGE(D19:H19) -> 0
B20: RANGE | D20: =MAX(D16:D18)-MIN(D16:D18) -> 0 | E20: =MAX(E16:E18)-MIN(E16:E18) -> 0 | F20: =MAX(F16:F18)-MIN(F16:F18) -> 0 | G20: =MAX(G16:G18)-MIN(G16:G18) -> 0 | H20: =MAX(H16:H18)-MIN(H16:H18) -> 0 | I20: Ra | J20: =AVERAGE(D20:H20) -> 0
B21: PART | I21: X | J21: =(J14+J9+J19)/3 -> 0
B22: AVE | C22: Xp | D22: =(D14+D9+D19)/3 -> 0 | E22: =(E14+E9+E19)/3 -> 0 | F22: =(F14+F9+F19)/3 -> 0 | G22: =(G14+G9+G19)/3 -> 0 | H22: =(H14+H9+H19)/3 -> 0 | I22: Rp | J22: =MAX(D22:H22)-MIN(D22:H22) -> 0
B23: R=(Ra+Rb+Rc)/3 | I23: R | J23: =(J15+J10+J20)/3 -> 0
B24: Max X-MaxB=X diff | I24: X diff | J24: =MAX(J9,J14,J19)-MIN(J9,J14,J19) -> 0
B26: R*D4=UCLR | J26: =J23*3.27 -> 0
B27: R*D3=LCLR | J27: =J23*0 -> 0
B29: Gage Repeatability and Reproducibility Report
E30: =G4 -> ICP- MS 金屬 R-R測試 | I30: Gage Nane | K30: ASSAY R&R | N30: Date: | O30: ='METAL RAW DATA'!#REF! -> #REF!
B31: Part No.and Name | I31: Gage No | N31: performed by
B32: Characteristics: | I32: Gage Type: | K32: METAL
B33: Specification:
E34: R= | F34: =J23 -> 0 | G34: x diff= | H34: =J24 -> 0 | I34: Rp= | K34: =J22 -> 0
B35: From date sheet: | I35: %Total Variation(TV)
E36: 操作人數(m=) | F36: 3 | G36: 重複測量(r=) | H36: 3 | I36: 測量樣品數(n=) | J36: 5
