Workbook

Sheet METAL (2)
D2: DATE | E2: ='METAL RAW DATA'!E2 -> 0
B3: ICP- MS 金屬 R＆R測試 | D3: A | E3: ='METAL RAW DATA'!E3 -> 0
D4: B | E4: ='METAL RAW DATA'!E4 -> 0
B6: 技師別 | C6: A | D6: A | E6: A | F6: A | G6: A | H6: A | I6: A | J6: A | K6: A | L6: A | M6: A | N6: A | O6: A | P6: A | Q6: A | R6: A | S6: A | T6: A | U6: A | V6: A
B7: N1 ~ N2 | C7: N1 | D7: N1 | E7: N1 | F7: N1 | G7: N1 | H7: N1 | I7: N1 | J7: N1 | K7: N1 | L7: N1 | M7: N2 | N7: N2 | O7: N2 | P7: N2 | Q7: N2 | R7: N2 | S7: N2 | T7: N2 | U7: N2 | V7: N2
B8: Na | C8: ='METAL RAW DATA'!C8 -> 0 | D8: ='METAL RAW DATA'!D8 -> 0 | E8: ='METAL RAW DATA'!E8 -> 0 | F8: ='METAL RAW DATA'!F8 -> 0 | G8: ='METAL RAW DATA'!G8 -> 0 | H8: ='METAL RAW DATA'!H8 -> 0 | I8: ='METAL RAW DATA'!I8 -> 0 | J8: ='METAL RAW DATA'!J8 -> 0 | ... V8: ='METAL RAW DATA'!V8 -> 0
B9: Mg | C9: ='METAL RAW DATA'!C9 -> 0 | D9: ='METAL RAW DATA'!D9 -> 0 | E9: ='METAL RAW DATA'!E9 -> 0 | F9: ='METAL RAW DATA'!F9 -> 0 | G9: ='METAL RAW DATA'!G9 -> 0 | H9: ='METAL RAW DATA'!H9 -> 0 | I9: ='METAL RAW DATA'!I9 -> 0 | J9: ='METAL RAW DATA'!J9 -> 0 | ... V9: ='METAL RAW DATA'!V9 -> 0
B10: Al | C10: ='METAL RAW DATA'!C10 -> 0 | D10: ='METAL RAW DATA'!D10 -> 0 | E10: ='METAL RAW DATA'!E10 -> 0 | F10: ='METAL RAW DATA'!F10 -> 0 | G10: ='METAL RAW DATA'!G10 -> 0 | H10: ='METAL RAW DATA'!H10 -> 0 | I10: ='METAL RAW DATA'!I10 -> 0 | J10: ='METAL RAW DATA'!J10 -> 0 | ... V10: ='METAL RAW DATA'!V10 -> 0
B11: K | C11: ='METAL RAW DATA'!C11 -> 0 | D11: ='METAL RAW DATA'!D11 -> 0 | E11: ='METAL RAW DATA'!E11 -> 0 | F11: ='METAL RAW DATA'!F11 -> 0 | G11: ='METAL RAW DATA'!G11 -> 0 | H11: ='METAL RAW DATA'!H11 -> 0 | I11: ='METAL RAW DATA'!I11 -> 0 | J11: ='METAL RAW DATA'!J11 -> 0 | ... V11: ='METAL RAW DATA'!V11 -> 0
B12: Ca | C12: ='METAL RAW DATA'!C12 -> 0 | D12: ='METAL RAW DATA'!D12 -> 0 | E12: ='METAL RAW DATA'!E12 -> 0 | F12: ='METAL RAW DATA'!F12 -> 0 | G12: ='METAL RAW DATA'!G12 -> 0 | H12: ='METAL RAW DATA'!H12 -> 0 | I12: ='METAL RAW DATA'!I12 -> 0 | J12: ='METAL RAW DATA'!J12 -> 0 | ... V12: ='METAL RAW DATA'!V12 -> 0
B13: Cr | C13: ='METAL RAW DATA'!C13 -> 0 | D13: ='METAL RAW DATA'!D13 -> 0 | E13: ='METAL RAW DATA'!E13 -> 0 | F13: ='METAL RAW DATA'!F13 -> 0 | G13: ='METAL RAW DATA'!G13 -> 0 | H13: ='METAL RAW DATA'!H13 -> 0 | I13: ='METAL RAW DATA'!I13 -> 0 | J13: ='METAL RAW DATA'!J13 -> 0 | ... V13: ='METAL RAW DATA'!V13 -> 0
B14: Mn | C14: ='METAL RAW DATA'!C14 -> 0 | D14: ='METAL RAW DATA'!D14 -> 0 | E14: ='METAL RAW DATA'!E14 -> 0 | F14: ='METAL RAW DATA'!F14 -> 0 | G14: ='METAL RAW DATA'!G14 -> 0 | H14: ='METAL RAW DATA'!H14 -> 0 | I14: ='METAL RAW DATA'!I14 -> 0 | J14: ='METAL RAW DATA'!J14 -> 0 | ... V14: ='METAL RAW DATA'!V14 -> 0
B15: Fe | C15: ='METAL RAW DATA'!C15 -> 0 | D15: ='METAL RAW DATA'!D15 -> 0 | E15: ='METAL RAW DATA'!E15 -> 0 | F15: ='METAL RAW DATA'!F15 -> 0 | G15: ='METAL RAW DATA'!G15 -> 0 | H15: ='METAL RAW DATA'!H15 -> 0 | I15: ='METAL RAW DATA'!I15 -> 0 | J15: ='METAL RAW DATA'!J15 -> 0 | ... V15: ='METAL RAW DATA'!V15 -> 0
B16: Ni | C16: ='METAL RAW DATA'!C16 -> 0 | D16: ='METAL RAW DATA'!D16 -> 0 | E16: ='METAL RAW DATA'!E16 -> 0 | F16: ='METAL RAW DATA'!F16 -> 0 | G16: ='METAL RAW DATA'!G16 -> 0 | H16: ='METAL RAW DATA'!H16 -> 0 | I16: ='METAL RAW DATA'!I16 -> 0 | J16: ='METAL RAW DATA'!J16 -> 0 | ... V16: ='METAL RAW DATA'!V16 -> 0
B17: Co | C17: ='METAL RAW DATA'!C17 -> 0 | D17: ='METAL RAW DATA'!D17 -> 0 | E17: ='METAL RAW DATA'!E17 -> 0 | F17: ='METAL RAW DATA'!F17 -> 0 | G17: ='METAL RAW DATA'!G17 -> 0 | H17: ='METAL RAW DATA'!H17 -> 0 | I17: ='METAL RAW DATA'!I17 -> 0 | J17: ='METAL RAW DATA'!J17 -> 0 | ... V17: ='METAL RAW DATA'!V17 -> 0
B18: Cu | C18: ='METAL RAW DATA'!C18 -> 0 | D18: ='METAL RAW DATA'!D18 -> 0 | E18: ='METAL RAW DATA'!E18 -> 0 | F18: ='METAL RAW DATA'!F18 -> 0 | G18: ='METAL RAW DATA'!G18 -> 0 | H18: ='METAL RAW DATA'!H18 -> 0 | I18: ='METAL RAW DATA'!I18 -> 0 | J18: ='METAL RAW DATA'!J18 -> 0 | ... V18: ='METAL RAW DATA'!V18 -> 0
B19: Zn | C19: ='METAL RAW DATA'!C19 -> 0 | D19: ='METAL RAW DATA'!D19 -> 0 | E19: ='METAL RAW DATA'!E19 -> 0 | F19: ='METAL RAW DATA'!F19 -> 0 | G19: ='METAL RAW DATA'!G19 -> 0 | H19: ='METAL RAW DATA'!H19 -> 0 | I19: ='METAL RAW DATA'!I19 -> 0 | J19: ='METAL RAW DATA'!J19 -> 0 | ... V19: ='METAL RAW DATA'!V19 -> 0
B20: Pb | C20: ='METAL RAW DATA'!C20 -> 0 | D20: ='METAL RAW DATA'!D20 -> 0 | E20: ='METAL RAW DATA'!E20 -> 0 | F20: ='METAL RAW DATA'!F20 -> 0 | G20: ='METAL RAW DATA'!G20 -> 0 | H20: ='METAL RAW DATA'!H20 -> 0 | I20: ='METAL RAW DATA'!I20 -> 0 | J20: ='METAL RAW DATA'!J20 -> 0 | ... V20: ='METAL RAW DATA'!V20 -> 0
B23: 技師別 | C23: B | D23: B | E23: B | F23: B | G23: B | H23: B | I23: B | J23: B | K23: B | L23: B | M23: B | N23: B | O23: B | P23: B | Q23: B | R23: B | S23: B | T23: B | U23: B | V23: B
B24: N1 ~ N2 | C24: N1 | D24: N1 | E24: N1 | F24: N1 | G24: N1 | H24: N1 | I24: N1 | J24: N1 | K24: N1 | L24: N1 | M24: N2 | N24: N2 | O24: N2 | P24: N2 | Q24: N2 | R24: N2 | S24: N2 | T24: N2 | U24: N2 | V24: N2
B25: Na | C25: ='METAL RAW DATA'!W8 -> 0 | D25: ='METAL RAW DATA'!X8 -> 0 | E25: ='METAL RAW DATA'!Y8 -> 0 | F25: ='METAL RAW DATA'!Z8 -> 0 | G25: ='METAL RAW DATA'!AA8 -> 0 | H25: ='METAL RAW DATA'!AB8 -> 0 | I25: ='METAL RAW DATA'!AC8 -> 0 | J25: ='METAL RAW DATA'!AD8 -> 0 | ... V25: ='METAL RAW DATA'!AP8 -> 0
B26: Mg | C26: ='METAL RAW DATA'!W9 -> 0 | D26: ='METAL RAW DATA'!X9 -> 0 | E26: ='METAL RAW DATA'!Y9 -> 0 | F26: ='METAL RAW DATA'!Z9 -> 0 | G26: ='METAL RAW DATA'!AA9 -> 0 | H26: ='METAL RAW DATA'!AB9 -> 0 | I26: ='METAL RAW DATA'!AC9 -> 0 | J26: ='METAL RAW DATA'!AD9 -> 0 | ... V26: ='METAL RAW DATA'!AP9 -> 0
B27: Al | C27: ='METAL RAW DATA'!W10 -> 0 | D27: ='METAL RAW DATA'!X10 -> 0 | E27: ='METAL RAW DATA'!Y10 -> 0 | F27: ='METAL RAW DATA'!Z10 -> 0 | G27: ='METAL RAW DATA'!AA10 -> 0 | H27: ='METAL RAW DATA'!AB10 -> 0 | I27: ='METAL RAW DATA'!AC10 -> 0 | J27: ='METAL RAW DATA'!AD10 -> 0 | ... V27: ='METAL RAW DATA'!AP10 -> 0
B28: K | C28: ='METAL RAW DATA'!W11 -> 0 | D28: ='METAL RAW DATA'!X11 -> 0 | E28: ='METAL RAW DATA'!Y11 -> 0 | F28: ='METAL RAW DATA'!Z11 -> 0 | G28: ='METAL RAW DATA'!AA11 -> 0 | H28: ='METAL RAW DATA'!AB11 -> 0 | I28: ='METAL RAW DATA'!AC11 -> 0 | J28: ='METAL RAW DATA'!AD11 -> 0 | ... V28: ='METAL RAW DATA'!AP11 -> 0
B29: Ca | C29: ='METAL RAW DATA'!W12 -> 0 | D29: ='METAL RAW DATA'!X12 -> 0 | E29: ='METAL RAW DATA'!Y12 -> 0 | F29: ='METAL RAW DATA'!Z12 -> 0 | G29: ='METAL RAW DATA'!AA12 -> 0 | H29: ='METAL RAW DATA'!AB12 -> 0 | I29: ='METAL RAW DATA'!AC12 -> 0 | J29: ='METAL RAW DATA'!AD12 -> 0 | ... V29: ='METAL RAW DATA'!AP12 -> 0
B30: Cr | C30: ='METAL RAW DATA'!W13 -> 0 | D30: ='METAL RAW DATA'!X13 -> 0 | E30: ='METAL RAW DATA'!Y13 -> 0 | F30: ='METAL RAW DATA'!Z13 -> 0 | G30: ='METAL RAW DATA'!AA13 -> 0 | H30: ='METAL RAW DATA'!AB13 -> 0 | I30: ='METAL RAW DATA'!AC13 -> 0 | J30: ='METAL RAW DATA'!AD13 -> 0 | ... V30: ='METAL RAW DATA'!AP13 -> 0
B31: Mn | C31: ='METAL RAW DATA'!W14 -> 0 | D31: ='METAL RAW DATA'!X14 -> 0 | E31: ='METAL RAW DATA'!Y14 -> 0 | F31: ='METAL RAW DATA'!Z14 -> 0 | G31: ='METAL RAW DATA'!AA14 -> 0 | H31: ='METAL RAW DATA'!AB14 -> 0 | I31: ='METAL RAW DATA'!AC14 -> 0 | J31: ='METAL RAW DATA'!AD14 -> 0 | ... V31: ='METAL RAW DATA'!AP14 -> 0
B32: Fe | C32: ='METAL RAW DATA'!W15 -> 0 | D32: ='METAL RAW DATA'!X15 -> 0 | E32: ='METAL RAW DATA'!Y15 -> 0 | F32: ='METAL RAW DATA'!Z15 -> 0 | G32: ='METAL RAW DATA'!AA15 -> 0 | H32: ='METAL RAW DATA'!AB15 -> 0 | I32: ='METAL RAW DATA'!AC15 -> 0 | J32: ='METAL RAW DATA'!AD15 -> 0 | ... V32: ='METAL RAW DATA'!AP15 -> 0
B33: Ni | C33: ='METAL RAW DATA'!W16 -> 0 | D33: ='METAL RAW DATA'!X16 -> 0 | E33: ='METAL RAW DATA'!Y16 -> 0 | F33: ='METAL RAW DATA'!Z16 -> 0 | G33: ='METAL RAW DATA'!AA16 -> 0 | H33: ='METAL RAW DATA'!AB16 -> 0 | I33: ='METAL RAW DATA'!AC16 -> 0 | J33: ='METAL RAW DATA'!AD16 -> 0 | ... V33: ='METAL RAW DATA'!AP16 -> 0
B34: Co | C34: ='METAL RAW DATA'!W17 -> 0 | D34: ='METAL RAW DATA'!X17 -> 0 | E34: ='METAL RAW DATA'!Y17 -> 0 | F34: ='METAL RAW DATA'!Z17 -> 0 | G34: ='METAL RAW DATA'!AA17 -> 0 | H34: ='METAL RAW DATA'!AB17 -> 0 | I34: ='METAL RAW DATA'!AC17 -> 0 | J34: ='METAL RAW DATA'!AD17 -> 0 | ... V34: ='METAL RAW DATA'!AP17 -> 0
B35: Cu | C35: ='METAL RAW DATA'!W18 -> 0 | D35: ='METAL RAW DATA'!X18 -> 0 | E35: ='METAL RAW DATA'!Y18 -> 0 | F35: ='METAL RAW DATA'!Z18 -> 0 | G35: ='METAL RAW DATA'!AA18 -> 0 | H35: ='METAL RAW DATA'!AB18 -> 0 | I35: ='METAL RAW DATA'!AC18 -> 0 | J35: ='METAL RAW DATA'!AD18 -> 0 | ... V35: ='METAL RAW DATA'!AP18 -> 0
B36: Zn | C36: ='METAL RAW DATA'!W19 -> 0 | D36: ='METAL RAW DATA'!X19 -> 0 | E36: ='METAL RAW DATA'!Y19 -> 0 | F36: ='METAL RAW DATA'!Z19 -> 0 | G36: ='METAL RAW DATA'!AA19 -> 0 | H36: ='METAL RAW DATA'!AB19 -> 0 | I36: ='METAL RAW DATA'!AC19 -> 0 | J36: ='METAL RAW DATA'!AD19 -> 0 | ... V36: ='METAL RAW DATA'!AP19 -> 0
B37: Pb | C37: ='METAL RAW DATA'!W20 -> 0 | D37: ='METAL RAW DATA'!X20 -> 0 | E37: ='METAL RAW DATA'!Y20 -> 0 | F37: ='METAL RAW DATA'!Z20 -> 0 | G37: ='METAL RAW DATA'!AA20 -> 0 | H37: ='METAL RAW DATA'!AB20 -> 0 | I37: ='METAL RAW DATA'!AC20 -> 0 | J37: ='METAL RAW DATA'!AD20 -> 0 | ... V37: ='METAL RAW DATA'!AP20 -> 0

Sheet METAL RAW DATA
B2: H2SO4 | D2: DATE
B3: ICP- MS 金屬 R-R測試 | D3: A
D4: B
B6: 技師別 | C6: A | D6: A | E6: A | F6: A | G6: A | H6: A | I6: A | J6: A | K6: A | L6: A | M6: A | N6: A | O6: A | P6: A | Q6: A | R6: A | S6: A | T6: A | U6: A | V6: A | W6: B | X6: B | Y6: B | Z6: B | AA6: B | AB6: B | AC6: B | AD6: B | AE6: B | AF6: B | AG6: B | AH6: B | AI6: B | AJ6: B | AK6: B | AL6: B | AM6: B | AN6: B | AO6: B | AP6: B
B7: N1 ~ N2 | C7: N1 | D7: N1 | E7: N1 | F7: N1 | G7: N1 | H7: N1 | I7: N1 | J7: N1 | K7: N1 | L7: N1 | M7: N2 | N7: N2 | O7: N2 | P7: N2 | Q7: N2 | R7: N2 | S7: N2 | T7: N2 | U7: N2 | V7: N2 | W7: N1 | X7: N1 | Y7: N1 | Z7: N1 | AA7: N1 | AB7: N1 | AC7: N1 | AD7: N1 | AE7: N1 | AF7: N1 | AG7: N2 | AH7: N2 | AI7: N2 | AJ7: N2 | AK7: N2 | AL7: N2 | AM7: N2 | AN7: N2 | AO7: N2 | AP7: N2
B8: Na
B9: Mg
B10: Al
B11: K
B12: Ca
B13: Cr
B14: Mn
B15: Fe
B16: Ni
B17: Co
B18: Cu
B19: Zn
B20: Pb

Sheet Na
F1: ='METAL RAW DATA'!B3 -> ICP- MS 金屬 R-R測試
B3: ITEM | C3: ='METAL RAW DATA'!B8 -> Na | F3: DATE | G3: ='METAL RAW DATA'!E2 -> 0 | L3: NDC= | M3: =1.41*(D47/D63) -> #DIV/0!
F4: 儀 器 | G4: ='METAL RAW DATA'!B3 -> ICP- MS 金屬 R-R測試
D5: 1 | E5: 2 | F5: 3 | G5: 4 | H5: 5 | I5: 6 | J5: 7 | K5: 8 | L5: 9 | M5: 10 | O5: AVE
B6: A | D6: ='METAL RAW DATA'!C8 -> 0 | E6: ='METAL RAW DATA'!D8 -> 0 | F6: ='METAL RAW DATA'!E8 -> 0 | G6: ='METAL RAW DATA'!F8 -> 0 | H6: ='METAL RAW DATA'!G8 -> 0 | I6: ='METAL RAW DATA'!H8 -> 0 | J6: ='METAL RAW DATA'!I8 -> 0 | K6: ='METAL RAW DATA'!J8 -> 0 | ... M6: ='METAL RAW DATA'!L8 -> 0 | O6: =SUM(D6:M6)/10 -> 0
B7: A | D7: ='METAL RAW DATA'!M8 -> 0 | E7: ='METAL RAW DATA'!N8 -> 0 | F7: ='METAL RAW DATA'!O8 -> 0 | G7: ='METAL RAW DATA'!P8 -> 0 | H7: ='METAL RAW DATA'!Q8 -> 0 | I7: ='METAL RAW DATA'!R8 -> 0 | J7: ='METAL RAW DATA'!S8 -> 0 | K7: ='METAL RAW DATA'!T8 -> 0 | ... M7: ='METAL RAW DATA'!V8 -> 0 | O7: =SUM(D7:M7)/10 -> 0
B8: AVE | D8: =AVERAGE(D6:D7) -> 0 | E8: =AVERAGE(E6:E7) -> 0 | F8: =AVERAGE(F6:F7) -> 0 | G8: =AVERAGE(G6:G7) -> 0 | H8: =AVERAGE(H6:H7) -> 0 | I8: =AVERAGE(I6:I7) -> 0 | J8: =AVERAGE(J6:J7) -> 0 | K8: =AVERAGE(K6:K7) -> 0 | ... M8: =AVERAGE(M6:M7) -> 0 | N8: Xa | O8: =AVERAGE(O6:O7) -> 0
B9: RANGE | D9: =MAX(D6:D7)-MIN(D6:D7) -> 0 | E9: =MAX(E6:E7)-MIN(E6:E7) -> 0 | F9: =MAX(F6:F7)-MIN(F6:F7) -> 0 | G9: =MAX(G6:G7)-MIN(G6:G7) -> 0 | H9: =MAX(H6:H7)-MIN(H6:H7) -> 0 | I9: =MAX(I6:I7)-MIN(I6:I7) -> 0 | J9: =MAX(J6:J7)-MIN(J6:J7) -> 0 | K9: =MAX(K6:K7)-MIN(K6:K7) -> 0 | ... M9: =MAX(M6:M7)-MIN(M6:M7) -> 0 | N9: Ra | O9: =SUM(D9:M9)/10 -> 0
B10: B | D10: ='METAL RAW DATA'!W8 -> 0 | E10: ='METAL RAW DATA'!X8 -> 0 | F10: ='METAL RAW DATA'!Y8 -> 0 | G10: ='METAL RAW DATA'!Z8 -> 0 | H10: ='METAL RAW DATA'!AA8 -> 0 | I10: ='METAL RAW DATA'!AB8 -> 0 | J10: ='METAL RAW DATA'!AC8 -> 0 | K10: ='METAL RAW DATA'!AD8 -> 0 | ... M10: ='METAL RAW DATA'!AF8 -> 0 | O10: =SUM(D10:M10)/10 -> 0
B11: B | D11: ='METAL RAW DATA'!AG8 -> 0 | E11: ='METAL RAW DATA'!AH8 -> 0 | F11: ='METAL RAW DATA'!AI8 -> 0 | G11: ='METAL RAW DATA'!AJ8 -> 0 | H11: ='METAL RAW DATA'!AK8 -> 0 | I11: ='METAL RAW DATA'!AL8 -> 0 | J11: ='METAL RAW DATA'!AM8 -> 0 | K11: ='METAL RAW DATA'!AN8 -> 0 | ... M11: ='METAL RAW DATA'!AP8 -> 0 | O11: =SUM(D11:M11)/10 -> 0
B12: AVE | D12: =AVERAGE(D10:D11) -> 0 | E12: =AVERAGE(E10:E11) -> 0 | F12: =AVERAGE(F10:F11) -> 0 | G12: =AVERAGE(G10:G11) -> 0 | H12: =AVERAGE(H10:H11) -> 0 | I12: =AVERAGE(I10:I11) -> 0 | J12: =AVERAGE(J10:J11) -> 0 | K12: =AVERAGE(K10:K11) -> 0 | ... M12: =AVERAGE(M10:M11) -> 0 | N12: Xb | O12: =SUM(D12:M12)/10 -> 0
B13: RANGE | D13: =MAX(D10:D11)-MIN(D10:D11) -> 0 | E13: =MAX(E10:E11)-MIN(E10:E11) -> 0 | F13: =MAX(F10:F11)-MIN(F10:F11) -> 0 | G13: =MAX(G10:G11)-MIN(G10:G11) -> 0 | H13: =MAX(H10:H11)-MIN(H10:H11) -> 0 | I13: =MAX(I10:I11)-MIN(I10:I11) -> 0 | J13: =MAX(J10:J11)-MIN(J10:J11) -> 0 | K13: =MAX(K10:K11)-MIN(K10:K11) -> 0 | ... M13: =MAX(M10:M11)-MIN(M10:M11) -> 0 | N13: Rb | O13: =SUM(D13:M13)/10 -> 0
B14: PART | N14: X | O14: =(O12+O8)/2 -> 0
B15: AVE | C15: Xp | D15: =(D12+D8)/2 -> 0 | E15: =(E12+E8)/2 -> 0 | F15: =(F12+F8)/2 -> 0 | G15: =(G12+G8)/2 -> 0 | H15: =(H12+H8)/2 -> 0 | I15: =(I12+I8)/2 -> 0 | J15: =(J12+J8)/2 -> 0 | K15: =(K12+K8)/2 -> 0 | ... M15: =(M12+M8)/2 -> 0 | N15: Rp | O15: =MAX(A15:M15)-MIN(A15:M15) -> 0
B16: R=(Ra+Rb)/2 | N16: R | O16: =(O13+O9)/2 -> 0
B17: Max X-MaxB=X diff | N17: X diff | O17: =MAX(O8,O12)-MIN(O8,O12) -> 0
B19: R*D4=UCLR | O19: =O16*3.27 -> 0
B20: R*D3=LCLR | O20: =P16*0 -> 0
B22: Gage Repeatability and Reproducibility Report
E23: =G4 -> ICP- MS 金屬 R-R測試 | I23: Gage Nane | K23: ASSAY R&R | N23: Date: | O23: ='METAL RAW DATA'!E2 -> 0
B24: Part No.and Name | I24: Gage No | N24: performed by
B25: Characteristics: | I25: Gage Type: | K25: METAL
B26: Specification:
E27: R= | F27: =O16 -> 0 | G27: x diff= | H27: =O17 -> 0 | I27: Rp= | K27: =O15 -> 0
B28: From date sheet: | I28: %Total Variation(TV)
E29: n= | F29: 2 | G29: test= | H29: 10
B30: Measurement Unit Analysis
B31: Repeatability-Equipment Variation(EV) | D31: EV = | E31: R × K1 | G31: Trials | H31: K1 | I31: %EV=100(EV/TV)
D32: =F27 -> 0 | E32: * | F32: =H32 -> 0.8862 | G32: 2 | H32: 0.8862 | I32: =100*(D33/D51) -> #DIV/0! | K32: %
B33: = | D33: =D32*F32 -> 0 | G33: 3 | H33: 0.5908
B34: 重複性-設備變異
B35: Reproducibity-Appraiser Variation(AV) | D35: AV= | E35: √【（Xdiff X K2）2-（EV2/nr）】 | I35: %AV=100(AV/TV)
I36: =100*(E37/D51) -> #DIV/0! | K36: %
D37: = | E37: =D59 -> 0
F38: Appraisers | G38: 2 | H38: 3 | I38: n=number of parts
F39: k2 | G39: 0.7071 | H39: 0.5231 | I39: r=number of trials
B40: 再現性-評價者變異
B41: Repeatability& Reproducibility(R&R) | D41: R&R= | E41: √(EV2+AV2 | I41: %R&R=100(R&R/TV)
D42: = | I42: =100*(E43/D51) -> #DIV/0! | K42: %
B43: 重複性及再現性 | D43: = | E43: =D63 -> 0 | I43: =100*(E43/F67) -> 0 | K43: %
...

Sheet Mg
F1: ='METAL RAW DATA'!B3 -> ICP- MS 金屬 R-R測試
B3: ITEM | C3: ='METAL RAW DATA'!B9 -> Mg | F3: DATE | G3: ='METAL RAW DATA'!E2 -> 0 | L3: NDC= | M3: =1.41*(D47/D63) -> #DIV/0!
F4: 儀 器 | G4: ='METAL RAW DATA'!B3 -> ICP- MS 金屬 R-R測試
D5: 1 | E5: 2 | F5: 3 | G5: 4 | H5: 5 | I5: 6 | J5: 7 | K5: 8 | L5: 9 | M5: 10 | O5: AVE
B6: A | D6: ='METAL RAW DATA'!C9 -> 0 | E6: ='METAL RAW DATA'!D9 -> 0 | F6: ='METAL RAW DATA'!E9 -> 0 | G6: ='METAL RAW DATA'!F9 -> 0 | H6: ='METAL RAW DATA'!G9 -> 0 | I6: ='METAL RAW DATA'!H9 -> 0 | J6: ='METAL RAW DATA'!I9 -> 0 | K6: ='METAL RAW DATA'!J9 -> 0 | ... M6: ='METAL RAW DATA'!L9 -> 0 | O6: =SUM(D6:M6)/10 -> 0
B7: A | D7: ='METAL RAW DATA'!M9 -> 0 | E7: ='METAL RAW DATA'!N9 -> 0 | F7: ='METAL RAW DATA'!O9 -> 0 | G7: ='METAL RAW DATA'!P9 -> 0 | H7: ='METAL RAW DATA'!Q9 -> 0 | I7: ='METAL RAW DATA'!R9 -> 0 | J7: ='METAL RAW DATA'!S9 -> 0 | K7: ='METAL RAW DATA'!T9 -> 0 | ... M7: ='METAL RAW DATA'!V9 -> 0 | O7: =SUM(D7:M7)/10 -> 0
B8: AVE | D8: =AVERAGE(D6:D7) -> 0 | E8: =AVERAGE(E6:E7) -> 0 | F8: =AVERAGE(F6:F7) -> 0 | G8: =AVERAGE(G6:G7) -> 0 | H8: =AVERAGE(H6:H7) -> 0 | I8: =AVERAGE(I6:I7) -> 0 | J8: =AVERAGE(J6:J7) -> 0 | K8: =AVERAGE(K6:K7) -> 0 | ... M8: =AVERAGE(M6:M7) -> 0 | N8: Xa | O8: =AVERAGE(O6:O7) -> 0
B9: RANGE | D9: =MAX(D6:D7)-MIN(D6:D7) -> 0 | E9: =MAX(E6:E7)-MIN(E6:E7) -> 0 | F9: =MAX(F6:F7)-MIN(F6:F7) -> 0 | G9: =MAX(G6:G7)-MIN(G6:G7) -> 0 | H9: =MAX(H6:H7)-MIN(H6:H7) -> 0 | I9: =MAX(I6:I7)-MIN(I6:I7) -> 0 | J9: =MAX(J6:J7)-MIN(J6:J7) -> 0 | K9: =MAX(K6:K7)-MIN(K6:K7) -> 0 | ... M9: =MAX(M6:M7)-MIN(M6:M7) -> 0 | N9: Ra | O9: =SUM(D9:M9)/8 -> 0
B10: B | D10: ='METAL RAW DATA'!W9 -> 0 | E10: ='METAL RAW DATA'!X9 -> 0 | F10: ='METAL RAW DATA'!Y9 -> 0 | G10: ='METAL RAW DATA'!Z9 -> 0 | H10: ='METAL RAW DATA'!AA9 -> 0 | I10: ='METAL RAW DATA'!AB9 -> 0 | J10: ='METAL RAW DATA'!AC9 -> 0 | K10: ='METAL RAW DATA'!AD9 -> 0 | ... M10: ='METAL RAW DATA'!AF9 -> 0 | O10: =SUM(D10:M10)/10 -> 0
B11: B | D11: ='METAL RAW DATA'!AG9 -> 0 | E11: ='METAL RAW DATA'!AH9 -> 0 | F11: ='METAL RAW DATA'!AI9 -> 0 | G11: ='METAL RAW DATA'!AJ9 -> 0 | H11: ='METAL RAW DATA'!AK9 -> 0 | I11: ='METAL RAW DATA'!AL9 -> 0 | J11: ='METAL RAW DATA'!AM9 -> 0 | K11: ='METAL RAW DATA'!AN9 -> 0 | ... M11: ='METAL RAW DATA'!AP9 -> 0 | O11: =SUM(D11:M11)/10 -> 0
B12: AVE | D12: =AVERAGE(D10:D11) -> 0 | E12: =AVERAGE(E10:E11) -> 0 | F12: =AVERAGE(F10:F11) -> 0 | G12: =AVERAGE(G10:G11) -> 0 | H12: =AVERAGE(H10:H11) -> 0 | I12: =AVERAGE(I10:I11) -> 0 | J12: =AVERAGE(J10:J11) -> 0 | K12: =AVERAGE(K10:K11) -> 0 | ... M12: =AVERAGE(M10:M11) -> 0 | N12: Xb | O12: =SUM(D12:M12)/10 -> 0
B13: RANGE | D13: =MAX(D10:D11)-MIN(D10:D11) -> 0 | E13: =MAX(E10:E11)-MIN(E10:E11) -> 0 | F13: =MAX(F10:F11)-MIN(F10:F11) -> 0 | G13: =MAX(G10:G11)-MIN(G10:G11) -> 0 | H13: =MAX(H10:H11)-MIN(H10:H11) -> 0 | I13: =MAX(I10:I11)-MIN(I10:I11) -> 0 | J13: =MAX(J10:J11)-MIN(J10:J11) -> 0 | K13: =MAX(K10:K11)-MIN(K10:K11) -> 0 | ... M13: =MAX(M10:M11)-MIN(M10:M11) -> 0 | N13: Rb | O13: =SUM(D13:M13)/10 -> 0
B14: PART | N14: X | O14: =(O12+O8)/2 -> 0
B15: AVE | C15: Xp | D15: =(D12+D8)/2 -> 0 | E15: =(E12+E8)/2 -> 0 | F15: =(F12+F8)/2 -> 0 | G15: =(G12+G8)/2 -> 0 | H15: =(H12+H8)/2 -> 0 | I15: =(I12+I8)/2 -> 0 | J15: =(J12+J8)/2 -> 0 | K15: =(K12+K8)/2 -> 0 | ... M15: =(M12+M8)/2 -> 0 | N15: Rp | O15: =MAX(A15:M15)-MIN(A15:M15) -> 0
B16: R=(Ra+Rb)/2 | N16: R | O16: =(O13+O9)/2 -> 0
B17: Max X-MaxB=X diff | N17: X diff | O17: =MAX(O8,O12)-MIN(O8,O12) -> 0
B19: R*D4=UCLR | O19: =O16*3.27 -> 0
B20: R*D3=LCLR | O20: =O16*0 -> 0
B22: Gage Repeatability and Reproducibility Report
E23: =G4 -> ICP- MS 金屬 R-R測試 | I23: Gage Nane | K23: ASSAY R&R | N23: Date: | O23: ='METAL RAW DATA'!E2 -> 0
B24: Part No.and Name | I24: Gage No | N24: performed by
B25: Characteristics: | I25: Gage Type: | K25: METAL
B26: Specification:
E27: R= | F27: =O16 -> 0 | G27: x diff= | H27: =O17 -> 0 | I27: Rp= | K27: =O15 -> 0
B28: From date sheet: | I28: %Total Variation(TV)
E29: n= | F29: 2 | G29: test= | H29: 10
B30: Measurement Unit Analysis
B31: Repeatability-Equipment Variation(EV) | D31: EV = | E31: R × K1 | G31: Trials | H31: K1 | I31: %EV=100(EV/TV)
D32: =F27 -> 0 | E32: * | F32: =H32 -> 0.8862 | G32: 2 | H32: 0.8862 | I32: =100*(D33/D51) -> #DIV/0! | K32: %
B33: = | D33: =D32*F32 -> 0 | G33: 3 | H33: 0.5908
B34: 重複性-設備變異
B35: Reproducibity-Appraiser Variation(AV) | D35: AV= | E35: √【（Xdiff X K2）2-（EV2/nr）】 | I35: %AV=100(AV/TV)
I36: =100*(E37/D51) -> #DIV/0! | K36: %
D37: = | E37: =D59 -> 0
F38: Appraisers | G38: 2 | H38: 3 | I38: n=number of parts
F39: k2 | G39: 0.7071 | H39: 0.5231 | I39: r=number of trials
B40: 再現性-評價者變異
B41: Repeatability& Reproducibility(R&R) | D41: R&R= | E41: √(EV2+AV2 | I41: %R&R=100(R&R/TV)
D42: = | I42: =100*(E43/D51) -> #DIV/0! | K42: %
B43: 重複性及再現性 | D43: = | E43: =D63 -> 0 | I43: =100*(E43/F67) -> 0 | K43: %
...

Sheet K
F1: ='METAL RAW DATA'!B3 -> ICP- MS 金屬 R-R測試
B3: ITEM | C3: ='METAL RAW DATA'!B11 -> K | F3: DATE | G3: ='METAL RAW DATA'!E2 -> 0 | L3: NDC= | M3: =1.41*(D47/D63) -> #DIV/0!
F4: 儀 器 | G4: ='METAL RAW DATA'!B3 -> ICP- MS 金屬 R-R測試
D5: 1 | E5: 2 | F5: 3 | G5: 4 | H5: 5 | I5: 6 | J5: 7 | K5: 8 | L5: 9 | M5: 10 | O5: AVE
B6: A | D6: ='METAL RAW DATA'!C11 -> 0 | E6: ='METAL RAW DATA'!D11 -> 0 | F6: ='METAL RAW DATA'!E11 -> 0 | G6: ='METAL RAW DATA'!F11 -> 0 | H6: ='METAL RAW DATA'!G11 -> 0 | I6: ='METAL RAW DATA'!H11 -> 0 | J6: ='METAL RAW DATA'!I11 -> 0 | K6: ='METAL RAW DATA'!J11 -> 0 | ... M6: ='METAL RAW DATA'!L11 -> 0 | O6: =SUM(D6:M6)/10 -> 0
B7: A | D7: ='METAL RAW DATA'!M11 -> 0 | E7: ='METAL RAW DATA'!N11 -> 0 | F7: ='METAL RAW DATA'!O11 -> 0 | G7: ='METAL RAW DATA'!P11 -> 0 | H7: ='METAL RAW DATA'!Q11 -> 0 | I7: ='METAL RAW DATA'!R11 -> 0 | J7: ='METAL RAW DATA'!S11 -> 0 | K7: ='METAL RAW DATA'!T11 -> 0 | ... M7: ='METAL RAW DATA'!V11 -> 0 | O7: =SUM(D7:M7)/10 -> 0
B8: AVE | D8: =AVERAGE(D6:D7) -> 0 | E8: =AVERAGE(E6:E7) -> 0 | F8: =AVERAGE(F6:F7) -> 0 | G8: =AVERAGE(G6:G7) -> 0 | H8: =AVERAGE(H6:H7) -> 0 | I8: =AVERAGE(I6:I7) -> 0 | J8: =AVERAGE(J6:J7) -> 0 | K8: =AVERAGE(K6:K7) -> 0 | ... M8: =AVERAGE(M6:M7) -> 0 | N8: Xa | O8: =AVERAGE(O6:O7) -> 0
B9: RANGE | D9: =MAX(D6:D7)-MIN(D6:D7) -> 0 | E9: =MAX(E6:E7)-MIN(E6:E7) -> 0 | F9: =MAX(F6:F7)-MIN(F6:F7) -> 0 | G9: =MAX(G6:G7)-MIN(G6:G7) -> 0 | H9: =MAX(H6:H7)-MIN(H6:H7) -> 0 | I9: =MAX(I6:I7)-MIN(I6:I7) -> 0 | J9: =MAX(J6:J7)-MIN(J6:J7) -> 0 | K9: =MAX(K6:K7)-MIN(K6:K7) -> 0 | ... M9: =MAX(M6:M7)-MIN(M6:M7) -> 0 | N9: Ra | O9: =SUM(D9:M9)/10 -> 0
B10: B | D10: ='METAL RAW DATA'!W11 -> 0 | E10: ='METAL RAW DATA'!X11 -> 0 | F10: ='METAL RAW DATA'!Y11 -> 0 | G10: ='METAL RAW DATA'!Z11 -> 0 | H10: ='METAL RAW DATA'!AA11 -> 0 | I10: ='METAL RAW DATA'!AB11 -> 0 | J10: ='METAL RAW DATA'!AC11 -> 0 | K10: ='METAL RAW DATA'!AD11 -> 0 | ... M10: ='METAL RAW DATA'!AF11 -> 0 | O10: =SUM(D10:M10)/10 -> 0
B11: B | D11: ='METAL RAW DATA'!AG11 -> 0 | E11: ='METAL RAW DATA'!AH11 -> 0 | F11: ='METAL RAW DATA'!AI11 -> 0 | G11: ='METAL RAW DATA'!AJ11 -> 0 | H11: ='METAL RAW DATA'!AK11 -> 0 | I11: ='METAL RAW DATA'!AL11 -> 0 | J11: ='METAL RAW DATA'!AM11 -> 0 | K11: ='METAL RAW DATA'!AN11 -> 0 | ... M11: ='METAL RAW DATA'!AP11 -> 0 | O11: =SUM(D11:M11)/10 -> 0
B12: AVE | D12: =AVERAGE(D10:D11) -> 0 | E12: =AVERAGE(E10:E11) -> 0 | F12: =AVERAGE(F10:F11) -> 0 | G12: =AVERAGE(G10:G11) -> 0 | H12: =AVERAGE(H10:H11) -> 0 | I12: =AVERAGE(I10:I11) -> 0 | J12: =AVERAGE(J10:J11) -> 0 | K12: =AVERAGE(K10:K11) -> 0 | ... M12: =AVERAGE(M10:M11) -> 0 | N12: Xb | O12: =SUM(D12:M12)/10 -> 0
B13: RANGE | D13: =MAX(D10:D11)-MIN(D10:D11) -> 0 | E13: =MAX(E10:E11)-MIN(E10:E11) -> 0 | F13: =MAX(F10:F11)-MIN(F10:F11) -> 0 | G13: =MAX(G10:G11)-MIN(G10:G11) -> 0 | H13: =MAX(H10:H11)-MIN(H10:H11) -> 0 | I13: =MAX(I10:I11)-MIN(I10:I11) -> 0 | J13: =MAX(J10:J11)-MIN(J10:J11) -> 0 | K13: =MAX(K10:K11)-MIN(K10:K11) -> 0 | ... M13: =MAX(M10:M11)-MIN(M10:M11) -> 0 | N13: Rb | O13: =SUM(D13:M13)/10 -> 0
B14: PART | N14: X | O14: =(O12+O8)/2 -> 0
B15: AVE | C15: Xp | D15: =(D12+D8)/2 -> 0 | E15: =(E12+E8)/2 -> 0 | F15: =(F12+F8)/2 -> 0 | G15: =(G12+G8)/2 -> 0 | H15: =(H12+H8)/2 -> 0 | I15: =(I12+I8)/2 -> 0 | J15: =(J12+J8)/2 -> 0 | K15: =(K12+K8)/2 -> 0 | ... M15: =(M12+M8)/2 -> 0 | N15: Rp | O15: =MAX(A15:M15)-MIN(A15:M15) -> 0
B16: R=(Ra+Rb)/2 | N16: R | O16: =(O13+O9)/2 -> 0
B17: Max X-MaxB=X diff | N17: X diff | O17: =MAX(O8,O12)-MIN(O8,O12) -> 0
B19: R*D4=UCLR | O19: =O16*3.27 -> 0
B20: R*D3=LCLR | O20: =O16*0 -> 0
B22: Gage Repeatability and Reproducibility Report
E23: =G4 -> ICP- MS 金屬 R-R測試 | I23: Gage Nane | K23: ASSAY R&R | N23: Date: | O23: ='METAL RAW DATA'!E2 -> 0
B24: Part No.and Name | I24: Gage No | N24: performed by
B25: Characteristics: | I25: Gage Type: | K25: METAL
B26: Specification:
E27: R= | F27: =O16 -> 0 | G27: x diff= | H27: =O17 -> 0 | I27: Rp= | K27: =O15 -> 0
B28: From date sheet: | I28: %Total Variation(TV)
E29: n= | F29: 2 | G29: test= | H29: 10
B30: Measurement Unit Analysis
B31: Repeatability-Equipment Variation(EV) | D31: EV = | E31: R × K1 | G31: Trials | H31: K1 | I31: %EV=100(EV/TV)
D32: =F27 -> 0 | E32: * | F32: =H32 -> 0.8862 | G32: 2 | H32: 0.8862 | I32: =100*(D33/D51) -> #DIV/0! | K32: %
B33: = | D33: =D32*F32 -> 0 | G33: 3 | H33: 0.5908
B34: 重複性-設備變異
B35: Reproducibity-Appraiser Variation(AV) | D35: AV= | E35: √【（Xdiff X K2）2-（EV2/nr）】 | I35: %AV=100(AV/TV)
I36: =100*(E37/D51) -> #DIV/0! | K36: %
D37: = | E37: =D59 -> 0
F38: Appraisers | G38: 2 | H38: 3 | I38: n=number of parts
F39: k2 | G39: 0.7071 | H39: 0.5231 | I39: r=number of trials
B40: 再現性-評價者變異
B41: Repeatability& Reproducibility(R&R) | D41: R&R= | E41: √(EV2+AV2 | I41: %R&R=100(R&R/TV)
D42: = | I42: =100*(E43/D51) -> #DIV/0! | K42: %
B43: 重複性及再現性 | D43: = | E43: =D63 -> 0 | I43: =100*(E43/F67) -> 0 | K43: %
...

Sheet AL
F1: ='METAL RAW DATA'!B3 -> ICP- MS 金屬 R-R測試
B3: ITEM | C3: ='METAL RAW DATA'!B10 -> Al | F3: DATE | G3: ='METAL RAW DATA'!E2 -> 0 | L3: NDC= | M3: =1.41*(D47/D63) -> #DIV/0!
F4: 儀 器 | G4: ='METAL RAW DATA'!B3 -> ICP- MS 金屬 R-R測試
D5: 1 | E5: 2 | F5: 3 | G5: 4 | H5: 5 | I5: 6 | J5: 7 | K5: 8 | L5: 9 | M5: 10 | O5: AVE
B6: A | D6: ='METAL RAW DATA'!C10 -> 0 | E6: ='METAL RAW DATA'!D10 -> 0 | F6: ='METAL RAW DATA'!E10 -> 0 | G6: ='METAL RAW DATA'!F10 -> 0 | H6: ='METAL RAW DATA'!G10 -> 0 | I6: ='METAL RAW DATA'!H10 -> 0 | J6: ='METAL RAW DATA'!I10 -> 0 | K6: ='METAL RAW DATA'!J10 -> 0 | ... M6: ='METAL RAW DATA'!L10 -> 0 | O6: =SUM(D6:M6)/10 -> 0
B7: A | D7: ='METAL RAW DATA'!M10 -> 0 | E7: ='METAL RAW DATA'!N10 -> 0 | F7: ='METAL RAW DATA'!O10 -> 0 | G7: ='METAL RAW DATA'!P10 -> 0 | H7: ='METAL RAW DATA'!Q10 -> 0 | I7: ='METAL RAW DATA'!R10 -> 0 | J7: ='METAL RAW DATA'!S10 -> 0 | K7: ='METAL RAW DATA'!T10 -> 0 | ... M7: ='METAL RAW DATA'!V10 -> 0 | O7: =SUM(D7:M7)/10 -> 0
B8: AVE | D8: =AVERAGE(D6:D7) -> 0 | E8: =AVERAGE(E6:E7) -> 0 | F8: =AVERAGE(F6:F7) -> 0 | G8: =AVERAGE(G6:G7) -> 0 | H8: =AVERAGE(H6:H7) -> 0 | I8: =AVERAGE(I6:I7) -> 0 | J8: =AVERAGE(J6:J7) -> 0 | K8: =AVERAGE(K6:K7) -> 0 | ... M8: =AVERAGE(M6:M7) -> 0 | N8: Xa | O8: =AVERAGE(O6:O7) -> 0
B9: RANGE | D9: =MAX(D6:D7)-MIN(D6:D7) -> 0 | E9: =MAX(E6:E7)-MIN(E6:E7) -> 0 | F9: =MAX(F6:F7)-MIN(F6:F7) -> 0 | G9: =MAX(G6:G7)-MIN(G6:G7) -> 0 | H9: =MAX(H6:H7)-MIN(H6:H7) -> 0 | I9: =MAX(I6:I7)-MIN(I6:I7) -> 0 | J9: =MAX(J6:J7)-MIN(J6:J7) -> 0 | K9: =MAX(K6:K7)-MIN(K6:K7) -> 0 | ... M9: =MAX(M6:M7)-MIN(M6:M7) -> 0 | N9: Ra | O9: =SUM(D9:M9)/10 -> 0
B10: B | D10: ='METAL RAW DATA'!W10 -> 0 | E10: ='METAL RAW DATA'!X10 -> 0 | F10: ='METAL RAW DATA'!Y10 -> 0 | G10: ='METAL RAW DATA'!Z10 -> 0 | H10: ='METAL RAW DATA'!AA10 -> 0 | I10: ='METAL RAW DATA'!AB10 -> 0 | J10: ='METAL RAW DATA'!AC10 -> 0 | K10: ='METAL RAW DATA'!AD10 -> 0 | ... M10: ='METAL RAW DATA'!AF10 -> 0 | O10: =SUM(D10:M10)/10 -> 0
B11: B | D11: ='METAL RAW DATA'!AG10 -> 0 | E11: ='METAL RAW DATA'!AH10 -> 0 | F11: ='METAL RAW DATA'!AI10 -> 0 | G11: ='METAL RAW DATA'!AJ10 -> 0 | H11: ='METAL RAW DATA'!AK10 -> 0 | I11: ='METAL RAW DATA'!AL10 -> 0 | J11: ='METAL RAW DATA'!AM10 -> 0 | K11: ='METAL RAW DATA'!AN10 -> 0 | ... M11: ='METAL RAW DATA'!AP10 -> 0 | O11: =SUM(D11:M11)/10 -> 0
B12: AVE | D12: =AVERAGE(D10:D11) -> 0 | E12: =AVERAGE(E10:E11) -> 0 | F12: =AVERAGE(F10:F11) -> 0 | G12: =AVERAGE(G10:G11) -> 0 | H12: =AVERAGE(H10:H11) -> 0 | I12: =AVERAGE(I10:I11) -> 0 | J12: =AVERAGE(J10:J11) -> 0 | K12: =AVERAGE(K10:K11) -> 0 | ... M12: =AVERAGE(M10:M11) -> 0 | N12: Xb | O12: =SUM(D12:M12)/10 -> 0
B13: RANGE | D13: =MAX(D10:D11)-MIN(D10:D11) -> 0 | E13: =MAX(E10:E11)-MIN(E10:E11) -> 0 | F13: =MAX(F10:F11)-MIN(F10:F11) -> 0 | G13: =MAX(G10:G11)-MIN(G10:G11) -> 0 | H13: =MAX(H10:H11)-MIN(H10:H11) -> 0 | I13: =MAX(I10:I11)-MIN(I10:I11) -> 0 | J13: =MAX(J10:J11)-MIN(J10:J11) -> 0 | K13: =MAX(K10:K11)-MIN(K10:K11) -> 0 | ... M13: =MAX(M10:M11)-MIN(M10:M11) -> 0 | N13: Rb | O13: =SUM(D13:M13)/10 -> 0
B14: PART | N14: X | O14: =(O12+O8)/2 -> 0
B15: AVE | C15: Xp | D15: =(D12+D8)/2 -> 0 | E15: =(E12+E8)/2 -> 0 | F15: =(F12+F8)/2 -> 0 | G15: =(G12+G8)/2 -> 0 | H15: =(H12+H8)/2 -> 0 | I15: =(I12+I8)/2 -> 0 | J15: =(J12+J8)/2 -> 0 | K15: =(K12+K8)/2 -> 0 | ... M15: =(M12+M8)/2 -> 0 | N15: Rp | O15: =MAX(A15:M15)-MIN(A15:M15) -> 0
B16: R=(Ra+Rb)/2 | N16: R | O16: =(O13+O9)/2 -> 0
B17: Max X-MaxB=X diff | N17: X diff | O17: =MAX(O8,O12)-MIN(O8,O12) -> 0
B19: R*D4=UCLR | O19: =O16*3.27 -> 0
B20: R*D3=LCLR | O20: =O16*0 -> 0
B22: Gage Repeatability and Reproducibility Report
E23: =G4 -> ICP- MS 金屬 R-R測試 | I23: Gage Nane | K23: ASSAY R&R | N23: Date: | O23: ='METAL RAW DATA'!E2 -> 0
B24: Part No.and Name | I24: Gage No | N24: performed by
B25: Characteristics: | I25: Gage Type: | K25: METAL
B26: Specification:
E27: R= | F27: =O16 -> 0 | G27: x diff= | H27: =O17 -> 0 | I27: Rp= | K27: =O15 -> 0
B28: From date sheet: | I28: %Total Variation(TV)
E29: n= | F29: 2 | G29: test= | H29: 10
B30: Measurement Unit Analysis
B31: Repeatability-Equipment Variation(EV) | D31: EV = | E31: R × K1 | G31: Trials | H31: K1 | I31: %EV=100(EV/TV)
D32: =F27 -> 0 | E32: * | F32: =H32 -> 0.8862 | G32: 2 | H32: 0.8862 | I32: =100*(D33/D51) -> #DIV/0! | K32: %
B33: = | D33: =D32*F32 -> 0 | G33: 3 | H33: 0.5908
B34: 重複性-設備變異
B35: Reproducibity-Appraiser Variation(AV) | D35: AV= | E35: √【（Xdiff X K2）2-（EV2/nr）】 | I35: %AV=100(AV/TV)
I36: =100*(E37/D51) -> #DIV/0! | K36: %
D37: = | E37: =D59 -> 0
F38: Appraisers | G38: 2 | H38: 3 | I38: n=number of parts
F39: k2 | G39: 0.7071 | H39: 0.5231 | I39: r=number of trials
B40: 再現性-評價者變異
B41: Repeatability& Reproducibility(R&R) | D41: R&R= | E41: √(EV2+AV2 | I41: %R&R=100(R&R/TV)
D42: = | I42: =100*(E43/D51) -> #DIV/0! | K42: %
B43: 重複性及再現性 | D43: = | E43: =D63 -> 0 | I43: =100*(E43/F67) -> 0 | K43: %
...

Sheet Ca
F1: ='METAL RAW DATA'!B3 -> ICP- MS 金屬 R-R測試
B3: ITEM | C3: ='METAL RAW DATA'!B12 -> Ca | F3: DATE | G3: ='METAL RAW DATA'!E2 -> 0 | L3: NDC= | M3: =1.41*(D47/D63) -> #DIV/0!
F4: 儀 器 | G4: ='METAL RAW DATA'!B3 -> ICP- MS 金屬 R-R測試
D5: 1 | E5: 2 | F5: 3 | G5: 4 | H5: 5 | I5: 6 | J5: 7 | K5: 8 | L5: 9 | M5: 10 | O5: AVE
B6: A | D6: ='METAL RAW DATA'!C12 -> 0 | E6: ='METAL RAW DATA'!D12 -> 0 | F6: ='METAL RAW DATA'!E12 -> 0 | G6: ='METAL RAW DATA'!F12 -> 0 | H6: ='METAL RAW DATA'!G12 -> 0 | I6: ='METAL RAW DATA'!H12 -> 0 | J6: ='METAL RAW DATA'!I12 -> 0 | K6: ='METAL RAW DATA'!J12 -> 0 | ... M6: ='METAL RAW DATA'!L12 -> 0 | O6: =SUM(D6:M6)/10 -> 0
B7: A | D7: ='METAL RAW DATA'!M12 -> 0 | E7: ='METAL RAW DATA'!N12 -> 0 | F7: ='METAL RAW DATA'!O12 -> 0 | G7: ='METAL RAW DATA'!P12 -> 0 | H7: ='METAL RAW DATA'!Q12 -> 0 | I7: ='METAL RAW DATA'!R12 -> 0 | J7: ='METAL RAW DATA'!S12 -> 0 | K7: ='METAL RAW DATA'!T12 -> 0 | ... M7: ='METAL RAW DATA'!V12 -> 0 | O7: =SUM(D7:M7)/10 -> 0
B8: AVE | D8: =AVERAGE(D6:D7) -> 0 | E8: =AVERAGE(E6:E7) -> 0 | F8: =AVERAGE(F6:F7) -> 0 | G8: =AVERAGE(G6:G7) -> 0 | H8: =AVERAGE(H6:H7) -> 0 | I8: =AVERAGE(I6:I7) -> 0 | J8: =AVERAGE(J6:J7) -> 0 | K8: =AVERAGE(K6:K7) -> 0 | ... M8: =AVERAGE(M6:M7) -> 0 | N8: Xa | O8: =AVERAGE(O6:O7) -> 0
B9: RANGE | D9: =MAX(D6:D7)-MIN(D6:D7) -> 0 | E9: =MAX(E6:E7)-MIN(E6:E7) -> 0 | F9: =MAX(F6:F7)-MIN(F6:F7) -> 0 | G9: =MAX(G6:G7)-MIN(G6:G7) -> 0 | H9: =MAX(H6:H7)-MIN(H6:H7) -> 0 | I9: =MAX(I6:I7)-MIN(I6:I7) -> 0 | J9: =MAX(J6:J7)-MIN(J6:J7) -> 0 | K9: =MAX(K6:K7)-MIN(K6:K7) -> 0 | ... M9: =MAX(M6:M7)-MIN(M6:M7) -> 0 | N9: Ra | O9: =SUM(D9:M9)/10 -> 0
B10: B | D10: ='METAL RAW DATA'!W12 -> 0 | E10: ='METAL RAW DATA'!X12 -> 0 | F10: ='METAL RAW DATA'!Y12 -> 0 | G10: ='METAL RAW DATA'!Z12 -> 0 | H10: ='METAL RAW DATA'!AA12 -> 0 | I10: ='METAL RAW DATA'!AB12 -> 0 | J10: ='METAL RAW DATA'!AC12 -> 0 | K10: ='METAL RAW DATA'!AD12 -> 0 | ... M10: ='METAL RAW DATA'!AF12 -> 0 | O10: =SUM(D10:M10)/10 -> 0
B11: B | D11: ='METAL RAW DATA'!AG12 -> 0 | E11: ='METAL RAW DATA'!AH12 -> 0 | F11: ='METAL RAW DATA'!AI12 -> 0 | G11: ='METAL RAW DATA'!AJ12 -> 0 | H11: ='METAL RAW DATA'!AK12 -> 0 | I11: ='METAL RAW DATA'!AL12 -> 0 | J11: ='METAL RAW DATA'!AM12 -> 0 | K11: ='METAL RAW DATA'!AN12 -> 0 | ... M11: ='METAL RAW DATA'!AP12 -> 0 | O11: =SUM(D11:M11)/10 -> 0
B12: AVE | D12: =AVERAGE(D10:D11) -> 0 | E12: =AVERAGE(E10:E11) -> 0 | F12: =AVERAGE(F10:F11) -> 0 | G12: =AVERAGE(G10:G11) -> 0 | H12: =AVERAGE(H10:H11) -> 0 | I12: =AVERAGE(I10:I11) -> 0 | J12: =AVERAGE(J10:J11) -> 0 | K12: =AVERAGE(K10:K11) -> 0 | ... M12: =AVERAGE(M10:M11) -> 0 | N12: Xb | O12: =SUM(D12:M12)/10 -> 0
B13: RANGE | D13: =MAX(D10:D11)-MIN(D10:D11) -> 0 | E13: =MAX(E10:E11)-MIN(E10:E11) -> 0 | F13: =MAX(F10:F11)-MIN(F10:F11) -> 0 | G13: =MAX(G10:G11)-MIN(G10:G11) -> 0 | H13: =MAX(H10:H11)-MIN(H10:H11) -> 0 | I13: =MAX(I10:I11)-MIN(I10:I11) -> 0 | J13: =MAX(J10:J11)-MIN(J10:J11) -> 0 | K13: =MAX(K10:K11)-MIN(K10:K11) -> 0 | ... M13: =MAX(M10:M11)-MIN(M10:M11) -> 0 | N13: Rb | O13: =SUM(D13:K13)/10 -> 0
B14: PART | N14: X | O14: =(O12+O8)/2 -> 0
B15: AVE | C15: Xp | D15: =(D12+D8)/2 -> 0 | E15: =(E12+E8)/2 -> 0 | F15: =(F12+F8)/2 -> 0 | G15: =(G12+G8)/2 -> 0 | H15: =(H12+H8)/2 -> 0 | I15: =(I12+I8)/2 -> 0 | J15: =(J12+J8)/2 -> 0 | K15: =(K12+K8)/2 -> 0 | ... M15: =(M12+M8)/2 -> 0 | N15: Rp | O15: =MAX(A15:M15)-MIN(A15:M15) -> 0
B16: R=(Ra+Rb)/2 | N16: R | O16: =(O13+O9)/2 -> 0
B17: Max X-MaxB=X diff | N17: X diff | O17: =MAX(O8,O12)-MIN(O8,O12) -> 0
B19: R*D4=UCLR | O19: =O16*3.27 -> 0
B20: R*D3=LCLR | O20: =O16*0 -> 0
B22: Gage Repeatability and Reproducibility Report
E23: =G4 -> ICP- MS 金屬 R-R測試 | I23: Gage Nane | K23: ASSAY R&R | N23: Date: | O23: ='METAL RAW DATA'!E2 -> 0
B24: Part No.and Name | I24: Gage No | N24: performed by
B25: Characteristics: | I25: Gage Type: | K25: METAL
B26: Specification:
E27: R= | F27: =O16 -> 0 | G27: x diff= | H27: =O17 -> 0 | I27: Rp= | K27: =O15 -> 0
B28: From date sheet: | I28: %Total Variation(TV)
E29: n= | F29: 2 | G29: test= | H29: 10
B30: Measurement Unit Analysis
B31: Repeatability-Equipment Variation(EV) | D31: EV = | E31: R × K1 | G31: Trials | H31: K1 | I31: %EV=100(EV/TV)
D32: =F27 -> 0 | E32: * | F32: =H32 -> 0.8862 | G32: 2 | H32: 0.8862 | I32: =100*(D33/D51) -> #DIV/0! | K32: %
B33: = | D33: =D32*F32 -> 0 | G33: 3 | H33: 0.5908
B34: 重複性-設備變異
B35: Reproducibity-Appraiser Variation(AV) | D35: AV= | E35: √【（Xdiff X K2）2-（EV2/nr）】 | I35: %AV=100(AV/TV)
I36: =100*(E37/D51) -> #DIV/0! | K36: %
D37: = | E37: =D59 -> 0
F38: Appraisers | G38: 2 | H38: 3 | I38: n=number of parts
F39: k2 | G39: 0.7071 | H39: 0.5231 | I39: r=number of trials
B40: 再現性-評價者變異
B41: Repeatability& Reproducibility(R&R) | D41: R&R= | E41: √(EV2+AV2 | I41: %R&R=100(R&R/TV)
D42: = | I42: =100*(E43/D51) -> #DIV/0! | K42: %
B43: 重複性及再現性 | D43: = | E43: =D63 -> 0 | I43: =100*(E43/F67) -> 0 | K43: %
...

Sheet Cr
F1: ='METAL RAW DATA'!B3 -> ICP- MS 金屬 R-R測試
B3: ITEM | C3: ='METAL RAW DATA'!B13 -> Cr | F3: DATE | G3: ='METAL RAW DATA'!E2 -> 0 | L3: NDC= | M3: =1.41*(D47/D63) -> #DIV/0!
F4: 儀 器 | G4: ='METAL RAW DATA'!B3 -> ICP- MS 金屬 R-R測試
D5: 1 | E5: 2 | F5: 3 | G5: 4 | H5: 5 | I5: 6 | J5: 7 | K5: 8 | L5: 9 | M5: 10 | O5: AVE
B6: A | D6: ='METAL RAW DATA'!C13 -> 0 | E6: ='METAL RAW DATA'!D13 -> 0 | F6: ='METAL RAW DATA'!E13 -> 0 | G6: ='METAL RAW DATA'!F13 -> 0 | H6: ='METAL RAW DATA'!G13 -> 0 | I6: ='METAL RAW DATA'!H13 -> 0 | J6: ='METAL RAW DATA'!I13 -> 0 | K6: ='METAL RAW DATA'!J13 -> 0 | ... M6: ='METAL RAW DATA'!L13 -> 0 | O6: =SUM(D6:M6)/10 -> 0
B7: A | D7: ='METAL RAW DATA'!M13 -> 0 | E7: ='METAL RAW DATA'!N13 -> 0 | F7: ='METAL RAW DATA'!O13 -> 0 | G7: ='METAL RAW DATA'!P13 -> 0 | H7: ='METAL RAW DATA'!Q13 -> 0 | I7: ='METAL RAW DATA'!R13 -> 0 | J7: ='METAL RAW DATA'!S13 -> 0 | K7: ='METAL RAW DATA'!T13 -> 0 | ... M7: ='METAL RAW DATA'!V13 -> 0 | O7: =SUM(D7:M7)/10 -> 0
B8: AVE | D8: =AVERAGE(D6:D7) -> 0 | E8: =AVERAGE(E6:E7) -> 0 | F8: =AVERAGE(F6:F7) -> 0 | G8: =AVERAGE(G6:G7) -> 0 | H8: =AVERAGE(H6:H7) -> 0 | I8: =AVERAGE(I6:I7) -> 0 | J8: =AVERAGE(J6:J7) -> 0 | K8: =AVERAGE(K6:K7) -> 0 | ... M8: =AVERAGE(M6:M7) -> 0 | N8: Xa | O8: =AVERAGE(O6:O7) -> 0
B9: RANGE | D9: =MAX(D6:D7)-MIN(D6:D7) -> 0 | E9: =MAX(E6:E7)-MIN(E6:E7) -> 0 | F9: =MAX(F6:F7)-MIN(F6:F7) -> 0 | G9: =MAX(G6:G7)-MIN(G6:G7) -> 0 | H9: =MAX(H6:H7)-MIN(H6:H7) -> 0 | I9: =MAX(I6:I7)-MIN(I6:I7) -> 0 | J9: =MAX(J6:J7)-MIN(J6:J7) -> 0 | K9: =MAX(K6:K7)-MIN(K6:K7) -> 0 | ... M9: =MAX(M6:M7)-MIN(M6:M7) -> 0 | N9: Ra | O9: =SUM(D9:M9)/10 -> 0
B10: B | D10: ='METAL RAW DATA'!W13 -> 0 | E10: ='METAL RAW DATA'!X13 -> 0 | F10: ='METAL RAW DATA'!Y13 -> 0 | G10: ='METAL RAW DATA'!Z13 -> 0 | H10: ='METAL RAW DATA'!AA13 -> 0 | I10: ='METAL RAW DATA'!AB13 -> 0 | J10: ='METAL RAW DATA'!AC13 -> 0 | K10: ='METAL RAW DATA'!AD13 -> 0 | ... M10: ='METAL RAW DATA'!AF13 -> 0 | O10: =SUM(D10:M10)/10 -> 0
B11: B | D11: ='METAL RAW DATA'!AG13 -> 0 | E11: ='METAL RAW DATA'!AH13 -> 0 | F11: ='METAL RAW DATA'!AI13 -> 0 | G11: ='METAL RAW DATA'!AJ13 -> 0 | H11: ='METAL RAW DATA'!AK13 -> 0 | I11: ='METAL RAW DATA'!AL13 -> 0 | J11: ='METAL RAW DATA'!AM13 -> 0 | K11: ='METAL RAW DATA'!AN13 -> 0 | ... M11: ='METAL RAW DATA'!AP13 -> 0 | O11: =SUM(D11:M11)/10 -> 0
B12: AVE | D12: =AVERAGE(D10:D11) -> 0 | E12: =AVERAGE(E10:E11) -> 0 | F12: =AVERAGE(F10:F11) -> 0 | G12: =AVERAGE(G10:G11) -> 0 | H12: =AVERAGE(H10:H11) -> 0 | I12: =AVERAGE(I10:I11) -> 0 | J12: =AVERAGE(J10:J11) -> 0 | K12: =AVERAGE(K10:K11) -> 0 | ... M12: =AVERAGE(M10:M11) -> 0 | N12: Xb | O12: =SUM(D12:M12)/10 -> 0
B13: RANGE | D13: =MAX(D10:D11)-MIN(D10:D11) -> 0 | E13: =MAX(E10:E11)-MIN(E10:E11) -> 0 | F13: =MAX(F10:F11)-MIN(F10:F11) -> 0 | G13: =MAX(G10:G11)-MIN(G10:G11) -> 0 | H13: =MAX(H10:H11)-MIN(H10:H11) -> 0 | I13: =MAX(I10:I11)-MIN(I10:I11) -> 0 | J13: =MAX(J10:J11)-MIN(J10:J11) -> 0 | K13: =MAX(K10:K11)-MIN(K10:K11) -> 0 | ... M13: =MAX(M10:M11)-MIN(M10:M11) -> 0 | N13: Rb | O13: =SUM(D13:M13)/10 -> 0
B14: PART | N14: X | O14: =(O12+O8)/2 -> 0
B15: AVE | C15: Xp | D15: =(D12+D8)/2 -> 0 | E15: =(E12+E8)/2 -> 0 | F15: =(F12+F8)/2 -> 0 | G15: =(G12+G8)/2 -> 0 | H15: =(H12+H8)/2 -> 0 | I15: =(I12+I8)/2 -> 0 | J15: =(J12+J8)/2 -> 0 | K15: =(K12+K8)/2 -> 0 | ... M15: =(M12+M8)/2 -> 0 | N15: Rp | O15: =MAX(A15:M15)-MIN(A15:M15) -> 0
B16: R=(Ra+Rb)/2 | N16: R | O16: =(O13+O9)/2 -> 0
B17: Max X-MaxB=X diff | N17: X diff | O17: =MAX(O8,O12)-MIN(O8,O12) -> 0
B19: R*D4=UCLR | O19: =O16*3.27 -> 0
B20: R*D3=LCLR | O20: =O16*0 -> 0
B22: Gage Repeatability and Reproducibility Report
E23: =G4 -> ICP- MS 金屬 R-R測試 | I23: Gage Nane | K23: ASSAY R&R | N23: Date: | O23: ='METAL RAW DATA'!E2 -> 0
B24: Part No.and Name | I24: Gage No | N24: performed by
B25: Characteristics: | I25: Gage Type: | K25: METAL
B26: Specification:
E27: R= | F27: =O16 -> 0 | G27: x diff= | H27: =O17 -> 0 | I27: Rp= | K27: =O15 -> 0
B28: From date sheet: | I28: %Total Variation(TV)
E29: n= | F29: 2 | G29: test= | H29: 10
B30: Measurement Unit Analysis
B31: Repeatability-Equipment Variation(EV) | D31: EV = | E31: R × K1 | G31: Trials | H31: K1 | I31: %EV=100(EV/TV)
D32: =F27 -> 0 | E32: * | F32: =H32 -> 0.8862 | G32: 2 | H32: 0.8862 | I32: =100*(D33/D51) -> #DIV/0! | K32: %
B33: = | D33: =D32*F32 -> 0 | G33: 3 | H33: 0.5908
B34: 重複性-設備變異
B35: Reproducibity-Appraiser Variation(AV) | D35: AV= | E35: √【（Xdiff X K2）2-（EV2/nr）】 | I35: %AV=100(AV/TV)
I36: =100*(E37/D51) -> #DIV/0! | K36: %
D37: = | E37: =D59 -> 0
F38: Appraisers | G38: 2 | H38: 3 | I38: n=number of parts
F39: k2 | G39: 0.7071 | H39: 0.5231 | I39: r=number of trials
B40: 再現性-評價者變異
B41: Repeatability& Reproducibility(R&R) | D41: R&R= | E41: √(EV2+AV2 | I41: %R&R=100(R&R/TV)
D42: = | I42: =100*(E43/D51) -> #DIV/0! | K42: %
B43: 重複性及再現性 | D43: = | E43: =D63 -> 0 | I43: =100*(E43/F67) -> 0 | K43: %
...

Sheet Mn
F1: ='METAL RAW DATA'!B3 -> ICP- MS 金屬 R-R測試
B3: ITEM | C3: ='METAL RAW DATA'!B14 -> Mn | F3: DATE | G3: ='METAL RAW DATA'!E2 -> 0 | L3: NDC= | M3: =1.41*(D47/D63) -> #DIV/0!
F4: 儀 器 | G4: ='METAL RAW DATA'!B3 -> ICP- MS 金屬 R-R測試
D5: 1 | E5: 2 | F5: 3 | G5: 4 | H5: 5 | I5: 6 | J5: 7 | K5: 8 | L5: 9 | M5: 10 | O5: AVE
B6: A | D6: ='METAL RAW DATA'!C14 -> 0 | E6: ='METAL RAW DATA'!D14 -> 0 | F6: ='METAL RAW DATA'!E14 -> 0 | G6: ='METAL RAW DATA'!F14 -> 0 | H6: ='METAL RAW DATA'!G14 -> 0 | I6: ='METAL RAW DATA'!H14 -> 0 | J6: ='METAL RAW DATA'!I14 -> 0 | K6: ='METAL RAW DATA'!J14 -> 0 | ... M6: ='METAL RAW DATA'!L14 -> 0 | O6: =SUM(D6:M6)/10 -> 0
B7: A | D7: ='METAL RAW DATA'!M14 -> 0 | E7: ='METAL RAW DATA'!N14 -> 0 | F7: ='METAL RAW DATA'!O14 -> 0 | G7: ='METAL RAW DATA'!P14 -> 0 | H7: ='METAL RAW DATA'!Q14 -> 0 | I7: ='METAL RAW DATA'!R14 -> 0 | J7: ='METAL RAW DATA'!S14 -> 0 | K7: ='METAL RAW DATA'!T14 -> 0 | ... M7: ='METAL RAW DATA'!V14 -> 0 | O7: =SUM(D7:M7)/10 -> 0
B8: AVE | D8: =AVERAGE(D6:D7) -> 0 | E8: =AVERAGE(E6:E7) -> 0 | F8: =AVERAGE(F6:F7) -> 0 | G8: =AVERAGE(G6:G7) -> 0 | H8: =AVERAGE(H6:H7) -> 0 | I8: =AVERAGE(I6:I7) -> 0 | J8: =AVERAGE(J6:J7) -> 0 | K8: =AVERAGE(K6:K7) -> 0 | ... M8: =AVERAGE(M6:M7) -> 0 | N8: Xa | O8: =AVERAGE(O6:O7) -> 0
B9: RANGE | D9: =MAX(D6:D7)-MIN(D6:D7) -> 0 | E9: =MAX(E6:E7)-MIN(E6:E7) -> 0 | F9: =MAX(F6:F7)-MIN(F6:F7) -> 0 | G9: =MAX(G6:G7)-MIN(G6:G7) -> 0 | H9: =MAX(H6:H7)-MIN(H6:H7) -> 0 | I9: =MAX(I6:I7)-MIN(I6:I7) -> 0 | J9: =MAX(J6:J7)-MIN(J6:J7) -> 0 | K9: =MAX(K6:K7)-MIN(K6:K7) -> 0 | ... M9: =MAX(M6:M7)-MIN(M6:M7) -> 0 | N9: Ra | O9: =SUM(D9:M9)/10 -> 0
B10: B | D10: ='METAL RAW DATA'!W14 -> 0 | E10: ='METAL RAW DATA'!X14 -> 0 | F10: ='METAL RAW DATA'!Y14 -> 0 | G10: ='METAL RAW DATA'!Z14 -> 0 | H10: ='METAL RAW DATA'!AA14 -> 0 | I10: ='METAL RAW DATA'!AB14 -> 0 | J10: ='METAL RAW DATA'!AC14 -> 0 | K10: ='METAL RAW DATA'!AD14 -> 0 | ... M10: ='METAL RAW DATA'!AF14 -> 0 | O10: =SUM(D10:M10)/10 -> 0
B11: B | D11: ='METAL RAW DATA'!AG14 -> 0 | E11: ='METAL RAW DATA'!AH14 -> 0 | F11: ='METAL RAW DATA'!AI14 -> 0 | G11: ='METAL RAW DATA'!AJ14 -> 0 | H11: ='METAL RAW DATA'!AK14 -> 0 | I11: ='METAL RAW DATA'!AL14 -> 0 | J11: ='METAL RAW DATA'!AM14 -> 0 | K11: ='METAL RAW DATA'!AN14 -> 0 | ... M11: ='METAL RAW DATA'!AP14 -> 0 | O11: =SUM(D11:M11)/10 -> 0
B12: AVE | D12: =AVERAGE(D10:D11) -> 0 | E12: =AVERAGE(E10:E11) -> 0 | F12: =AVERAGE(F10:F11) -> 0 | G12: =AVERAGE(G10:G11) -> 0 | H12: =AVERAGE(H10:H11) -> 0 | I12: =AVERAGE(I10:I11) -> 0 | J12: =AVERAGE(J10:J11) -> 0 | K12: =AVERAGE(K10:K11) -> 0 | ... M12: =AVERAGE(M10:M11) -> 0 | N12: Xb | O12: =SUM(D12:M12)/10 -> 0
B13: RANGE | D13: =MAX(D10:D11)-MIN(D10:D11) -> 0 | E13: =MAX(E10:E11)-MIN(E10:E11) -> 0 | F13: =MAX(F10:F11)-MIN(F10:F11) -> 0 | G13: =MAX(G10:G11)-MIN(G10:G11) -> 0 | H13: =MAX(H10:H11)-MIN(H10:H11) -> 0 | I13: =MAX(I10:I11)-MIN(I10:I11) -> 0 | J13: =MAX(J10:J11)-MIN(J10:J11) -> 0 | K13: =MAX(K10:K11)-MIN(K10:K11) -> 0 | ... M13: =MAX(M10:M11)-MIN(M10:M11) -> 0 | N13: Rb | O13: =SUM(D13:M13)/10 -> 0
B14: PART | N14: X | O14: =(O12+O8)/2 -> 0
B15: AVE | C15: Xp | D15: =(D12+D8)/2 -> 0 | E15: =(E12+E8)/2 -> 0 | F15: =(F12+F8)/2 -> 0 | G15: =(G12+G8)/2 -> 0 | H15: =(H12+H8)/2 -> 0 | I15: =(I12+I8)/2 -> 0 | J15: =(J12+J8)/2 -> 0 | K15: =(K12+K8)/2 -> 0 | ... M15: =(M12+M8)/2 -> 0 | N15: Rp | O15: =MAX(A15:M15)-MIN(A15:M15) -> 0
B16: R=(Ra+Rb)/2 | N16: R | O16: =(O13+O9)/2 -> 0
B17: Max X-MaxB=X diff | N17: X diff | O17: =MAX(O8,O12)-MIN(O8,O12) -> 0
B19: R*D4=UCLR | O19: =O16*3.27 -> 0
B20: R*D3=LCLR | O20: =O16*0 -> 0
B22: Gage Repeatability and Reproducibility Report
E23: =G4 -> ICP- MS 金屬 R-R測試 | I23: Gage Nane | K23: ASSAY R&R | N23: Date: | O23: ='METAL RAW DATA'!E2 -> 0
B24: Part No.and Name | I24: Gage No | N24: performed by
B25: Characteristics: | I25: Gage Type: | K25: METAL
B26: Specification:
E27: R= | F27: =O16 -> 0 | G27: x diff= | H27: =O17 -> 0 | I27: Rp= | K27: =O15 -> 0
B28: From date sheet: | I28: %Total Variation(TV)
E29: n= | F29: 2 | G29: test= | H29: 10
B30: Measurement Unit Analysis
B31: Repeatability-Equipment Variation(EV) | D31: EV = | E31: R × K1 | G31: Trials | H31: K1 | I31: %EV=100(EV/TV)
D32: =F27 -> 0 | E32: * | F32: =H32 -> 0.8862 | G32: 2 | H32: 0.8862 | I32: =100*(D33/D51) -> #DIV/0! | K32: %
B33: = | D33: =D32*F32 -> 0 | G33: 3 | H33: 0.5908
B34: 重複性-設備變異
B35: Reproducibity-Appraiser Variation(AV) | D35: AV= | E35: √【（Xdiff X K2）2-（EV2/nr）】 | I35: %AV=100(AV/TV)
I36: =100*(E37/D51) -> #DIV/0! | K36: %
D37: = | E37: =D59 -> 0
F38: Appraisers | G38: 2 | H38: 3 | I38: n=number of parts
F39: k2 | G39: 0.7071 | H39: 0.5231 | I39: r=number of trials
B40: 再現性-評價者變異
B41: Repeatability& Reproducibility(R&R) | D41: R&R= | E41: √(EV2+AV2 | I41: %R&R=100(R&R/TV)
D42: = | I42: =100*(E43/D51) -> #DIV/0! | K42: %
B43: 重複性及再現性 | D43: = | E43: =D63 -> 0 | I43: =100*(E43/F67) -> 0 | K43: %
...

Sheet Fe
F1: ='METAL RAW DATA'!B3 -> ICP- MS 金屬 R-R測試
B3: ITEM | C3: ='METAL RAW DATA'!B15 -> Fe | F3: DATE | G3: ='METAL RAW DATA'!E2 -> 0 | L3: NDC= | M3: =1.41*(D47/D63) -> #DIV/0!
F4: 儀 器 | G4: ='METAL RAW DATA'!B3 -> ICP- MS 金屬 R-R測試
D5: 1 | E5: 2 | F5: 3 | G5: 4 | H5: 5 | I5: 6 | J5: 7 | K5: 8 | L5: 9 | M5: 10 | O5: AVE
B6: A | D6: ='METAL RAW DATA'!C15 -> 0 | E6: ='METAL RAW DATA'!D15 -> 0 | F6: ='METAL RAW DATA'!E15 -> 0 | G6: ='METAL RAW DATA'!F15 -> 0 | H6: ='METAL RAW DATA'!G15 -> 0 | I6: ='METAL RAW DATA'!H15 -> 0 | J6: ='METAL RAW DATA'!I15 -> 0 | K6: ='METAL RAW DATA'!J15 -> 0 | ... M6: ='METAL RAW DATA'!L15 -> 0 | O6: =SUM(D6:M6)/10 -> 0
B7: A | D7: ='METAL RAW DATA'!M15 -> 0 | E7: ='METAL RAW DATA'!N15 -> 0 | F7: ='METAL RAW DATA'!O15 -> 0 | G7: ='METAL RAW DATA'!P15 -> 0 | H7: ='METAL RAW DATA'!Q15 -> 0 | I7: ='METAL RAW DATA'!R15 -> 0 | J7: ='METAL RAW DATA'!S15 -> 0 | K7: ='METAL RAW DATA'!T15 -> 0 | ... M7: ='METAL RAW DATA'!V15 -> 0 | O7: =SUM(D7:M7)/10 -> 0
B8: AVE | D8: =AVERAGE(D6:D7) -> 0 | E8: =AVERAGE(E6:E7) -> 0 | F8: =AVERAGE(F6:F7) -> 0 | G8: =AVERAGE(G6:G7) -> 0 | H8: =AVERAGE(H6:H7) -> 0 | I8: =AVERAGE(I6:I7) -> 0 | J8: =AVERAGE(J6:J7) -> 0 | K8: =AVERAGE(K6:K7) -> 0 | ... M8: =AVERAGE(M6:M7) -> 0 | N8: Xa | O8: =AVERAGE(O6:O7) -> 0
B9: RANGE | D9: =MAX(D6:D7)-MIN(D6:D7) -> 0 | E9: =MAX(E6:E7)-MIN(E6:E7) -> 0 | F9: =MAX(F6:F7)-MIN(F6:F7) -> 0 | G9: =MAX(G6:G7)-MIN(G6:G7) -> 0 | H9: =MAX(H6:H7)-MIN(H6:H7) -> 0 | I9: =MAX(I6:I7)-MIN(I6:I7) -> 0 | J9: =MAX(J6:J7)-MIN(J6:J7) -> 0 | K9: =MAX(K6:K7)-MIN(K6:K7) -> 0 | ... M9: =MAX(M6:M7)-MIN(M6:M7) -> 0 | N9: Ra | O9: =SUM(D9:M9)/10 -> 0
B10: B | D10: ='METAL RAW DATA'!W15 -> 0 | E10: ='METAL RAW DATA'!X15 -> 0 | F10: ='METAL RAW DATA'!Y15 -> 0 | G10: ='METAL RAW DATA'!Z15 -> 0 | H10: ='METAL RAW DATA'!AA15 -> 0 | I10: ='METAL RAW DATA'!AB15 -> 0 | J10: ='METAL RAW DATA'!AC15 -> 0 | K10: ='METAL RAW DATA'!AD15 -> 0 | ... M10: ='METAL RAW DATA'!AF15 -> 0 | O10: =SUM(D10:M10)/10 -> 0
B11: B | D11: ='METAL RAW DATA'!AG15 -> 0 | E11: ='METAL RAW DATA'!AH15 -> 0 | F11: ='METAL RAW DATA'!AI15 -> 0 | G11: ='METAL RAW DATA'!AJ15 -> 0 | H11: ='METAL RAW DATA'!AK15 -> 0 | I11: ='METAL RAW DATA'!AL15 -> 0 | J11: ='METAL RAW DATA'!AM15 -> 0 | K11: ='METAL RAW DATA'!AN15 -> 0 | ... M11: ='METAL RAW DATA'!AP15 -> 0 | O11: =SUM(D11:M11)/10 -> 0
B12: AVE | D12: =AVERAGE(D10:D11) -> 0 | E12: =AVERAGE(E10:E11) -> 0 | F12: =AVERAGE(F10:F11) -> 0 | G12: =AVERAGE(G10:G11) -> 0 | H12: =AVERAGE(H10:H11) -> 0 | I12: =AVERAGE(I10:I11) -> 0 | J12: =AVERAGE(J10:J11) -> 0 | K12: =AVERAGE(K10:K11) -> 0 | ... M12: =AVERAGE(M10:M11) -> 0 | N12: Xb | O12: =SUM(D12:M12)/10 -> 0
B13: RANGE | D13: =MAX(D10:D11)-MIN(D10:D11) -> 0 | E13: =MAX(E10:E11)-MIN(E10:E11) -> 0 | F13: =MAX(F10:F11)-MIN(F10:F11) -> 0 | G13: =MAX(G10:G11)-MIN(G10:G11) -> 0 | H13: =MAX(H10:H11)-MIN(H10:H11) -> 0 | I13: =MAX(I10:I11)-MIN(I10:I11) -> 0 | J13: =MAX(J10:J11)-MIN(J10:J11) -> 0 | K13: =MAX(K10:K11)-MIN(K10:K11) -> 0 | ... M13: =MAX(M10:M11)-MIN(M10:M11) -> 0 | N13: Rb | O13: =SUM(D13:M13)/10 -> 0
B14: PART | N14: X | O14: =(O12+O8)/2 -> 0
B15: AVE | C15: Xp | D15: =(D12+D8)/2 -> 0 | E15: =(E12+E8)/2 -> 0 | F15: =(F12+F8)/2 -> 0 | G15: =(G12+G8)/2 -> 0 | H15: =(H12+H8)/2 -> 0 | I15: =(I12+I8)/2 -> 0 | J15: =(J12+J8)/2 -> 0 | K15: =(K12+K8)/2 -> 0 | ... M15: =(M12+M8)/2 -> 0 | N15: Rp | O15: =MAX(D15:M15)-MIN(D15:M15) -> 0
B16: R=(Ra+Rb)/2 | N16: R | O16: =(O13+O9)/2 -> 0
B17: Max X-MaxB=X diff | N17: X diff | O17: =MAX(O8,O12)-MIN(O8,O12) -> 0
B19: R*D4=UCLR | O19: =O16*3.27 -> 0
B20: R*D3=LCLR | O20: =O16*0 -> 0
B22: Gage Repeatability and Reproducibility Report
E23: =G4 -> ICP- MS 金屬 R-R測試 | I23: Gage Nane | K23: ASSAY R&R | N23: Date: | O23: ='METAL RAW DATA'!E2 -> 0
B24: Part No.and Name | I24: Gage No | N24: performed by
B25: Characteristics: | I25: Gage Type: | K25: METAL
B26: Specification:
E27: R= | F27: =O16 -> 0 | G27: x diff= | H27: =O17 -> 0 | I27: Rp= | K27: =O15 -> 0
B28: From date sheet: | I28: %Total Variation(TV)
E29: n= | F29: 2 | G29: test= | H29: 10
B30: Measurement Unit Analysis
B31: Repeatability-Equipment Variation(EV) | D31: EV = | E31: R × K1 | G31: Trials | H31: K1 | I31: %EV=100(EV/TV)
D32: =F27 -> 0 | E32: * | F32: =H32 -> 0.8862 | G32: 2 | H32: 0.8862 | I32: =100*(D33/D51) -> #DIV/0! | K32: %
B33: = | D33: =D32*F32 -> 0 | G33: 3 | H33: 0.5908
B34: 重複性-設備變異
B35: Reproducibity-Appraiser Variation(AV) | D35: AV= | E35: √【（Xdiff X K2）2-（EV2/nr）】 | I35: %AV=100(AV/TV)
I36: =100*(E37/D51) -> #DIV/0! | K36: %
D37: = | E37: =D59 -> 0
F38: Appraisers | G38: 2 | H38: 3 | I38: n=number of parts
F39: k2 | G39: 0.7071 | H39: 0.5231 | I39: r=number of trials
B40: 再現性-評價者變異
B41: Repeatability& Reproducibility(R&R) | D41: R&R= | E41: √(EV2+AV2 | I41: %R&R=100(R&R/TV)
D42: = | I42: =100*(E43/D51) -> #DIV/0! | K42: %
B43: 重複性及再現性 | D43: = | E43: =D63 -> 0 | I43: =100*(E43/F67) -> 0 | K43: %
...

Sheet Ni
F1: ='METAL RAW DATA'!B3 -> ICP- MS 金屬 R-R測試
B3: ITEM | C3: ='METAL RAW DATA'!B16 -> Ni | F3: DATE | G3: ='METAL RAW DATA'!E2 -> 0 | L3: NDC= | M3: =1.41*(D47/D63) -> #DIV/0!
F4: 儀 器 | G4: ='METAL RAW DATA'!B3 -> ICP- MS 金屬 R-R測試
D5: 1 | E5: 2 | F5: 3 | G5: 4 | H5: 5 | I5: 6 | J5: 7 | K5: 8 | L5: 9 | M5: 10 | O5: AVE
B6: A | D6: ='METAL RAW DATA'!C16 -> 0 | E6: ='METAL RAW DATA'!D16 -> 0 | F6: ='METAL RAW DATA'!E16 -> 0 | G6: ='METAL RAW DATA'!F16 -> 0 | H6: ='METAL RAW DATA'!G16 -> 0 | I6: ='METAL RAW DATA'!H16 -> 0 | J6: ='METAL RAW DATA'!I16 -> 0 | K6: ='METAL RAW DATA'!J16 -> 0 | ... M6: ='METAL RAW DATA'!L16 -> 0 | O6: =SUM(D6:M6)/10 -> 0
B7: A | D7: ='METAL RAW DATA'!M16 -> 0 | E7: ='METAL RAW DATA'!N16 -> 0 | F7: ='METAL RAW DATA'!O16 -> 0 | G7: ='METAL RAW DATA'!P16 -> 0 | H7: ='METAL RAW DATA'!Q16 -> 0 | I7: ='METAL RAW DATA'!R16 -> 0 | J7: ='METAL RAW DATA'!S16 -> 0 | K7: ='METAL RAW DATA'!T16 -> 0 | ... M7: ='METAL RAW DATA'!V16 -> 0 | O7: =SUM(D7:M7)/10 -> 0
B8: AVE | D8: =AVERAGE(D6:D7) -> 0 | E8: =AVERAGE(E6:E7) -> 0 | F8: =AVERAGE(F6:F7) -> 0 | G8: =AVERAGE(G6:G7) -> 0 | H8: =AVERAGE(H6:H7) -> 0 | I8: =AVERAGE(I6:I7) -> 0 | J8: =AVERAGE(J6:J7) -> 0 | K8: =AVERAGE(K6:K7) -> 0 | ... M8: =AVERAGE(M6:M7) -> 0 | N8: Xa | O8: =AVERAGE(O6:O7) -> 0
B9: RANGE | D9: =MAX(D6:D7)-MIN(D6:D7) -> 0 | E9: =MAX(E6:E7)-MIN(E6:E7) -> 0 | F9: =MAX(F6:F7)-MIN(F6:F7) -> 0 | G9: =MAX(G6:G7)-MIN(G6:G7) -> 0 | H9: =MAX(H6:H7)-MIN(H6:H7) -> 0 | I9: =MAX(I6:I7)-MIN(I6:I7) -> 0 | J9: =MAX(J6:J7)-MIN(J6:J7) -> 0 | K9: =MAX(K6:K7)-MIN(K6:K7) -> 0 | ... M9: =MAX(M6:M7)-MIN(M6:M7) -> 0 | N9: Ra | O9: =SUM(D9:M9)/10 -> 0
B10: B | D10: ='METAL RAW DATA'!W16 -> 0 | E10: ='METAL RAW DATA'!X16 -> 0 | F10: ='METAL RAW DATA'!Y16 -> 0 | G10: ='METAL RAW DATA'!Z16 -> 0 | H10: ='METAL RAW DATA'!AA16 -> 0 | I10: ='METAL RAW DATA'!AB16 -> 0 | J10: ='METAL RAW DATA'!AC16 -> 0 | K10: ='METAL RAW DATA'!AD16 -> 0 | ... M10: ='METAL RAW DATA'!AF16 -> 0 | O10: =SUM(D10:M10)/10 -> 0
B11: B | D11: ='METAL RAW DATA'!AG16 -> 0 | E11: ='METAL RAW DATA'!AH16 -> 0 | F11: ='METAL RAW DATA'!AI16 -> 0 | G11: ='METAL RAW DATA'!AJ16 -> 0 | H11: ='METAL RAW DATA'!AK16 -> 0 | I11: ='METAL RAW DATA'!AL16 -> 0 | J11: ='METAL RAW DATA'!AM16 -> 0 | K11: ='METAL RAW DATA'!AN16 -> 0 | ... M11: ='METAL RAW DATA'!AP16 -> 0 | O11: =SUM(D11:M11)/10 -> 0
B12: AVE | D12: =AVERAGE(D10:D11) -> 0 | E12: =AVERAGE(E10:E11) -> 0 | F12: =AVERAGE(F10:F11) -> 0 | G12: =AVERAGE(G10:G11) -> 0 | H12: =AVERAGE(H10:H11) -> 0 | I12: =AVERAGE(I10:I11) -> 0 | J12: =AVERAGE(J10:J11) -> 0 | K12: =AVERAGE(K10:K11) -> 0 | ... M12: =AVERAGE(M10:M11) -> 0 | N12: Xb | O12: =SUM(D12:M12)/10 -> 0
B13: RANGE | D13: =MAX(D10:D11)-MIN(D10:D11) -> 0 | E13: =MAX(E10:E11)-MIN(E10:E11) -> 0 | F13: =MAX(F10:F11)-MIN(F10:F11) -> 0 | G13: =MAX(G10:G11)-MIN(G10:G11) -> 0 | H13: =MAX(H10:H11)-MIN(H10:H11) -> 0 | I13: =MAX(I10:I11)-MIN(I10:I11) -> 0 | J13: =MAX(J10:J11)-MIN(J10:J11) -> 0 | K13: =MAX(K10:K11)-MIN(K10:K11) -> 0 | ... M13: =MAX(M10:M11)-MIN(M10:M11) -> 0 | N13: Rb | O13: =SUM(D13:M13)/10 -> 0
B14: PART | N14: X | O14: =(O12+O8)/2 -> 0
B15: AVE | C15: Xp | D15: =(D12+D8)/2 -> 0 | E15: =(E12+E8)/2 -> 0 | F15: =(F12+F8)/2 -> 0 | G15: =(G12+G8)/2 -> 0 | H15: =(H12+H8)/2 -> 0 | I15: =(I12+I8)/2 -> 0 | J15: =(J12+J8)/2 -> 0 | K15: =(K12+K8)/2 -> 0 | ... M15: =(M12+M8)/2 -> 0 | N15: Rp | O15: =MAX(A15:M15)-MIN(A15:M15) -> 0
B16: R=(Ra+Rb)/2 | N16: R | O16: =(O13+O9)/2 -> 0
B17: Max X-MaxB=X diff | N17: X diff | O17: =MAX(O8,O12)-MIN(O8,O12) -> 0
B19: R*D4=UCLR | O19: =O16*3.27 -> 0
B20: R*D3=LCLR | O20: =O16*0 -> 0
B22: Gage Repeatability and Reproducibility Report
E23: =G4 -> ICP- MS 金屬 R-R測試 | I23: Gage Nane | K23: ASSAY R&R | N23: Date: | O23: ='METAL RAW DATA'!E2 -> 0
B24: Part No.and Name | I24: Gage No | N24: performed by
B25: Characteristics: | I25: Gage Type: | K25: METAL
B26: Specification:
E27: R= | F27: =O16 -> 0 | G27: x diff= | H27: =O17 -> 0 | I27: Rp= | K27: =O15 -> 0
B28: From date sheet: | I28: %Total Variation(TV)
E29: n= | F29: 2 | G29: test= | H29: 10
B30: Measurement Unit Analysis
B31: Repeatability-Equipment Variation(EV) | D31: EV = | E31: R × K1 | G31: Trials | H31: K1 | I31: %EV=100(EV/TV)
D32: =F27 -> 0 | E32: * | F32: =H32 -> 0.8862 | G32: 2 | H32: 0.8862 | I32: =100*(D33/D51) -> #DIV/0! | K32: %
B33: = | D33: =D32*F32 -> 0 | G33: 3 | H33: 0.5908
B34: 重複性-設備變異
B35: Reproducibity-Appraiser Variation(AV) | D35: AV= | E35: √【（Xdiff X K2）2-（EV2/nr）】 | I35: %AV=100(AV/TV)
I36: =100*(E37/D51) -> #DIV/0! | K36: %
D37: = | E37: =D59 -> 0
F38: Appraisers | G38: 2 | H38: 3 | I38: n=number of parts
F39: k2 | G39: 0.7071 | H39: 0.5231 | I39: r=number of trials
B40: 再現性-評價者變異
B41: Repeatability& Reproducibility(R&R) | D41: R&R= | E41: √(EV2+AV2 | I41: %R&R=100(R&R/TV)
D42: = | I42: =100*(E43/D51) -> #DIV/0! | K42: %
B43: 重複性及再現性 | D43: = | E43: =D63 -> 0 | I43: =100*(E43/F67) -> 0 | K43: %
...

Sheet Co
F1: ='METAL RAW DATA'!B3 -> ICP- MS 金屬 R-R測試
B3: ITEM | C3: ='METAL RAW DATA'!B17 -> Co | F3: DATE | G3: ='METAL RAW DATA'!E2 -> 0 | L3: NDC= | M3: =1.41*(D47/D63) -> #DIV/0!
F4: 儀 器 | G4: ='METAL RAW DATA'!B3 -> ICP- MS 金屬 R-R測試
D5: 1 | E5: 2 | F5: 3 | G5: 4 | H5: 5 | I5: 6 | J5: 7 | K5: 8 | L5: 9 | M5: 10 | O5: AVE
B6: A | D6: ='METAL RAW DATA'!C17 -> 0 | E6: ='METAL RAW DATA'!D17 -> 0 | F6: ='METAL RAW DATA'!E17 -> 0 | G6: ='METAL RAW DATA'!F17 -> 0 | H6: ='METAL RAW DATA'!G17 -> 0 | I6: ='METAL RAW DATA'!H17 -> 0 | J6: ='METAL RAW DATA'!I17 -> 0 | K6: ='METAL RAW DATA'!J17 -> 0 | ... M6: ='METAL RAW DATA'!L17 -> 0 | O6: =SUM(D6:M6)/10 -> 0
B7: A | D7: ='METAL RAW DATA'!M17 -> 0 | E7: ='METAL RAW DATA'!N17 -> 0 | F7: ='METAL RAW DATA'!O17 -> 0 | G7: ='METAL RAW DATA'!P17 -> 0 | H7: ='METAL RAW DATA'!Q17 -> 0 | I7: ='METAL RAW DATA'!R17 -> 0 | J7: ='METAL RAW DATA'!S17 -> 0 | K7: ='METAL RAW DATA'!T17 -> 0 | ... M7: ='METAL RAW DATA'!V17 -> 0 | O7: =SUM(D7:M7)/10 -> 0
B8: AVE | D8: =AVERAGE(D6:D7) -> 0 | E8: =AVERAGE(E6:E7) -> 0 | F8: =AVERAGE(F6:F7) -> 0 | G8: =AVERAGE(G6:G7) -> 0 | H8: =AVERAGE(H6:H7) -> 0 | I8: =AVERAGE(I6:I7) -> 0 | J8: =AVERAGE(J6:J7) -> 0 | K8: =AVERAGE(K6:K7) -> 0 | ... M8: =AVERAGE(M6:M7) -> 0 | N8: Xa | O8: =AVERAGE(O6:O7) -> 0
B9: RANGE | D9: =MAX(D6:D7)-MIN(D6:D7) -> 0 | E9: =MAX(E6:E7)-MIN(E6:E7) -> 0 | F9: =MAX(F6:F7)-MIN(F6:F7) -> 0 | G9: =MAX(G6:G7)-MIN(G6:G7) -> 0 | H9: =MAX(H6:H7)-MIN(H6:H7) -> 0 | I9: =MAX(I6:I7)-MIN(I6:I7) -> 0 | J9: =MAX(J6:J7)-MIN(J6:J7) -> 0 | K9: =MAX(K6:K7)-MIN(K6:K7) -> 0 | ... M9: =MAX(M6:M7)-MIN(M6:M7) -> 0 | N9: Ra | O9: =SUM(D9:M9)/10 -> 0
B10: B | D10: ='METAL RAW DATA'!W17 -> 0 | E10: ='METAL RAW DATA'!X17 -> 0 | F10: ='METAL RAW DATA'!Y17 -> 0 | G10: ='METAL RAW DATA'!Z17 -> 0 | H10: ='METAL RAW DATA'!AA17 -> 0 | I10: ='METAL RAW DATA'!AB17 -> 0 | J10: ='METAL RAW DATA'!AC17 -> 0 | K10: ='METAL RAW DATA'!AD17 -> 0 | ... M10: ='METAL RAW DATA'!AF17 -> 0 | O10: =SUM(D10:M10)/10 -> 0
B11: B | D11: ='METAL RAW DATA'!AG17 -> 0 | E11: ='METAL RAW DATA'!AH17 -> 0 | F11: ='METAL RAW DATA'!AI17 -> 0 | G11: ='METAL RAW DATA'!AJ17 -> 0 | H11: ='METAL RAW DATA'!AK17 -> 0 | I11: ='METAL RAW DATA'!AL17 -> 0 | J11: ='METAL RAW DATA'!AM17 -> 0 | K11: ='METAL RAW DATA'!AN17 -> 0 | ... M11: ='METAL RAW DATA'!AP17 -> 0 | O11: =SUM(D11:M11)/10 -> 0
B12: AVE | D12: =AVERAGE(D10:D11) -> 0 | E12: =AVERAGE(E10:E11) -> 0 | F12: =AVERAGE(F10:F11) -> 0 | G12: =AVERAGE(G10:G11) -> 0 | H12: =AVERAGE(H10:H11) -> 0 | I12: =AVERAGE(I10:I11) -> 0 | J12: =AVERAGE(J10:J11) -> 0 | K12: =AVERAGE(K10:K11) -> 0 | ... M12: =AVERAGE(M10:M11) -> 0 | N12: Xb | O12: =SUM(D12:M12)/10 -> 0
B13: RANGE | D13: =MAX(D10:D11)-MIN(D10:D11) -> 0 | E13: =MAX(E10:E11)-MIN(E10:E11) -> 0 | F13: =MAX(F10:F11)-MIN(F10:F11) -> 0 | G13: =MAX(G10:G11)-MIN(G10:G11) -> 0 | H13: =MAX(H10:H11)-MIN(H10:H11) -> 0 | I13: =MAX(I10:I11)-MIN(I10:I11) -> 0 | J13: =MAX(J10:J11)-MIN(J10:J11) -> 0 | K13: =MAX(K10:K11)-MIN(K10:K11) -> 0 | ... M13: =MAX(M10:M11)-MIN(M10:M11) -> 0 | N13: Rb | O13: =SUM(D13:M13)/10 -> 0
B14: PART | N14: X | O14: =(O12+O8)/2 -> 0
B15: AVE | C15: Xp | D15: =(D12+D8)/2 -> 0 | E15: =(E12+E8)/2 -> 0 | F15: =(F12+F8)/2 -> 0 | G15: =(G12+G8)/2 -> 0 | H15: =(H12+H8)/2 -> 0 | I15: =(I12+I8)/2 -> 0 | J15: =(J12+J8)/2 -> 0 | K15: =(K12+K8)/2 -> 0 | ... M15: =(M12+M8)/2 -> 0 | N15: Rp | O15: =MAX(A15:M15)-MIN(A15:M15) -> 0
B16: R=(Ra+Rb)/2 | N16: R | O16: =(O13+O9)/2 -> 0
B17: Max X-MaxB=X diff | N17: X diff | O17: =MAX(O8,O12)-MIN(O8,O12) -> 0
B19: R*D4=UCLR | O19: =O16*3.27 -> 0
B20: R*D3=LCLR | O20: =O16*0 -> 0
B22: Gage Repeatability and Reproducibility Report
E23: =G4 -> ICP- MS 金屬 R-R測試 | I23: Gage Nane | K23: ASSAY R&R | N23: Date: | O23: ='METAL RAW DATA'!E2 -> 0
B24: Part No.and Name | I24: Gage No | N24: performed by
B25: Characteristics: | I25: Gage Type: | K25: METAL
B26: Specification:
E27: R= | F27: =O16 -> 0 | G27: x diff= | H27: =O17 -> 0 | I27: Rp= | K27: =O15 -> 0
B28: From date sheet: | I28: %Total Variation(TV)
E29: n= | F29: 2 | G29: test= | H29: 10
B30: Measurement Unit Analysis
B31: Repeatability-Equipment Variation(EV) | D31: EV = | E31: R × K1 | G31: Trials | H31: K1 | I31: %EV=100(EV/TV)
D32: =F27 -> 0 | E32: * | F32: =H32 -> 0.8862 | G32: 2 | H32: 0.8862 | I32: =100*(D33/D51) -> #DIV/0! | K32: %
B33: = | D33: =D32*F32 -> 0 | G33: 3 | H33: 0.5908
B34: 重複性-設備變異
B35: Reproducibity-Appraiser Variation(AV) | D35: AV= | E35: √【（Xdiff X K2）2-（EV2/nr）】 | I35: %AV=100(AV/TV)
I36: =100*(E37/D51) -> #DIV/0! | K36: %
D37: = | E37: =D59 -> 0
F38: Appraisers | G38: 2 | H38: 3 | I38: n=number of parts
F39: k2 | G39: 0.7071 | H39: 0.5231 | I39: r=number of trials
B40: 再現性-評價者變異
B41: Repeatability& Reproducibility(R&R) | D41: R&R= | E41: √(EV2+AV2 | I41: %R&R=100(R&R/TV)
D42: = | I42: =100*(E43/D51) -> #DIV/0! | K42: %
B43: 重複性及再現性 | D43: = | E43: =D63 -> 0 | I43: =100*(E43/F67) -> 0 | K43: %
...

Sheet Cu
F1: ='METAL RAW DATA'!B3 -> ICP- MS 金屬 R-R測試
B3: ITEM | C3: ='METAL RAW DATA'!B18 -> Cu | F3: DATE | G3: ='METAL RAW DATA'!E2 -> 0 | L3: NDC= | M3: =1.41*(D47/D63) -> #DIV/0!
F4: 儀 器 | G4: ='METAL RAW DATA'!B3 -> ICP- MS 金屬 R-R測試
D5: 1 | E5: 2 | F5: 3 | G5: 4 | H5: 5 | I5: 6 | J5: 7 | K5: 8 | L5: 9 | M5: 10 | O5: AVE
B6: A | D6: ='METAL RAW DATA'!C18 -> 0 | E6: ='METAL RAW DATA'!D18 -> 0 | F6: ='METAL RAW DATA'!E18 -> 0 | G6: ='METAL RAW DATA'!F18 -> 0 | H6: ='METAL RAW DATA'!G18 -> 0 | I6: ='METAL RAW DATA'!H18 -> 0 | J6: ='METAL RAW DATA'!I18 -> 0 | K6: ='METAL RAW DATA'!J18 -> 0 | ... M6: ='METAL RAW DATA'!L18 -> 0 | O6: =SUM(D6:M6)/10 -> 0
